2021-01-27 08:54:34,237 -  nornir.core -     INFO -        run() - Running task 'render_config' with args {} on 2 hosts
2021-01-27 08:54:34,245 - nornir.core.task -    ERROR -      start() - Host 'nxos2': task 'template_file' failed with traceback:
Traceback (most recent call last):
  File "/home/bradfernan/VENV/py3_venv/lib64/python3.7/site-packages/nornir/core/task.py", line 85, in start
    r = self.task(self, **self.params)
  File "/home/bradfernan/VENV/py3_venv/lib64/python3.7/site-packages/nornir/plugins/tasks/text/template_file.py", line 35, in template_file
    **kwargs
  File "/home/bradfernan/VENV/py3_venv/lib64/python3.7/site-packages/nornir/core/helpers/jinja_helper.py", line 18, in render_from_file
    return t.render(**kwargs)
  File "/home/bradfernan/VENV/py3_venv/lib64/python3.7/site-packages/jinja2/environment.py", line 1090, in render
    self.environment.handle_exception()
  File "/home/bradfernan/VENV/py3_venv/lib64/python3.7/site-packages/jinja2/environment.py", line 832, in handle_exception
    reraise(*rewrite_traceback_stack(source=source))
  File "/home/bradfernan/VENV/py3_venv/lib64/python3.7/site-packages/jinja2/_compat.py", line 28, in reraise
    raise value.with_traceback(tb)
  File "./loopback_int.j2", line 1, in top-level template code
    {%- for data in loopbacks %}
jinja2.exceptions.UndefinedError: 'loopbacks' is undefined

