2020-12-21 22:04:48,326 -  nornir.core -     INFO -        run() - Running task 'netmiko_send_command' with args {'command_string': 'show ip int brief'} on 2 hosts
2020-12-21 22:35:20,374 -  nornir.core -     INFO -        run() - Running task 'netmiko_send_command' with args {'command_string': 'show ip int brief'} on 2 hosts
2020-12-21 22:35:23,140 - nornir.core.task -    ERROR -      start() - Host 'cisco3': task 'netmiko_send_command' failed with traceback:
Traceback (most recent call last):
  File "/home/bradfernan/VENV/py3_venv/lib64/python3.7/site-packages/netmiko/base_connection.py", line 915, in establish_connection
    self.remote_conn_pre.connect(**ssh_connect_params)
  File "/home/bradfernan/VENV/py3_venv/lib64/python3.7/site-packages/paramiko/client.py", line 446, in connect
    passphrase,
  File "/home/bradfernan/VENV/py3_venv/lib64/python3.7/site-packages/paramiko/client.py", line 764, in _auth
    raise saved_exception
  File "/home/bradfernan/VENV/py3_venv/lib64/python3.7/site-packages/paramiko/client.py", line 751, in _auth
    self._transport.auth_password(username, password)
  File "/home/bradfernan/VENV/py3_venv/lib64/python3.7/site-packages/paramiko/transport.py", line 1509, in auth_password
    return self.auth_handler.wait_for_response(my_event)
  File "/home/bradfernan/VENV/py3_venv/lib64/python3.7/site-packages/paramiko/auth_handler.py", line 250, in wait_for_response
    raise e
paramiko.ssh_exception.AuthenticationException: Authentication failed.

During handling of the above exception, another exception occurred:

Traceback (most recent call last):
  File "/home/bradfernan/VENV/py3_venv/lib64/python3.7/site-packages/nornir/core/task.py", line 85, in start
    r = self.task(self, **self.params)
  File "/home/bradfernan/VENV/py3_venv/lib64/python3.7/site-packages/nornir/plugins/tasks/networking/netmiko_send_command.py", line 26, in netmiko_send_command
    net_connect = task.host.get_connection("netmiko", task.nornir.config)
  File "/home/bradfernan/VENV/py3_venv/lib64/python3.7/site-packages/nornir/core/inventory.py", line 302, in get_connection
    extras=conn.extras,
  File "/home/bradfernan/VENV/py3_venv/lib64/python3.7/site-packages/nornir/core/inventory.py", line 352, in open_connection
    configuration=configuration,
  File "/home/bradfernan/VENV/py3_venv/lib64/python3.7/site-packages/nornir/plugins/connections/netmiko.py", line 58, in open
    self.connection = ConnectHandler(**parameters)
  File "/home/bradfernan/VENV/py3_venv/lib64/python3.7/site-packages/netmiko/ssh_dispatcher.py", line 298, in ConnectHandler
    return ConnectionClass(*args, **kwargs)
  File "/home/bradfernan/VENV/py3_venv/lib64/python3.7/site-packages/netmiko/base_connection.py", line 341, in __init__
    self._open()
  File "/home/bradfernan/VENV/py3_venv/lib64/python3.7/site-packages/netmiko/base_connection.py", line 346, in _open
    self.establish_connection()
  File "/home/bradfernan/VENV/py3_venv/lib64/python3.7/site-packages/netmiko/base_connection.py", line 944, in establish_connection
    raise NetmikoAuthenticationException(msg)
netmiko.ssh_exception.NetmikoAuthenticationException: Authentication failure: unable to connect cisco_ios cisco3.lasthop.io:22
Authentication failed.

2020-12-21 22:36:13,204 -  nornir.core -     INFO -        run() - Running task 'netmiko_send_command' with args {'command_string': 'show ip int brief'} on 2 hosts
2020-12-21 22:36:15,944 - nornir.core.task -    ERROR -      start() - Host 'cisco3': task 'netmiko_send_command' failed with traceback:
Traceback (most recent call last):
  File "/home/bradfernan/VENV/py3_venv/lib64/python3.7/site-packages/netmiko/base_connection.py", line 915, in establish_connection
    self.remote_conn_pre.connect(**ssh_connect_params)
  File "/home/bradfernan/VENV/py3_venv/lib64/python3.7/site-packages/paramiko/client.py", line 446, in connect
    passphrase,
  File "/home/bradfernan/VENV/py3_venv/lib64/python3.7/site-packages/paramiko/client.py", line 764, in _auth
    raise saved_exception
  File "/home/bradfernan/VENV/py3_venv/lib64/python3.7/site-packages/paramiko/client.py", line 751, in _auth
    self._transport.auth_password(username, password)
  File "/home/bradfernan/VENV/py3_venv/lib64/python3.7/site-packages/paramiko/transport.py", line 1509, in auth_password
    return self.auth_handler.wait_for_response(my_event)
  File "/home/bradfernan/VENV/py3_venv/lib64/python3.7/site-packages/paramiko/auth_handler.py", line 250, in wait_for_response
    raise e
paramiko.ssh_exception.AuthenticationException: Authentication failed.

During handling of the above exception, another exception occurred:

Traceback (most recent call last):
  File "/home/bradfernan/VENV/py3_venv/lib64/python3.7/site-packages/nornir/core/task.py", line 85, in start
    r = self.task(self, **self.params)
  File "/home/bradfernan/VENV/py3_venv/lib64/python3.7/site-packages/nornir/plugins/tasks/networking/netmiko_send_command.py", line 26, in netmiko_send_command
    net_connect = task.host.get_connection("netmiko", task.nornir.config)
  File "/home/bradfernan/VENV/py3_venv/lib64/python3.7/site-packages/nornir/core/inventory.py", line 302, in get_connection
    extras=conn.extras,
  File "/home/bradfernan/VENV/py3_venv/lib64/python3.7/site-packages/nornir/core/inventory.py", line 352, in open_connection
    configuration=configuration,
  File "/home/bradfernan/VENV/py3_venv/lib64/python3.7/site-packages/nornir/plugins/connections/netmiko.py", line 58, in open
    self.connection = ConnectHandler(**parameters)
  File "/home/bradfernan/VENV/py3_venv/lib64/python3.7/site-packages/netmiko/ssh_dispatcher.py", line 298, in ConnectHandler
    return ConnectionClass(*args, **kwargs)
  File "/home/bradfernan/VENV/py3_venv/lib64/python3.7/site-packages/netmiko/base_connection.py", line 341, in __init__
    self._open()
  File "/home/bradfernan/VENV/py3_venv/lib64/python3.7/site-packages/netmiko/base_connection.py", line 346, in _open
    self.establish_connection()
  File "/home/bradfernan/VENV/py3_venv/lib64/python3.7/site-packages/netmiko/base_connection.py", line 944, in establish_connection
    raise NetmikoAuthenticationException(msg)
netmiko.ssh_exception.NetmikoAuthenticationException: Authentication failure: unable to connect cisco_ios cisco3.lasthop.io:22
Authentication failed.

2020-12-21 22:36:54,718 -  nornir.core -     INFO -        run() - Running task 'netmiko_send_command' with args {'command_string': 'show ip int brief'} on 2 hosts
2020-12-21 22:36:57,459 - nornir.core.task -    ERROR -      start() - Host 'cisco3': task 'netmiko_send_command' failed with traceback:
Traceback (most recent call last):
  File "/home/bradfernan/VENV/py3_venv/lib64/python3.7/site-packages/netmiko/base_connection.py", line 915, in establish_connection
    self.remote_conn_pre.connect(**ssh_connect_params)
  File "/home/bradfernan/VENV/py3_venv/lib64/python3.7/site-packages/paramiko/client.py", line 446, in connect
    passphrase,
  File "/home/bradfernan/VENV/py3_venv/lib64/python3.7/site-packages/paramiko/client.py", line 764, in _auth
    raise saved_exception
  File "/home/bradfernan/VENV/py3_venv/lib64/python3.7/site-packages/paramiko/client.py", line 751, in _auth
    self._transport.auth_password(username, password)
  File "/home/bradfernan/VENV/py3_venv/lib64/python3.7/site-packages/paramiko/transport.py", line 1509, in auth_password
    return self.auth_handler.wait_for_response(my_event)
  File "/home/bradfernan/VENV/py3_venv/lib64/python3.7/site-packages/paramiko/auth_handler.py", line 250, in wait_for_response
    raise e
paramiko.ssh_exception.AuthenticationException: Authentication failed.

During handling of the above exception, another exception occurred:

Traceback (most recent call last):
  File "/home/bradfernan/VENV/py3_venv/lib64/python3.7/site-packages/nornir/core/task.py", line 85, in start
    r = self.task(self, **self.params)
  File "/home/bradfernan/VENV/py3_venv/lib64/python3.7/site-packages/nornir/plugins/tasks/networking/netmiko_send_command.py", line 26, in netmiko_send_command
    net_connect = task.host.get_connection("netmiko", task.nornir.config)
  File "/home/bradfernan/VENV/py3_venv/lib64/python3.7/site-packages/nornir/core/inventory.py", line 302, in get_connection
    extras=conn.extras,
  File "/home/bradfernan/VENV/py3_venv/lib64/python3.7/site-packages/nornir/core/inventory.py", line 352, in open_connection
    configuration=configuration,
  File "/home/bradfernan/VENV/py3_venv/lib64/python3.7/site-packages/nornir/plugins/connections/netmiko.py", line 58, in open
    self.connection = ConnectHandler(**parameters)
  File "/home/bradfernan/VENV/py3_venv/lib64/python3.7/site-packages/netmiko/ssh_dispatcher.py", line 298, in ConnectHandler
    return ConnectionClass(*args, **kwargs)
  File "/home/bradfernan/VENV/py3_venv/lib64/python3.7/site-packages/netmiko/base_connection.py", line 341, in __init__
    self._open()
  File "/home/bradfernan/VENV/py3_venv/lib64/python3.7/site-packages/netmiko/base_connection.py", line 346, in _open
    self.establish_connection()
  File "/home/bradfernan/VENV/py3_venv/lib64/python3.7/site-packages/netmiko/base_connection.py", line 944, in establish_connection
    raise NetmikoAuthenticationException(msg)
netmiko.ssh_exception.NetmikoAuthenticationException: Authentication failure: unable to connect cisco_ios cisco3.lasthop.io:22
Authentication failed.

2020-12-22 06:56:21,092 -  nornir.core -     INFO -        run() - Running task 'netmiko_send_command' with args {'command_string': 'show ip int brief'} on 2 hosts
2020-12-22 07:09:30,414 -  nornir.core -     INFO -        run() - Running task 'netmiko_send_command' with args {'command_string': 'show ip int brief'} on 2 hosts
2020-12-22 07:09:33,168 - nornir.core.task -    ERROR -      start() - Host 'cisco3': task 'netmiko_send_command' failed with traceback:
Traceback (most recent call last):
  File "/home/bradfernan/VENV/py3_venv/lib64/python3.7/site-packages/netmiko/base_connection.py", line 915, in establish_connection
    self.remote_conn_pre.connect(**ssh_connect_params)
  File "/home/bradfernan/VENV/py3_venv/lib64/python3.7/site-packages/paramiko/client.py", line 446, in connect
    passphrase,
  File "/home/bradfernan/VENV/py3_venv/lib64/python3.7/site-packages/paramiko/client.py", line 764, in _auth
    raise saved_exception
  File "/home/bradfernan/VENV/py3_venv/lib64/python3.7/site-packages/paramiko/client.py", line 751, in _auth
    self._transport.auth_password(username, password)
  File "/home/bradfernan/VENV/py3_venv/lib64/python3.7/site-packages/paramiko/transport.py", line 1509, in auth_password
    return self.auth_handler.wait_for_response(my_event)
  File "/home/bradfernan/VENV/py3_venv/lib64/python3.7/site-packages/paramiko/auth_handler.py", line 250, in wait_for_response
    raise e
paramiko.ssh_exception.AuthenticationException: Authentication failed.

During handling of the above exception, another exception occurred:

Traceback (most recent call last):
  File "/home/bradfernan/VENV/py3_venv/lib64/python3.7/site-packages/nornir/core/task.py", line 85, in start
    r = self.task(self, **self.params)
  File "/home/bradfernan/VENV/py3_venv/lib64/python3.7/site-packages/nornir/plugins/tasks/networking/netmiko_send_command.py", line 26, in netmiko_send_command
    net_connect = task.host.get_connection("netmiko", task.nornir.config)
  File "/home/bradfernan/VENV/py3_venv/lib64/python3.7/site-packages/nornir/core/inventory.py", line 302, in get_connection
    extras=conn.extras,
  File "/home/bradfernan/VENV/py3_venv/lib64/python3.7/site-packages/nornir/core/inventory.py", line 352, in open_connection
    configuration=configuration,
  File "/home/bradfernan/VENV/py3_venv/lib64/python3.7/site-packages/nornir/plugins/connections/netmiko.py", line 58, in open
    self.connection = ConnectHandler(**parameters)
  File "/home/bradfernan/VENV/py3_venv/lib64/python3.7/site-packages/netmiko/ssh_dispatcher.py", line 298, in ConnectHandler
    return ConnectionClass(*args, **kwargs)
  File "/home/bradfernan/VENV/py3_venv/lib64/python3.7/site-packages/netmiko/base_connection.py", line 341, in __init__
    self._open()
  File "/home/bradfernan/VENV/py3_venv/lib64/python3.7/site-packages/netmiko/base_connection.py", line 346, in _open
    self.establish_connection()
  File "/home/bradfernan/VENV/py3_venv/lib64/python3.7/site-packages/netmiko/base_connection.py", line 944, in establish_connection
    raise NetmikoAuthenticationException(msg)
netmiko.ssh_exception.NetmikoAuthenticationException: Authentication failure: unable to connect cisco_ios cisco3.lasthop.io:22
Authentication failed.

2020-12-22 07:10:25,994 -  nornir.core -     INFO -        run() - Running task 'netmiko_send_command' with args {'command_string': 'show ip int brief'} on 2 hosts
2020-12-22 07:10:28,738 - nornir.core.task -    ERROR -      start() - Host 'cisco3': task 'netmiko_send_command' failed with traceback:
Traceback (most recent call last):
  File "/home/bradfernan/VENV/py3_venv/lib64/python3.7/site-packages/netmiko/base_connection.py", line 915, in establish_connection
    self.remote_conn_pre.connect(**ssh_connect_params)
  File "/home/bradfernan/VENV/py3_venv/lib64/python3.7/site-packages/paramiko/client.py", line 446, in connect
    passphrase,
  File "/home/bradfernan/VENV/py3_venv/lib64/python3.7/site-packages/paramiko/client.py", line 764, in _auth
    raise saved_exception
  File "/home/bradfernan/VENV/py3_venv/lib64/python3.7/site-packages/paramiko/client.py", line 751, in _auth
    self._transport.auth_password(username, password)
  File "/home/bradfernan/VENV/py3_venv/lib64/python3.7/site-packages/paramiko/transport.py", line 1509, in auth_password
    return self.auth_handler.wait_for_response(my_event)
  File "/home/bradfernan/VENV/py3_venv/lib64/python3.7/site-packages/paramiko/auth_handler.py", line 250, in wait_for_response
    raise e
paramiko.ssh_exception.AuthenticationException: Authentication failed.

During handling of the above exception, another exception occurred:

Traceback (most recent call last):
  File "/home/bradfernan/VENV/py3_venv/lib64/python3.7/site-packages/nornir/core/task.py", line 85, in start
    r = self.task(self, **self.params)
  File "/home/bradfernan/VENV/py3_venv/lib64/python3.7/site-packages/nornir/plugins/tasks/networking/netmiko_send_command.py", line 26, in netmiko_send_command
    net_connect = task.host.get_connection("netmiko", task.nornir.config)
  File "/home/bradfernan/VENV/py3_venv/lib64/python3.7/site-packages/nornir/core/inventory.py", line 302, in get_connection
    extras=conn.extras,
  File "/home/bradfernan/VENV/py3_venv/lib64/python3.7/site-packages/nornir/core/inventory.py", line 352, in open_connection
    configuration=configuration,
  File "/home/bradfernan/VENV/py3_venv/lib64/python3.7/site-packages/nornir/plugins/connections/netmiko.py", line 58, in open
    self.connection = ConnectHandler(**parameters)
  File "/home/bradfernan/VENV/py3_venv/lib64/python3.7/site-packages/netmiko/ssh_dispatcher.py", line 298, in ConnectHandler
    return ConnectionClass(*args, **kwargs)
  File "/home/bradfernan/VENV/py3_venv/lib64/python3.7/site-packages/netmiko/base_connection.py", line 341, in __init__
    self._open()
  File "/home/bradfernan/VENV/py3_venv/lib64/python3.7/site-packages/netmiko/base_connection.py", line 346, in _open
    self.establish_connection()
  File "/home/bradfernan/VENV/py3_venv/lib64/python3.7/site-packages/netmiko/base_connection.py", line 944, in establish_connection
    raise NetmikoAuthenticationException(msg)
netmiko.ssh_exception.NetmikoAuthenticationException: Authentication failure: unable to connect cisco_ios cisco3.lasthop.io:22
Authentication failed.

2020-12-22 07:11:01,494 -  nornir.core -     INFO -        run() - Running task 'netmiko_send_command' with args {'command_string': 'show ip int brief'} on 2 hosts
2020-12-22 07:11:02,861 - nornir.core.task -    ERROR -      start() - Host 'cisco3': task 'netmiko_send_command' failed with traceback:
Traceback (most recent call last):
  File "/home/bradfernan/VENV/py3_venv/lib64/python3.7/site-packages/netmiko/base_connection.py", line 915, in establish_connection
    self.remote_conn_pre.connect(**ssh_connect_params)
  File "/home/bradfernan/VENV/py3_venv/lib64/python3.7/site-packages/paramiko/client.py", line 446, in connect
    passphrase,
  File "/home/bradfernan/VENV/py3_venv/lib64/python3.7/site-packages/paramiko/client.py", line 764, in _auth
    raise saved_exception
  File "/home/bradfernan/VENV/py3_venv/lib64/python3.7/site-packages/paramiko/client.py", line 751, in _auth
    self._transport.auth_password(username, password)
  File "/home/bradfernan/VENV/py3_venv/lib64/python3.7/site-packages/paramiko/transport.py", line 1509, in auth_password
    return self.auth_handler.wait_for_response(my_event)
  File "/home/bradfernan/VENV/py3_venv/lib64/python3.7/site-packages/paramiko/auth_handler.py", line 236, in wait_for_response
    raise e
paramiko.ssh_exception.AuthenticationException: Authentication failed.

During handling of the above exception, another exception occurred:

Traceback (most recent call last):
  File "/home/bradfernan/VENV/py3_venv/lib64/python3.7/site-packages/nornir/core/task.py", line 85, in start
    r = self.task(self, **self.params)
  File "/home/bradfernan/VENV/py3_venv/lib64/python3.7/site-packages/nornir/plugins/tasks/networking/netmiko_send_command.py", line 26, in netmiko_send_command
    net_connect = task.host.get_connection("netmiko", task.nornir.config)
  File "/home/bradfernan/VENV/py3_venv/lib64/python3.7/site-packages/nornir/core/inventory.py", line 302, in get_connection
    extras=conn.extras,
  File "/home/bradfernan/VENV/py3_venv/lib64/python3.7/site-packages/nornir/core/inventory.py", line 352, in open_connection
    configuration=configuration,
  File "/home/bradfernan/VENV/py3_venv/lib64/python3.7/site-packages/nornir/plugins/connections/netmiko.py", line 58, in open
    self.connection = ConnectHandler(**parameters)
  File "/home/bradfernan/VENV/py3_venv/lib64/python3.7/site-packages/netmiko/ssh_dispatcher.py", line 298, in ConnectHandler
    return ConnectionClass(*args, **kwargs)
  File "/home/bradfernan/VENV/py3_venv/lib64/python3.7/site-packages/netmiko/base_connection.py", line 341, in __init__
    self._open()
  File "/home/bradfernan/VENV/py3_venv/lib64/python3.7/site-packages/netmiko/base_connection.py", line 346, in _open
    self.establish_connection()
  File "/home/bradfernan/VENV/py3_venv/lib64/python3.7/site-packages/netmiko/base_connection.py", line 944, in establish_connection
    raise NetmikoAuthenticationException(msg)
netmiko.ssh_exception.NetmikoAuthenticationException: Authentication failure: unable to connect cisco_ios cisco3.lasthop.io:22
Authentication failed.

2020-12-22 07:11:05,559 - nornir.core.task -    ERROR -      start() - Host 'cisco4': task 'netmiko_send_command' failed with traceback:
Traceback (most recent call last):
  File "/home/bradfernan/VENV/py3_venv/lib64/python3.7/site-packages/nornir/core/task.py", line 85, in start
    r = self.task(self, **self.params)
  File "/home/bradfernan/VENV/py3_venv/lib64/python3.7/site-packages/nornir/plugins/tasks/networking/netmiko_send_command.py", line 26, in netmiko_send_command
    net_connect = task.host.get_connection("netmiko", task.nornir.config)
  File "/home/bradfernan/VENV/py3_venv/lib64/python3.7/site-packages/nornir/core/inventory.py", line 302, in get_connection
    extras=conn.extras,
  File "/home/bradfernan/VENV/py3_venv/lib64/python3.7/site-packages/nornir/core/inventory.py", line 352, in open_connection
    configuration=configuration,
  File "/home/bradfernan/VENV/py3_venv/lib64/python3.7/site-packages/nornir/plugins/connections/netmiko.py", line 58, in open
    self.connection = ConnectHandler(**parameters)
  File "/home/bradfernan/VENV/py3_venv/lib64/python3.7/site-packages/netmiko/ssh_dispatcher.py", line 298, in ConnectHandler
    return ConnectionClass(*args, **kwargs)
  File "/home/bradfernan/VENV/py3_venv/lib64/python3.7/site-packages/netmiko/base_connection.py", line 341, in __init__
    self._open()
  File "/home/bradfernan/VENV/py3_venv/lib64/python3.7/site-packages/netmiko/base_connection.py", line 347, in _open
    self._try_session_preparation()
  File "/home/bradfernan/VENV/py3_venv/lib64/python3.7/site-packages/netmiko/base_connection.py", line 772, in _try_session_preparation
    self.session_preparation()
  File "/home/bradfernan/VENV/py3_venv/lib64/python3.7/site-packages/netmiko/cisco/cisco_ios.py", line 16, in session_preparation
    self.set_base_prompt()
  File "/home/bradfernan/VENV/py3_venv/lib64/python3.7/site-packages/netmiko/base_connection.py", line 1106, in set_base_prompt
    prompt = self.find_prompt(delay_factor=delay_factor)
  File "/home/bradfernan/VENV/py3_venv/lib64/python3.7/site-packages/netmiko/base_connection.py", line 1121, in find_prompt
    self.write_channel(self.RETURN)
  File "/home/bradfernan/VENV/py3_venv/lib64/python3.7/site-packages/netmiko/base_connection.py", line 450, in write_channel
    self._write_channel(out_data)
  File "/home/bradfernan/VENV/py3_venv/lib64/python3.7/site-packages/netmiko/base_connection.py", line 408, in _write_channel
    self.remote_conn.sendall(write_bytes(out_data, encoding=self.encoding))
  File "/home/bradfernan/VENV/py3_venv/lib64/python3.7/site-packages/paramiko/channel.py", line 846, in sendall
    sent = self.send(s)
  File "/home/bradfernan/VENV/py3_venv/lib64/python3.7/site-packages/paramiko/channel.py", line 801, in send
    return self._send(s, m)
  File "/home/bradfernan/VENV/py3_venv/lib64/python3.7/site-packages/paramiko/channel.py", line 1198, in _send
    raise socket.error("Socket is closed")
OSError: Socket is closed

2020-12-22 07:11:36,888 -  nornir.core -     INFO -        run() - Running task 'netmiko_send_command' with args {'command_string': 'show ip int brief'} on 2 hosts
2020-12-22 07:11:39,595 - nornir.core.task -    ERROR -      start() - Host 'cisco3': task 'netmiko_send_command' failed with traceback:
Traceback (most recent call last):
  File "/home/bradfernan/VENV/py3_venv/lib64/python3.7/site-packages/netmiko/base_connection.py", line 915, in establish_connection
    self.remote_conn_pre.connect(**ssh_connect_params)
  File "/home/bradfernan/VENV/py3_venv/lib64/python3.7/site-packages/paramiko/client.py", line 446, in connect
    passphrase,
  File "/home/bradfernan/VENV/py3_venv/lib64/python3.7/site-packages/paramiko/client.py", line 764, in _auth
    raise saved_exception
  File "/home/bradfernan/VENV/py3_venv/lib64/python3.7/site-packages/paramiko/client.py", line 751, in _auth
    self._transport.auth_password(username, password)
  File "/home/bradfernan/VENV/py3_venv/lib64/python3.7/site-packages/paramiko/transport.py", line 1509, in auth_password
    return self.auth_handler.wait_for_response(my_event)
  File "/home/bradfernan/VENV/py3_venv/lib64/python3.7/site-packages/paramiko/auth_handler.py", line 250, in wait_for_response
    raise e
paramiko.ssh_exception.AuthenticationException: Authentication failed.

During handling of the above exception, another exception occurred:

Traceback (most recent call last):
  File "/home/bradfernan/VENV/py3_venv/lib64/python3.7/site-packages/nornir/core/task.py", line 85, in start
    r = self.task(self, **self.params)
  File "/home/bradfernan/VENV/py3_venv/lib64/python3.7/site-packages/nornir/plugins/tasks/networking/netmiko_send_command.py", line 26, in netmiko_send_command
    net_connect = task.host.get_connection("netmiko", task.nornir.config)
  File "/home/bradfernan/VENV/py3_venv/lib64/python3.7/site-packages/nornir/core/inventory.py", line 302, in get_connection
    extras=conn.extras,
  File "/home/bradfernan/VENV/py3_venv/lib64/python3.7/site-packages/nornir/core/inventory.py", line 352, in open_connection
    configuration=configuration,
  File "/home/bradfernan/VENV/py3_venv/lib64/python3.7/site-packages/nornir/plugins/connections/netmiko.py", line 58, in open
    self.connection = ConnectHandler(**parameters)
  File "/home/bradfernan/VENV/py3_venv/lib64/python3.7/site-packages/netmiko/ssh_dispatcher.py", line 298, in ConnectHandler
    return ConnectionClass(*args, **kwargs)
  File "/home/bradfernan/VENV/py3_venv/lib64/python3.7/site-packages/netmiko/base_connection.py", line 341, in __init__
    self._open()
  File "/home/bradfernan/VENV/py3_venv/lib64/python3.7/site-packages/netmiko/base_connection.py", line 346, in _open
    self.establish_connection()
  File "/home/bradfernan/VENV/py3_venv/lib64/python3.7/site-packages/netmiko/base_connection.py", line 944, in establish_connection
    raise NetmikoAuthenticationException(msg)
netmiko.ssh_exception.NetmikoAuthenticationException: Authentication failure: unable to connect cisco_ios cisco3.lasthop.io:22
Authentication failed.

2020-12-22 07:12:16,964 -  nornir.core -     INFO -        run() - Running task 'netmiko_send_command' with args {'command_string': 'show ip int brief'} on 2 hosts
2020-12-22 07:12:19,711 - nornir.core.task -    ERROR -      start() - Host 'cisco3': task 'netmiko_send_command' failed with traceback:
Traceback (most recent call last):
  File "/home/bradfernan/VENV/py3_venv/lib64/python3.7/site-packages/netmiko/base_connection.py", line 915, in establish_connection
    self.remote_conn_pre.connect(**ssh_connect_params)
  File "/home/bradfernan/VENV/py3_venv/lib64/python3.7/site-packages/paramiko/client.py", line 446, in connect
    passphrase,
  File "/home/bradfernan/VENV/py3_venv/lib64/python3.7/site-packages/paramiko/client.py", line 764, in _auth
    raise saved_exception
  File "/home/bradfernan/VENV/py3_venv/lib64/python3.7/site-packages/paramiko/client.py", line 751, in _auth
    self._transport.auth_password(username, password)
  File "/home/bradfernan/VENV/py3_venv/lib64/python3.7/site-packages/paramiko/transport.py", line 1509, in auth_password
    return self.auth_handler.wait_for_response(my_event)
  File "/home/bradfernan/VENV/py3_venv/lib64/python3.7/site-packages/paramiko/auth_handler.py", line 250, in wait_for_response
    raise e
paramiko.ssh_exception.AuthenticationException: Authentication failed.

During handling of the above exception, another exception occurred:

Traceback (most recent call last):
  File "/home/bradfernan/VENV/py3_venv/lib64/python3.7/site-packages/nornir/core/task.py", line 85, in start
    r = self.task(self, **self.params)
  File "/home/bradfernan/VENV/py3_venv/lib64/python3.7/site-packages/nornir/plugins/tasks/networking/netmiko_send_command.py", line 26, in netmiko_send_command
    net_connect = task.host.get_connection("netmiko", task.nornir.config)
  File "/home/bradfernan/VENV/py3_venv/lib64/python3.7/site-packages/nornir/core/inventory.py", line 302, in get_connection
    extras=conn.extras,
  File "/home/bradfernan/VENV/py3_venv/lib64/python3.7/site-packages/nornir/core/inventory.py", line 352, in open_connection
    configuration=configuration,
  File "/home/bradfernan/VENV/py3_venv/lib64/python3.7/site-packages/nornir/plugins/connections/netmiko.py", line 58, in open
    self.connection = ConnectHandler(**parameters)
  File "/home/bradfernan/VENV/py3_venv/lib64/python3.7/site-packages/netmiko/ssh_dispatcher.py", line 298, in ConnectHandler
    return ConnectionClass(*args, **kwargs)
  File "/home/bradfernan/VENV/py3_venv/lib64/python3.7/site-packages/netmiko/base_connection.py", line 341, in __init__
    self._open()
  File "/home/bradfernan/VENV/py3_venv/lib64/python3.7/site-packages/netmiko/base_connection.py", line 346, in _open
    self.establish_connection()
  File "/home/bradfernan/VENV/py3_venv/lib64/python3.7/site-packages/netmiko/base_connection.py", line 944, in establish_connection
    raise NetmikoAuthenticationException(msg)
netmiko.ssh_exception.NetmikoAuthenticationException: Authentication failure: unable to connect cisco_ios cisco3.lasthop.io:22
Authentication failed.

2020-12-22 07:13:22,273 -  nornir.core -     INFO -        run() - Running task 'netmiko_send_command' with args {'command_string': 'show ip int brief'} on 2 hosts
2020-12-22 07:13:24,968 - nornir.core.task -    ERROR -      start() - Host 'cisco3': task 'netmiko_send_command' failed with traceback:
Traceback (most recent call last):
  File "/home/bradfernan/VENV/py3_venv/lib64/python3.7/site-packages/netmiko/base_connection.py", line 915, in establish_connection
    self.remote_conn_pre.connect(**ssh_connect_params)
  File "/home/bradfernan/VENV/py3_venv/lib64/python3.7/site-packages/paramiko/client.py", line 446, in connect
    passphrase,
  File "/home/bradfernan/VENV/py3_venv/lib64/python3.7/site-packages/paramiko/client.py", line 764, in _auth
    raise saved_exception
  File "/home/bradfernan/VENV/py3_venv/lib64/python3.7/site-packages/paramiko/client.py", line 751, in _auth
    self._transport.auth_password(username, password)
  File "/home/bradfernan/VENV/py3_venv/lib64/python3.7/site-packages/paramiko/transport.py", line 1509, in auth_password
    return self.auth_handler.wait_for_response(my_event)
  File "/home/bradfernan/VENV/py3_venv/lib64/python3.7/site-packages/paramiko/auth_handler.py", line 250, in wait_for_response
    raise e
paramiko.ssh_exception.AuthenticationException: Authentication failed.

During handling of the above exception, another exception occurred:

Traceback (most recent call last):
  File "/home/bradfernan/VENV/py3_venv/lib64/python3.7/site-packages/nornir/core/task.py", line 85, in start
    r = self.task(self, **self.params)
  File "/home/bradfernan/VENV/py3_venv/lib64/python3.7/site-packages/nornir/plugins/tasks/networking/netmiko_send_command.py", line 26, in netmiko_send_command
    net_connect = task.host.get_connection("netmiko", task.nornir.config)
  File "/home/bradfernan/VENV/py3_venv/lib64/python3.7/site-packages/nornir/core/inventory.py", line 302, in get_connection
    extras=conn.extras,
  File "/home/bradfernan/VENV/py3_venv/lib64/python3.7/site-packages/nornir/core/inventory.py", line 352, in open_connection
    configuration=configuration,
  File "/home/bradfernan/VENV/py3_venv/lib64/python3.7/site-packages/nornir/plugins/connections/netmiko.py", line 58, in open
    self.connection = ConnectHandler(**parameters)
  File "/home/bradfernan/VENV/py3_venv/lib64/python3.7/site-packages/netmiko/ssh_dispatcher.py", line 298, in ConnectHandler
    return ConnectionClass(*args, **kwargs)
  File "/home/bradfernan/VENV/py3_venv/lib64/python3.7/site-packages/netmiko/base_connection.py", line 341, in __init__
    self._open()
  File "/home/bradfernan/VENV/py3_venv/lib64/python3.7/site-packages/netmiko/base_connection.py", line 346, in _open
    self.establish_connection()
  File "/home/bradfernan/VENV/py3_venv/lib64/python3.7/site-packages/netmiko/base_connection.py", line 944, in establish_connection
    raise NetmikoAuthenticationException(msg)
netmiko.ssh_exception.NetmikoAuthenticationException: Authentication failure: unable to connect cisco_ios cisco3.lasthop.io:22
Authentication failed.

2020-12-22 07:18:17,304 -  nornir.core -     INFO -        run() - Running task 'netmiko_send_command' with args {'command_string': 'show ip int brief'} on 2 hosts
2020-12-22 07:18:20,016 - nornir.core.task -    ERROR -      start() - Host 'cisco3': task 'netmiko_send_command' failed with traceback:
Traceback (most recent call last):
  File "/home/bradfernan/VENV/py3_venv/lib64/python3.7/site-packages/netmiko/base_connection.py", line 915, in establish_connection
    self.remote_conn_pre.connect(**ssh_connect_params)
  File "/home/bradfernan/VENV/py3_venv/lib64/python3.7/site-packages/paramiko/client.py", line 446, in connect
    passphrase,
  File "/home/bradfernan/VENV/py3_venv/lib64/python3.7/site-packages/paramiko/client.py", line 764, in _auth
    raise saved_exception
  File "/home/bradfernan/VENV/py3_venv/lib64/python3.7/site-packages/paramiko/client.py", line 751, in _auth
    self._transport.auth_password(username, password)
  File "/home/bradfernan/VENV/py3_venv/lib64/python3.7/site-packages/paramiko/transport.py", line 1509, in auth_password
    return self.auth_handler.wait_for_response(my_event)
  File "/home/bradfernan/VENV/py3_venv/lib64/python3.7/site-packages/paramiko/auth_handler.py", line 250, in wait_for_response
    raise e
paramiko.ssh_exception.AuthenticationException: Authentication failed.

During handling of the above exception, another exception occurred:

Traceback (most recent call last):
  File "/home/bradfernan/VENV/py3_venv/lib64/python3.7/site-packages/nornir/core/task.py", line 85, in start
    r = self.task(self, **self.params)
  File "/home/bradfernan/VENV/py3_venv/lib64/python3.7/site-packages/nornir/plugins/tasks/networking/netmiko_send_command.py", line 26, in netmiko_send_command
    net_connect = task.host.get_connection("netmiko", task.nornir.config)
  File "/home/bradfernan/VENV/py3_venv/lib64/python3.7/site-packages/nornir/core/inventory.py", line 302, in get_connection
    extras=conn.extras,
  File "/home/bradfernan/VENV/py3_venv/lib64/python3.7/site-packages/nornir/core/inventory.py", line 352, in open_connection
    configuration=configuration,
  File "/home/bradfernan/VENV/py3_venv/lib64/python3.7/site-packages/nornir/plugins/connections/netmiko.py", line 58, in open
    self.connection = ConnectHandler(**parameters)
  File "/home/bradfernan/VENV/py3_venv/lib64/python3.7/site-packages/netmiko/ssh_dispatcher.py", line 298, in ConnectHandler
    return ConnectionClass(*args, **kwargs)
  File "/home/bradfernan/VENV/py3_venv/lib64/python3.7/site-packages/netmiko/base_connection.py", line 341, in __init__
    self._open()
  File "/home/bradfernan/VENV/py3_venv/lib64/python3.7/site-packages/netmiko/base_connection.py", line 346, in _open
    self.establish_connection()
  File "/home/bradfernan/VENV/py3_venv/lib64/python3.7/site-packages/netmiko/base_connection.py", line 944, in establish_connection
    raise NetmikoAuthenticationException(msg)
netmiko.ssh_exception.NetmikoAuthenticationException: Authentication failure: unable to connect cisco_ios cisco3.lasthop.io:22
Authentication failed.

2020-12-22 07:18:57,533 -  nornir.core -     INFO -        run() - Running task 'netmiko_send_command' with args {'command_string': 'show ip int brief'} on 2 hosts
2020-12-22 07:19:00,276 - nornir.core.task -    ERROR -      start() - Host 'cisco3': task 'netmiko_send_command' failed with traceback:
Traceback (most recent call last):
  File "/home/bradfernan/VENV/py3_venv/lib64/python3.7/site-packages/netmiko/base_connection.py", line 915, in establish_connection
    self.remote_conn_pre.connect(**ssh_connect_params)
  File "/home/bradfernan/VENV/py3_venv/lib64/python3.7/site-packages/paramiko/client.py", line 446, in connect
    passphrase,
  File "/home/bradfernan/VENV/py3_venv/lib64/python3.7/site-packages/paramiko/client.py", line 764, in _auth
    raise saved_exception
  File "/home/bradfernan/VENV/py3_venv/lib64/python3.7/site-packages/paramiko/client.py", line 751, in _auth
    self._transport.auth_password(username, password)
  File "/home/bradfernan/VENV/py3_venv/lib64/python3.7/site-packages/paramiko/transport.py", line 1509, in auth_password
    return self.auth_handler.wait_for_response(my_event)
  File "/home/bradfernan/VENV/py3_venv/lib64/python3.7/site-packages/paramiko/auth_handler.py", line 250, in wait_for_response
    raise e
paramiko.ssh_exception.AuthenticationException: Authentication failed.

During handling of the above exception, another exception occurred:

Traceback (most recent call last):
  File "/home/bradfernan/VENV/py3_venv/lib64/python3.7/site-packages/nornir/core/task.py", line 85, in start
    r = self.task(self, **self.params)
  File "/home/bradfernan/VENV/py3_venv/lib64/python3.7/site-packages/nornir/plugins/tasks/networking/netmiko_send_command.py", line 26, in netmiko_send_command
    net_connect = task.host.get_connection("netmiko", task.nornir.config)
  File "/home/bradfernan/VENV/py3_venv/lib64/python3.7/site-packages/nornir/core/inventory.py", line 302, in get_connection
    extras=conn.extras,
  File "/home/bradfernan/VENV/py3_venv/lib64/python3.7/site-packages/nornir/core/inventory.py", line 352, in open_connection
    configuration=configuration,
  File "/home/bradfernan/VENV/py3_venv/lib64/python3.7/site-packages/nornir/plugins/connections/netmiko.py", line 58, in open
    self.connection = ConnectHandler(**parameters)
  File "/home/bradfernan/VENV/py3_venv/lib64/python3.7/site-packages/netmiko/ssh_dispatcher.py", line 298, in ConnectHandler
    return ConnectionClass(*args, **kwargs)
  File "/home/bradfernan/VENV/py3_venv/lib64/python3.7/site-packages/netmiko/base_connection.py", line 341, in __init__
    self._open()
  File "/home/bradfernan/VENV/py3_venv/lib64/python3.7/site-packages/netmiko/base_connection.py", line 346, in _open
    self.establish_connection()
  File "/home/bradfernan/VENV/py3_venv/lib64/python3.7/site-packages/netmiko/base_connection.py", line 944, in establish_connection
    raise NetmikoAuthenticationException(msg)
netmiko.ssh_exception.NetmikoAuthenticationException: Authentication failure: unable to connect cisco_ios cisco3.lasthop.io:22
Authentication failed.

2020-12-22 07:20:00,361 -  nornir.core -     INFO -        run() - Running task 'netmiko_send_command' with args {'command_string': 'show ip int brief'} on 2 hosts
2020-12-22 07:20:02,862 - nornir.core.task -    ERROR -      start() - Host 'cisco3': task 'netmiko_send_command' failed with traceback:
Traceback (most recent call last):
  File "/home/bradfernan/VENV/py3_venv/lib64/python3.7/site-packages/netmiko/base_connection.py", line 915, in establish_connection
    self.remote_conn_pre.connect(**ssh_connect_params)
  File "/home/bradfernan/VENV/py3_venv/lib64/python3.7/site-packages/paramiko/client.py", line 446, in connect
    passphrase,
  File "/home/bradfernan/VENV/py3_venv/lib64/python3.7/site-packages/paramiko/client.py", line 764, in _auth
    raise saved_exception
  File "/home/bradfernan/VENV/py3_venv/lib64/python3.7/site-packages/paramiko/client.py", line 751, in _auth
    self._transport.auth_password(username, password)
  File "/home/bradfernan/VENV/py3_venv/lib64/python3.7/site-packages/paramiko/transport.py", line 1509, in auth_password
    return self.auth_handler.wait_for_response(my_event)
  File "/home/bradfernan/VENV/py3_venv/lib64/python3.7/site-packages/paramiko/auth_handler.py", line 250, in wait_for_response
    raise e
paramiko.ssh_exception.AuthenticationException: Authentication failed.

During handling of the above exception, another exception occurred:

Traceback (most recent call last):
  File "/home/bradfernan/VENV/py3_venv/lib64/python3.7/site-packages/nornir/core/task.py", line 85, in start
    r = self.task(self, **self.params)
  File "/home/bradfernan/VENV/py3_venv/lib64/python3.7/site-packages/nornir/plugins/tasks/networking/netmiko_send_command.py", line 26, in netmiko_send_command
    net_connect = task.host.get_connection("netmiko", task.nornir.config)
  File "/home/bradfernan/VENV/py3_venv/lib64/python3.7/site-packages/nornir/core/inventory.py", line 302, in get_connection
    extras=conn.extras,
  File "/home/bradfernan/VENV/py3_venv/lib64/python3.7/site-packages/nornir/core/inventory.py", line 352, in open_connection
    configuration=configuration,
  File "/home/bradfernan/VENV/py3_venv/lib64/python3.7/site-packages/nornir/plugins/connections/netmiko.py", line 58, in open
    self.connection = ConnectHandler(**parameters)
  File "/home/bradfernan/VENV/py3_venv/lib64/python3.7/site-packages/netmiko/ssh_dispatcher.py", line 298, in ConnectHandler
    return ConnectionClass(*args, **kwargs)
  File "/home/bradfernan/VENV/py3_venv/lib64/python3.7/site-packages/netmiko/base_connection.py", line 341, in __init__
    self._open()
  File "/home/bradfernan/VENV/py3_venv/lib64/python3.7/site-packages/netmiko/base_connection.py", line 346, in _open
    self.establish_connection()
  File "/home/bradfernan/VENV/py3_venv/lib64/python3.7/site-packages/netmiko/base_connection.py", line 944, in establish_connection
    raise NetmikoAuthenticationException(msg)
netmiko.ssh_exception.NetmikoAuthenticationException: Authentication failure: unable to connect cisco_ios cisco3.lasthop.io:22
Authentication failed.

2020-12-22 07:28:26,938 -  nornir.core -     INFO -        run() - Running task 'netmiko_send_command' with args {'command_string': 'show ip int brief'} on 2 hosts
2020-12-22 07:28:29,695 - nornir.core.task -    ERROR -      start() - Host 'cisco3': task 'netmiko_send_command' failed with traceback:
Traceback (most recent call last):
  File "/home/bradfernan/VENV/py3_venv/lib64/python3.7/site-packages/netmiko/base_connection.py", line 915, in establish_connection
    self.remote_conn_pre.connect(**ssh_connect_params)
  File "/home/bradfernan/VENV/py3_venv/lib64/python3.7/site-packages/paramiko/client.py", line 446, in connect
    passphrase,
  File "/home/bradfernan/VENV/py3_venv/lib64/python3.7/site-packages/paramiko/client.py", line 764, in _auth
    raise saved_exception
  File "/home/bradfernan/VENV/py3_venv/lib64/python3.7/site-packages/paramiko/client.py", line 751, in _auth
    self._transport.auth_password(username, password)
  File "/home/bradfernan/VENV/py3_venv/lib64/python3.7/site-packages/paramiko/transport.py", line 1509, in auth_password
    return self.auth_handler.wait_for_response(my_event)
  File "/home/bradfernan/VENV/py3_venv/lib64/python3.7/site-packages/paramiko/auth_handler.py", line 250, in wait_for_response
    raise e
paramiko.ssh_exception.AuthenticationException: Authentication failed.

During handling of the above exception, another exception occurred:

Traceback (most recent call last):
  File "/home/bradfernan/VENV/py3_venv/lib64/python3.7/site-packages/nornir/core/task.py", line 85, in start
    r = self.task(self, **self.params)
  File "/home/bradfernan/VENV/py3_venv/lib64/python3.7/site-packages/nornir/plugins/tasks/networking/netmiko_send_command.py", line 26, in netmiko_send_command
    net_connect = task.host.get_connection("netmiko", task.nornir.config)
  File "/home/bradfernan/VENV/py3_venv/lib64/python3.7/site-packages/nornir/core/inventory.py", line 302, in get_connection
    extras=conn.extras,
  File "/home/bradfernan/VENV/py3_venv/lib64/python3.7/site-packages/nornir/core/inventory.py", line 352, in open_connection
    configuration=configuration,
  File "/home/bradfernan/VENV/py3_venv/lib64/python3.7/site-packages/nornir/plugins/connections/netmiko.py", line 58, in open
    self.connection = ConnectHandler(**parameters)
  File "/home/bradfernan/VENV/py3_venv/lib64/python3.7/site-packages/netmiko/ssh_dispatcher.py", line 298, in ConnectHandler
    return ConnectionClass(*args, **kwargs)
  File "/home/bradfernan/VENV/py3_venv/lib64/python3.7/site-packages/netmiko/base_connection.py", line 341, in __init__
    self._open()
  File "/home/bradfernan/VENV/py3_venv/lib64/python3.7/site-packages/netmiko/base_connection.py", line 346, in _open
    self.establish_connection()
  File "/home/bradfernan/VENV/py3_venv/lib64/python3.7/site-packages/netmiko/base_connection.py", line 944, in establish_connection
    raise NetmikoAuthenticationException(msg)
netmiko.ssh_exception.NetmikoAuthenticationException: Authentication failure: unable to connect cisco_ios cisco3.lasthop.io:22
Authentication failed.

2020-12-22 07:30:41,466 -  nornir.core -     INFO -        run() - Running task 'netmiko_send_command' with args {'command_string': 'show ip int brief'} on 2 hosts
2020-12-22 07:30:43,998 - nornir.core.task -    ERROR -      start() - Host 'cisco3': task 'netmiko_send_command' failed with traceback:
Traceback (most recent call last):
  File "/home/bradfernan/VENV/py3_venv/lib64/python3.7/site-packages/netmiko/base_connection.py", line 915, in establish_connection
    self.remote_conn_pre.connect(**ssh_connect_params)
  File "/home/bradfernan/VENV/py3_venv/lib64/python3.7/site-packages/paramiko/client.py", line 446, in connect
    passphrase,
  File "/home/bradfernan/VENV/py3_venv/lib64/python3.7/site-packages/paramiko/client.py", line 764, in _auth
    raise saved_exception
  File "/home/bradfernan/VENV/py3_venv/lib64/python3.7/site-packages/paramiko/client.py", line 751, in _auth
    self._transport.auth_password(username, password)
  File "/home/bradfernan/VENV/py3_venv/lib64/python3.7/site-packages/paramiko/transport.py", line 1509, in auth_password
    return self.auth_handler.wait_for_response(my_event)
  File "/home/bradfernan/VENV/py3_venv/lib64/python3.7/site-packages/paramiko/auth_handler.py", line 250, in wait_for_response
    raise e
paramiko.ssh_exception.AuthenticationException: Authentication failed.

During handling of the above exception, another exception occurred:

Traceback (most recent call last):
  File "/home/bradfernan/VENV/py3_venv/lib64/python3.7/site-packages/nornir/core/task.py", line 85, in start
    r = self.task(self, **self.params)
  File "/home/bradfernan/VENV/py3_venv/lib64/python3.7/site-packages/nornir/plugins/tasks/networking/netmiko_send_command.py", line 26, in netmiko_send_command
    net_connect = task.host.get_connection("netmiko", task.nornir.config)
  File "/home/bradfernan/VENV/py3_venv/lib64/python3.7/site-packages/nornir/core/inventory.py", line 302, in get_connection
    extras=conn.extras,
  File "/home/bradfernan/VENV/py3_venv/lib64/python3.7/site-packages/nornir/core/inventory.py", line 352, in open_connection
    configuration=configuration,
  File "/home/bradfernan/VENV/py3_venv/lib64/python3.7/site-packages/nornir/plugins/connections/netmiko.py", line 58, in open
    self.connection = ConnectHandler(**parameters)
  File "/home/bradfernan/VENV/py3_venv/lib64/python3.7/site-packages/netmiko/ssh_dispatcher.py", line 298, in ConnectHandler
    return ConnectionClass(*args, **kwargs)
  File "/home/bradfernan/VENV/py3_venv/lib64/python3.7/site-packages/netmiko/base_connection.py", line 341, in __init__
    self._open()
  File "/home/bradfernan/VENV/py3_venv/lib64/python3.7/site-packages/netmiko/base_connection.py", line 346, in _open
    self.establish_connection()
  File "/home/bradfernan/VENV/py3_venv/lib64/python3.7/site-packages/netmiko/base_connection.py", line 944, in establish_connection
    raise NetmikoAuthenticationException(msg)
netmiko.ssh_exception.NetmikoAuthenticationException: Authentication failure: unable to connect cisco_ios cisco3.lasthop.io:22
Authentication failed.

2020-12-22 07:31:24,413 -  nornir.core -     INFO -        run() - Running task 'netmiko_send_command' with args {'command_string': 'show ip int brief'} on 2 hosts
2020-12-22 07:31:27,103 - nornir.core.task -    ERROR -      start() - Host 'cisco3': task 'netmiko_send_command' failed with traceback:
Traceback (most recent call last):
  File "/home/bradfernan/VENV/py3_venv/lib64/python3.7/site-packages/netmiko/base_connection.py", line 915, in establish_connection
    self.remote_conn_pre.connect(**ssh_connect_params)
  File "/home/bradfernan/VENV/py3_venv/lib64/python3.7/site-packages/paramiko/client.py", line 446, in connect
    passphrase,
  File "/home/bradfernan/VENV/py3_venv/lib64/python3.7/site-packages/paramiko/client.py", line 764, in _auth
    raise saved_exception
  File "/home/bradfernan/VENV/py3_venv/lib64/python3.7/site-packages/paramiko/client.py", line 751, in _auth
    self._transport.auth_password(username, password)
  File "/home/bradfernan/VENV/py3_venv/lib64/python3.7/site-packages/paramiko/transport.py", line 1509, in auth_password
    return self.auth_handler.wait_for_response(my_event)
  File "/home/bradfernan/VENV/py3_venv/lib64/python3.7/site-packages/paramiko/auth_handler.py", line 250, in wait_for_response
    raise e
paramiko.ssh_exception.AuthenticationException: Authentication failed.

During handling of the above exception, another exception occurred:

Traceback (most recent call last):
  File "/home/bradfernan/VENV/py3_venv/lib64/python3.7/site-packages/nornir/core/task.py", line 85, in start
    r = self.task(self, **self.params)
  File "/home/bradfernan/VENV/py3_venv/lib64/python3.7/site-packages/nornir/plugins/tasks/networking/netmiko_send_command.py", line 26, in netmiko_send_command
    net_connect = task.host.get_connection("netmiko", task.nornir.config)
  File "/home/bradfernan/VENV/py3_venv/lib64/python3.7/site-packages/nornir/core/inventory.py", line 302, in get_connection
    extras=conn.extras,
  File "/home/bradfernan/VENV/py3_venv/lib64/python3.7/site-packages/nornir/core/inventory.py", line 352, in open_connection
    configuration=configuration,
  File "/home/bradfernan/VENV/py3_venv/lib64/python3.7/site-packages/nornir/plugins/connections/netmiko.py", line 58, in open
    self.connection = ConnectHandler(**parameters)
  File "/home/bradfernan/VENV/py3_venv/lib64/python3.7/site-packages/netmiko/ssh_dispatcher.py", line 298, in ConnectHandler
    return ConnectionClass(*args, **kwargs)
  File "/home/bradfernan/VENV/py3_venv/lib64/python3.7/site-packages/netmiko/base_connection.py", line 341, in __init__
    self._open()
  File "/home/bradfernan/VENV/py3_venv/lib64/python3.7/site-packages/netmiko/base_connection.py", line 346, in _open
    self.establish_connection()
  File "/home/bradfernan/VENV/py3_venv/lib64/python3.7/site-packages/netmiko/base_connection.py", line 944, in establish_connection
    raise NetmikoAuthenticationException(msg)
netmiko.ssh_exception.NetmikoAuthenticationException: Authentication failure: unable to connect cisco_ios cisco3.lasthop.io:22
Authentication failed.

2020-12-22 07:38:01,607 -  nornir.core -     INFO -        run() - Running task 'netmiko_send_command' with args {'command_string': 'show ip int brief'} on 2 hosts
2020-12-22 07:38:04,139 - nornir.core.task -    ERROR -      start() - Host 'cisco3': task 'netmiko_send_command' failed with traceback:
Traceback (most recent call last):
  File "/home/bradfernan/VENV/py3_venv/lib64/python3.7/site-packages/netmiko/base_connection.py", line 915, in establish_connection
    self.remote_conn_pre.connect(**ssh_connect_params)
  File "/home/bradfernan/VENV/py3_venv/lib64/python3.7/site-packages/paramiko/client.py", line 446, in connect
    passphrase,
  File "/home/bradfernan/VENV/py3_venv/lib64/python3.7/site-packages/paramiko/client.py", line 764, in _auth
    raise saved_exception
  File "/home/bradfernan/VENV/py3_venv/lib64/python3.7/site-packages/paramiko/client.py", line 751, in _auth
    self._transport.auth_password(username, password)
  File "/home/bradfernan/VENV/py3_venv/lib64/python3.7/site-packages/paramiko/transport.py", line 1509, in auth_password
    return self.auth_handler.wait_for_response(my_event)
  File "/home/bradfernan/VENV/py3_venv/lib64/python3.7/site-packages/paramiko/auth_handler.py", line 250, in wait_for_response
    raise e
paramiko.ssh_exception.AuthenticationException: Authentication failed.

During handling of the above exception, another exception occurred:

Traceback (most recent call last):
  File "/home/bradfernan/VENV/py3_venv/lib64/python3.7/site-packages/nornir/core/task.py", line 85, in start
    r = self.task(self, **self.params)
  File "/home/bradfernan/VENV/py3_venv/lib64/python3.7/site-packages/nornir/plugins/tasks/networking/netmiko_send_command.py", line 26, in netmiko_send_command
    net_connect = task.host.get_connection("netmiko", task.nornir.config)
  File "/home/bradfernan/VENV/py3_venv/lib64/python3.7/site-packages/nornir/core/inventory.py", line 302, in get_connection
    extras=conn.extras,
  File "/home/bradfernan/VENV/py3_venv/lib64/python3.7/site-packages/nornir/core/inventory.py", line 352, in open_connection
    configuration=configuration,
  File "/home/bradfernan/VENV/py3_venv/lib64/python3.7/site-packages/nornir/plugins/connections/netmiko.py", line 58, in open
    self.connection = ConnectHandler(**parameters)
  File "/home/bradfernan/VENV/py3_venv/lib64/python3.7/site-packages/netmiko/ssh_dispatcher.py", line 298, in ConnectHandler
    return ConnectionClass(*args, **kwargs)
  File "/home/bradfernan/VENV/py3_venv/lib64/python3.7/site-packages/netmiko/base_connection.py", line 341, in __init__
    self._open()
  File "/home/bradfernan/VENV/py3_venv/lib64/python3.7/site-packages/netmiko/base_connection.py", line 346, in _open
    self.establish_connection()
  File "/home/bradfernan/VENV/py3_venv/lib64/python3.7/site-packages/netmiko/base_connection.py", line 944, in establish_connection
    raise NetmikoAuthenticationException(msg)
netmiko.ssh_exception.NetmikoAuthenticationException: Authentication failure: unable to connect cisco_ios cisco3.lasthop.io:22
Authentication failed.

2020-12-22 20:47:03,989 -  nornir.core -     INFO -        run() - Running task 'netmiko_send_command' with args {'command_string': 'show ip int brief'} on 2 hosts
2020-12-22 21:03:08,861 -  nornir.core -     INFO -        run() - Running task 'netmiko_send_command' with args {'command_string': 'show ip int brief'} on 2 hosts
2020-12-22 21:03:11,580 - nornir.core.task -    ERROR -      start() - Host 'cisco3': task 'netmiko_send_command' failed with traceback:
Traceback (most recent call last):
  File "/home/bradfernan/VENV/py3_venv/lib64/python3.7/site-packages/netmiko/base_connection.py", line 915, in establish_connection
    self.remote_conn_pre.connect(**ssh_connect_params)
  File "/home/bradfernan/VENV/py3_venv/lib64/python3.7/site-packages/paramiko/client.py", line 446, in connect
    passphrase,
  File "/home/bradfernan/VENV/py3_venv/lib64/python3.7/site-packages/paramiko/client.py", line 764, in _auth
    raise saved_exception
  File "/home/bradfernan/VENV/py3_venv/lib64/python3.7/site-packages/paramiko/client.py", line 751, in _auth
    self._transport.auth_password(username, password)
  File "/home/bradfernan/VENV/py3_venv/lib64/python3.7/site-packages/paramiko/transport.py", line 1509, in auth_password
    return self.auth_handler.wait_for_response(my_event)
  File "/home/bradfernan/VENV/py3_venv/lib64/python3.7/site-packages/paramiko/auth_handler.py", line 250, in wait_for_response
    raise e
paramiko.ssh_exception.AuthenticationException: Authentication failed.

During handling of the above exception, another exception occurred:

Traceback (most recent call last):
  File "/home/bradfernan/VENV/py3_venv/lib64/python3.7/site-packages/nornir/core/task.py", line 85, in start
    r = self.task(self, **self.params)
  File "/home/bradfernan/VENV/py3_venv/lib64/python3.7/site-packages/nornir/plugins/tasks/networking/netmiko_send_command.py", line 26, in netmiko_send_command
    net_connect = task.host.get_connection("netmiko", task.nornir.config)
  File "/home/bradfernan/VENV/py3_venv/lib64/python3.7/site-packages/nornir/core/inventory.py", line 302, in get_connection
    extras=conn.extras,
  File "/home/bradfernan/VENV/py3_venv/lib64/python3.7/site-packages/nornir/core/inventory.py", line 352, in open_connection
    configuration=configuration,
  File "/home/bradfernan/VENV/py3_venv/lib64/python3.7/site-packages/nornir/plugins/connections/netmiko.py", line 58, in open
    self.connection = ConnectHandler(**parameters)
  File "/home/bradfernan/VENV/py3_venv/lib64/python3.7/site-packages/netmiko/ssh_dispatcher.py", line 298, in ConnectHandler
    return ConnectionClass(*args, **kwargs)
  File "/home/bradfernan/VENV/py3_venv/lib64/python3.7/site-packages/netmiko/base_connection.py", line 341, in __init__
    self._open()
  File "/home/bradfernan/VENV/py3_venv/lib64/python3.7/site-packages/netmiko/base_connection.py", line 346, in _open
    self.establish_connection()
  File "/home/bradfernan/VENV/py3_venv/lib64/python3.7/site-packages/netmiko/base_connection.py", line 944, in establish_connection
    raise NetmikoAuthenticationException(msg)
netmiko.ssh_exception.NetmikoAuthenticationException: Authentication failure: unable to connect cisco_ios cisco3.lasthop.io:22
Authentication failed.

2020-12-22 21:09:11,332 -  nornir.core -     INFO -        run() - Running task 'netmiko_send_command' with args {'command_string': 'show ip int brief'} on 2 hosts
2020-12-22 21:09:14,085 - nornir.core.task -    ERROR -      start() - Host 'cisco3': task 'netmiko_send_command' failed with traceback:
Traceback (most recent call last):
  File "/home/bradfernan/VENV/py3_venv/lib64/python3.7/site-packages/netmiko/base_connection.py", line 915, in establish_connection
    self.remote_conn_pre.connect(**ssh_connect_params)
  File "/home/bradfernan/VENV/py3_venv/lib64/python3.7/site-packages/paramiko/client.py", line 446, in connect
    passphrase,
  File "/home/bradfernan/VENV/py3_venv/lib64/python3.7/site-packages/paramiko/client.py", line 764, in _auth
    raise saved_exception
  File "/home/bradfernan/VENV/py3_venv/lib64/python3.7/site-packages/paramiko/client.py", line 751, in _auth
    self._transport.auth_password(username, password)
  File "/home/bradfernan/VENV/py3_venv/lib64/python3.7/site-packages/paramiko/transport.py", line 1509, in auth_password
    return self.auth_handler.wait_for_response(my_event)
  File "/home/bradfernan/VENV/py3_venv/lib64/python3.7/site-packages/paramiko/auth_handler.py", line 250, in wait_for_response
    raise e
paramiko.ssh_exception.AuthenticationException: Authentication failed.

During handling of the above exception, another exception occurred:

Traceback (most recent call last):
  File "/home/bradfernan/VENV/py3_venv/lib64/python3.7/site-packages/nornir/core/task.py", line 85, in start
    r = self.task(self, **self.params)
  File "/home/bradfernan/VENV/py3_venv/lib64/python3.7/site-packages/nornir/plugins/tasks/networking/netmiko_send_command.py", line 26, in netmiko_send_command
    net_connect = task.host.get_connection("netmiko", task.nornir.config)
  File "/home/bradfernan/VENV/py3_venv/lib64/python3.7/site-packages/nornir/core/inventory.py", line 302, in get_connection
    extras=conn.extras,
  File "/home/bradfernan/VENV/py3_venv/lib64/python3.7/site-packages/nornir/core/inventory.py", line 352, in open_connection
    configuration=configuration,
  File "/home/bradfernan/VENV/py3_venv/lib64/python3.7/site-packages/nornir/plugins/connections/netmiko.py", line 58, in open
    self.connection = ConnectHandler(**parameters)
  File "/home/bradfernan/VENV/py3_venv/lib64/python3.7/site-packages/netmiko/ssh_dispatcher.py", line 298, in ConnectHandler
    return ConnectionClass(*args, **kwargs)
  File "/home/bradfernan/VENV/py3_venv/lib64/python3.7/site-packages/netmiko/base_connection.py", line 341, in __init__
    self._open()
  File "/home/bradfernan/VENV/py3_venv/lib64/python3.7/site-packages/netmiko/base_connection.py", line 346, in _open
    self.establish_connection()
  File "/home/bradfernan/VENV/py3_venv/lib64/python3.7/site-packages/netmiko/base_connection.py", line 944, in establish_connection
    raise NetmikoAuthenticationException(msg)
netmiko.ssh_exception.NetmikoAuthenticationException: Authentication failure: unable to connect cisco_ios cisco3.lasthop.io:22
Authentication failed.

2020-12-22 21:21:21,372 -  nornir.core -     INFO -        run() - Running task 'netmiko_send_command' with args {'command_string': 'show ip int brief'} on 2 hosts
2020-12-22 21:21:24,124 - nornir.core.task -    ERROR -      start() - Host 'cisco3': task 'netmiko_send_command' failed with traceback:
Traceback (most recent call last):
  File "/home/bradfernan/VENV/py3_venv/lib64/python3.7/site-packages/netmiko/base_connection.py", line 915, in establish_connection
    self.remote_conn_pre.connect(**ssh_connect_params)
  File "/home/bradfernan/VENV/py3_venv/lib64/python3.7/site-packages/paramiko/client.py", line 446, in connect
    passphrase,
  File "/home/bradfernan/VENV/py3_venv/lib64/python3.7/site-packages/paramiko/client.py", line 764, in _auth
    raise saved_exception
  File "/home/bradfernan/VENV/py3_venv/lib64/python3.7/site-packages/paramiko/client.py", line 751, in _auth
    self._transport.auth_password(username, password)
  File "/home/bradfernan/VENV/py3_venv/lib64/python3.7/site-packages/paramiko/transport.py", line 1509, in auth_password
    return self.auth_handler.wait_for_response(my_event)
  File "/home/bradfernan/VENV/py3_venv/lib64/python3.7/site-packages/paramiko/auth_handler.py", line 250, in wait_for_response
    raise e
paramiko.ssh_exception.AuthenticationException: Authentication failed.

During handling of the above exception, another exception occurred:

Traceback (most recent call last):
  File "/home/bradfernan/VENV/py3_venv/lib64/python3.7/site-packages/nornir/core/task.py", line 85, in start
    r = self.task(self, **self.params)
  File "/home/bradfernan/VENV/py3_venv/lib64/python3.7/site-packages/nornir/plugins/tasks/networking/netmiko_send_command.py", line 26, in netmiko_send_command
    net_connect = task.host.get_connection("netmiko", task.nornir.config)
  File "/home/bradfernan/VENV/py3_venv/lib64/python3.7/site-packages/nornir/core/inventory.py", line 302, in get_connection
    extras=conn.extras,
  File "/home/bradfernan/VENV/py3_venv/lib64/python3.7/site-packages/nornir/core/inventory.py", line 352, in open_connection
    configuration=configuration,
  File "/home/bradfernan/VENV/py3_venv/lib64/python3.7/site-packages/nornir/plugins/connections/netmiko.py", line 58, in open
    self.connection = ConnectHandler(**parameters)
  File "/home/bradfernan/VENV/py3_venv/lib64/python3.7/site-packages/netmiko/ssh_dispatcher.py", line 298, in ConnectHandler
    return ConnectionClass(*args, **kwargs)
  File "/home/bradfernan/VENV/py3_venv/lib64/python3.7/site-packages/netmiko/base_connection.py", line 341, in __init__
    self._open()
  File "/home/bradfernan/VENV/py3_venv/lib64/python3.7/site-packages/netmiko/base_connection.py", line 346, in _open
    self.establish_connection()
  File "/home/bradfernan/VENV/py3_venv/lib64/python3.7/site-packages/netmiko/base_connection.py", line 944, in establish_connection
    raise NetmikoAuthenticationException(msg)
netmiko.ssh_exception.NetmikoAuthenticationException: Authentication failure: unable to connect cisco_ios cisco3.lasthop.io:22
Authentication failed.

2020-12-22 21:22:04,212 -  nornir.core -     INFO -        run() - Running task 'netmiko_send_command' with args {'command_string': 'show ip int brief'} on 2 hosts
2020-12-22 21:22:06,756 - nornir.core.task -    ERROR -      start() - Host 'cisco3': task 'netmiko_send_command' failed with traceback:
Traceback (most recent call last):
  File "/home/bradfernan/VENV/py3_venv/lib64/python3.7/site-packages/netmiko/base_connection.py", line 915, in establish_connection
    self.remote_conn_pre.connect(**ssh_connect_params)
  File "/home/bradfernan/VENV/py3_venv/lib64/python3.7/site-packages/paramiko/client.py", line 446, in connect
    passphrase,
  File "/home/bradfernan/VENV/py3_venv/lib64/python3.7/site-packages/paramiko/client.py", line 764, in _auth
    raise saved_exception
  File "/home/bradfernan/VENV/py3_venv/lib64/python3.7/site-packages/paramiko/client.py", line 751, in _auth
    self._transport.auth_password(username, password)
  File "/home/bradfernan/VENV/py3_venv/lib64/python3.7/site-packages/paramiko/transport.py", line 1509, in auth_password
    return self.auth_handler.wait_for_response(my_event)
  File "/home/bradfernan/VENV/py3_venv/lib64/python3.7/site-packages/paramiko/auth_handler.py", line 250, in wait_for_response
    raise e
paramiko.ssh_exception.AuthenticationException: Authentication failed.

During handling of the above exception, another exception occurred:

Traceback (most recent call last):
  File "/home/bradfernan/VENV/py3_venv/lib64/python3.7/site-packages/nornir/core/task.py", line 85, in start
    r = self.task(self, **self.params)
  File "/home/bradfernan/VENV/py3_venv/lib64/python3.7/site-packages/nornir/plugins/tasks/networking/netmiko_send_command.py", line 26, in netmiko_send_command
    net_connect = task.host.get_connection("netmiko", task.nornir.config)
  File "/home/bradfernan/VENV/py3_venv/lib64/python3.7/site-packages/nornir/core/inventory.py", line 302, in get_connection
    extras=conn.extras,
  File "/home/bradfernan/VENV/py3_venv/lib64/python3.7/site-packages/nornir/core/inventory.py", line 352, in open_connection
    configuration=configuration,
  File "/home/bradfernan/VENV/py3_venv/lib64/python3.7/site-packages/nornir/plugins/connections/netmiko.py", line 58, in open
    self.connection = ConnectHandler(**parameters)
  File "/home/bradfernan/VENV/py3_venv/lib64/python3.7/site-packages/netmiko/ssh_dispatcher.py", line 298, in ConnectHandler
    return ConnectionClass(*args, **kwargs)
  File "/home/bradfernan/VENV/py3_venv/lib64/python3.7/site-packages/netmiko/base_connection.py", line 341, in __init__
    self._open()
  File "/home/bradfernan/VENV/py3_venv/lib64/python3.7/site-packages/netmiko/base_connection.py", line 346, in _open
    self.establish_connection()
  File "/home/bradfernan/VENV/py3_venv/lib64/python3.7/site-packages/netmiko/base_connection.py", line 944, in establish_connection
    raise NetmikoAuthenticationException(msg)
netmiko.ssh_exception.NetmikoAuthenticationException: Authentication failure: unable to connect cisco_ios cisco3.lasthop.io:22
Authentication failed.

2020-12-22 21:22:10,140 -  nornir.core -     INFO -        run() - Running task 'netmiko_send_command' with args {'command_string': 'show ip int brief'} on 2 hosts
2020-12-22 21:22:59,930 -  nornir.core -     INFO -        run() - Running task 'netmiko_send_command' with args {'command_string': 'show ip int brief'} on 2 hosts
2020-12-22 21:23:02,672 - nornir.core.task -    ERROR -      start() - Host 'cisco3': task 'netmiko_send_command' failed with traceback:
Traceback (most recent call last):
  File "/home/bradfernan/VENV/py3_venv/lib64/python3.7/site-packages/netmiko/base_connection.py", line 915, in establish_connection
    self.remote_conn_pre.connect(**ssh_connect_params)
  File "/home/bradfernan/VENV/py3_venv/lib64/python3.7/site-packages/paramiko/client.py", line 446, in connect
    passphrase,
  File "/home/bradfernan/VENV/py3_venv/lib64/python3.7/site-packages/paramiko/client.py", line 764, in _auth
    raise saved_exception
  File "/home/bradfernan/VENV/py3_venv/lib64/python3.7/site-packages/paramiko/client.py", line 751, in _auth
    self._transport.auth_password(username, password)
  File "/home/bradfernan/VENV/py3_venv/lib64/python3.7/site-packages/paramiko/transport.py", line 1509, in auth_password
    return self.auth_handler.wait_for_response(my_event)
  File "/home/bradfernan/VENV/py3_venv/lib64/python3.7/site-packages/paramiko/auth_handler.py", line 250, in wait_for_response
    raise e
paramiko.ssh_exception.AuthenticationException: Authentication failed.

During handling of the above exception, another exception occurred:

Traceback (most recent call last):
  File "/home/bradfernan/VENV/py3_venv/lib64/python3.7/site-packages/nornir/core/task.py", line 85, in start
    r = self.task(self, **self.params)
  File "/home/bradfernan/VENV/py3_venv/lib64/python3.7/site-packages/nornir/plugins/tasks/networking/netmiko_send_command.py", line 26, in netmiko_send_command
    net_connect = task.host.get_connection("netmiko", task.nornir.config)
  File "/home/bradfernan/VENV/py3_venv/lib64/python3.7/site-packages/nornir/core/inventory.py", line 302, in get_connection
    extras=conn.extras,
  File "/home/bradfernan/VENV/py3_venv/lib64/python3.7/site-packages/nornir/core/inventory.py", line 352, in open_connection
    configuration=configuration,
  File "/home/bradfernan/VENV/py3_venv/lib64/python3.7/site-packages/nornir/plugins/connections/netmiko.py", line 58, in open
    self.connection = ConnectHandler(**parameters)
  File "/home/bradfernan/VENV/py3_venv/lib64/python3.7/site-packages/netmiko/ssh_dispatcher.py", line 298, in ConnectHandler
    return ConnectionClass(*args, **kwargs)
  File "/home/bradfernan/VENV/py3_venv/lib64/python3.7/site-packages/netmiko/base_connection.py", line 341, in __init__
    self._open()
  File "/home/bradfernan/VENV/py3_venv/lib64/python3.7/site-packages/netmiko/base_connection.py", line 346, in _open
    self.establish_connection()
  File "/home/bradfernan/VENV/py3_venv/lib64/python3.7/site-packages/netmiko/base_connection.py", line 944, in establish_connection
    raise NetmikoAuthenticationException(msg)
netmiko.ssh_exception.NetmikoAuthenticationException: Authentication failure: unable to connect cisco_ios cisco3.lasthop.io:22
Authentication failed.

2020-12-22 21:23:05,908 -  nornir.core -     INFO -        run() - Running task 'netmiko_send_command' with args {'command_string': 'show ip int brief'} on 2 hosts
2020-12-22 21:59:08,660 -  nornir.core -     INFO -        run() - Running task 'netmiko_send_command' with args {'command_string': 'show ip int brief'} on 2 hosts
2020-12-22 21:59:11,414 - nornir.core.task -    ERROR -      start() - Host 'cisco3': task 'netmiko_send_command' failed with traceback:
Traceback (most recent call last):
  File "/home/bradfernan/VENV/py3_venv/lib64/python3.7/site-packages/netmiko/base_connection.py", line 915, in establish_connection
    self.remote_conn_pre.connect(**ssh_connect_params)
  File "/home/bradfernan/VENV/py3_venv/lib64/python3.7/site-packages/paramiko/client.py", line 446, in connect
    passphrase,
  File "/home/bradfernan/VENV/py3_venv/lib64/python3.7/site-packages/paramiko/client.py", line 764, in _auth
    raise saved_exception
  File "/home/bradfernan/VENV/py3_venv/lib64/python3.7/site-packages/paramiko/client.py", line 751, in _auth
    self._transport.auth_password(username, password)
  File "/home/bradfernan/VENV/py3_venv/lib64/python3.7/site-packages/paramiko/transport.py", line 1509, in auth_password
    return self.auth_handler.wait_for_response(my_event)
  File "/home/bradfernan/VENV/py3_venv/lib64/python3.7/site-packages/paramiko/auth_handler.py", line 250, in wait_for_response
    raise e
paramiko.ssh_exception.AuthenticationException: Authentication failed.

During handling of the above exception, another exception occurred:

Traceback (most recent call last):
  File "/home/bradfernan/VENV/py3_venv/lib64/python3.7/site-packages/nornir/core/task.py", line 85, in start
    r = self.task(self, **self.params)
  File "/home/bradfernan/VENV/py3_venv/lib64/python3.7/site-packages/nornir/plugins/tasks/networking/netmiko_send_command.py", line 26, in netmiko_send_command
    net_connect = task.host.get_connection("netmiko", task.nornir.config)
  File "/home/bradfernan/VENV/py3_venv/lib64/python3.7/site-packages/nornir/core/inventory.py", line 302, in get_connection
    extras=conn.extras,
  File "/home/bradfernan/VENV/py3_venv/lib64/python3.7/site-packages/nornir/core/inventory.py", line 352, in open_connection
    configuration=configuration,
  File "/home/bradfernan/VENV/py3_venv/lib64/python3.7/site-packages/nornir/plugins/connections/netmiko.py", line 58, in open
    self.connection = ConnectHandler(**parameters)
  File "/home/bradfernan/VENV/py3_venv/lib64/python3.7/site-packages/netmiko/ssh_dispatcher.py", line 298, in ConnectHandler
    return ConnectionClass(*args, **kwargs)
  File "/home/bradfernan/VENV/py3_venv/lib64/python3.7/site-packages/netmiko/base_connection.py", line 341, in __init__
    self._open()
  File "/home/bradfernan/VENV/py3_venv/lib64/python3.7/site-packages/netmiko/base_connection.py", line 346, in _open
    self.establish_connection()
  File "/home/bradfernan/VENV/py3_venv/lib64/python3.7/site-packages/netmiko/base_connection.py", line 944, in establish_connection
    raise NetmikoAuthenticationException(msg)
netmiko.ssh_exception.NetmikoAuthenticationException: Authentication failure: unable to connect cisco_ios cisco3.lasthop.io:22
Authentication failed.

2020-12-22 21:59:14,665 -  nornir.core -     INFO -        run() - Running task 'netmiko_send_command' with args {'command_string': 'show ip int brief'} on 2 hosts
2020-12-22 21:59:14,666 - nornir.core.task -    ERROR -      start() - Host 'cisco3': task 'netmiko_send_command' failed with traceback:
Traceback (most recent call last):
  File "/home/bradfernan/VENV/py3_venv/lib64/python3.7/site-packages/nornir/core/task.py", line 85, in start
    r = self.task(self, **self.params)
  File "/home/bradfernan/VENV/py3_venv/lib64/python3.7/site-packages/nornir/plugins/tasks/networking/netmiko_send_command.py", line 32, in netmiko_send_command
    result = net_connect.send_command(command_string, **kwargs)
AttributeError: 'UnestablishedConnection' object has no attribute 'send_command'

2020-12-22 22:01:51,625 -  nornir.core -     INFO -        run() - Running task 'netmiko_send_command' with args {'command_string': 'show ip int brief'} on 2 hosts
2020-12-22 22:01:54,365 - nornir.core.task -    ERROR -      start() - Host 'cisco3': task 'netmiko_send_command' failed with traceback:
Traceback (most recent call last):
  File "/home/bradfernan/VENV/py3_venv/lib64/python3.7/site-packages/netmiko/base_connection.py", line 915, in establish_connection
    self.remote_conn_pre.connect(**ssh_connect_params)
  File "/home/bradfernan/VENV/py3_venv/lib64/python3.7/site-packages/paramiko/client.py", line 446, in connect
    passphrase,
  File "/home/bradfernan/VENV/py3_venv/lib64/python3.7/site-packages/paramiko/client.py", line 764, in _auth
    raise saved_exception
  File "/home/bradfernan/VENV/py3_venv/lib64/python3.7/site-packages/paramiko/client.py", line 751, in _auth
    self._transport.auth_password(username, password)
  File "/home/bradfernan/VENV/py3_venv/lib64/python3.7/site-packages/paramiko/transport.py", line 1509, in auth_password
    return self.auth_handler.wait_for_response(my_event)
  File "/home/bradfernan/VENV/py3_venv/lib64/python3.7/site-packages/paramiko/auth_handler.py", line 250, in wait_for_response
    raise e
paramiko.ssh_exception.AuthenticationException: Authentication failed.

During handling of the above exception, another exception occurred:

Traceback (most recent call last):
  File "/home/bradfernan/VENV/py3_venv/lib64/python3.7/site-packages/nornir/core/task.py", line 85, in start
    r = self.task(self, **self.params)
  File "/home/bradfernan/VENV/py3_venv/lib64/python3.7/site-packages/nornir/plugins/tasks/networking/netmiko_send_command.py", line 26, in netmiko_send_command
    net_connect = task.host.get_connection("netmiko", task.nornir.config)
  File "/home/bradfernan/VENV/py3_venv/lib64/python3.7/site-packages/nornir/core/inventory.py", line 302, in get_connection
    extras=conn.extras,
  File "/home/bradfernan/VENV/py3_venv/lib64/python3.7/site-packages/nornir/core/inventory.py", line 352, in open_connection
    configuration=configuration,
  File "/home/bradfernan/VENV/py3_venv/lib64/python3.7/site-packages/nornir/plugins/connections/netmiko.py", line 58, in open
    self.connection = ConnectHandler(**parameters)
  File "/home/bradfernan/VENV/py3_venv/lib64/python3.7/site-packages/netmiko/ssh_dispatcher.py", line 298, in ConnectHandler
    return ConnectionClass(*args, **kwargs)
  File "/home/bradfernan/VENV/py3_venv/lib64/python3.7/site-packages/netmiko/base_connection.py", line 341, in __init__
    self._open()
  File "/home/bradfernan/VENV/py3_venv/lib64/python3.7/site-packages/netmiko/base_connection.py", line 346, in _open
    self.establish_connection()
  File "/home/bradfernan/VENV/py3_venv/lib64/python3.7/site-packages/netmiko/base_connection.py", line 944, in establish_connection
    raise NetmikoAuthenticationException(msg)
netmiko.ssh_exception.NetmikoAuthenticationException: Authentication failure: unable to connect cisco_ios cisco3.lasthop.io:22
Authentication failed.

2020-12-22 22:04:04,423 -  nornir.core -     INFO -        run() - Running task 'netmiko_send_command' with args {'command_string': 'show ip int brief'} on 2 hosts
2020-12-22 22:04:07,166 - nornir.core.task -    ERROR -      start() - Host 'cisco3': task 'netmiko_send_command' failed with traceback:
Traceback (most recent call last):
  File "/home/bradfernan/VENV/py3_venv/lib64/python3.7/site-packages/netmiko/base_connection.py", line 915, in establish_connection
    self.remote_conn_pre.connect(**ssh_connect_params)
  File "/home/bradfernan/VENV/py3_venv/lib64/python3.7/site-packages/paramiko/client.py", line 446, in connect
    passphrase,
  File "/home/bradfernan/VENV/py3_venv/lib64/python3.7/site-packages/paramiko/client.py", line 764, in _auth
    raise saved_exception
  File "/home/bradfernan/VENV/py3_venv/lib64/python3.7/site-packages/paramiko/client.py", line 751, in _auth
    self._transport.auth_password(username, password)
  File "/home/bradfernan/VENV/py3_venv/lib64/python3.7/site-packages/paramiko/transport.py", line 1509, in auth_password
    return self.auth_handler.wait_for_response(my_event)
  File "/home/bradfernan/VENV/py3_venv/lib64/python3.7/site-packages/paramiko/auth_handler.py", line 250, in wait_for_response
    raise e
paramiko.ssh_exception.AuthenticationException: Authentication failed.

During handling of the above exception, another exception occurred:

Traceback (most recent call last):
  File "/home/bradfernan/VENV/py3_venv/lib64/python3.7/site-packages/nornir/core/task.py", line 85, in start
    r = self.task(self, **self.params)
  File "/home/bradfernan/VENV/py3_venv/lib64/python3.7/site-packages/nornir/plugins/tasks/networking/netmiko_send_command.py", line 26, in netmiko_send_command
    net_connect = task.host.get_connection("netmiko", task.nornir.config)
  File "/home/bradfernan/VENV/py3_venv/lib64/python3.7/site-packages/nornir/core/inventory.py", line 302, in get_connection
    extras=conn.extras,
  File "/home/bradfernan/VENV/py3_venv/lib64/python3.7/site-packages/nornir/core/inventory.py", line 352, in open_connection
    configuration=configuration,
  File "/home/bradfernan/VENV/py3_venv/lib64/python3.7/site-packages/nornir/plugins/connections/netmiko.py", line 58, in open
    self.connection = ConnectHandler(**parameters)
  File "/home/bradfernan/VENV/py3_venv/lib64/python3.7/site-packages/netmiko/ssh_dispatcher.py", line 298, in ConnectHandler
    return ConnectionClass(*args, **kwargs)
  File "/home/bradfernan/VENV/py3_venv/lib64/python3.7/site-packages/netmiko/base_connection.py", line 341, in __init__
    self._open()
  File "/home/bradfernan/VENV/py3_venv/lib64/python3.7/site-packages/netmiko/base_connection.py", line 346, in _open
    self.establish_connection()
  File "/home/bradfernan/VENV/py3_venv/lib64/python3.7/site-packages/netmiko/base_connection.py", line 944, in establish_connection
    raise NetmikoAuthenticationException(msg)
netmiko.ssh_exception.NetmikoAuthenticationException: Authentication failure: unable to connect cisco_ios cisco3.lasthop.io:22
Authentication failed.

2020-12-22 22:04:10,403 -  nornir.core -     INFO -        run() - Running task 'netmiko_send_command' with args {'command_string': 'show ip int brief'} on 2 hosts
2020-12-22 22:13:47,606 -  nornir.core -     INFO -        run() - Running task 'netmiko_send_command' with args {'command_string': 'show ip int brief'} on 2 hosts
2020-12-22 22:13:50,150 - nornir.core.task -    ERROR -      start() - Host 'cisco3': task 'netmiko_send_command' failed with traceback:
Traceback (most recent call last):
  File "/home/bradfernan/VENV/py3_venv/lib64/python3.7/site-packages/netmiko/base_connection.py", line 915, in establish_connection
    self.remote_conn_pre.connect(**ssh_connect_params)
  File "/home/bradfernan/VENV/py3_venv/lib64/python3.7/site-packages/paramiko/client.py", line 446, in connect
    passphrase,
  File "/home/bradfernan/VENV/py3_venv/lib64/python3.7/site-packages/paramiko/client.py", line 764, in _auth
    raise saved_exception
  File "/home/bradfernan/VENV/py3_venv/lib64/python3.7/site-packages/paramiko/client.py", line 751, in _auth
    self._transport.auth_password(username, password)
  File "/home/bradfernan/VENV/py3_venv/lib64/python3.7/site-packages/paramiko/transport.py", line 1509, in auth_password
    return self.auth_handler.wait_for_response(my_event)
  File "/home/bradfernan/VENV/py3_venv/lib64/python3.7/site-packages/paramiko/auth_handler.py", line 250, in wait_for_response
    raise e
paramiko.ssh_exception.AuthenticationException: Authentication failed.

During handling of the above exception, another exception occurred:

Traceback (most recent call last):
  File "/home/bradfernan/VENV/py3_venv/lib64/python3.7/site-packages/nornir/core/task.py", line 85, in start
    r = self.task(self, **self.params)
  File "/home/bradfernan/VENV/py3_venv/lib64/python3.7/site-packages/nornir/plugins/tasks/networking/netmiko_send_command.py", line 26, in netmiko_send_command
    net_connect = task.host.get_connection("netmiko", task.nornir.config)
  File "/home/bradfernan/VENV/py3_venv/lib64/python3.7/site-packages/nornir/core/inventory.py", line 302, in get_connection
    extras=conn.extras,
  File "/home/bradfernan/VENV/py3_venv/lib64/python3.7/site-packages/nornir/core/inventory.py", line 352, in open_connection
    configuration=configuration,
  File "/home/bradfernan/VENV/py3_venv/lib64/python3.7/site-packages/nornir/plugins/connections/netmiko.py", line 58, in open
    self.connection = ConnectHandler(**parameters)
  File "/home/bradfernan/VENV/py3_venv/lib64/python3.7/site-packages/netmiko/ssh_dispatcher.py", line 298, in ConnectHandler
    return ConnectionClass(*args, **kwargs)
  File "/home/bradfernan/VENV/py3_venv/lib64/python3.7/site-packages/netmiko/base_connection.py", line 341, in __init__
    self._open()
  File "/home/bradfernan/VENV/py3_venv/lib64/python3.7/site-packages/netmiko/base_connection.py", line 346, in _open
    self.establish_connection()
  File "/home/bradfernan/VENV/py3_venv/lib64/python3.7/site-packages/netmiko/base_connection.py", line 944, in establish_connection
    raise NetmikoAuthenticationException(msg)
netmiko.ssh_exception.NetmikoAuthenticationException: Authentication failure: unable to connect cisco_ios cisco3.lasthop.io:22
Authentication failed.

2020-12-22 22:14:14,455 -  nornir.core -     INFO -        run() - Running task 'netmiko_send_command' with args {'command_string': 'show ip int brief'} on 2 hosts
2020-12-22 22:14:17,193 - nornir.core.task -    ERROR -      start() - Host 'cisco3': task 'netmiko_send_command' failed with traceback:
Traceback (most recent call last):
  File "/home/bradfernan/VENV/py3_venv/lib64/python3.7/site-packages/netmiko/base_connection.py", line 915, in establish_connection
    self.remote_conn_pre.connect(**ssh_connect_params)
  File "/home/bradfernan/VENV/py3_venv/lib64/python3.7/site-packages/paramiko/client.py", line 446, in connect
    passphrase,
  File "/home/bradfernan/VENV/py3_venv/lib64/python3.7/site-packages/paramiko/client.py", line 764, in _auth
    raise saved_exception
  File "/home/bradfernan/VENV/py3_venv/lib64/python3.7/site-packages/paramiko/client.py", line 751, in _auth
    self._transport.auth_password(username, password)
  File "/home/bradfernan/VENV/py3_venv/lib64/python3.7/site-packages/paramiko/transport.py", line 1509, in auth_password
    return self.auth_handler.wait_for_response(my_event)
  File "/home/bradfernan/VENV/py3_venv/lib64/python3.7/site-packages/paramiko/auth_handler.py", line 250, in wait_for_response
    raise e
paramiko.ssh_exception.AuthenticationException: Authentication failed.

During handling of the above exception, another exception occurred:

Traceback (most recent call last):
  File "/home/bradfernan/VENV/py3_venv/lib64/python3.7/site-packages/nornir/core/task.py", line 85, in start
    r = self.task(self, **self.params)
  File "/home/bradfernan/VENV/py3_venv/lib64/python3.7/site-packages/nornir/plugins/tasks/networking/netmiko_send_command.py", line 26, in netmiko_send_command
    net_connect = task.host.get_connection("netmiko", task.nornir.config)
  File "/home/bradfernan/VENV/py3_venv/lib64/python3.7/site-packages/nornir/core/inventory.py", line 302, in get_connection
    extras=conn.extras,
  File "/home/bradfernan/VENV/py3_venv/lib64/python3.7/site-packages/nornir/core/inventory.py", line 352, in open_connection
    configuration=configuration,
  File "/home/bradfernan/VENV/py3_venv/lib64/python3.7/site-packages/nornir/plugins/connections/netmiko.py", line 58, in open
    self.connection = ConnectHandler(**parameters)
  File "/home/bradfernan/VENV/py3_venv/lib64/python3.7/site-packages/netmiko/ssh_dispatcher.py", line 298, in ConnectHandler
    return ConnectionClass(*args, **kwargs)
  File "/home/bradfernan/VENV/py3_venv/lib64/python3.7/site-packages/netmiko/base_connection.py", line 341, in __init__
    self._open()
  File "/home/bradfernan/VENV/py3_venv/lib64/python3.7/site-packages/netmiko/base_connection.py", line 346, in _open
    self.establish_connection()
  File "/home/bradfernan/VENV/py3_venv/lib64/python3.7/site-packages/netmiko/base_connection.py", line 944, in establish_connection
    raise NetmikoAuthenticationException(msg)
netmiko.ssh_exception.NetmikoAuthenticationException: Authentication failure: unable to connect cisco_ios cisco3.lasthop.io:22
Authentication failed.

2020-12-22 22:14:20,447 -  nornir.core -     INFO -        run() - Running task 'netmiko_send_command' with args {'command_string': 'show ip int brief'} on 2 hosts
2020-12-22 22:15:04,663 -  nornir.core -     INFO -        run() - Running task 'netmiko_send_command' with args {'command_string': 'show ip int brief'} on 2 hosts
2020-12-22 22:15:07,401 - nornir.core.task -    ERROR -      start() - Host 'cisco3': task 'netmiko_send_command' failed with traceback:
Traceback (most recent call last):
  File "/home/bradfernan/VENV/py3_venv/lib64/python3.7/site-packages/netmiko/base_connection.py", line 915, in establish_connection
    self.remote_conn_pre.connect(**ssh_connect_params)
  File "/home/bradfernan/VENV/py3_venv/lib64/python3.7/site-packages/paramiko/client.py", line 446, in connect
    passphrase,
  File "/home/bradfernan/VENV/py3_venv/lib64/python3.7/site-packages/paramiko/client.py", line 764, in _auth
    raise saved_exception
  File "/home/bradfernan/VENV/py3_venv/lib64/python3.7/site-packages/paramiko/client.py", line 751, in _auth
    self._transport.auth_password(username, password)
  File "/home/bradfernan/VENV/py3_venv/lib64/python3.7/site-packages/paramiko/transport.py", line 1509, in auth_password
    return self.auth_handler.wait_for_response(my_event)
  File "/home/bradfernan/VENV/py3_venv/lib64/python3.7/site-packages/paramiko/auth_handler.py", line 250, in wait_for_response
    raise e
paramiko.ssh_exception.AuthenticationException: Authentication failed.

During handling of the above exception, another exception occurred:

Traceback (most recent call last):
  File "/home/bradfernan/VENV/py3_venv/lib64/python3.7/site-packages/nornir/core/task.py", line 85, in start
    r = self.task(self, **self.params)
  File "/home/bradfernan/VENV/py3_venv/lib64/python3.7/site-packages/nornir/plugins/tasks/networking/netmiko_send_command.py", line 26, in netmiko_send_command
    net_connect = task.host.get_connection("netmiko", task.nornir.config)
  File "/home/bradfernan/VENV/py3_venv/lib64/python3.7/site-packages/nornir/core/inventory.py", line 302, in get_connection
    extras=conn.extras,
  File "/home/bradfernan/VENV/py3_venv/lib64/python3.7/site-packages/nornir/core/inventory.py", line 352, in open_connection
    configuration=configuration,
  File "/home/bradfernan/VENV/py3_venv/lib64/python3.7/site-packages/nornir/plugins/connections/netmiko.py", line 58, in open
    self.connection = ConnectHandler(**parameters)
  File "/home/bradfernan/VENV/py3_venv/lib64/python3.7/site-packages/netmiko/ssh_dispatcher.py", line 298, in ConnectHandler
    return ConnectionClass(*args, **kwargs)
  File "/home/bradfernan/VENV/py3_venv/lib64/python3.7/site-packages/netmiko/base_connection.py", line 341, in __init__
    self._open()
  File "/home/bradfernan/VENV/py3_venv/lib64/python3.7/site-packages/netmiko/base_connection.py", line 346, in _open
    self.establish_connection()
  File "/home/bradfernan/VENV/py3_venv/lib64/python3.7/site-packages/netmiko/base_connection.py", line 944, in establish_connection
    raise NetmikoAuthenticationException(msg)
netmiko.ssh_exception.NetmikoAuthenticationException: Authentication failure: unable to connect cisco_ios cisco3.lasthop.io:22
Authentication failed.

2020-12-22 22:15:10,643 -  nornir.core -     INFO -        run() - Running task 'netmiko_send_command' with args {'command_string': 'show ip int brief'} on 2 hosts
2020-12-23 06:39:17,914 -  nornir.core -     INFO -        run() - Running task 'netmiko_send_command' with args {'command_string': 'show ip int brief'} on 2 hosts
2020-12-23 06:39:20,469 - nornir.core.task -    ERROR -      start() - Host 'cisco3': task 'netmiko_send_command' failed with traceback:
Traceback (most recent call last):
  File "/home/bradfernan/VENV/py3_venv/lib64/python3.7/site-packages/netmiko/base_connection.py", line 915, in establish_connection
    self.remote_conn_pre.connect(**ssh_connect_params)
  File "/home/bradfernan/VENV/py3_venv/lib64/python3.7/site-packages/paramiko/client.py", line 446, in connect
    passphrase,
  File "/home/bradfernan/VENV/py3_venv/lib64/python3.7/site-packages/paramiko/client.py", line 764, in _auth
    raise saved_exception
  File "/home/bradfernan/VENV/py3_venv/lib64/python3.7/site-packages/paramiko/client.py", line 751, in _auth
    self._transport.auth_password(username, password)
  File "/home/bradfernan/VENV/py3_venv/lib64/python3.7/site-packages/paramiko/transport.py", line 1509, in auth_password
    return self.auth_handler.wait_for_response(my_event)
  File "/home/bradfernan/VENV/py3_venv/lib64/python3.7/site-packages/paramiko/auth_handler.py", line 250, in wait_for_response
    raise e
paramiko.ssh_exception.AuthenticationException: Authentication failed.

During handling of the above exception, another exception occurred:

Traceback (most recent call last):
  File "/home/bradfernan/VENV/py3_venv/lib64/python3.7/site-packages/nornir/core/task.py", line 85, in start
    r = self.task(self, **self.params)
  File "/home/bradfernan/VENV/py3_venv/lib64/python3.7/site-packages/nornir/plugins/tasks/networking/netmiko_send_command.py", line 26, in netmiko_send_command
    net_connect = task.host.get_connection("netmiko", task.nornir.config)
  File "/home/bradfernan/VENV/py3_venv/lib64/python3.7/site-packages/nornir/core/inventory.py", line 302, in get_connection
    extras=conn.extras,
  File "/home/bradfernan/VENV/py3_venv/lib64/python3.7/site-packages/nornir/core/inventory.py", line 352, in open_connection
    configuration=configuration,
  File "/home/bradfernan/VENV/py3_venv/lib64/python3.7/site-packages/nornir/plugins/connections/netmiko.py", line 58, in open
    self.connection = ConnectHandler(**parameters)
  File "/home/bradfernan/VENV/py3_venv/lib64/python3.7/site-packages/netmiko/ssh_dispatcher.py", line 298, in ConnectHandler
    return ConnectionClass(*args, **kwargs)
  File "/home/bradfernan/VENV/py3_venv/lib64/python3.7/site-packages/netmiko/base_connection.py", line 341, in __init__
    self._open()
  File "/home/bradfernan/VENV/py3_venv/lib64/python3.7/site-packages/netmiko/base_connection.py", line 346, in _open
    self.establish_connection()
  File "/home/bradfernan/VENV/py3_venv/lib64/python3.7/site-packages/netmiko/base_connection.py", line 944, in establish_connection
    raise NetmikoAuthenticationException(msg)
netmiko.ssh_exception.NetmikoAuthenticationException: Authentication failure: unable to connect cisco_ios cisco3.lasthop.io:22
Authentication failed.

2020-12-23 06:39:23,870 -  nornir.core -     INFO -        run() - Running task 'netmiko_send_command' with args {'command_string': 'show ip int brief'} on 2 hosts
2020-12-23 20:20:55,078 -  nornir.core -     INFO -        run() - Running task 'netmiko_send_command' with args {'command_string': 'show ip int brief'} on 2 hosts
2020-12-23 20:22:05,163 -  nornir.core -     INFO -        run() - Running task 'netmiko_send_command' with args {'command_string': 'show ip int brief'} on 2 hosts
2020-12-23 20:22:07,915 - nornir.core.task -    ERROR -      start() - Host 'cisco3': task 'netmiko_send_command' failed with traceback:
Traceback (most recent call last):
  File "/home/bradfernan/VENV/py3_venv/lib64/python3.7/site-packages/netmiko/base_connection.py", line 915, in establish_connection
    self.remote_conn_pre.connect(**ssh_connect_params)
  File "/home/bradfernan/VENV/py3_venv/lib64/python3.7/site-packages/paramiko/client.py", line 446, in connect
    passphrase,
  File "/home/bradfernan/VENV/py3_venv/lib64/python3.7/site-packages/paramiko/client.py", line 764, in _auth
    raise saved_exception
  File "/home/bradfernan/VENV/py3_venv/lib64/python3.7/site-packages/paramiko/client.py", line 751, in _auth
    self._transport.auth_password(username, password)
  File "/home/bradfernan/VENV/py3_venv/lib64/python3.7/site-packages/paramiko/transport.py", line 1509, in auth_password
    return self.auth_handler.wait_for_response(my_event)
  File "/home/bradfernan/VENV/py3_venv/lib64/python3.7/site-packages/paramiko/auth_handler.py", line 250, in wait_for_response
    raise e
paramiko.ssh_exception.AuthenticationException: Authentication failed.

During handling of the above exception, another exception occurred:

Traceback (most recent call last):
  File "/home/bradfernan/VENV/py3_venv/lib64/python3.7/site-packages/nornir/core/task.py", line 85, in start
    r = self.task(self, **self.params)
  File "/home/bradfernan/VENV/py3_venv/lib64/python3.7/site-packages/nornir/plugins/tasks/networking/netmiko_send_command.py", line 26, in netmiko_send_command
    net_connect = task.host.get_connection("netmiko", task.nornir.config)
  File "/home/bradfernan/VENV/py3_venv/lib64/python3.7/site-packages/nornir/core/inventory.py", line 302, in get_connection
    extras=conn.extras,
  File "/home/bradfernan/VENV/py3_venv/lib64/python3.7/site-packages/nornir/core/inventory.py", line 352, in open_connection
    configuration=configuration,
  File "/home/bradfernan/VENV/py3_venv/lib64/python3.7/site-packages/nornir/plugins/connections/netmiko.py", line 58, in open
    self.connection = ConnectHandler(**parameters)
  File "/home/bradfernan/VENV/py3_venv/lib64/python3.7/site-packages/netmiko/ssh_dispatcher.py", line 298, in ConnectHandler
    return ConnectionClass(*args, **kwargs)
  File "/home/bradfernan/VENV/py3_venv/lib64/python3.7/site-packages/netmiko/base_connection.py", line 341, in __init__
    self._open()
  File "/home/bradfernan/VENV/py3_venv/lib64/python3.7/site-packages/netmiko/base_connection.py", line 346, in _open
    self.establish_connection()
  File "/home/bradfernan/VENV/py3_venv/lib64/python3.7/site-packages/netmiko/base_connection.py", line 944, in establish_connection
    raise NetmikoAuthenticationException(msg)
netmiko.ssh_exception.NetmikoAuthenticationException: Authentication failure: unable to connect cisco_ios cisco3.lasthop.io:22
Authentication failed.

2020-12-23 20:23:10,988 -  nornir.core -     INFO -        run() - Running task 'netmiko_send_command' with args {'command_string': 'show ip int brief'} on 2 hosts
2020-12-23 20:23:13,731 - nornir.core.task -    ERROR -      start() - Host 'cisco3': task 'netmiko_send_command' failed with traceback:
Traceback (most recent call last):
  File "/home/bradfernan/VENV/py3_venv/lib64/python3.7/site-packages/netmiko/base_connection.py", line 915, in establish_connection
    self.remote_conn_pre.connect(**ssh_connect_params)
  File "/home/bradfernan/VENV/py3_venv/lib64/python3.7/site-packages/paramiko/client.py", line 446, in connect
    passphrase,
  File "/home/bradfernan/VENV/py3_venv/lib64/python3.7/site-packages/paramiko/client.py", line 764, in _auth
    raise saved_exception
  File "/home/bradfernan/VENV/py3_venv/lib64/python3.7/site-packages/paramiko/client.py", line 751, in _auth
    self._transport.auth_password(username, password)
  File "/home/bradfernan/VENV/py3_venv/lib64/python3.7/site-packages/paramiko/transport.py", line 1509, in auth_password
    return self.auth_handler.wait_for_response(my_event)
  File "/home/bradfernan/VENV/py3_venv/lib64/python3.7/site-packages/paramiko/auth_handler.py", line 250, in wait_for_response
    raise e
paramiko.ssh_exception.AuthenticationException: Authentication failed.

During handling of the above exception, another exception occurred:

Traceback (most recent call last):
  File "/home/bradfernan/VENV/py3_venv/lib64/python3.7/site-packages/nornir/core/task.py", line 85, in start
    r = self.task(self, **self.params)
  File "/home/bradfernan/VENV/py3_venv/lib64/python3.7/site-packages/nornir/plugins/tasks/networking/netmiko_send_command.py", line 26, in netmiko_send_command
    net_connect = task.host.get_connection("netmiko", task.nornir.config)
  File "/home/bradfernan/VENV/py3_venv/lib64/python3.7/site-packages/nornir/core/inventory.py", line 302, in get_connection
    extras=conn.extras,
  File "/home/bradfernan/VENV/py3_venv/lib64/python3.7/site-packages/nornir/core/inventory.py", line 352, in open_connection
    configuration=configuration,
  File "/home/bradfernan/VENV/py3_venv/lib64/python3.7/site-packages/nornir/plugins/connections/netmiko.py", line 58, in open
    self.connection = ConnectHandler(**parameters)
  File "/home/bradfernan/VENV/py3_venv/lib64/python3.7/site-packages/netmiko/ssh_dispatcher.py", line 298, in ConnectHandler
    return ConnectionClass(*args, **kwargs)
  File "/home/bradfernan/VENV/py3_venv/lib64/python3.7/site-packages/netmiko/base_connection.py", line 341, in __init__
    self._open()
  File "/home/bradfernan/VENV/py3_venv/lib64/python3.7/site-packages/netmiko/base_connection.py", line 346, in _open
    self.establish_connection()
  File "/home/bradfernan/VENV/py3_venv/lib64/python3.7/site-packages/netmiko/base_connection.py", line 944, in establish_connection
    raise NetmikoAuthenticationException(msg)
netmiko.ssh_exception.NetmikoAuthenticationException: Authentication failure: unable to connect cisco_ios cisco3.lasthop.io:22
Authentication failed.

2020-12-23 20:33:54,332 -  nornir.core -     INFO -        run() - Running task 'netmiko_send_command' with args {'command_string': 'show ip int brief'} on 2 hosts
2020-12-23 20:33:57,090 - nornir.core.task -    ERROR -      start() - Host 'cisco3': task 'netmiko_send_command' failed with traceback:
Traceback (most recent call last):
  File "/home/bradfernan/VENV/py3_venv/lib64/python3.7/site-packages/netmiko/base_connection.py", line 915, in establish_connection
    self.remote_conn_pre.connect(**ssh_connect_params)
  File "/home/bradfernan/VENV/py3_venv/lib64/python3.7/site-packages/paramiko/client.py", line 446, in connect
    passphrase,
  File "/home/bradfernan/VENV/py3_venv/lib64/python3.7/site-packages/paramiko/client.py", line 764, in _auth
    raise saved_exception
  File "/home/bradfernan/VENV/py3_venv/lib64/python3.7/site-packages/paramiko/client.py", line 751, in _auth
    self._transport.auth_password(username, password)
  File "/home/bradfernan/VENV/py3_venv/lib64/python3.7/site-packages/paramiko/transport.py", line 1509, in auth_password
    return self.auth_handler.wait_for_response(my_event)
  File "/home/bradfernan/VENV/py3_venv/lib64/python3.7/site-packages/paramiko/auth_handler.py", line 250, in wait_for_response
    raise e
paramiko.ssh_exception.AuthenticationException: Authentication failed.

During handling of the above exception, another exception occurred:

Traceback (most recent call last):
  File "/home/bradfernan/VENV/py3_venv/lib64/python3.7/site-packages/nornir/core/task.py", line 85, in start
    r = self.task(self, **self.params)
  File "/home/bradfernan/VENV/py3_venv/lib64/python3.7/site-packages/nornir/plugins/tasks/networking/netmiko_send_command.py", line 26, in netmiko_send_command
    net_connect = task.host.get_connection("netmiko", task.nornir.config)
  File "/home/bradfernan/VENV/py3_venv/lib64/python3.7/site-packages/nornir/core/inventory.py", line 302, in get_connection
    extras=conn.extras,
  File "/home/bradfernan/VENV/py3_venv/lib64/python3.7/site-packages/nornir/core/inventory.py", line 352, in open_connection
    configuration=configuration,
  File "/home/bradfernan/VENV/py3_venv/lib64/python3.7/site-packages/nornir/plugins/connections/netmiko.py", line 58, in open
    self.connection = ConnectHandler(**parameters)
  File "/home/bradfernan/VENV/py3_venv/lib64/python3.7/site-packages/netmiko/ssh_dispatcher.py", line 298, in ConnectHandler
    return ConnectionClass(*args, **kwargs)
  File "/home/bradfernan/VENV/py3_venv/lib64/python3.7/site-packages/netmiko/base_connection.py", line 341, in __init__
    self._open()
  File "/home/bradfernan/VENV/py3_venv/lib64/python3.7/site-packages/netmiko/base_connection.py", line 346, in _open
    self.establish_connection()
  File "/home/bradfernan/VENV/py3_venv/lib64/python3.7/site-packages/netmiko/base_connection.py", line 944, in establish_connection
    raise NetmikoAuthenticationException(msg)
netmiko.ssh_exception.NetmikoAuthenticationException: Authentication failure: unable to connect cisco_ios cisco3.lasthop.io:22
Authentication failed.

2020-12-23 20:34:00,324 -  nornir.core -     INFO -        run() - Running task 'netmiko_send_command' with args {'command_string': 'show ip int brief'} on 2 hosts
2020-12-23 20:37:01,722 -  nornir.core -     INFO -        run() - Running task 'netmiko_send_command' with args {'command_string': 'show ip int brief'} on 2 hosts
2020-12-23 20:37:04,466 - nornir.core.task -    ERROR -      start() - Host 'cisco3': task 'netmiko_send_command' failed with traceback:
Traceback (most recent call last):
  File "/home/bradfernan/VENV/py3_venv/lib64/python3.7/site-packages/netmiko/base_connection.py", line 915, in establish_connection
    self.remote_conn_pre.connect(**ssh_connect_params)
  File "/home/bradfernan/VENV/py3_venv/lib64/python3.7/site-packages/paramiko/client.py", line 446, in connect
    passphrase,
  File "/home/bradfernan/VENV/py3_venv/lib64/python3.7/site-packages/paramiko/client.py", line 764, in _auth
    raise saved_exception
  File "/home/bradfernan/VENV/py3_venv/lib64/python3.7/site-packages/paramiko/client.py", line 751, in _auth
    self._transport.auth_password(username, password)
  File "/home/bradfernan/VENV/py3_venv/lib64/python3.7/site-packages/paramiko/transport.py", line 1509, in auth_password
    return self.auth_handler.wait_for_response(my_event)
  File "/home/bradfernan/VENV/py3_venv/lib64/python3.7/site-packages/paramiko/auth_handler.py", line 250, in wait_for_response
    raise e
paramiko.ssh_exception.AuthenticationException: Authentication failed.

During handling of the above exception, another exception occurred:

Traceback (most recent call last):
  File "/home/bradfernan/VENV/py3_venv/lib64/python3.7/site-packages/nornir/core/task.py", line 85, in start
    r = self.task(self, **self.params)
  File "/home/bradfernan/VENV/py3_venv/lib64/python3.7/site-packages/nornir/plugins/tasks/networking/netmiko_send_command.py", line 26, in netmiko_send_command
    net_connect = task.host.get_connection("netmiko", task.nornir.config)
  File "/home/bradfernan/VENV/py3_venv/lib64/python3.7/site-packages/nornir/core/inventory.py", line 302, in get_connection
    extras=conn.extras,
  File "/home/bradfernan/VENV/py3_venv/lib64/python3.7/site-packages/nornir/core/inventory.py", line 352, in open_connection
    configuration=configuration,
  File "/home/bradfernan/VENV/py3_venv/lib64/python3.7/site-packages/nornir/plugins/connections/netmiko.py", line 58, in open
    self.connection = ConnectHandler(**parameters)
  File "/home/bradfernan/VENV/py3_venv/lib64/python3.7/site-packages/netmiko/ssh_dispatcher.py", line 298, in ConnectHandler
    return ConnectionClass(*args, **kwargs)
  File "/home/bradfernan/VENV/py3_venv/lib64/python3.7/site-packages/netmiko/base_connection.py", line 341, in __init__
    self._open()
  File "/home/bradfernan/VENV/py3_venv/lib64/python3.7/site-packages/netmiko/base_connection.py", line 346, in _open
    self.establish_connection()
  File "/home/bradfernan/VENV/py3_venv/lib64/python3.7/site-packages/netmiko/base_connection.py", line 944, in establish_connection
    raise NetmikoAuthenticationException(msg)
netmiko.ssh_exception.NetmikoAuthenticationException: Authentication failure: unable to connect cisco_ios cisco3.lasthop.io:22
Authentication failed.

2020-12-23 20:39:11,986 -  nornir.core -     INFO -        run() - Running task 'netmiko_send_command' with args {'command_string': 'show ip int brief'} on 2 hosts
2020-12-23 20:39:14,750 - nornir.core.task -    ERROR -      start() - Host 'cisco3': task 'netmiko_send_command' failed with traceback:
Traceback (most recent call last):
  File "/home/bradfernan/VENV/py3_venv/lib64/python3.7/site-packages/netmiko/base_connection.py", line 915, in establish_connection
    self.remote_conn_pre.connect(**ssh_connect_params)
  File "/home/bradfernan/VENV/py3_venv/lib64/python3.7/site-packages/paramiko/client.py", line 446, in connect
    passphrase,
  File "/home/bradfernan/VENV/py3_venv/lib64/python3.7/site-packages/paramiko/client.py", line 764, in _auth
    raise saved_exception
  File "/home/bradfernan/VENV/py3_venv/lib64/python3.7/site-packages/paramiko/client.py", line 751, in _auth
    self._transport.auth_password(username, password)
  File "/home/bradfernan/VENV/py3_venv/lib64/python3.7/site-packages/paramiko/transport.py", line 1509, in auth_password
    return self.auth_handler.wait_for_response(my_event)
  File "/home/bradfernan/VENV/py3_venv/lib64/python3.7/site-packages/paramiko/auth_handler.py", line 250, in wait_for_response
    raise e
paramiko.ssh_exception.AuthenticationException: Authentication failed.

During handling of the above exception, another exception occurred:

Traceback (most recent call last):
  File "/home/bradfernan/VENV/py3_venv/lib64/python3.7/site-packages/nornir/core/task.py", line 85, in start
    r = self.task(self, **self.params)
  File "/home/bradfernan/VENV/py3_venv/lib64/python3.7/site-packages/nornir/plugins/tasks/networking/netmiko_send_command.py", line 26, in netmiko_send_command
    net_connect = task.host.get_connection("netmiko", task.nornir.config)
  File "/home/bradfernan/VENV/py3_venv/lib64/python3.7/site-packages/nornir/core/inventory.py", line 302, in get_connection
    extras=conn.extras,
  File "/home/bradfernan/VENV/py3_venv/lib64/python3.7/site-packages/nornir/core/inventory.py", line 352, in open_connection
    configuration=configuration,
  File "/home/bradfernan/VENV/py3_venv/lib64/python3.7/site-packages/nornir/plugins/connections/netmiko.py", line 58, in open
    self.connection = ConnectHandler(**parameters)
  File "/home/bradfernan/VENV/py3_venv/lib64/python3.7/site-packages/netmiko/ssh_dispatcher.py", line 298, in ConnectHandler
    return ConnectionClass(*args, **kwargs)
  File "/home/bradfernan/VENV/py3_venv/lib64/python3.7/site-packages/netmiko/base_connection.py", line 341, in __init__
    self._open()
  File "/home/bradfernan/VENV/py3_venv/lib64/python3.7/site-packages/netmiko/base_connection.py", line 346, in _open
    self.establish_connection()
  File "/home/bradfernan/VENV/py3_venv/lib64/python3.7/site-packages/netmiko/base_connection.py", line 944, in establish_connection
    raise NetmikoAuthenticationException(msg)
netmiko.ssh_exception.NetmikoAuthenticationException: Authentication failure: unable to connect cisco_ios cisco3.lasthop.io:22
Authentication failed.

2020-12-23 20:40:25,814 -  nornir.core -     INFO -        run() - Running task 'netmiko_send_command' with args {'command_string': 'show ip int brief'} on 2 hosts
2020-12-23 20:40:28,562 - nornir.core.task -    ERROR -      start() - Host 'cisco3': task 'netmiko_send_command' failed with traceback:
Traceback (most recent call last):
  File "/home/bradfernan/VENV/py3_venv/lib64/python3.7/site-packages/netmiko/base_connection.py", line 915, in establish_connection
    self.remote_conn_pre.connect(**ssh_connect_params)
  File "/home/bradfernan/VENV/py3_venv/lib64/python3.7/site-packages/paramiko/client.py", line 446, in connect
    passphrase,
  File "/home/bradfernan/VENV/py3_venv/lib64/python3.7/site-packages/paramiko/client.py", line 764, in _auth
    raise saved_exception
  File "/home/bradfernan/VENV/py3_venv/lib64/python3.7/site-packages/paramiko/client.py", line 751, in _auth
    self._transport.auth_password(username, password)
  File "/home/bradfernan/VENV/py3_venv/lib64/python3.7/site-packages/paramiko/transport.py", line 1509, in auth_password
    return self.auth_handler.wait_for_response(my_event)
  File "/home/bradfernan/VENV/py3_venv/lib64/python3.7/site-packages/paramiko/auth_handler.py", line 250, in wait_for_response
    raise e
paramiko.ssh_exception.AuthenticationException: Authentication failed.

During handling of the above exception, another exception occurred:

Traceback (most recent call last):
  File "/home/bradfernan/VENV/py3_venv/lib64/python3.7/site-packages/nornir/core/task.py", line 85, in start
    r = self.task(self, **self.params)
  File "/home/bradfernan/VENV/py3_venv/lib64/python3.7/site-packages/nornir/plugins/tasks/networking/netmiko_send_command.py", line 26, in netmiko_send_command
    net_connect = task.host.get_connection("netmiko", task.nornir.config)
  File "/home/bradfernan/VENV/py3_venv/lib64/python3.7/site-packages/nornir/core/inventory.py", line 302, in get_connection
    extras=conn.extras,
  File "/home/bradfernan/VENV/py3_venv/lib64/python3.7/site-packages/nornir/core/inventory.py", line 352, in open_connection
    configuration=configuration,
  File "/home/bradfernan/VENV/py3_venv/lib64/python3.7/site-packages/nornir/plugins/connections/netmiko.py", line 58, in open
    self.connection = ConnectHandler(**parameters)
  File "/home/bradfernan/VENV/py3_venv/lib64/python3.7/site-packages/netmiko/ssh_dispatcher.py", line 298, in ConnectHandler
    return ConnectionClass(*args, **kwargs)
  File "/home/bradfernan/VENV/py3_venv/lib64/python3.7/site-packages/netmiko/base_connection.py", line 341, in __init__
    self._open()
  File "/home/bradfernan/VENV/py3_venv/lib64/python3.7/site-packages/netmiko/base_connection.py", line 346, in _open
    self.establish_connection()
  File "/home/bradfernan/VENV/py3_venv/lib64/python3.7/site-packages/netmiko/base_connection.py", line 944, in establish_connection
    raise NetmikoAuthenticationException(msg)
netmiko.ssh_exception.NetmikoAuthenticationException: Authentication failure: unable to connect cisco_ios cisco3.lasthop.io:22
Authentication failed.

2020-12-23 20:40:31,800 -  nornir.core -     INFO -        run() - Running task 'netmiko_send_command' with args {'command_string': 'show ip int brief'} on 2 hosts
2020-12-23 20:41:07,120 -  nornir.core -     INFO -        run() - Running task 'netmiko_send_command' with args {'command_string': 'show ip int brief'} on 2 hosts
2020-12-23 20:41:09,862 - nornir.core.task -    ERROR -      start() - Host 'cisco3': task 'netmiko_send_command' failed with traceback:
Traceback (most recent call last):
  File "/home/bradfernan/VENV/py3_venv/lib64/python3.7/site-packages/netmiko/base_connection.py", line 915, in establish_connection
    self.remote_conn_pre.connect(**ssh_connect_params)
  File "/home/bradfernan/VENV/py3_venv/lib64/python3.7/site-packages/paramiko/client.py", line 446, in connect
    passphrase,
  File "/home/bradfernan/VENV/py3_venv/lib64/python3.7/site-packages/paramiko/client.py", line 764, in _auth
    raise saved_exception
  File "/home/bradfernan/VENV/py3_venv/lib64/python3.7/site-packages/paramiko/client.py", line 751, in _auth
    self._transport.auth_password(username, password)
  File "/home/bradfernan/VENV/py3_venv/lib64/python3.7/site-packages/paramiko/transport.py", line 1509, in auth_password
    return self.auth_handler.wait_for_response(my_event)
  File "/home/bradfernan/VENV/py3_venv/lib64/python3.7/site-packages/paramiko/auth_handler.py", line 250, in wait_for_response
    raise e
paramiko.ssh_exception.AuthenticationException: Authentication failed.

During handling of the above exception, another exception occurred:

Traceback (most recent call last):
  File "/home/bradfernan/VENV/py3_venv/lib64/python3.7/site-packages/nornir/core/task.py", line 85, in start
    r = self.task(self, **self.params)
  File "/home/bradfernan/VENV/py3_venv/lib64/python3.7/site-packages/nornir/plugins/tasks/networking/netmiko_send_command.py", line 26, in netmiko_send_command
    net_connect = task.host.get_connection("netmiko", task.nornir.config)
  File "/home/bradfernan/VENV/py3_venv/lib64/python3.7/site-packages/nornir/core/inventory.py", line 302, in get_connection
    extras=conn.extras,
  File "/home/bradfernan/VENV/py3_venv/lib64/python3.7/site-packages/nornir/core/inventory.py", line 352, in open_connection
    configuration=configuration,
  File "/home/bradfernan/VENV/py3_venv/lib64/python3.7/site-packages/nornir/plugins/connections/netmiko.py", line 58, in open
    self.connection = ConnectHandler(**parameters)
  File "/home/bradfernan/VENV/py3_venv/lib64/python3.7/site-packages/netmiko/ssh_dispatcher.py", line 298, in ConnectHandler
    return ConnectionClass(*args, **kwargs)
  File "/home/bradfernan/VENV/py3_venv/lib64/python3.7/site-packages/netmiko/base_connection.py", line 341, in __init__
    self._open()
  File "/home/bradfernan/VENV/py3_venv/lib64/python3.7/site-packages/netmiko/base_connection.py", line 346, in _open
    self.establish_connection()
  File "/home/bradfernan/VENV/py3_venv/lib64/python3.7/site-packages/netmiko/base_connection.py", line 944, in establish_connection
    raise NetmikoAuthenticationException(msg)
netmiko.ssh_exception.NetmikoAuthenticationException: Authentication failure: unable to connect cisco_ios cisco3.lasthop.io:22
Authentication failed.

2020-12-23 20:41:13,097 -  nornir.core -     INFO -        run() - Running task 'netmiko_send_command' with args {'command_string': 'show ip int brief'} on 2 hosts
2020-12-23 20:43:58,390 -  nornir.core -     INFO -        run() - Running task 'netmiko_send_command' with args {'command_string': 'show ip int brief'} on 2 hosts
2020-12-23 20:44:00,887 - nornir.core.task -    ERROR -      start() - Host 'cisco3': task 'netmiko_send_command' failed with traceback:
Traceback (most recent call last):
  File "/home/bradfernan/VENV/py3_venv/lib64/python3.7/site-packages/netmiko/base_connection.py", line 915, in establish_connection
    self.remote_conn_pre.connect(**ssh_connect_params)
  File "/home/bradfernan/VENV/py3_venv/lib64/python3.7/site-packages/paramiko/client.py", line 446, in connect
    passphrase,
  File "/home/bradfernan/VENV/py3_venv/lib64/python3.7/site-packages/paramiko/client.py", line 764, in _auth
    raise saved_exception
  File "/home/bradfernan/VENV/py3_venv/lib64/python3.7/site-packages/paramiko/client.py", line 751, in _auth
    self._transport.auth_password(username, password)
  File "/home/bradfernan/VENV/py3_venv/lib64/python3.7/site-packages/paramiko/transport.py", line 1509, in auth_password
    return self.auth_handler.wait_for_response(my_event)
  File "/home/bradfernan/VENV/py3_venv/lib64/python3.7/site-packages/paramiko/auth_handler.py", line 250, in wait_for_response
    raise e
paramiko.ssh_exception.AuthenticationException: Authentication failed.

During handling of the above exception, another exception occurred:

Traceback (most recent call last):
  File "/home/bradfernan/VENV/py3_venv/lib64/python3.7/site-packages/nornir/core/task.py", line 85, in start
    r = self.task(self, **self.params)
  File "/home/bradfernan/VENV/py3_venv/lib64/python3.7/site-packages/nornir/plugins/tasks/networking/netmiko_send_command.py", line 26, in netmiko_send_command
    net_connect = task.host.get_connection("netmiko", task.nornir.config)
  File "/home/bradfernan/VENV/py3_venv/lib64/python3.7/site-packages/nornir/core/inventory.py", line 302, in get_connection
    extras=conn.extras,
  File "/home/bradfernan/VENV/py3_venv/lib64/python3.7/site-packages/nornir/core/inventory.py", line 352, in open_connection
    configuration=configuration,
  File "/home/bradfernan/VENV/py3_venv/lib64/python3.7/site-packages/nornir/plugins/connections/netmiko.py", line 58, in open
    self.connection = ConnectHandler(**parameters)
  File "/home/bradfernan/VENV/py3_venv/lib64/python3.7/site-packages/netmiko/ssh_dispatcher.py", line 298, in ConnectHandler
    return ConnectionClass(*args, **kwargs)
  File "/home/bradfernan/VENV/py3_venv/lib64/python3.7/site-packages/netmiko/base_connection.py", line 341, in __init__
    self._open()
  File "/home/bradfernan/VENV/py3_venv/lib64/python3.7/site-packages/netmiko/base_connection.py", line 346, in _open
    self.establish_connection()
  File "/home/bradfernan/VENV/py3_venv/lib64/python3.7/site-packages/netmiko/base_connection.py", line 944, in establish_connection
    raise NetmikoAuthenticationException(msg)
netmiko.ssh_exception.NetmikoAuthenticationException: Authentication failure: unable to connect cisco_ios cisco3.lasthop.io:22
Authentication failed.

2020-12-23 20:44:04,324 -  nornir.core -     INFO -        run() - Running task 'netmiko_send_command' with args {'command_string': 'show ip int brief'} on 2 hosts
2020-12-23 20:49:09,329 -  nornir.core -     INFO -        run() - Running task 'netmiko_send_command' with args {'command_string': 'show ip int brief'} on 2 hosts
2020-12-23 20:49:12,097 - nornir.core.task -    ERROR -      start() - Host 'cisco3': task 'netmiko_send_command' failed with traceback:
Traceback (most recent call last):
  File "/home/bradfernan/VENV/py3_venv/lib64/python3.7/site-packages/netmiko/base_connection.py", line 915, in establish_connection
    self.remote_conn_pre.connect(**ssh_connect_params)
  File "/home/bradfernan/VENV/py3_venv/lib64/python3.7/site-packages/paramiko/client.py", line 446, in connect
    passphrase,
  File "/home/bradfernan/VENV/py3_venv/lib64/python3.7/site-packages/paramiko/client.py", line 764, in _auth
    raise saved_exception
  File "/home/bradfernan/VENV/py3_venv/lib64/python3.7/site-packages/paramiko/client.py", line 751, in _auth
    self._transport.auth_password(username, password)
  File "/home/bradfernan/VENV/py3_venv/lib64/python3.7/site-packages/paramiko/transport.py", line 1509, in auth_password
    return self.auth_handler.wait_for_response(my_event)
  File "/home/bradfernan/VENV/py3_venv/lib64/python3.7/site-packages/paramiko/auth_handler.py", line 250, in wait_for_response
    raise e
paramiko.ssh_exception.AuthenticationException: Authentication failed.

During handling of the above exception, another exception occurred:

Traceback (most recent call last):
  File "/home/bradfernan/VENV/py3_venv/lib64/python3.7/site-packages/nornir/core/task.py", line 85, in start
    r = self.task(self, **self.params)
  File "/home/bradfernan/VENV/py3_venv/lib64/python3.7/site-packages/nornir/plugins/tasks/networking/netmiko_send_command.py", line 26, in netmiko_send_command
    net_connect = task.host.get_connection("netmiko", task.nornir.config)
  File "/home/bradfernan/VENV/py3_venv/lib64/python3.7/site-packages/nornir/core/inventory.py", line 302, in get_connection
    extras=conn.extras,
  File "/home/bradfernan/VENV/py3_venv/lib64/python3.7/site-packages/nornir/core/inventory.py", line 352, in open_connection
    configuration=configuration,
  File "/home/bradfernan/VENV/py3_venv/lib64/python3.7/site-packages/nornir/plugins/connections/netmiko.py", line 58, in open
    self.connection = ConnectHandler(**parameters)
  File "/home/bradfernan/VENV/py3_venv/lib64/python3.7/site-packages/netmiko/ssh_dispatcher.py", line 298, in ConnectHandler
    return ConnectionClass(*args, **kwargs)
  File "/home/bradfernan/VENV/py3_venv/lib64/python3.7/site-packages/netmiko/base_connection.py", line 341, in __init__
    self._open()
  File "/home/bradfernan/VENV/py3_venv/lib64/python3.7/site-packages/netmiko/base_connection.py", line 346, in _open
    self.establish_connection()
  File "/home/bradfernan/VENV/py3_venv/lib64/python3.7/site-packages/netmiko/base_connection.py", line 944, in establish_connection
    raise NetmikoAuthenticationException(msg)
netmiko.ssh_exception.NetmikoAuthenticationException: Authentication failure: unable to connect cisco_ios cisco3.lasthop.io:22
Authentication failed.

2020-12-23 20:49:15,330 -  nornir.core -     INFO -        run() - Running task 'netmiko_send_command' with args {'command_string': 'show ip int brief'} on 2 hosts
2020-12-23 20:49:54,391 -  nornir.core -     INFO -        run() - Running task 'netmiko_send_command' with args {'command_string': 'show ip int brief'} on 2 hosts
2020-12-23 20:49:57,138 - nornir.core.task -    ERROR -      start() - Host 'cisco3': task 'netmiko_send_command' failed with traceback:
Traceback (most recent call last):
  File "/home/bradfernan/VENV/py3_venv/lib64/python3.7/site-packages/netmiko/base_connection.py", line 915, in establish_connection
    self.remote_conn_pre.connect(**ssh_connect_params)
  File "/home/bradfernan/VENV/py3_venv/lib64/python3.7/site-packages/paramiko/client.py", line 446, in connect
    passphrase,
  File "/home/bradfernan/VENV/py3_venv/lib64/python3.7/site-packages/paramiko/client.py", line 764, in _auth
    raise saved_exception
  File "/home/bradfernan/VENV/py3_venv/lib64/python3.7/site-packages/paramiko/client.py", line 751, in _auth
    self._transport.auth_password(username, password)
  File "/home/bradfernan/VENV/py3_venv/lib64/python3.7/site-packages/paramiko/transport.py", line 1509, in auth_password
    return self.auth_handler.wait_for_response(my_event)
  File "/home/bradfernan/VENV/py3_venv/lib64/python3.7/site-packages/paramiko/auth_handler.py", line 250, in wait_for_response
    raise e
paramiko.ssh_exception.AuthenticationException: Authentication failed.

During handling of the above exception, another exception occurred:

Traceback (most recent call last):
  File "/home/bradfernan/VENV/py3_venv/lib64/python3.7/site-packages/nornir/core/task.py", line 85, in start
    r = self.task(self, **self.params)
  File "/home/bradfernan/VENV/py3_venv/lib64/python3.7/site-packages/nornir/plugins/tasks/networking/netmiko_send_command.py", line 26, in netmiko_send_command
    net_connect = task.host.get_connection("netmiko", task.nornir.config)
  File "/home/bradfernan/VENV/py3_venv/lib64/python3.7/site-packages/nornir/core/inventory.py", line 302, in get_connection
    extras=conn.extras,
  File "/home/bradfernan/VENV/py3_venv/lib64/python3.7/site-packages/nornir/core/inventory.py", line 352, in open_connection
    configuration=configuration,
  File "/home/bradfernan/VENV/py3_venv/lib64/python3.7/site-packages/nornir/plugins/connections/netmiko.py", line 58, in open
    self.connection = ConnectHandler(**parameters)
  File "/home/bradfernan/VENV/py3_venv/lib64/python3.7/site-packages/netmiko/ssh_dispatcher.py", line 298, in ConnectHandler
    return ConnectionClass(*args, **kwargs)
  File "/home/bradfernan/VENV/py3_venv/lib64/python3.7/site-packages/netmiko/base_connection.py", line 341, in __init__
    self._open()
  File "/home/bradfernan/VENV/py3_venv/lib64/python3.7/site-packages/netmiko/base_connection.py", line 346, in _open
    self.establish_connection()
  File "/home/bradfernan/VENV/py3_venv/lib64/python3.7/site-packages/netmiko/base_connection.py", line 944, in establish_connection
    raise NetmikoAuthenticationException(msg)
netmiko.ssh_exception.NetmikoAuthenticationException: Authentication failure: unable to connect cisco_ios cisco3.lasthop.io:22
Authentication failed.

2020-12-23 20:50:00,366 -  nornir.core -     INFO -        run() - Running task 'netmiko_send_command' with args {'command_string': 'show ip int brief'} on 2 hosts
2020-12-23 20:55:10,314 -  nornir.core -     INFO -        run() - Running task 'netmiko_send_command' with args {'command_string': 'show ip int brief'} on 2 hosts
2020-12-23 20:55:13,014 - nornir.core.task -    ERROR -      start() - Host 'cisco3': task 'netmiko_send_command' failed with traceback:
Traceback (most recent call last):
  File "/home/bradfernan/VENV/py3_venv/lib64/python3.7/site-packages/netmiko/base_connection.py", line 915, in establish_connection
    self.remote_conn_pre.connect(**ssh_connect_params)
  File "/home/bradfernan/VENV/py3_venv/lib64/python3.7/site-packages/paramiko/client.py", line 446, in connect
    passphrase,
  File "/home/bradfernan/VENV/py3_venv/lib64/python3.7/site-packages/paramiko/client.py", line 764, in _auth
    raise saved_exception
  File "/home/bradfernan/VENV/py3_venv/lib64/python3.7/site-packages/paramiko/client.py", line 751, in _auth
    self._transport.auth_password(username, password)
  File "/home/bradfernan/VENV/py3_venv/lib64/python3.7/site-packages/paramiko/transport.py", line 1509, in auth_password
    return self.auth_handler.wait_for_response(my_event)
  File "/home/bradfernan/VENV/py3_venv/lib64/python3.7/site-packages/paramiko/auth_handler.py", line 250, in wait_for_response
    raise e
paramiko.ssh_exception.AuthenticationException: Authentication failed.

During handling of the above exception, another exception occurred:

Traceback (most recent call last):
  File "/home/bradfernan/VENV/py3_venv/lib64/python3.7/site-packages/nornir/core/task.py", line 85, in start
    r = self.task(self, **self.params)
  File "/home/bradfernan/VENV/py3_venv/lib64/python3.7/site-packages/nornir/plugins/tasks/networking/netmiko_send_command.py", line 26, in netmiko_send_command
    net_connect = task.host.get_connection("netmiko", task.nornir.config)
  File "/home/bradfernan/VENV/py3_venv/lib64/python3.7/site-packages/nornir/core/inventory.py", line 302, in get_connection
    extras=conn.extras,
  File "/home/bradfernan/VENV/py3_venv/lib64/python3.7/site-packages/nornir/core/inventory.py", line 352, in open_connection
    configuration=configuration,
  File "/home/bradfernan/VENV/py3_venv/lib64/python3.7/site-packages/nornir/plugins/connections/netmiko.py", line 58, in open
    self.connection = ConnectHandler(**parameters)
  File "/home/bradfernan/VENV/py3_venv/lib64/python3.7/site-packages/netmiko/ssh_dispatcher.py", line 298, in ConnectHandler
    return ConnectionClass(*args, **kwargs)
  File "/home/bradfernan/VENV/py3_venv/lib64/python3.7/site-packages/netmiko/base_connection.py", line 341, in __init__
    self._open()
  File "/home/bradfernan/VENV/py3_venv/lib64/python3.7/site-packages/netmiko/base_connection.py", line 346, in _open
    self.establish_connection()
  File "/home/bradfernan/VENV/py3_venv/lib64/python3.7/site-packages/netmiko/base_connection.py", line 944, in establish_connection
    raise NetmikoAuthenticationException(msg)
netmiko.ssh_exception.NetmikoAuthenticationException: Authentication failure: unable to connect cisco_ios cisco3.lasthop.io:22
Authentication failed.

2020-12-23 21:10:47,100 -  nornir.core -     INFO -        run() - Running task 'netmiko_send_command' with args {'command_string': 'show ip int brief'} on 2 hosts
2020-12-23 21:10:49,857 - nornir.core.task -    ERROR -      start() - Host 'cisco3': task 'netmiko_send_command' failed with traceback:
Traceback (most recent call last):
  File "/home/bradfernan/VENV/py3_venv/lib64/python3.7/site-packages/netmiko/base_connection.py", line 915, in establish_connection
    self.remote_conn_pre.connect(**ssh_connect_params)
  File "/home/bradfernan/VENV/py3_venv/lib64/python3.7/site-packages/paramiko/client.py", line 446, in connect
    passphrase,
  File "/home/bradfernan/VENV/py3_venv/lib64/python3.7/site-packages/paramiko/client.py", line 764, in _auth
    raise saved_exception
  File "/home/bradfernan/VENV/py3_venv/lib64/python3.7/site-packages/paramiko/client.py", line 751, in _auth
    self._transport.auth_password(username, password)
  File "/home/bradfernan/VENV/py3_venv/lib64/python3.7/site-packages/paramiko/transport.py", line 1509, in auth_password
    return self.auth_handler.wait_for_response(my_event)
  File "/home/bradfernan/VENV/py3_venv/lib64/python3.7/site-packages/paramiko/auth_handler.py", line 250, in wait_for_response
    raise e
paramiko.ssh_exception.AuthenticationException: Authentication failed.

During handling of the above exception, another exception occurred:

Traceback (most recent call last):
  File "/home/bradfernan/VENV/py3_venv/lib64/python3.7/site-packages/nornir/core/task.py", line 85, in start
    r = self.task(self, **self.params)
  File "/home/bradfernan/VENV/py3_venv/lib64/python3.7/site-packages/nornir/plugins/tasks/networking/netmiko_send_command.py", line 26, in netmiko_send_command
    net_connect = task.host.get_connection("netmiko", task.nornir.config)
  File "/home/bradfernan/VENV/py3_venv/lib64/python3.7/site-packages/nornir/core/inventory.py", line 302, in get_connection
    extras=conn.extras,
  File "/home/bradfernan/VENV/py3_venv/lib64/python3.7/site-packages/nornir/core/inventory.py", line 352, in open_connection
    configuration=configuration,
  File "/home/bradfernan/VENV/py3_venv/lib64/python3.7/site-packages/nornir/plugins/connections/netmiko.py", line 58, in open
    self.connection = ConnectHandler(**parameters)
  File "/home/bradfernan/VENV/py3_venv/lib64/python3.7/site-packages/netmiko/ssh_dispatcher.py", line 298, in ConnectHandler
    return ConnectionClass(*args, **kwargs)
  File "/home/bradfernan/VENV/py3_venv/lib64/python3.7/site-packages/netmiko/base_connection.py", line 341, in __init__
    self._open()
  File "/home/bradfernan/VENV/py3_venv/lib64/python3.7/site-packages/netmiko/base_connection.py", line 346, in _open
    self.establish_connection()
  File "/home/bradfernan/VENV/py3_venv/lib64/python3.7/site-packages/netmiko/base_connection.py", line 944, in establish_connection
    raise NetmikoAuthenticationException(msg)
netmiko.ssh_exception.NetmikoAuthenticationException: Authentication failure: unable to connect cisco_ios cisco3.lasthop.io:22
Authentication failed.

2020-12-23 21:10:53,102 -  nornir.core -     INFO -        run() - Running task 'netmiko_send_command' with args {'command_string': 'show ip int brief'} on 2 hosts
2020-12-23 21:56:49,293 -  nornir.core -     INFO -        run() - Running task 'netmiko_send_command' with args {'command_string': 'show ip int brief'} on 2 hosts
2020-12-23 21:56:52,067 - nornir.core.task -    ERROR -      start() - Host 'cisco3': task 'netmiko_send_command' failed with traceback:
Traceback (most recent call last):
  File "/home/bradfernan/VENV/py3_venv/lib64/python3.7/site-packages/netmiko/base_connection.py", line 915, in establish_connection
    self.remote_conn_pre.connect(**ssh_connect_params)
  File "/home/bradfernan/VENV/py3_venv/lib64/python3.7/site-packages/paramiko/client.py", line 446, in connect
    passphrase,
  File "/home/bradfernan/VENV/py3_venv/lib64/python3.7/site-packages/paramiko/client.py", line 764, in _auth
    raise saved_exception
  File "/home/bradfernan/VENV/py3_venv/lib64/python3.7/site-packages/paramiko/client.py", line 751, in _auth
    self._transport.auth_password(username, password)
  File "/home/bradfernan/VENV/py3_venv/lib64/python3.7/site-packages/paramiko/transport.py", line 1509, in auth_password
    return self.auth_handler.wait_for_response(my_event)
  File "/home/bradfernan/VENV/py3_venv/lib64/python3.7/site-packages/paramiko/auth_handler.py", line 250, in wait_for_response
    raise e
paramiko.ssh_exception.AuthenticationException: Authentication failed.

During handling of the above exception, another exception occurred:

Traceback (most recent call last):
  File "/home/bradfernan/VENV/py3_venv/lib64/python3.7/site-packages/nornir/core/task.py", line 85, in start
    r = self.task(self, **self.params)
  File "/home/bradfernan/VENV/py3_venv/lib64/python3.7/site-packages/nornir/plugins/tasks/networking/netmiko_send_command.py", line 26, in netmiko_send_command
    net_connect = task.host.get_connection("netmiko", task.nornir.config)
  File "/home/bradfernan/VENV/py3_venv/lib64/python3.7/site-packages/nornir/core/inventory.py", line 302, in get_connection
    extras=conn.extras,
  File "/home/bradfernan/VENV/py3_venv/lib64/python3.7/site-packages/nornir/core/inventory.py", line 352, in open_connection
    configuration=configuration,
  File "/home/bradfernan/VENV/py3_venv/lib64/python3.7/site-packages/nornir/plugins/connections/netmiko.py", line 58, in open
    self.connection = ConnectHandler(**parameters)
  File "/home/bradfernan/VENV/py3_venv/lib64/python3.7/site-packages/netmiko/ssh_dispatcher.py", line 298, in ConnectHandler
    return ConnectionClass(*args, **kwargs)
  File "/home/bradfernan/VENV/py3_venv/lib64/python3.7/site-packages/netmiko/base_connection.py", line 341, in __init__
    self._open()
  File "/home/bradfernan/VENV/py3_venv/lib64/python3.7/site-packages/netmiko/base_connection.py", line 346, in _open
    self.establish_connection()
  File "/home/bradfernan/VENV/py3_venv/lib64/python3.7/site-packages/netmiko/base_connection.py", line 944, in establish_connection
    raise NetmikoAuthenticationException(msg)
netmiko.ssh_exception.NetmikoAuthenticationException: Authentication failure: unable to connect cisco_ios cisco3.lasthop.io:22
Authentication failed.

2020-12-23 21:56:55,303 -  nornir.core -     INFO -        run() - Running task 'netmiko_send_command' with args {'command_string': 'show ip int brief'} on 2 hosts
2020-12-23 22:01:52,508 -  nornir.core -     INFO -        run() - Running task 'netmiko_send_command' with args {'command_string': 'show ip int brief'} on 2 hosts
2020-12-23 22:01:55,262 - nornir.core.task -    ERROR -      start() - Host 'cisco3': task 'netmiko_send_command' failed with traceback:
Traceback (most recent call last):
  File "/home/bradfernan/VENV/py3_venv/lib64/python3.7/site-packages/netmiko/base_connection.py", line 915, in establish_connection
    self.remote_conn_pre.connect(**ssh_connect_params)
  File "/home/bradfernan/VENV/py3_venv/lib64/python3.7/site-packages/paramiko/client.py", line 446, in connect
    passphrase,
  File "/home/bradfernan/VENV/py3_venv/lib64/python3.7/site-packages/paramiko/client.py", line 764, in _auth
    raise saved_exception
  File "/home/bradfernan/VENV/py3_venv/lib64/python3.7/site-packages/paramiko/client.py", line 751, in _auth
    self._transport.auth_password(username, password)
  File "/home/bradfernan/VENV/py3_venv/lib64/python3.7/site-packages/paramiko/transport.py", line 1509, in auth_password
    return self.auth_handler.wait_for_response(my_event)
  File "/home/bradfernan/VENV/py3_venv/lib64/python3.7/site-packages/paramiko/auth_handler.py", line 250, in wait_for_response
    raise e
paramiko.ssh_exception.AuthenticationException: Authentication failed.

During handling of the above exception, another exception occurred:

Traceback (most recent call last):
  File "/home/bradfernan/VENV/py3_venv/lib64/python3.7/site-packages/nornir/core/task.py", line 85, in start
    r = self.task(self, **self.params)
  File "/home/bradfernan/VENV/py3_venv/lib64/python3.7/site-packages/nornir/plugins/tasks/networking/netmiko_send_command.py", line 26, in netmiko_send_command
    net_connect = task.host.get_connection("netmiko", task.nornir.config)
  File "/home/bradfernan/VENV/py3_venv/lib64/python3.7/site-packages/nornir/core/inventory.py", line 302, in get_connection
    extras=conn.extras,
  File "/home/bradfernan/VENV/py3_venv/lib64/python3.7/site-packages/nornir/core/inventory.py", line 352, in open_connection
    configuration=configuration,
  File "/home/bradfernan/VENV/py3_venv/lib64/python3.7/site-packages/nornir/plugins/connections/netmiko.py", line 58, in open
    self.connection = ConnectHandler(**parameters)
  File "/home/bradfernan/VENV/py3_venv/lib64/python3.7/site-packages/netmiko/ssh_dispatcher.py", line 298, in ConnectHandler
    return ConnectionClass(*args, **kwargs)
  File "/home/bradfernan/VENV/py3_venv/lib64/python3.7/site-packages/netmiko/base_connection.py", line 341, in __init__
    self._open()
  File "/home/bradfernan/VENV/py3_venv/lib64/python3.7/site-packages/netmiko/base_connection.py", line 346, in _open
    self.establish_connection()
  File "/home/bradfernan/VENV/py3_venv/lib64/python3.7/site-packages/netmiko/base_connection.py", line 944, in establish_connection
    raise NetmikoAuthenticationException(msg)
netmiko.ssh_exception.NetmikoAuthenticationException: Authentication failure: unable to connect cisco_ios cisco3.lasthop.io:22
Authentication failed.

2020-12-23 22:01:58,496 -  nornir.core -     INFO -        run() - Running task 'netmiko_send_command' with args {'command_string': 'show ip int brief'} on 2 hosts
2020-12-23 22:02:38,665 -  nornir.core -     INFO -        run() - Running task 'netmiko_send_command' with args {'command_string': 'show ip int brief'} on 2 hosts
2020-12-23 22:02:41,355 - nornir.core.task -    ERROR -      start() - Host 'cisco3': task 'netmiko_send_command' failed with traceback:
Traceback (most recent call last):
  File "/home/bradfernan/VENV/py3_venv/lib64/python3.7/site-packages/netmiko/base_connection.py", line 915, in establish_connection
    self.remote_conn_pre.connect(**ssh_connect_params)
  File "/home/bradfernan/VENV/py3_venv/lib64/python3.7/site-packages/paramiko/client.py", line 446, in connect
    passphrase,
  File "/home/bradfernan/VENV/py3_venv/lib64/python3.7/site-packages/paramiko/client.py", line 764, in _auth
    raise saved_exception
  File "/home/bradfernan/VENV/py3_venv/lib64/python3.7/site-packages/paramiko/client.py", line 751, in _auth
    self._transport.auth_password(username, password)
  File "/home/bradfernan/VENV/py3_venv/lib64/python3.7/site-packages/paramiko/transport.py", line 1509, in auth_password
    return self.auth_handler.wait_for_response(my_event)
  File "/home/bradfernan/VENV/py3_venv/lib64/python3.7/site-packages/paramiko/auth_handler.py", line 250, in wait_for_response
    raise e
paramiko.ssh_exception.AuthenticationException: Authentication failed.

During handling of the above exception, another exception occurred:

Traceback (most recent call last):
  File "/home/bradfernan/VENV/py3_venv/lib64/python3.7/site-packages/nornir/core/task.py", line 85, in start
    r = self.task(self, **self.params)
  File "/home/bradfernan/VENV/py3_venv/lib64/python3.7/site-packages/nornir/plugins/tasks/networking/netmiko_send_command.py", line 26, in netmiko_send_command
    net_connect = task.host.get_connection("netmiko", task.nornir.config)
  File "/home/bradfernan/VENV/py3_venv/lib64/python3.7/site-packages/nornir/core/inventory.py", line 302, in get_connection
    extras=conn.extras,
  File "/home/bradfernan/VENV/py3_venv/lib64/python3.7/site-packages/nornir/core/inventory.py", line 352, in open_connection
    configuration=configuration,
  File "/home/bradfernan/VENV/py3_venv/lib64/python3.7/site-packages/nornir/plugins/connections/netmiko.py", line 58, in open
    self.connection = ConnectHandler(**parameters)
  File "/home/bradfernan/VENV/py3_venv/lib64/python3.7/site-packages/netmiko/ssh_dispatcher.py", line 298, in ConnectHandler
    return ConnectionClass(*args, **kwargs)
  File "/home/bradfernan/VENV/py3_venv/lib64/python3.7/site-packages/netmiko/base_connection.py", line 341, in __init__
    self._open()
  File "/home/bradfernan/VENV/py3_venv/lib64/python3.7/site-packages/netmiko/base_connection.py", line 346, in _open
    self.establish_connection()
  File "/home/bradfernan/VENV/py3_venv/lib64/python3.7/site-packages/netmiko/base_connection.py", line 944, in establish_connection
    raise NetmikoAuthenticationException(msg)
netmiko.ssh_exception.NetmikoAuthenticationException: Authentication failure: unable to connect cisco_ios cisco3.lasthop.io:22
Authentication failed.

2020-12-23 22:02:42,483 - nornir.core.task -    ERROR -      start() - Host 'cisco4': task 'netmiko_send_command' failed with traceback:
Traceback (most recent call last):
  File "/home/bradfernan/VENV/py3_venv/lib64/python3.7/site-packages/nornir/core/task.py", line 85, in start
    r = self.task(self, **self.params)
  File "/home/bradfernan/VENV/py3_venv/lib64/python3.7/site-packages/nornir/plugins/tasks/networking/netmiko_send_command.py", line 26, in netmiko_send_command
    net_connect = task.host.get_connection("netmiko", task.nornir.config)
  File "/home/bradfernan/VENV/py3_venv/lib64/python3.7/site-packages/nornir/core/inventory.py", line 302, in get_connection
    extras=conn.extras,
  File "/home/bradfernan/VENV/py3_venv/lib64/python3.7/site-packages/nornir/core/inventory.py", line 352, in open_connection
    configuration=configuration,
  File "/home/bradfernan/VENV/py3_venv/lib64/python3.7/site-packages/nornir/plugins/connections/netmiko.py", line 58, in open
    self.connection = ConnectHandler(**parameters)
  File "/home/bradfernan/VENV/py3_venv/lib64/python3.7/site-packages/netmiko/ssh_dispatcher.py", line 298, in ConnectHandler
    return ConnectionClass(*args, **kwargs)
  File "/home/bradfernan/VENV/py3_venv/lib64/python3.7/site-packages/netmiko/base_connection.py", line 341, in __init__
    self._open()
  File "/home/bradfernan/VENV/py3_venv/lib64/python3.7/site-packages/netmiko/base_connection.py", line 347, in _open
    self._try_session_preparation()
  File "/home/bradfernan/VENV/py3_venv/lib64/python3.7/site-packages/netmiko/base_connection.py", line 772, in _try_session_preparation
    self.session_preparation()
  File "/home/bradfernan/VENV/py3_venv/lib64/python3.7/site-packages/netmiko/cisco/cisco_ios.py", line 16, in session_preparation
    self.set_base_prompt()
  File "/home/bradfernan/VENV/py3_venv/lib64/python3.7/site-packages/netmiko/base_connection.py", line 1106, in set_base_prompt
    prompt = self.find_prompt(delay_factor=delay_factor)
  File "/home/bradfernan/VENV/py3_venv/lib64/python3.7/site-packages/netmiko/base_connection.py", line 1121, in find_prompt
    self.write_channel(self.RETURN)
  File "/home/bradfernan/VENV/py3_venv/lib64/python3.7/site-packages/netmiko/base_connection.py", line 450, in write_channel
    self._write_channel(out_data)
  File "/home/bradfernan/VENV/py3_venv/lib64/python3.7/site-packages/netmiko/base_connection.py", line 408, in _write_channel
    self.remote_conn.sendall(write_bytes(out_data, encoding=self.encoding))
  File "/home/bradfernan/VENV/py3_venv/lib64/python3.7/site-packages/paramiko/channel.py", line 846, in sendall
    sent = self.send(s)
  File "/home/bradfernan/VENV/py3_venv/lib64/python3.7/site-packages/paramiko/channel.py", line 801, in send
    return self._send(s, m)
  File "/home/bradfernan/VENV/py3_venv/lib64/python3.7/site-packages/paramiko/channel.py", line 1198, in _send
    raise socket.error("Socket is closed")
OSError: Socket is closed

2020-12-23 22:03:05,522 -  nornir.core -     INFO -        run() - Running task 'netmiko_send_command' with args {'command_string': 'show ip int brief'} on 2 hosts
2020-12-23 22:03:08,263 - nornir.core.task -    ERROR -      start() - Host 'cisco3': task 'netmiko_send_command' failed with traceback:
Traceback (most recent call last):
  File "/home/bradfernan/VENV/py3_venv/lib64/python3.7/site-packages/netmiko/base_connection.py", line 915, in establish_connection
    self.remote_conn_pre.connect(**ssh_connect_params)
  File "/home/bradfernan/VENV/py3_venv/lib64/python3.7/site-packages/paramiko/client.py", line 446, in connect
    passphrase,
  File "/home/bradfernan/VENV/py3_venv/lib64/python3.7/site-packages/paramiko/client.py", line 764, in _auth
    raise saved_exception
  File "/home/bradfernan/VENV/py3_venv/lib64/python3.7/site-packages/paramiko/client.py", line 751, in _auth
    self._transport.auth_password(username, password)
  File "/home/bradfernan/VENV/py3_venv/lib64/python3.7/site-packages/paramiko/transport.py", line 1509, in auth_password
    return self.auth_handler.wait_for_response(my_event)
  File "/home/bradfernan/VENV/py3_venv/lib64/python3.7/site-packages/paramiko/auth_handler.py", line 250, in wait_for_response
    raise e
paramiko.ssh_exception.AuthenticationException: Authentication failed.

During handling of the above exception, another exception occurred:

Traceback (most recent call last):
  File "/home/bradfernan/VENV/py3_venv/lib64/python3.7/site-packages/nornir/core/task.py", line 85, in start
    r = self.task(self, **self.params)
  File "/home/bradfernan/VENV/py3_venv/lib64/python3.7/site-packages/nornir/plugins/tasks/networking/netmiko_send_command.py", line 26, in netmiko_send_command
    net_connect = task.host.get_connection("netmiko", task.nornir.config)
  File "/home/bradfernan/VENV/py3_venv/lib64/python3.7/site-packages/nornir/core/inventory.py", line 302, in get_connection
    extras=conn.extras,
  File "/home/bradfernan/VENV/py3_venv/lib64/python3.7/site-packages/nornir/core/inventory.py", line 352, in open_connection
    configuration=configuration,
  File "/home/bradfernan/VENV/py3_venv/lib64/python3.7/site-packages/nornir/plugins/connections/netmiko.py", line 58, in open
    self.connection = ConnectHandler(**parameters)
  File "/home/bradfernan/VENV/py3_venv/lib64/python3.7/site-packages/netmiko/ssh_dispatcher.py", line 298, in ConnectHandler
    return ConnectionClass(*args, **kwargs)
  File "/home/bradfernan/VENV/py3_venv/lib64/python3.7/site-packages/netmiko/base_connection.py", line 341, in __init__
    self._open()
  File "/home/bradfernan/VENV/py3_venv/lib64/python3.7/site-packages/netmiko/base_connection.py", line 346, in _open
    self.establish_connection()
  File "/home/bradfernan/VENV/py3_venv/lib64/python3.7/site-packages/netmiko/base_connection.py", line 944, in establish_connection
    raise NetmikoAuthenticationException(msg)
netmiko.ssh_exception.NetmikoAuthenticationException: Authentication failure: unable to connect cisco_ios cisco3.lasthop.io:22
Authentication failed.

2020-12-23 22:03:11,506 -  nornir.core -     INFO -        run() - Running task 'netmiko_send_command' with args {'command_string': 'show ip int brief'} on 2 hosts
