2021-01-05 08:56:15,160 -  nornir.core -     INFO -        run() - Running task 'get_uptime' with args {} on 9 hosts
2021-01-05 08:56:40,573 -  nornir.core -     INFO -        run() - Running task 'get_uptime' with args {} on 9 hosts
2021-01-05 09:00:36,402 -  nornir.core -     INFO -        run() - Running task 'get_uptime' with args {} on 9 hosts
2021-01-05 09:00:36,402 -  nornir.core -     INFO -        run() - Running task 'netmiko_send_command' with args {'command_string': 'show version | inc uptime'} on 9 hosts
2021-01-05 09:00:36,403 -  nornir.core -     INFO -        run() - Running task 'netmiko_send_command' with args {'command_string': 'show version | inc uptime'} on 9 hosts
2021-01-05 09:00:36,406 - nornir.core.task -    ERROR -      start() - Host 'cisco3': task 'netmiko_send_command' failed with traceback:
Traceback (most recent call last):
  File "/home/bradfernan/VENV/py3_venv/lib64/python3.7/site-packages/nornir/core/task.py", line 85, in start
    r = self.task(self, **self.params)
  File "/home/bradfernan/VENV/py3_venv/lib64/python3.7/site-packages/nornir/plugins/tasks/networking/netmiko_send_command.py", line 32, in netmiko_send_command
    result = net_connect.send_command(command_string, **kwargs)
AttributeError: 'UnestablishedConnection' object has no attribute 'send_command'

2021-01-05 09:00:36,406 - nornir.core.task -    ERROR -      start() - Host 'nxos1': task 'netmiko_send_command' failed with traceback:
Traceback (most recent call last):
  File "/home/bradfernan/VENV/py3_venv/lib64/python3.7/site-packages/nornir/core/task.py", line 85, in start
    r = self.task(self, **self.params)
  File "/home/bradfernan/VENV/py3_venv/lib64/python3.7/site-packages/nornir/plugins/tasks/networking/netmiko_send_command.py", line 32, in netmiko_send_command
    result = net_connect.send_command(command_string, **kwargs)
AttributeError: 'UnestablishedConnection' object has no attribute 'send_command'

2021-01-05 09:00:36,406 - nornir.core.task -    ERROR -      start() - Host 'cisco4': task 'netmiko_send_command' failed with traceback:
Traceback (most recent call last):
  File "/home/bradfernan/VENV/py3_venv/lib64/python3.7/site-packages/nornir/core/task.py", line 85, in start
    r = self.task(self, **self.params)
  File "/home/bradfernan/VENV/py3_venv/lib64/python3.7/site-packages/nornir/plugins/tasks/networking/netmiko_send_command.py", line 32, in netmiko_send_command
    result = net_connect.send_command(command_string, **kwargs)
AttributeError: 'UnestablishedConnection' object has no attribute 'send_command'

2021-01-05 09:00:36,407 - nornir.core.task -    ERROR -      start() - Host 'nxos2': task 'netmiko_send_command' failed with traceback:
Traceback (most recent call last):
  File "/home/bradfernan/VENV/py3_venv/lib64/python3.7/site-packages/nornir/core/task.py", line 85, in start
    r = self.task(self, **self.params)
  File "/home/bradfernan/VENV/py3_venv/lib64/python3.7/site-packages/nornir/plugins/tasks/networking/netmiko_send_command.py", line 32, in netmiko_send_command
    result = net_connect.send_command(command_string, **kwargs)
AttributeError: 'UnestablishedConnection' object has no attribute 'send_command'

2021-01-05 09:00:36,408 - nornir.core.task -    ERROR -      start() - Host 'arista1': task 'netmiko_send_command' failed with traceback:
Traceback (most recent call last):
  File "/home/bradfernan/VENV/py3_venv/lib64/python3.7/site-packages/nornir/core/task.py", line 85, in start
    r = self.task(self, **self.params)
  File "/home/bradfernan/VENV/py3_venv/lib64/python3.7/site-packages/nornir/plugins/tasks/networking/netmiko_send_command.py", line 32, in netmiko_send_command
    result = net_connect.send_command(command_string, **kwargs)
AttributeError: 'UnestablishedConnection' object has no attribute 'send_command'

2021-01-05 09:00:36,409 - nornir.core.task -    ERROR -      start() - Host 'arista2': task 'netmiko_send_command' failed with traceback:
Traceback (most recent call last):
  File "/home/bradfernan/VENV/py3_venv/lib64/python3.7/site-packages/nornir/core/task.py", line 85, in start
    r = self.task(self, **self.params)
  File "/home/bradfernan/VENV/py3_venv/lib64/python3.7/site-packages/nornir/plugins/tasks/networking/netmiko_send_command.py", line 32, in netmiko_send_command
    result = net_connect.send_command(command_string, **kwargs)
AttributeError: 'UnestablishedConnection' object has no attribute 'send_command'

2021-01-05 09:00:36,410 - nornir.core.task -    ERROR -      start() - Host 'arista3': task 'netmiko_send_command' failed with traceback:
Traceback (most recent call last):
  File "/home/bradfernan/VENV/py3_venv/lib64/python3.7/site-packages/nornir/core/task.py", line 85, in start
    r = self.task(self, **self.params)
  File "/home/bradfernan/VENV/py3_venv/lib64/python3.7/site-packages/nornir/plugins/tasks/networking/netmiko_send_command.py", line 32, in netmiko_send_command
    result = net_connect.send_command(command_string, **kwargs)
AttributeError: 'UnestablishedConnection' object has no attribute 'send_command'

2021-01-05 09:00:36,411 - nornir.core.task -    ERROR -      start() - Host 'arista4': task 'netmiko_send_command' failed with traceback:
Traceback (most recent call last):
  File "/home/bradfernan/VENV/py3_venv/lib64/python3.7/site-packages/nornir/core/task.py", line 85, in start
    r = self.task(self, **self.params)
  File "/home/bradfernan/VENV/py3_venv/lib64/python3.7/site-packages/nornir/plugins/tasks/networking/netmiko_send_command.py", line 32, in netmiko_send_command
    result = net_connect.send_command(command_string, **kwargs)
AttributeError: 'UnestablishedConnection' object has no attribute 'send_command'

2021-01-05 09:00:36,412 - nornir.core.task -    ERROR -      start() - Host 'srx2': task 'netmiko_send_command' failed with traceback:
Traceback (most recent call last):
  File "/home/bradfernan/VENV/py3_venv/lib64/python3.7/site-packages/nornir/core/task.py", line 85, in start
    r = self.task(self, **self.params)
  File "/home/bradfernan/VENV/py3_venv/lib64/python3.7/site-packages/nornir/plugins/tasks/networking/netmiko_send_command.py", line 32, in netmiko_send_command
    result = net_connect.send_command(command_string, **kwargs)
AttributeError: 'UnestablishedConnection' object has no attribute 'send_command'

2021-01-05 09:01:01,252 - nornir.core.task -    ERROR -      start() - Host 'srx2': task 'netmiko_send_command' failed with traceback:
Traceback (most recent call last):
  File "/home/bradfernan/VENV/py3_venv/lib64/python3.7/site-packages/nornir/core/task.py", line 85, in start
    r = self.task(self, **self.params)
  File "/home/bradfernan/VENV/py3_venv/lib64/python3.7/site-packages/nornir/plugins/tasks/networking/netmiko_send_command.py", line 32, in netmiko_send_command
    result = net_connect.send_command(command_string, **kwargs)
  File "/home/bradfernan/VENV/py3_venv/lib64/python3.7/site-packages/netmiko/utilities.py", line 347, in wrapper_decorator
    return func(self, *args, **kwargs)
  File "/home/bradfernan/VENV/py3_venv/lib64/python3.7/site-packages/netmiko/base_connection.py", line 1415, in send_command
    new_data = self.read_until_pattern(pattern=re.escape(cmd))
  File "/home/bradfernan/VENV/py3_venv/lib64/python3.7/site-packages/netmiko/base_connection.py", line 641, in read_until_pattern
    return self._read_channel_expect(*args, **kwargs)
  File "/home/bradfernan/VENV/py3_venv/lib64/python3.7/site-packages/netmiko/base_connection.py", line 566, in _read_channel_expect
    raise EOFError("Channel stream closed by remote device.")
EOFError: Channel stream closed by remote device.

2021-01-05 09:05:09,932 -  nornir.core -     INFO -        run() - Running task 'get_uptime' with args {} on 9 hosts
2021-01-05 09:05:09,933 -  nornir.core -     INFO -        run() - Running task 'netmiko_send_command' with args {'command_string': 'show version | inc uptime'} on 9 hosts
2021-01-05 09:05:09,934 -  nornir.core -     INFO -        run() - Running task 'netmiko_send_command' with args {'command_string': 'show version | inc uptime'} on 9 hosts
2021-01-05 09:05:09,936 - nornir.core.task -    ERROR -      start() - Host 'cisco3': task 'netmiko_send_command' failed with traceback:
Traceback (most recent call last):
  File "/home/bradfernan/VENV/py3_venv/lib64/python3.7/site-packages/nornir/core/task.py", line 85, in start
    r = self.task(self, **self.params)
  File "/home/bradfernan/VENV/py3_venv/lib64/python3.7/site-packages/nornir/plugins/tasks/networking/netmiko_send_command.py", line 32, in netmiko_send_command
    result = net_connect.send_command(command_string, **kwargs)
AttributeError: 'UnestablishedConnection' object has no attribute 'send_command'

2021-01-05 09:05:09,936 - nornir.core.task -    ERROR -      start() - Host 'cisco4': task 'netmiko_send_command' failed with traceback:
Traceback (most recent call last):
  File "/home/bradfernan/VENV/py3_venv/lib64/python3.7/site-packages/nornir/core/task.py", line 85, in start
    r = self.task(self, **self.params)
  File "/home/bradfernan/VENV/py3_venv/lib64/python3.7/site-packages/nornir/plugins/tasks/networking/netmiko_send_command.py", line 32, in netmiko_send_command
    result = net_connect.send_command(command_string, **kwargs)
AttributeError: 'UnestablishedConnection' object has no attribute 'send_command'

2021-01-05 09:05:09,937 - nornir.core.task -    ERROR -      start() - Host 'nxos1': task 'netmiko_send_command' failed with traceback:
Traceback (most recent call last):
  File "/home/bradfernan/VENV/py3_venv/lib64/python3.7/site-packages/nornir/core/task.py", line 85, in start
    r = self.task(self, **self.params)
  File "/home/bradfernan/VENV/py3_venv/lib64/python3.7/site-packages/nornir/plugins/tasks/networking/netmiko_send_command.py", line 32, in netmiko_send_command
    result = net_connect.send_command(command_string, **kwargs)
AttributeError: 'UnestablishedConnection' object has no attribute 'send_command'

2021-01-05 09:05:09,938 - nornir.core.task -    ERROR -      start() - Host 'nxos2': task 'netmiko_send_command' failed with traceback:
Traceback (most recent call last):
  File "/home/bradfernan/VENV/py3_venv/lib64/python3.7/site-packages/nornir/core/task.py", line 85, in start
    r = self.task(self, **self.params)
  File "/home/bradfernan/VENV/py3_venv/lib64/python3.7/site-packages/nornir/plugins/tasks/networking/netmiko_send_command.py", line 32, in netmiko_send_command
    result = net_connect.send_command(command_string, **kwargs)
AttributeError: 'UnestablishedConnection' object has no attribute 'send_command'

2021-01-05 09:05:09,940 - nornir.core.task -    ERROR -      start() - Host 'arista1': task 'netmiko_send_command' failed with traceback:
Traceback (most recent call last):
  File "/home/bradfernan/VENV/py3_venv/lib64/python3.7/site-packages/nornir/core/task.py", line 85, in start
    r = self.task(self, **self.params)
  File "/home/bradfernan/VENV/py3_venv/lib64/python3.7/site-packages/nornir/plugins/tasks/networking/netmiko_send_command.py", line 32, in netmiko_send_command
    result = net_connect.send_command(command_string, **kwargs)
AttributeError: 'UnestablishedConnection' object has no attribute 'send_command'

2021-01-05 09:05:09,941 - nornir.core.task -    ERROR -      start() - Host 'arista2': task 'netmiko_send_command' failed with traceback:
Traceback (most recent call last):
  File "/home/bradfernan/VENV/py3_venv/lib64/python3.7/site-packages/nornir/core/task.py", line 85, in start
    r = self.task(self, **self.params)
  File "/home/bradfernan/VENV/py3_venv/lib64/python3.7/site-packages/nornir/plugins/tasks/networking/netmiko_send_command.py", line 32, in netmiko_send_command
    result = net_connect.send_command(command_string, **kwargs)
AttributeError: 'UnestablishedConnection' object has no attribute 'send_command'

2021-01-05 09:05:09,943 - nornir.core.task -    ERROR -      start() - Host 'arista3': task 'netmiko_send_command' failed with traceback:
Traceback (most recent call last):
  File "/home/bradfernan/VENV/py3_venv/lib64/python3.7/site-packages/nornir/core/task.py", line 85, in start
    r = self.task(self, **self.params)
  File "/home/bradfernan/VENV/py3_venv/lib64/python3.7/site-packages/nornir/plugins/tasks/networking/netmiko_send_command.py", line 32, in netmiko_send_command
    result = net_connect.send_command(command_string, **kwargs)
AttributeError: 'UnestablishedConnection' object has no attribute 'send_command'

2021-01-05 09:05:09,945 - nornir.core.task -    ERROR -      start() - Host 'arista4': task 'netmiko_send_command' failed with traceback:
Traceback (most recent call last):
  File "/home/bradfernan/VENV/py3_venv/lib64/python3.7/site-packages/nornir/core/task.py", line 85, in start
    r = self.task(self, **self.params)
  File "/home/bradfernan/VENV/py3_venv/lib64/python3.7/site-packages/nornir/plugins/tasks/networking/netmiko_send_command.py", line 32, in netmiko_send_command
    result = net_connect.send_command(command_string, **kwargs)
AttributeError: 'UnestablishedConnection' object has no attribute 'send_command'

2021-01-05 09:05:09,947 - nornir.core.task -    ERROR -      start() - Host 'srx2': task 'netmiko_send_command' failed with traceback:
Traceback (most recent call last):
  File "/home/bradfernan/VENV/py3_venv/lib64/python3.7/site-packages/nornir/core/task.py", line 85, in start
    r = self.task(self, **self.params)
  File "/home/bradfernan/VENV/py3_venv/lib64/python3.7/site-packages/nornir/plugins/tasks/networking/netmiko_send_command.py", line 32, in netmiko_send_command
    result = net_connect.send_command(command_string, **kwargs)
AttributeError: 'UnestablishedConnection' object has no attribute 'send_command'

2021-01-05 09:05:37,026 - nornir.core.task -    ERROR -      start() - Host 'srx2': task 'netmiko_send_command' failed with traceback:
Traceback (most recent call last):
  File "/home/bradfernan/VENV/py3_venv/lib64/python3.7/site-packages/paramiko/channel.py", line 699, in recv
    out = self.in_buffer.read(nbytes, self.timeout)
  File "/home/bradfernan/VENV/py3_venv/lib64/python3.7/site-packages/paramiko/buffered_pipe.py", line 164, in read
    raise PipeTimeout()
paramiko.buffered_pipe.PipeTimeout

During handling of the above exception, another exception occurred:

Traceback (most recent call last):
  File "/home/bradfernan/VENV/py3_venv/lib64/python3.7/site-packages/netmiko/base_connection.py", line 564, in _read_channel_expect
    new_data = self.remote_conn.recv(MAX_BUFFER)
  File "/home/bradfernan/VENV/py3_venv/lib64/python3.7/site-packages/paramiko/channel.py", line 701, in recv
    raise socket.timeout()
socket.timeout

During handling of the above exception, another exception occurred:

Traceback (most recent call last):
  File "/home/bradfernan/VENV/py3_venv/lib64/python3.7/site-packages/nornir/core/task.py", line 85, in start
    r = self.task(self, **self.params)
  File "/home/bradfernan/VENV/py3_venv/lib64/python3.7/site-packages/nornir/plugins/tasks/networking/netmiko_send_command.py", line 32, in netmiko_send_command
    result = net_connect.send_command(command_string, **kwargs)
  File "/home/bradfernan/VENV/py3_venv/lib64/python3.7/site-packages/netmiko/utilities.py", line 347, in wrapper_decorator
    return func(self, *args, **kwargs)
  File "/home/bradfernan/VENV/py3_venv/lib64/python3.7/site-packages/netmiko/base_connection.py", line 1415, in send_command
    new_data = self.read_until_pattern(pattern=re.escape(cmd))
  File "/home/bradfernan/VENV/py3_venv/lib64/python3.7/site-packages/netmiko/base_connection.py", line 641, in read_until_pattern
    return self._read_channel_expect(*args, **kwargs)
  File "/home/bradfernan/VENV/py3_venv/lib64/python3.7/site-packages/netmiko/base_connection.py", line 575, in _read_channel_expect
    "Timed-out reading channel, data not available."
netmiko.ssh_exception.NetmikoTimeoutException: Timed-out reading channel, data not available.

2021-01-05 09:05:37,112 -  nornir.core -     INFO -        run() - Running task 'get_uptime' with args {} on 9 hosts
2021-01-05 09:05:37,113 -  nornir.core -     INFO -        run() - Running task 'netmiko_send_command' with args {'command_string': 'show version | inc uptime'} on 9 hosts
2021-01-05 09:05:37,113 -  nornir.core -     INFO -        run() - Running task 'netmiko_send_command' with args {'command_string': 'show version | inc uptime'} on 9 hosts
2021-01-05 09:05:37,115 - nornir.core.task -    ERROR -      start() - Host 'cisco3': task 'netmiko_send_command' failed with traceback:
Traceback (most recent call last):
  File "/home/bradfernan/VENV/py3_venv/lib64/python3.7/site-packages/nornir/core/task.py", line 85, in start
    r = self.task(self, **self.params)
  File "/home/bradfernan/VENV/py3_venv/lib64/python3.7/site-packages/nornir/plugins/tasks/networking/netmiko_send_command.py", line 32, in netmiko_send_command
    result = net_connect.send_command(command_string, **kwargs)
AttributeError: 'UnestablishedConnection' object has no attribute 'send_command'

2021-01-05 09:05:37,115 - nornir.core.task -    ERROR -      start() - Host 'cisco4': task 'netmiko_send_command' failed with traceback:
Traceback (most recent call last):
  File "/home/bradfernan/VENV/py3_venv/lib64/python3.7/site-packages/nornir/core/task.py", line 85, in start
    r = self.task(self, **self.params)
  File "/home/bradfernan/VENV/py3_venv/lib64/python3.7/site-packages/nornir/plugins/tasks/networking/netmiko_send_command.py", line 32, in netmiko_send_command
    result = net_connect.send_command(command_string, **kwargs)
AttributeError: 'UnestablishedConnection' object has no attribute 'send_command'

2021-01-05 09:05:37,116 - nornir.core.task -    ERROR -      start() - Host 'nxos1': task 'netmiko_send_command' failed with traceback:
Traceback (most recent call last):
  File "/home/bradfernan/VENV/py3_venv/lib64/python3.7/site-packages/nornir/core/task.py", line 85, in start
    r = self.task(self, **self.params)
  File "/home/bradfernan/VENV/py3_venv/lib64/python3.7/site-packages/nornir/plugins/tasks/networking/netmiko_send_command.py", line 32, in netmiko_send_command
    result = net_connect.send_command(command_string, **kwargs)
AttributeError: 'UnestablishedConnection' object has no attribute 'send_command'

2021-01-05 09:05:37,117 - nornir.core.task -    ERROR -      start() - Host 'nxos2': task 'netmiko_send_command' failed with traceback:
Traceback (most recent call last):
  File "/home/bradfernan/VENV/py3_venv/lib64/python3.7/site-packages/nornir/core/task.py", line 85, in start
    r = self.task(self, **self.params)
  File "/home/bradfernan/VENV/py3_venv/lib64/python3.7/site-packages/nornir/plugins/tasks/networking/netmiko_send_command.py", line 32, in netmiko_send_command
    result = net_connect.send_command(command_string, **kwargs)
AttributeError: 'UnestablishedConnection' object has no attribute 'send_command'

2021-01-05 09:05:37,118 - nornir.core.task -    ERROR -      start() - Host 'arista1': task 'netmiko_send_command' failed with traceback:
Traceback (most recent call last):
  File "/home/bradfernan/VENV/py3_venv/lib64/python3.7/site-packages/nornir/core/task.py", line 85, in start
    r = self.task(self, **self.params)
  File "/home/bradfernan/VENV/py3_venv/lib64/python3.7/site-packages/nornir/plugins/tasks/networking/netmiko_send_command.py", line 32, in netmiko_send_command
    result = net_connect.send_command(command_string, **kwargs)
AttributeError: 'UnestablishedConnection' object has no attribute 'send_command'

2021-01-05 09:05:37,119 - nornir.core.task -    ERROR -      start() - Host 'arista2': task 'netmiko_send_command' failed with traceback:
Traceback (most recent call last):
  File "/home/bradfernan/VENV/py3_venv/lib64/python3.7/site-packages/nornir/core/task.py", line 85, in start
    r = self.task(self, **self.params)
  File "/home/bradfernan/VENV/py3_venv/lib64/python3.7/site-packages/nornir/plugins/tasks/networking/netmiko_send_command.py", line 32, in netmiko_send_command
    result = net_connect.send_command(command_string, **kwargs)
AttributeError: 'UnestablishedConnection' object has no attribute 'send_command'

2021-01-05 09:05:37,120 - nornir.core.task -    ERROR -      start() - Host 'arista3': task 'netmiko_send_command' failed with traceback:
Traceback (most recent call last):
  File "/home/bradfernan/VENV/py3_venv/lib64/python3.7/site-packages/nornir/core/task.py", line 85, in start
    r = self.task(self, **self.params)
  File "/home/bradfernan/VENV/py3_venv/lib64/python3.7/site-packages/nornir/plugins/tasks/networking/netmiko_send_command.py", line 32, in netmiko_send_command
    result = net_connect.send_command(command_string, **kwargs)
AttributeError: 'UnestablishedConnection' object has no attribute 'send_command'

2021-01-05 09:05:37,122 - nornir.core.task -    ERROR -      start() - Host 'arista4': task 'netmiko_send_command' failed with traceback:
Traceback (most recent call last):
  File "/home/bradfernan/VENV/py3_venv/lib64/python3.7/site-packages/nornir/core/task.py", line 85, in start
    r = self.task(self, **self.params)
  File "/home/bradfernan/VENV/py3_venv/lib64/python3.7/site-packages/nornir/plugins/tasks/networking/netmiko_send_command.py", line 32, in netmiko_send_command
    result = net_connect.send_command(command_string, **kwargs)
AttributeError: 'UnestablishedConnection' object has no attribute 'send_command'

2021-01-05 09:05:37,122 - nornir.core.task -    ERROR -      start() - Host 'srx2': task 'netmiko_send_command' failed with traceback:
Traceback (most recent call last):
  File "/home/bradfernan/VENV/py3_venv/lib64/python3.7/site-packages/nornir/core/task.py", line 85, in start
    r = self.task(self, **self.params)
  File "/home/bradfernan/VENV/py3_venv/lib64/python3.7/site-packages/nornir/plugins/tasks/networking/netmiko_send_command.py", line 32, in netmiko_send_command
    result = net_connect.send_command(command_string, **kwargs)
AttributeError: 'UnestablishedConnection' object has no attribute 'send_command'

2021-01-05 09:06:04,247 - nornir.core.task -    ERROR -      start() - Host 'srx2': task 'netmiko_send_command' failed with traceback:
Traceback (most recent call last):
  File "/home/bradfernan/VENV/py3_venv/lib64/python3.7/site-packages/paramiko/channel.py", line 699, in recv
    out = self.in_buffer.read(nbytes, self.timeout)
  File "/home/bradfernan/VENV/py3_venv/lib64/python3.7/site-packages/paramiko/buffered_pipe.py", line 164, in read
    raise PipeTimeout()
paramiko.buffered_pipe.PipeTimeout

During handling of the above exception, another exception occurred:

Traceback (most recent call last):
  File "/home/bradfernan/VENV/py3_venv/lib64/python3.7/site-packages/netmiko/base_connection.py", line 564, in _read_channel_expect
    new_data = self.remote_conn.recv(MAX_BUFFER)
  File "/home/bradfernan/VENV/py3_venv/lib64/python3.7/site-packages/paramiko/channel.py", line 701, in recv
    raise socket.timeout()
socket.timeout

During handling of the above exception, another exception occurred:

Traceback (most recent call last):
  File "/home/bradfernan/VENV/py3_venv/lib64/python3.7/site-packages/nornir/core/task.py", line 85, in start
    r = self.task(self, **self.params)
  File "/home/bradfernan/VENV/py3_venv/lib64/python3.7/site-packages/nornir/plugins/tasks/networking/netmiko_send_command.py", line 32, in netmiko_send_command
    result = net_connect.send_command(command_string, **kwargs)
  File "/home/bradfernan/VENV/py3_venv/lib64/python3.7/site-packages/netmiko/utilities.py", line 347, in wrapper_decorator
    return func(self, *args, **kwargs)
  File "/home/bradfernan/VENV/py3_venv/lib64/python3.7/site-packages/netmiko/base_connection.py", line 1415, in send_command
    new_data = self.read_until_pattern(pattern=re.escape(cmd))
  File "/home/bradfernan/VENV/py3_venv/lib64/python3.7/site-packages/netmiko/base_connection.py", line 641, in read_until_pattern
    return self._read_channel_expect(*args, **kwargs)
  File "/home/bradfernan/VENV/py3_venv/lib64/python3.7/site-packages/netmiko/base_connection.py", line 575, in _read_channel_expect
    "Timed-out reading channel, data not available."
netmiko.ssh_exception.NetmikoTimeoutException: Timed-out reading channel, data not available.

2021-01-05 09:06:36,117 -  nornir.core -     INFO -        run() - Running task 'get_uptime' with args {} on 9 hosts
2021-01-05 09:06:36,117 -  nornir.core -     INFO -        run() - Running task 'netmiko_send_command' with args {'command_string': 'show version | inc uptime'} on 9 hosts
2021-01-05 09:06:36,118 -  nornir.core -     INFO -        run() - Running task 'netmiko_send_command' with args {'command_string': 'show version | inc uptime'} on 9 hosts
2021-01-05 09:06:36,120 - nornir.core.task -    ERROR -      start() - Host 'cisco3': task 'netmiko_send_command' failed with traceback:
Traceback (most recent call last):
  File "/home/bradfernan/VENV/py3_venv/lib64/python3.7/site-packages/nornir/core/task.py", line 85, in start
    r = self.task(self, **self.params)
  File "/home/bradfernan/VENV/py3_venv/lib64/python3.7/site-packages/nornir/plugins/tasks/networking/netmiko_send_command.py", line 32, in netmiko_send_command
    result = net_connect.send_command(command_string, **kwargs)
AttributeError: 'UnestablishedConnection' object has no attribute 'send_command'

2021-01-05 09:06:36,120 - nornir.core.task -    ERROR -      start() - Host 'cisco4': task 'netmiko_send_command' failed with traceback:
Traceback (most recent call last):
  File "/home/bradfernan/VENV/py3_venv/lib64/python3.7/site-packages/nornir/core/task.py", line 85, in start
    r = self.task(self, **self.params)
  File "/home/bradfernan/VENV/py3_venv/lib64/python3.7/site-packages/nornir/plugins/tasks/networking/netmiko_send_command.py", line 32, in netmiko_send_command
    result = net_connect.send_command(command_string, **kwargs)
AttributeError: 'UnestablishedConnection' object has no attribute 'send_command'

2021-01-05 09:06:36,121 - nornir.core.task -    ERROR -      start() - Host 'nxos1': task 'netmiko_send_command' failed with traceback:
Traceback (most recent call last):
  File "/home/bradfernan/VENV/py3_venv/lib64/python3.7/site-packages/nornir/core/task.py", line 85, in start
    r = self.task(self, **self.params)
  File "/home/bradfernan/VENV/py3_venv/lib64/python3.7/site-packages/nornir/plugins/tasks/networking/netmiko_send_command.py", line 32, in netmiko_send_command
    result = net_connect.send_command(command_string, **kwargs)
AttributeError: 'UnestablishedConnection' object has no attribute 'send_command'

2021-01-05 09:06:36,122 - nornir.core.task -    ERROR -      start() - Host 'nxos2': task 'netmiko_send_command' failed with traceback:
Traceback (most recent call last):
  File "/home/bradfernan/VENV/py3_venv/lib64/python3.7/site-packages/nornir/core/task.py", line 85, in start
    r = self.task(self, **self.params)
  File "/home/bradfernan/VENV/py3_venv/lib64/python3.7/site-packages/nornir/plugins/tasks/networking/netmiko_send_command.py", line 32, in netmiko_send_command
    result = net_connect.send_command(command_string, **kwargs)
AttributeError: 'UnestablishedConnection' object has no attribute 'send_command'

2021-01-05 09:06:36,124 - nornir.core.task -    ERROR -      start() - Host 'arista1': task 'netmiko_send_command' failed with traceback:
Traceback (most recent call last):
  File "/home/bradfernan/VENV/py3_venv/lib64/python3.7/site-packages/nornir/core/task.py", line 85, in start
    r = self.task(self, **self.params)
  File "/home/bradfernan/VENV/py3_venv/lib64/python3.7/site-packages/nornir/plugins/tasks/networking/netmiko_send_command.py", line 32, in netmiko_send_command
    result = net_connect.send_command(command_string, **kwargs)
AttributeError: 'UnestablishedConnection' object has no attribute 'send_command'

2021-01-05 09:06:36,125 - nornir.core.task -    ERROR -      start() - Host 'arista2': task 'netmiko_send_command' failed with traceback:
Traceback (most recent call last):
  File "/home/bradfernan/VENV/py3_venv/lib64/python3.7/site-packages/nornir/core/task.py", line 85, in start
    r = self.task(self, **self.params)
  File "/home/bradfernan/VENV/py3_venv/lib64/python3.7/site-packages/nornir/plugins/tasks/networking/netmiko_send_command.py", line 32, in netmiko_send_command
    result = net_connect.send_command(command_string, **kwargs)
AttributeError: 'UnestablishedConnection' object has no attribute 'send_command'

2021-01-05 09:06:36,126 - nornir.core.task -    ERROR -      start() - Host 'arista3': task 'netmiko_send_command' failed with traceback:
Traceback (most recent call last):
  File "/home/bradfernan/VENV/py3_venv/lib64/python3.7/site-packages/nornir/core/task.py", line 85, in start
    r = self.task(self, **self.params)
  File "/home/bradfernan/VENV/py3_venv/lib64/python3.7/site-packages/nornir/plugins/tasks/networking/netmiko_send_command.py", line 32, in netmiko_send_command
    result = net_connect.send_command(command_string, **kwargs)
AttributeError: 'UnestablishedConnection' object has no attribute 'send_command'

2021-01-05 09:06:36,128 - nornir.core.task -    ERROR -      start() - Host 'arista4': task 'netmiko_send_command' failed with traceback:
Traceback (most recent call last):
  File "/home/bradfernan/VENV/py3_venv/lib64/python3.7/site-packages/nornir/core/task.py", line 85, in start
    r = self.task(self, **self.params)
  File "/home/bradfernan/VENV/py3_venv/lib64/python3.7/site-packages/nornir/plugins/tasks/networking/netmiko_send_command.py", line 32, in netmiko_send_command
    result = net_connect.send_command(command_string, **kwargs)
AttributeError: 'UnestablishedConnection' object has no attribute 'send_command'

2021-01-05 09:06:36,130 - nornir.core.task -    ERROR -      start() - Host 'srx2': task 'netmiko_send_command' failed with traceback:
Traceback (most recent call last):
  File "/home/bradfernan/VENV/py3_venv/lib64/python3.7/site-packages/nornir/core/task.py", line 85, in start
    r = self.task(self, **self.params)
  File "/home/bradfernan/VENV/py3_venv/lib64/python3.7/site-packages/nornir/plugins/tasks/networking/netmiko_send_command.py", line 32, in netmiko_send_command
    result = net_connect.send_command(command_string, **kwargs)
AttributeError: 'UnestablishedConnection' object has no attribute 'send_command'

2021-01-05 09:07:03,326 - nornir.core.task -    ERROR -      start() - Host 'srx2': task 'netmiko_send_command' failed with traceback:
Traceback (most recent call last):
  File "/home/bradfernan/VENV/py3_venv/lib64/python3.7/site-packages/paramiko/channel.py", line 699, in recv
    out = self.in_buffer.read(nbytes, self.timeout)
  File "/home/bradfernan/VENV/py3_venv/lib64/python3.7/site-packages/paramiko/buffered_pipe.py", line 164, in read
    raise PipeTimeout()
paramiko.buffered_pipe.PipeTimeout

During handling of the above exception, another exception occurred:

Traceback (most recent call last):
  File "/home/bradfernan/VENV/py3_venv/lib64/python3.7/site-packages/netmiko/base_connection.py", line 564, in _read_channel_expect
    new_data = self.remote_conn.recv(MAX_BUFFER)
  File "/home/bradfernan/VENV/py3_venv/lib64/python3.7/site-packages/paramiko/channel.py", line 701, in recv
    raise socket.timeout()
socket.timeout

During handling of the above exception, another exception occurred:

Traceback (most recent call last):
  File "/home/bradfernan/VENV/py3_venv/lib64/python3.7/site-packages/nornir/core/task.py", line 85, in start
    r = self.task(self, **self.params)
  File "/home/bradfernan/VENV/py3_venv/lib64/python3.7/site-packages/nornir/plugins/tasks/networking/netmiko_send_command.py", line 32, in netmiko_send_command
    result = net_connect.send_command(command_string, **kwargs)
  File "/home/bradfernan/VENV/py3_venv/lib64/python3.7/site-packages/netmiko/utilities.py", line 347, in wrapper_decorator
    return func(self, *args, **kwargs)
  File "/home/bradfernan/VENV/py3_venv/lib64/python3.7/site-packages/netmiko/base_connection.py", line 1415, in send_command
    new_data = self.read_until_pattern(pattern=re.escape(cmd))
  File "/home/bradfernan/VENV/py3_venv/lib64/python3.7/site-packages/netmiko/base_connection.py", line 641, in read_until_pattern
    return self._read_channel_expect(*args, **kwargs)
  File "/home/bradfernan/VENV/py3_venv/lib64/python3.7/site-packages/netmiko/base_connection.py", line 575, in _read_channel_expect
    "Timed-out reading channel, data not available."
netmiko.ssh_exception.NetmikoTimeoutException: Timed-out reading channel, data not available.

2021-01-05 09:08:09,086 -  nornir.core -     INFO -        run() - Running task 'get_uptime' with args {} on 9 hosts
2021-01-05 09:08:09,087 -  nornir.core -     INFO -        run() - Running task 'netmiko_send_command' with args {'command_string': 'show version | inc uptime'} on 9 hosts
2021-01-05 09:08:09,087 -  nornir.core -     INFO -        run() - Running task 'netmiko_send_command' with args {'command_string': 'show version | inc uptime'} on 9 hosts
2021-01-05 09:08:09,089 - nornir.core.task -    ERROR -      start() - Host 'cisco3': task 'netmiko_send_command' failed with traceback:
Traceback (most recent call last):
  File "/home/bradfernan/VENV/py3_venv/lib64/python3.7/site-packages/nornir/core/task.py", line 85, in start
    r = self.task(self, **self.params)
  File "/home/bradfernan/VENV/py3_venv/lib64/python3.7/site-packages/nornir/plugins/tasks/networking/netmiko_send_command.py", line 32, in netmiko_send_command
    result = net_connect.send_command(command_string, **kwargs)
AttributeError: 'UnestablishedConnection' object has no attribute 'send_command'

2021-01-05 09:08:09,090 - nornir.core.task -    ERROR -      start() - Host 'cisco4': task 'netmiko_send_command' failed with traceback:
Traceback (most recent call last):
  File "/home/bradfernan/VENV/py3_venv/lib64/python3.7/site-packages/nornir/core/task.py", line 85, in start
    r = self.task(self, **self.params)
  File "/home/bradfernan/VENV/py3_venv/lib64/python3.7/site-packages/nornir/plugins/tasks/networking/netmiko_send_command.py", line 32, in netmiko_send_command
    result = net_connect.send_command(command_string, **kwargs)
AttributeError: 'UnestablishedConnection' object has no attribute 'send_command'

2021-01-05 09:08:09,091 - nornir.core.task -    ERROR -      start() - Host 'nxos1': task 'netmiko_send_command' failed with traceback:
Traceback (most recent call last):
  File "/home/bradfernan/VENV/py3_venv/lib64/python3.7/site-packages/nornir/core/task.py", line 85, in start
    r = self.task(self, **self.params)
  File "/home/bradfernan/VENV/py3_venv/lib64/python3.7/site-packages/nornir/plugins/tasks/networking/netmiko_send_command.py", line 32, in netmiko_send_command
    result = net_connect.send_command(command_string, **kwargs)
AttributeError: 'UnestablishedConnection' object has no attribute 'send_command'

2021-01-05 09:08:09,091 - nornir.core.task -    ERROR -      start() - Host 'nxos2': task 'netmiko_send_command' failed with traceback:
Traceback (most recent call last):
  File "/home/bradfernan/VENV/py3_venv/lib64/python3.7/site-packages/nornir/core/task.py", line 85, in start
    r = self.task(self, **self.params)
  File "/home/bradfernan/VENV/py3_venv/lib64/python3.7/site-packages/nornir/plugins/tasks/networking/netmiko_send_command.py", line 32, in netmiko_send_command
    result = net_connect.send_command(command_string, **kwargs)
AttributeError: 'UnestablishedConnection' object has no attribute 'send_command'

2021-01-05 09:08:09,092 - nornir.core.task -    ERROR -      start() - Host 'arista1': task 'netmiko_send_command' failed with traceback:
Traceback (most recent call last):
  File "/home/bradfernan/VENV/py3_venv/lib64/python3.7/site-packages/nornir/core/task.py", line 85, in start
    r = self.task(self, **self.params)
  File "/home/bradfernan/VENV/py3_venv/lib64/python3.7/site-packages/nornir/plugins/tasks/networking/netmiko_send_command.py", line 32, in netmiko_send_command
    result = net_connect.send_command(command_string, **kwargs)
AttributeError: 'UnestablishedConnection' object has no attribute 'send_command'

2021-01-05 09:08:09,094 - nornir.core.task -    ERROR -      start() - Host 'arista2': task 'netmiko_send_command' failed with traceback:
Traceback (most recent call last):
  File "/home/bradfernan/VENV/py3_venv/lib64/python3.7/site-packages/nornir/core/task.py", line 85, in start
    r = self.task(self, **self.params)
  File "/home/bradfernan/VENV/py3_venv/lib64/python3.7/site-packages/nornir/plugins/tasks/networking/netmiko_send_command.py", line 32, in netmiko_send_command
    result = net_connect.send_command(command_string, **kwargs)
AttributeError: 'UnestablishedConnection' object has no attribute 'send_command'

2021-01-05 09:08:09,095 - nornir.core.task -    ERROR -      start() - Host 'arista3': task 'netmiko_send_command' failed with traceback:
Traceback (most recent call last):
  File "/home/bradfernan/VENV/py3_venv/lib64/python3.7/site-packages/nornir/core/task.py", line 85, in start
    r = self.task(self, **self.params)
  File "/home/bradfernan/VENV/py3_venv/lib64/python3.7/site-packages/nornir/plugins/tasks/networking/netmiko_send_command.py", line 32, in netmiko_send_command
    result = net_connect.send_command(command_string, **kwargs)
AttributeError: 'UnestablishedConnection' object has no attribute 'send_command'

2021-01-05 09:08:09,096 - nornir.core.task -    ERROR -      start() - Host 'arista4': task 'netmiko_send_command' failed with traceback:
Traceback (most recent call last):
  File "/home/bradfernan/VENV/py3_venv/lib64/python3.7/site-packages/nornir/core/task.py", line 85, in start
    r = self.task(self, **self.params)
  File "/home/bradfernan/VENV/py3_venv/lib64/python3.7/site-packages/nornir/plugins/tasks/networking/netmiko_send_command.py", line 32, in netmiko_send_command
    result = net_connect.send_command(command_string, **kwargs)
AttributeError: 'UnestablishedConnection' object has no attribute 'send_command'

2021-01-05 09:08:09,098 - nornir.core.task -    ERROR -      start() - Host 'srx2': task 'netmiko_send_command' failed with traceback:
Traceback (most recent call last):
  File "/home/bradfernan/VENV/py3_venv/lib64/python3.7/site-packages/nornir/core/task.py", line 85, in start
    r = self.task(self, **self.params)
  File "/home/bradfernan/VENV/py3_venv/lib64/python3.7/site-packages/nornir/plugins/tasks/networking/netmiko_send_command.py", line 32, in netmiko_send_command
    result = net_connect.send_command(command_string, **kwargs)
AttributeError: 'UnestablishedConnection' object has no attribute 'send_command'

2021-01-05 09:08:36,092 - nornir.core.task -    ERROR -      start() - Host 'srx2': task 'netmiko_send_command' failed with traceback:
Traceback (most recent call last):
  File "/home/bradfernan/VENV/py3_venv/lib64/python3.7/site-packages/paramiko/channel.py", line 699, in recv
    out = self.in_buffer.read(nbytes, self.timeout)
  File "/home/bradfernan/VENV/py3_venv/lib64/python3.7/site-packages/paramiko/buffered_pipe.py", line 164, in read
    raise PipeTimeout()
paramiko.buffered_pipe.PipeTimeout

During handling of the above exception, another exception occurred:

Traceback (most recent call last):
  File "/home/bradfernan/VENV/py3_venv/lib64/python3.7/site-packages/netmiko/base_connection.py", line 564, in _read_channel_expect
    new_data = self.remote_conn.recv(MAX_BUFFER)
  File "/home/bradfernan/VENV/py3_venv/lib64/python3.7/site-packages/paramiko/channel.py", line 701, in recv
    raise socket.timeout()
socket.timeout

During handling of the above exception, another exception occurred:

Traceback (most recent call last):
  File "/home/bradfernan/VENV/py3_venv/lib64/python3.7/site-packages/nornir/core/task.py", line 85, in start
    r = self.task(self, **self.params)
  File "/home/bradfernan/VENV/py3_venv/lib64/python3.7/site-packages/nornir/plugins/tasks/networking/netmiko_send_command.py", line 32, in netmiko_send_command
    result = net_connect.send_command(command_string, **kwargs)
  File "/home/bradfernan/VENV/py3_venv/lib64/python3.7/site-packages/netmiko/utilities.py", line 347, in wrapper_decorator
    return func(self, *args, **kwargs)
  File "/home/bradfernan/VENV/py3_venv/lib64/python3.7/site-packages/netmiko/base_connection.py", line 1415, in send_command
    new_data = self.read_until_pattern(pattern=re.escape(cmd))
  File "/home/bradfernan/VENV/py3_venv/lib64/python3.7/site-packages/netmiko/base_connection.py", line 641, in read_until_pattern
    return self._read_channel_expect(*args, **kwargs)
  File "/home/bradfernan/VENV/py3_venv/lib64/python3.7/site-packages/netmiko/base_connection.py", line 575, in _read_channel_expect
    "Timed-out reading channel, data not available."
netmiko.ssh_exception.NetmikoTimeoutException: Timed-out reading channel, data not available.

2021-01-05 09:08:56,575 - nornir.core.task -    ERROR -      start() - Host 'cisco4': task 'get_uptime' failed with traceback:
Traceback (most recent call last):
  File "/home/bradfernan/VENV/py3_venv/lib64/python3.7/site-packages/nornir/core/task.py", line 85, in start
    r = self.task(self, **self.params)
  File "exercise1a.py", line 14, in get_uptime
    print(uptime)
  File "exercise1a.py", line 14, in get_uptime
    print(uptime)
  File "/usr/lib64/python3.7/bdb.py", line 88, in trace_dispatch
    return self.dispatch_line(frame)
  File "/usr/lib64/python3.7/bdb.py", line 113, in dispatch_line
    if self.quitting: raise BdbQuit
bdb.BdbQuit

2021-01-05 09:09:02,162 - nornir.core.task -    ERROR -      start() - Host 'cisco3': task 'get_uptime' failed with traceback:
Traceback (most recent call last):
  File "/home/bradfernan/VENV/py3_venv/lib64/python3.7/site-packages/nornir/core/task.py", line 85, in start
    r = self.task(self, **self.params)
  File "exercise1a.py", line 14, in get_uptime
    print(uptime)
  File "exercise1a.py", line 14, in get_uptime
    print(uptime)
  File "/usr/lib64/python3.7/bdb.py", line 88, in trace_dispatch
    return self.dispatch_line(frame)
  File "/usr/lib64/python3.7/bdb.py", line 113, in dispatch_line
    if self.quitting: raise BdbQuit
bdb.BdbQuit

2021-01-05 09:10:56,020 -  nornir.core -     INFO -        run() - Running task 'get_uptime' with args {} on 9 hosts
2021-01-05 09:10:56,021 -  nornir.core -     INFO -        run() - Running task 'netmiko_send_command' with args {'command_string': 'show version | inc uptime'} on 9 hosts
2021-01-05 09:10:56,021 -  nornir.core -     INFO -        run() - Running task 'netmiko_send_command' with args {'command_string': 'show version | inc uptime'} on 9 hosts
2021-01-05 09:10:56,023 - nornir.core.task -    ERROR -      start() - Host 'cisco3': task 'netmiko_send_command' failed with traceback:
Traceback (most recent call last):
  File "/home/bradfernan/VENV/py3_venv/lib64/python3.7/site-packages/nornir/core/task.py", line 85, in start
    r = self.task(self, **self.params)
  File "/home/bradfernan/VENV/py3_venv/lib64/python3.7/site-packages/nornir/plugins/tasks/networking/netmiko_send_command.py", line 32, in netmiko_send_command
    result = net_connect.send_command(command_string, **kwargs)
AttributeError: 'UnestablishedConnection' object has no attribute 'send_command'

2021-01-05 09:10:56,024 - nornir.core.task -    ERROR -      start() - Host 'cisco4': task 'netmiko_send_command' failed with traceback:
Traceback (most recent call last):
  File "/home/bradfernan/VENV/py3_venv/lib64/python3.7/site-packages/nornir/core/task.py", line 85, in start
    r = self.task(self, **self.params)
  File "/home/bradfernan/VENV/py3_venv/lib64/python3.7/site-packages/nornir/plugins/tasks/networking/netmiko_send_command.py", line 32, in netmiko_send_command
    result = net_connect.send_command(command_string, **kwargs)
AttributeError: 'UnestablishedConnection' object has no attribute 'send_command'

2021-01-05 09:10:56,025 - nornir.core.task -    ERROR -      start() - Host 'nxos1': task 'netmiko_send_command' failed with traceback:
Traceback (most recent call last):
  File "/home/bradfernan/VENV/py3_venv/lib64/python3.7/site-packages/nornir/core/task.py", line 85, in start
    r = self.task(self, **self.params)
  File "/home/bradfernan/VENV/py3_venv/lib64/python3.7/site-packages/nornir/plugins/tasks/networking/netmiko_send_command.py", line 32, in netmiko_send_command
    result = net_connect.send_command(command_string, **kwargs)
AttributeError: 'UnestablishedConnection' object has no attribute 'send_command'

2021-01-05 09:10:56,025 - nornir.core.task -    ERROR -      start() - Host 'nxos2': task 'netmiko_send_command' failed with traceback:
Traceback (most recent call last):
  File "/home/bradfernan/VENV/py3_venv/lib64/python3.7/site-packages/nornir/core/task.py", line 85, in start
    r = self.task(self, **self.params)
  File "/home/bradfernan/VENV/py3_venv/lib64/python3.7/site-packages/nornir/plugins/tasks/networking/netmiko_send_command.py", line 32, in netmiko_send_command
    result = net_connect.send_command(command_string, **kwargs)
AttributeError: 'UnestablishedConnection' object has no attribute 'send_command'

2021-01-05 09:10:56,026 - nornir.core.task -    ERROR -      start() - Host 'arista1': task 'netmiko_send_command' failed with traceback:
Traceback (most recent call last):
  File "/home/bradfernan/VENV/py3_venv/lib64/python3.7/site-packages/nornir/core/task.py", line 85, in start
    r = self.task(self, **self.params)
  File "/home/bradfernan/VENV/py3_venv/lib64/python3.7/site-packages/nornir/plugins/tasks/networking/netmiko_send_command.py", line 32, in netmiko_send_command
    result = net_connect.send_command(command_string, **kwargs)
AttributeError: 'UnestablishedConnection' object has no attribute 'send_command'

2021-01-05 09:10:56,028 - nornir.core.task -    ERROR -      start() - Host 'arista2': task 'netmiko_send_command' failed with traceback:
Traceback (most recent call last):
  File "/home/bradfernan/VENV/py3_venv/lib64/python3.7/site-packages/nornir/core/task.py", line 85, in start
    r = self.task(self, **self.params)
  File "/home/bradfernan/VENV/py3_venv/lib64/python3.7/site-packages/nornir/plugins/tasks/networking/netmiko_send_command.py", line 32, in netmiko_send_command
    result = net_connect.send_command(command_string, **kwargs)
AttributeError: 'UnestablishedConnection' object has no attribute 'send_command'

2021-01-05 09:10:56,028 - nornir.core.task -    ERROR -      start() - Host 'arista3': task 'netmiko_send_command' failed with traceback:
Traceback (most recent call last):
  File "/home/bradfernan/VENV/py3_venv/lib64/python3.7/site-packages/nornir/core/task.py", line 85, in start
    r = self.task(self, **self.params)
  File "/home/bradfernan/VENV/py3_venv/lib64/python3.7/site-packages/nornir/plugins/tasks/networking/netmiko_send_command.py", line 32, in netmiko_send_command
    result = net_connect.send_command(command_string, **kwargs)
AttributeError: 'UnestablishedConnection' object has no attribute 'send_command'

2021-01-05 09:10:56,030 - nornir.core.task -    ERROR -      start() - Host 'arista4': task 'netmiko_send_command' failed with traceback:
Traceback (most recent call last):
  File "/home/bradfernan/VENV/py3_venv/lib64/python3.7/site-packages/nornir/core/task.py", line 85, in start
    r = self.task(self, **self.params)
  File "/home/bradfernan/VENV/py3_venv/lib64/python3.7/site-packages/nornir/plugins/tasks/networking/netmiko_send_command.py", line 32, in netmiko_send_command
    result = net_connect.send_command(command_string, **kwargs)
AttributeError: 'UnestablishedConnection' object has no attribute 'send_command'

2021-01-05 09:10:56,031 - nornir.core.task -    ERROR -      start() - Host 'srx2': task 'netmiko_send_command' failed with traceback:
Traceback (most recent call last):
  File "/home/bradfernan/VENV/py3_venv/lib64/python3.7/site-packages/nornir/core/task.py", line 85, in start
    r = self.task(self, **self.params)
  File "/home/bradfernan/VENV/py3_venv/lib64/python3.7/site-packages/nornir/plugins/tasks/networking/netmiko_send_command.py", line 32, in netmiko_send_command
    result = net_connect.send_command(command_string, **kwargs)
AttributeError: 'UnestablishedConnection' object has no attribute 'send_command'

2021-01-05 09:11:04,273 - nornir.core.task -    ERROR -      start() - Host 'cisco3': task 'get_uptime' failed with traceback:
Traceback (most recent call last):
  File "/home/bradfernan/VENV/py3_venv/lib64/python3.7/site-packages/nornir/core/task.py", line 85, in start
    r = self.task(self, **self.params)
  File "exercise1a.py", line 13, in get_uptime
    for host, multi_result in uptime:
ValueError: too many values to unpack (expected 2)

2021-01-05 09:11:23,063 - nornir.core.task -    ERROR -      start() - Host 'srx2': task 'netmiko_send_command' failed with traceback:
Traceback (most recent call last):
  File "/home/bradfernan/VENV/py3_venv/lib64/python3.7/site-packages/paramiko/channel.py", line 699, in recv
    out = self.in_buffer.read(nbytes, self.timeout)
  File "/home/bradfernan/VENV/py3_venv/lib64/python3.7/site-packages/paramiko/buffered_pipe.py", line 164, in read
    raise PipeTimeout()
paramiko.buffered_pipe.PipeTimeout

During handling of the above exception, another exception occurred:

Traceback (most recent call last):
  File "/home/bradfernan/VENV/py3_venv/lib64/python3.7/site-packages/netmiko/base_connection.py", line 564, in _read_channel_expect
    new_data = self.remote_conn.recv(MAX_BUFFER)
  File "/home/bradfernan/VENV/py3_venv/lib64/python3.7/site-packages/paramiko/channel.py", line 701, in recv
    raise socket.timeout()
socket.timeout

During handling of the above exception, another exception occurred:

Traceback (most recent call last):
  File "/home/bradfernan/VENV/py3_venv/lib64/python3.7/site-packages/nornir/core/task.py", line 85, in start
    r = self.task(self, **self.params)
  File "/home/bradfernan/VENV/py3_venv/lib64/python3.7/site-packages/nornir/plugins/tasks/networking/netmiko_send_command.py", line 32, in netmiko_send_command
    result = net_connect.send_command(command_string, **kwargs)
  File "/home/bradfernan/VENV/py3_venv/lib64/python3.7/site-packages/netmiko/utilities.py", line 347, in wrapper_decorator
    return func(self, *args, **kwargs)
  File "/home/bradfernan/VENV/py3_venv/lib64/python3.7/site-packages/netmiko/base_connection.py", line 1415, in send_command
    new_data = self.read_until_pattern(pattern=re.escape(cmd))
  File "/home/bradfernan/VENV/py3_venv/lib64/python3.7/site-packages/netmiko/base_connection.py", line 641, in read_until_pattern
    return self._read_channel_expect(*args, **kwargs)
  File "/home/bradfernan/VENV/py3_venv/lib64/python3.7/site-packages/netmiko/base_connection.py", line 575, in _read_channel_expect
    "Timed-out reading channel, data not available."
netmiko.ssh_exception.NetmikoTimeoutException: Timed-out reading channel, data not available.

2021-01-05 09:11:23,064 - nornir.core.task -    ERROR -      start() - Host 'cisco4': task 'get_uptime' failed with traceback:
Traceback (most recent call last):
  File "/home/bradfernan/VENV/py3_venv/lib64/python3.7/site-packages/nornir/core/task.py", line 85, in start
    r = self.task(self, **self.params)
  File "exercise1a.py", line 13, in get_uptime
    for host, multi_result in uptime:
ValueError: too many values to unpack (expected 2)

2021-01-05 09:12:21,405 -  nornir.core -     INFO -        run() - Running task 'get_uptime' with args {} on 9 hosts
2021-01-05 09:12:21,894 - nornir.core.task -    ERROR -      start() - Host 'cisco4': task 'get_uptime' failed with traceback:
Traceback (most recent call last):
  File "/home/bradfernan/VENV/py3_venv/lib64/python3.7/site-packages/nornir/core/task.py", line 85, in start
    r = self.task(self, **self.params)
  File "exercise1a.py", line 8, in get_uptime
    import ipdb; ipdb.set_result()
AttributeError: module 'ipdb' has no attribute 'set_result'

2021-01-05 09:12:21,894 - nornir.core.task -    ERROR -      start() - Host 'nxos1': task 'get_uptime' failed with traceback:
Traceback (most recent call last):
  File "/home/bradfernan/VENV/py3_venv/lib64/python3.7/site-packages/nornir/core/task.py", line 85, in start
    r = self.task(self, **self.params)
  File "exercise1a.py", line 8, in get_uptime
    import ipdb; ipdb.set_result()
AttributeError: module 'ipdb' has no attribute 'set_result'

2021-01-05 09:12:21,894 - nornir.core.task -    ERROR -      start() - Host 'nxos2': task 'get_uptime' failed with traceback:
Traceback (most recent call last):
  File "/home/bradfernan/VENV/py3_venv/lib64/python3.7/site-packages/nornir/core/task.py", line 85, in start
    r = self.task(self, **self.params)
  File "exercise1a.py", line 8, in get_uptime
    import ipdb; ipdb.set_result()
AttributeError: module 'ipdb' has no attribute 'set_result'

2021-01-05 09:12:21,895 - nornir.core.task -    ERROR -      start() - Host 'arista1': task 'get_uptime' failed with traceback:
Traceback (most recent call last):
  File "/home/bradfernan/VENV/py3_venv/lib64/python3.7/site-packages/nornir/core/task.py", line 85, in start
    r = self.task(self, **self.params)
  File "exercise1a.py", line 8, in get_uptime
    import ipdb; ipdb.set_result()
AttributeError: module 'ipdb' has no attribute 'set_result'

2021-01-05 09:12:21,895 - nornir.core.task -    ERROR -      start() - Host 'arista2': task 'get_uptime' failed with traceback:
Traceback (most recent call last):
  File "/home/bradfernan/VENV/py3_venv/lib64/python3.7/site-packages/nornir/core/task.py", line 85, in start
    r = self.task(self, **self.params)
  File "exercise1a.py", line 8, in get_uptime
    import ipdb; ipdb.set_result()
AttributeError: module 'ipdb' has no attribute 'set_result'

2021-01-05 09:12:21,895 - nornir.core.task -    ERROR -      start() - Host 'arista3': task 'get_uptime' failed with traceback:
Traceback (most recent call last):
  File "/home/bradfernan/VENV/py3_venv/lib64/python3.7/site-packages/nornir/core/task.py", line 85, in start
    r = self.task(self, **self.params)
  File "exercise1a.py", line 8, in get_uptime
    import ipdb; ipdb.set_result()
AttributeError: module 'ipdb' has no attribute 'set_result'

2021-01-05 09:12:21,896 - nornir.core.task -    ERROR -      start() - Host 'arista4': task 'get_uptime' failed with traceback:
Traceback (most recent call last):
  File "/home/bradfernan/VENV/py3_venv/lib64/python3.7/site-packages/nornir/core/task.py", line 85, in start
    r = self.task(self, **self.params)
  File "exercise1a.py", line 8, in get_uptime
    import ipdb; ipdb.set_result()
AttributeError: module 'ipdb' has no attribute 'set_result'

2021-01-05 09:12:21,896 - nornir.core.task -    ERROR -      start() - Host 'srx2': task 'get_uptime' failed with traceback:
Traceback (most recent call last):
  File "/home/bradfernan/VENV/py3_venv/lib64/python3.7/site-packages/nornir/core/task.py", line 85, in start
    r = self.task(self, **self.params)
  File "exercise1a.py", line 8, in get_uptime
    import ipdb; ipdb.set_result()
AttributeError: module 'ipdb' has no attribute 'set_result'

2021-01-05 09:12:21,896 - nornir.core.task -    ERROR -      start() - Host 'cisco3': task 'get_uptime' failed with traceback:
Traceback (most recent call last):
  File "/home/bradfernan/VENV/py3_venv/lib64/python3.7/site-packages/nornir/core/task.py", line 85, in start
    r = self.task(self, **self.params)
  File "exercise1a.py", line 8, in get_uptime
    import ipdb; ipdb.set_result()
AttributeError: module 'ipdb' has no attribute 'set_result'

2021-01-05 09:13:17,225 -  nornir.core -     INFO -        run() - Running task 'get_uptime' with args {} on 9 hosts
2021-01-05 09:13:17,715 - nornir.core.task -    ERROR -      start() - Host 'cisco3': task 'get_uptime' failed with traceback:
Traceback (most recent call last):
  File "/home/bradfernan/VENV/py3_venv/lib64/python3.7/site-packages/nornir/core/task.py", line 85, in start
    r = self.task(self, **self.params)
  File "exercise1a.py", line 8, in get_uptime
    import ipdb; ipdb.set_result()
AttributeError: module 'ipdb' has no attribute 'set_result'

2021-01-05 09:13:17,715 - nornir.core.task -    ERROR -      start() - Host 'cisco4': task 'get_uptime' failed with traceback:
Traceback (most recent call last):
  File "/home/bradfernan/VENV/py3_venv/lib64/python3.7/site-packages/nornir/core/task.py", line 85, in start
    r = self.task(self, **self.params)
  File "exercise1a.py", line 8, in get_uptime
    import ipdb; ipdb.set_result()
AttributeError: module 'ipdb' has no attribute 'set_result'

2021-01-05 09:13:17,715 - nornir.core.task -    ERROR -      start() - Host 'nxos1': task 'get_uptime' failed with traceback:
Traceback (most recent call last):
  File "/home/bradfernan/VENV/py3_venv/lib64/python3.7/site-packages/nornir/core/task.py", line 85, in start
    r = self.task(self, **self.params)
  File "exercise1a.py", line 8, in get_uptime
    import ipdb; ipdb.set_result()
AttributeError: module 'ipdb' has no attribute 'set_result'

2021-01-05 09:13:17,716 - nornir.core.task -    ERROR -      start() - Host 'nxos2': task 'get_uptime' failed with traceback:
Traceback (most recent call last):
  File "/home/bradfernan/VENV/py3_venv/lib64/python3.7/site-packages/nornir/core/task.py", line 85, in start
    r = self.task(self, **self.params)
  File "exercise1a.py", line 8, in get_uptime
    import ipdb; ipdb.set_result()
AttributeError: module 'ipdb' has no attribute 'set_result'

2021-01-05 09:13:17,716 - nornir.core.task -    ERROR -      start() - Host 'arista1': task 'get_uptime' failed with traceback:
Traceback (most recent call last):
  File "/home/bradfernan/VENV/py3_venv/lib64/python3.7/site-packages/nornir/core/task.py", line 85, in start
    r = self.task(self, **self.params)
  File "exercise1a.py", line 8, in get_uptime
    import ipdb; ipdb.set_result()
AttributeError: module 'ipdb' has no attribute 'set_result'

2021-01-05 09:13:17,716 - nornir.core.task -    ERROR -      start() - Host 'arista2': task 'get_uptime' failed with traceback:
Traceback (most recent call last):
  File "/home/bradfernan/VENV/py3_venv/lib64/python3.7/site-packages/nornir/core/task.py", line 85, in start
    r = self.task(self, **self.params)
  File "exercise1a.py", line 8, in get_uptime
    import ipdb; ipdb.set_result()
AttributeError: module 'ipdb' has no attribute 'set_result'

2021-01-05 09:13:17,716 - nornir.core.task -    ERROR -      start() - Host 'arista3': task 'get_uptime' failed with traceback:
Traceback (most recent call last):
  File "/home/bradfernan/VENV/py3_venv/lib64/python3.7/site-packages/nornir/core/task.py", line 85, in start
    r = self.task(self, **self.params)
  File "exercise1a.py", line 8, in get_uptime
    import ipdb; ipdb.set_result()
AttributeError: module 'ipdb' has no attribute 'set_result'

2021-01-05 09:13:17,716 - nornir.core.task -    ERROR -      start() - Host 'arista4': task 'get_uptime' failed with traceback:
Traceback (most recent call last):
  File "/home/bradfernan/VENV/py3_venv/lib64/python3.7/site-packages/nornir/core/task.py", line 85, in start
    r = self.task(self, **self.params)
  File "exercise1a.py", line 8, in get_uptime
    import ipdb; ipdb.set_result()
AttributeError: module 'ipdb' has no attribute 'set_result'

2021-01-05 09:13:17,717 - nornir.core.task -    ERROR -      start() - Host 'srx2': task 'get_uptime' failed with traceback:
Traceback (most recent call last):
  File "/home/bradfernan/VENV/py3_venv/lib64/python3.7/site-packages/nornir/core/task.py", line 85, in start
    r = self.task(self, **self.params)
  File "exercise1a.py", line 8, in get_uptime
    import ipdb; ipdb.set_result()
AttributeError: module 'ipdb' has no attribute 'set_result'

2021-01-05 09:13:37,342 -  nornir.core -     INFO -        run() - Running task 'get_uptime' with args {} on 9 hosts
2021-01-05 09:16:28,575 - nornir.core.task -    ERROR -      start() - Host 'cisco3': task 'get_uptime' failed with traceback:
Traceback (most recent call last):
  File "/home/bradfernan/VENV/py3_venv/lib64/python3.7/site-packages/nornir/core/task.py", line 85, in start
    r = self.task(self, **self.params)
  File "exercise1a.py", line 9, in get_uptime
    if task.host.groups[0] == 'ios':
  File "exercise1a.py", line 9, in get_uptime
    if task.host.groups[0] == 'ios':
  File "/usr/lib64/python3.7/bdb.py", line 88, in trace_dispatch
    return self.dispatch_line(frame)
  File "/usr/lib64/python3.7/bdb.py", line 113, in dispatch_line
    if self.quitting: raise BdbQuit
bdb.BdbQuit

2021-01-05 09:16:30,157 - nornir.core.task -    ERROR -      start() - Host 'cisco4': task 'get_uptime' failed with traceback:
Traceback (most recent call last):
  File "/home/bradfernan/VENV/py3_venv/lib64/python3.7/site-packages/nornir/core/task.py", line 85, in start
    r = self.task(self, **self.params)
  File "exercise1a.py", line 9, in get_uptime
    if task.host.groups[0] == 'ios':
  File "exercise1a.py", line 9, in get_uptime
    if task.host.groups[0] == 'ios':
  File "/usr/lib64/python3.7/bdb.py", line 88, in trace_dispatch
    return self.dispatch_line(frame)
  File "/usr/lib64/python3.7/bdb.py", line 113, in dispatch_line
    if self.quitting: raise BdbQuit
bdb.BdbQuit

2021-01-05 09:16:37,845 - nornir.core.task -    ERROR -      start() - Host 'nxos1': task 'get_uptime' failed with traceback:
Traceback (most recent call last):
  File "/home/bradfernan/VENV/py3_venv/lib64/python3.7/site-packages/nornir/core/task.py", line 85, in start
    r = self.task(self, **self.params)
  File "exercise1a.py", line 9, in get_uptime
    if task.host.groups[0] == 'ios':
  File "exercise1a.py", line 9, in get_uptime
    if task.host.groups[0] == 'ios':
  File "/usr/lib64/python3.7/bdb.py", line 88, in trace_dispatch
    return self.dispatch_line(frame)
  File "/usr/lib64/python3.7/bdb.py", line 113, in dispatch_line
    if self.quitting: raise BdbQuit
bdb.BdbQuit

2021-01-05 09:16:39,419 - nornir.core.task -    ERROR -      start() - Host 'nxos2': task 'get_uptime' failed with traceback:
Traceback (most recent call last):
  File "/home/bradfernan/VENV/py3_venv/lib64/python3.7/site-packages/nornir/core/task.py", line 85, in start
    r = self.task(self, **self.params)
  File "exercise1a.py", line 9, in get_uptime
    if task.host.groups[0] == 'ios':
  File "exercise1a.py", line 9, in get_uptime
    if task.host.groups[0] == 'ios':
  File "/usr/lib64/python3.7/bdb.py", line 88, in trace_dispatch
    return self.dispatch_line(frame)
  File "/usr/lib64/python3.7/bdb.py", line 113, in dispatch_line
    if self.quitting: raise BdbQuit
bdb.BdbQuit

2021-01-05 09:16:43,439 - nornir.core.task -    ERROR -      start() - Host 'arista1': task 'get_uptime' failed with traceback:
Traceback (most recent call last):
  File "/home/bradfernan/VENV/py3_venv/lib64/python3.7/site-packages/nornir/core/task.py", line 85, in start
    r = self.task(self, **self.params)
  File "exercise1a.py", line 9, in get_uptime
    if task.host.groups[0] == 'ios':
  File "exercise1a.py", line 9, in get_uptime
    if task.host.groups[0] == 'ios':
  File "/usr/lib64/python3.7/bdb.py", line 88, in trace_dispatch
    return self.dispatch_line(frame)
  File "/usr/lib64/python3.7/bdb.py", line 113, in dispatch_line
    if self.quitting: raise BdbQuit
bdb.BdbQuit

2021-01-05 09:16:44,939 - nornir.core.task -    ERROR -      start() - Host 'arista2': task 'get_uptime' failed with traceback:
Traceback (most recent call last):
  File "/home/bradfernan/VENV/py3_venv/lib64/python3.7/site-packages/nornir/core/task.py", line 85, in start
    r = self.task(self, **self.params)
  File "exercise1a.py", line 9, in get_uptime
    if task.host.groups[0] == 'ios':
  File "exercise1a.py", line 9, in get_uptime
    if task.host.groups[0] == 'ios':
  File "/usr/lib64/python3.7/bdb.py", line 88, in trace_dispatch
    return self.dispatch_line(frame)
  File "/usr/lib64/python3.7/bdb.py", line 113, in dispatch_line
    if self.quitting: raise BdbQuit
bdb.BdbQuit

2021-01-05 09:16:46,950 - nornir.core.task -    ERROR -      start() - Host 'arista3': task 'get_uptime' failed with traceback:
Traceback (most recent call last):
  File "/home/bradfernan/VENV/py3_venv/lib64/python3.7/site-packages/nornir/core/task.py", line 85, in start
    r = self.task(self, **self.params)
  File "exercise1a.py", line 9, in get_uptime
    if task.host.groups[0] == 'ios':
  File "exercise1a.py", line 9, in get_uptime
    if task.host.groups[0] == 'ios':
  File "/usr/lib64/python3.7/bdb.py", line 88, in trace_dispatch
    return self.dispatch_line(frame)
  File "/usr/lib64/python3.7/bdb.py", line 113, in dispatch_line
    if self.quitting: raise BdbQuit
bdb.BdbQuit

2021-01-05 09:16:55,602 - nornir.core.task -    ERROR -      start() - Host 'arista4': task 'get_uptime' failed with traceback:
Traceback (most recent call last):
  File "/home/bradfernan/VENV/py3_venv/lib64/python3.7/site-packages/nornir/core/task.py", line 85, in start
    r = self.task(self, **self.params)
  File "exercise1a.py", line 9, in get_uptime
    if task.host.groups[0] == 'ios':
  File "exercise1a.py", line 9, in get_uptime
    if task.host.groups[0] == 'ios':
  File "/usr/lib64/python3.7/bdb.py", line 88, in trace_dispatch
    return self.dispatch_line(frame)
  File "/usr/lib64/python3.7/bdb.py", line 113, in dispatch_line
    if self.quitting: raise BdbQuit
bdb.BdbQuit

2021-01-05 09:16:56,496 - nornir.core.task -    ERROR -      start() - Host 'srx2': task 'get_uptime' failed with traceback:
Traceback (most recent call last):
  File "/home/bradfernan/VENV/py3_venv/lib64/python3.7/site-packages/nornir/core/task.py", line 85, in start
    r = self.task(self, **self.params)
  File "exercise1a.py", line 9, in get_uptime
    if task.host.groups[0] == 'ios':
  File "exercise1a.py", line 9, in get_uptime
    if task.host.groups[0] == 'ios':
  File "/usr/lib64/python3.7/bdb.py", line 88, in trace_dispatch
    return self.dispatch_line(frame)
  File "/usr/lib64/python3.7/bdb.py", line 113, in dispatch_line
    if self.quitting: raise BdbQuit
bdb.BdbQuit

2021-01-05 09:17:55,186 -  nornir.core -     INFO -        run() - Running task 'get_uptime' with args {} on 9 hosts
2021-01-05 09:18:45,885 -  nornir.core -     INFO -        run() - Running task 'get_uptime' with args {} on 9 hosts
2021-01-05 09:19:28,784 -  nornir.core -     INFO -        run() - Running task 'get_uptime' with args {} on 9 hosts
2021-01-05 09:21:56,659 -  nornir.core -     INFO -        run() - Running task 'get_uptime' with args {} on 9 hosts
2021-01-05 09:27:19,891 -  nornir.core -     INFO -        run() - Running task 'get_uptime' with args {} on 9 hosts
2021-01-05 09:44:01,045 -  nornir.core -     INFO -        run() - Running task 'get_uptime' with args {} on 2 hosts
2021-01-05 10:12:36,148 -  nornir.core -     INFO -        run() - Running task 'get_uptime' with args {} on 2 hosts
2021-01-05 10:13:02,954 -  nornir.core -     INFO -        run() - Running task 'get_uptime' with args {} on 2 hosts
2021-01-05 10:17:26,599 -  nornir.core -     INFO -        run() - Running task 'get_uptime' with args {} on 2 hosts
2021-01-05 10:27:58,406 -  nornir.core -     INFO -        run() - Running task 'get_uptime' with args {} on 2 hosts
2021-01-05 10:30:33,848 -  nornir.core -     INFO -        run() - Running task 'get_uptime' with args {} on 2 hosts
2021-01-05 10:32:00,499 -  nornir.core -     INFO -        run() - Running task 'get_uptime' with args {} on 2 hosts
2021-01-05 10:32:55,667 -  nornir.core -     INFO -        run() - Running task 'get_uptime' with args {} on 2 hosts
2021-01-05 10:34:16,806 -  nornir.core -     INFO -        run() - Running task 'get_uptime' with args {} on 2 hosts
2021-01-05 10:50:28,445 -  nornir.core -     INFO -        run() - Running task 'get_uptime' with args {} on 2 hosts
2021-01-05 11:12:01,498 -  nornir.core -     INFO -        run() - Running task 'get_uptime' with args {} on 9 hosts
2021-01-05 11:12:01,500 - nornir.core.task -    ERROR -      start() - Host 'nxos1': task 'get_uptime' failed with traceback:
Traceback (most recent call last):
  File "/home/bradfernan/VENV/py3_venv/lib64/python3.7/site-packages/nornir/core/task.py", line 85, in start
    r = self.task(self, **self.params)
  File "exercise1a.py", line 15, in get_uptime
    return Result(host=task.host, result=uptime[0].result)
UnboundLocalError: local variable 'uptime' referenced before assignment

2021-01-05 11:12:01,500 - nornir.core.task -    ERROR -      start() - Host 'nxos2': task 'get_uptime' failed with traceback:
Traceback (most recent call last):
  File "/home/bradfernan/VENV/py3_venv/lib64/python3.7/site-packages/nornir/core/task.py", line 85, in start
    r = self.task(self, **self.params)
  File "exercise1a.py", line 15, in get_uptime
    return Result(host=task.host, result=uptime[0].result)
UnboundLocalError: local variable 'uptime' referenced before assignment

2021-01-05 11:12:01,500 - nornir.core.task -    ERROR -      start() - Host 'arista1': task 'get_uptime' failed with traceback:
Traceback (most recent call last):
  File "/home/bradfernan/VENV/py3_venv/lib64/python3.7/site-packages/nornir/core/task.py", line 85, in start
    r = self.task(self, **self.params)
  File "exercise1a.py", line 15, in get_uptime
    return Result(host=task.host, result=uptime[0].result)
UnboundLocalError: local variable 'uptime' referenced before assignment

2021-01-05 11:12:01,501 - nornir.core.task -    ERROR -      start() - Host 'arista2': task 'get_uptime' failed with traceback:
Traceback (most recent call last):
  File "/home/bradfernan/VENV/py3_venv/lib64/python3.7/site-packages/nornir/core/task.py", line 85, in start
    r = self.task(self, **self.params)
  File "exercise1a.py", line 15, in get_uptime
    return Result(host=task.host, result=uptime[0].result)
UnboundLocalError: local variable 'uptime' referenced before assignment

2021-01-05 11:12:01,501 - nornir.core.task -    ERROR -      start() - Host 'arista3': task 'get_uptime' failed with traceback:
Traceback (most recent call last):
  File "/home/bradfernan/VENV/py3_venv/lib64/python3.7/site-packages/nornir/core/task.py", line 85, in start
    r = self.task(self, **self.params)
  File "exercise1a.py", line 15, in get_uptime
    return Result(host=task.host, result=uptime[0].result)
UnboundLocalError: local variable 'uptime' referenced before assignment

2021-01-05 11:12:01,501 - nornir.core.task -    ERROR -      start() - Host 'arista4': task 'get_uptime' failed with traceback:
Traceback (most recent call last):
  File "/home/bradfernan/VENV/py3_venv/lib64/python3.7/site-packages/nornir/core/task.py", line 85, in start
    r = self.task(self, **self.params)
  File "exercise1a.py", line 15, in get_uptime
    return Result(host=task.host, result=uptime[0].result)
UnboundLocalError: local variable 'uptime' referenced before assignment

2021-01-05 11:12:01,502 - nornir.core.task -    ERROR -      start() - Host 'srx2': task 'get_uptime' failed with traceback:
Traceback (most recent call last):
  File "/home/bradfernan/VENV/py3_venv/lib64/python3.7/site-packages/nornir/core/task.py", line 85, in start
    r = self.task(self, **self.params)
  File "exercise1a.py", line 15, in get_uptime
    return Result(host=task.host, result=uptime[0].result)
UnboundLocalError: local variable 'uptime' referenced before assignment

2021-01-05 11:13:27,400 -  nornir.core -     INFO -        run() - Running task 'get_uptime' with args {} on 9 hosts
2021-01-05 11:13:39,452 - nornir.core.task -    ERROR -      start() - Host 'nxos1': task 'get_uptime' failed with traceback:
Traceback (most recent call last):
  File "/home/bradfernan/VENV/py3_venv/lib64/python3.7/site-packages/nornir/core/task.py", line 85, in start
    r = self.task(self, **self.params)
  File "exercise1a.py", line 15, in get_uptime
    return Result(host=task.host, result=uptime[0].result)
UnboundLocalError: local variable 'uptime' referenced before assignment

2021-01-05 11:13:39,452 - nornir.core.task -    ERROR -      start() - Host 'nxos2': task 'get_uptime' failed with traceback:
Traceback (most recent call last):
  File "/home/bradfernan/VENV/py3_venv/lib64/python3.7/site-packages/nornir/core/task.py", line 85, in start
    r = self.task(self, **self.params)
  File "exercise1a.py", line 15, in get_uptime
    return Result(host=task.host, result=uptime[0].result)
UnboundLocalError: local variable 'uptime' referenced before assignment

2021-01-05 11:13:39,453 - nornir.core.task -    ERROR -      start() - Host 'arista1': task 'get_uptime' failed with traceback:
Traceback (most recent call last):
  File "/home/bradfernan/VENV/py3_venv/lib64/python3.7/site-packages/nornir/core/task.py", line 85, in start
    r = self.task(self, **self.params)
  File "exercise1a.py", line 15, in get_uptime
    return Result(host=task.host, result=uptime[0].result)
UnboundLocalError: local variable 'uptime' referenced before assignment

2021-01-05 11:13:39,453 - nornir.core.task -    ERROR -      start() - Host 'arista2': task 'get_uptime' failed with traceback:
Traceback (most recent call last):
  File "/home/bradfernan/VENV/py3_venv/lib64/python3.7/site-packages/nornir/core/task.py", line 85, in start
    r = self.task(self, **self.params)
  File "exercise1a.py", line 15, in get_uptime
    return Result(host=task.host, result=uptime[0].result)
UnboundLocalError: local variable 'uptime' referenced before assignment

2021-01-05 11:13:39,453 - nornir.core.task -    ERROR -      start() - Host 'arista3': task 'get_uptime' failed with traceback:
Traceback (most recent call last):
  File "/home/bradfernan/VENV/py3_venv/lib64/python3.7/site-packages/nornir/core/task.py", line 85, in start
    r = self.task(self, **self.params)
  File "exercise1a.py", line 15, in get_uptime
    return Result(host=task.host, result=uptime[0].result)
UnboundLocalError: local variable 'uptime' referenced before assignment

2021-01-05 11:13:39,453 - nornir.core.task -    ERROR -      start() - Host 'arista4': task 'get_uptime' failed with traceback:
Traceback (most recent call last):
  File "/home/bradfernan/VENV/py3_venv/lib64/python3.7/site-packages/nornir/core/task.py", line 85, in start
    r = self.task(self, **self.params)
  File "exercise1a.py", line 15, in get_uptime
    return Result(host=task.host, result=uptime[0].result)
UnboundLocalError: local variable 'uptime' referenced before assignment

2021-01-05 11:13:39,453 - nornir.core.task -    ERROR -      start() - Host 'srx2': task 'get_uptime' failed with traceback:
Traceback (most recent call last):
  File "/home/bradfernan/VENV/py3_venv/lib64/python3.7/site-packages/nornir/core/task.py", line 85, in start
    r = self.task(self, **self.params)
  File "exercise1a.py", line 15, in get_uptime
    return Result(host=task.host, result=uptime[0].result)
UnboundLocalError: local variable 'uptime' referenced before assignment

2021-01-05 11:16:57,508 -  nornir.core -     INFO -        run() - Running task 'get_uptime' with args {} on 9 hosts
2021-01-05 11:18:07,191 -  nornir.core -     INFO -        run() - Running task 'get_uptime' with args {} on 9 hosts
2021-01-05 11:18:34,116 - nornir.core.task -    ERROR -      start() - Host 'srx2': task 'netmiko_send_command' failed with traceback:
Traceback (most recent call last):
  File "/home/bradfernan/VENV/py3_venv/lib64/python3.7/site-packages/paramiko/channel.py", line 699, in recv
    out = self.in_buffer.read(nbytes, self.timeout)
  File "/home/bradfernan/VENV/py3_venv/lib64/python3.7/site-packages/paramiko/buffered_pipe.py", line 164, in read
    raise PipeTimeout()
paramiko.buffered_pipe.PipeTimeout

During handling of the above exception, another exception occurred:

Traceback (most recent call last):
  File "/home/bradfernan/VENV/py3_venv/lib64/python3.7/site-packages/netmiko/base_connection.py", line 564, in _read_channel_expect
    new_data = self.remote_conn.recv(MAX_BUFFER)
  File "/home/bradfernan/VENV/py3_venv/lib64/python3.7/site-packages/paramiko/channel.py", line 701, in recv
    raise socket.timeout()
socket.timeout

During handling of the above exception, another exception occurred:

Traceback (most recent call last):
  File "/home/bradfernan/VENV/py3_venv/lib64/python3.7/site-packages/nornir/core/task.py", line 85, in start
    r = self.task(self, **self.params)
  File "/home/bradfernan/VENV/py3_venv/lib64/python3.7/site-packages/nornir/plugins/tasks/networking/netmiko_send_command.py", line 32, in netmiko_send_command
    result = net_connect.send_command(command_string, **kwargs)
  File "/home/bradfernan/VENV/py3_venv/lib64/python3.7/site-packages/netmiko/utilities.py", line 347, in wrapper_decorator
    return func(self, *args, **kwargs)
  File "/home/bradfernan/VENV/py3_venv/lib64/python3.7/site-packages/netmiko/base_connection.py", line 1415, in send_command
    new_data = self.read_until_pattern(pattern=re.escape(cmd))
  File "/home/bradfernan/VENV/py3_venv/lib64/python3.7/site-packages/netmiko/base_connection.py", line 641, in read_until_pattern
    return self._read_channel_expect(*args, **kwargs)
  File "/home/bradfernan/VENV/py3_venv/lib64/python3.7/site-packages/netmiko/base_connection.py", line 575, in _read_channel_expect
    "Timed-out reading channel, data not available."
netmiko.ssh_exception.NetmikoTimeoutException: Timed-out reading channel, data not available.

2021-01-05 11:18:34,116 - nornir.core.task -    ERROR -      start() - Host 'srx2': task 'get_uptime' failed with traceback:
Traceback (most recent call last):
  File "/home/bradfernan/VENV/py3_venv/lib64/python3.7/site-packages/nornir/core/task.py", line 85, in start
    r = self.task(self, **self.params)
  File "exercise1a.py", line 14, in get_uptime
    uptime = task.run(task=netmiko_send_command, command_string=cmd)
  File "/home/bradfernan/VENV/py3_venv/lib64/python3.7/site-packages/nornir/core/task.py", line 147, in run
    raise NornirSubTaskError(task=task, result=r)
nornir.core.exceptions.NornirSubTaskError: Subtask: <function netmiko_send_command at 0x7f0513210cb0> (failed)


2021-01-05 11:20:27,438 -  nornir.core -     INFO -        run() - Running task 'get_uptime' with args {} on 9 hosts
2021-01-05 11:20:54,438 - nornir.core.task -    ERROR -      start() - Host 'srx2': task 'netmiko_send_command' failed with traceback:
Traceback (most recent call last):
  File "/home/bradfernan/VENV/py3_venv/lib64/python3.7/site-packages/paramiko/channel.py", line 699, in recv
    out = self.in_buffer.read(nbytes, self.timeout)
  File "/home/bradfernan/VENV/py3_venv/lib64/python3.7/site-packages/paramiko/buffered_pipe.py", line 164, in read
    raise PipeTimeout()
paramiko.buffered_pipe.PipeTimeout

During handling of the above exception, another exception occurred:

Traceback (most recent call last):
  File "/home/bradfernan/VENV/py3_venv/lib64/python3.7/site-packages/netmiko/base_connection.py", line 564, in _read_channel_expect
    new_data = self.remote_conn.recv(MAX_BUFFER)
  File "/home/bradfernan/VENV/py3_venv/lib64/python3.7/site-packages/paramiko/channel.py", line 701, in recv
    raise socket.timeout()
socket.timeout

During handling of the above exception, another exception occurred:

Traceback (most recent call last):
  File "/home/bradfernan/VENV/py3_venv/lib64/python3.7/site-packages/nornir/core/task.py", line 85, in start
    r = self.task(self, **self.params)
  File "/home/bradfernan/VENV/py3_venv/lib64/python3.7/site-packages/nornir/plugins/tasks/networking/netmiko_send_command.py", line 32, in netmiko_send_command
    result = net_connect.send_command(command_string, **kwargs)
  File "/home/bradfernan/VENV/py3_venv/lib64/python3.7/site-packages/netmiko/utilities.py", line 347, in wrapper_decorator
    return func(self, *args, **kwargs)
  File "/home/bradfernan/VENV/py3_venv/lib64/python3.7/site-packages/netmiko/base_connection.py", line 1415, in send_command
    new_data = self.read_until_pattern(pattern=re.escape(cmd))
  File "/home/bradfernan/VENV/py3_venv/lib64/python3.7/site-packages/netmiko/base_connection.py", line 641, in read_until_pattern
    return self._read_channel_expect(*args, **kwargs)
  File "/home/bradfernan/VENV/py3_venv/lib64/python3.7/site-packages/netmiko/base_connection.py", line 575, in _read_channel_expect
    "Timed-out reading channel, data not available."
netmiko.ssh_exception.NetmikoTimeoutException: Timed-out reading channel, data not available.

2021-01-05 11:20:54,439 - nornir.core.task -    ERROR -      start() - Host 'srx2': task 'get_uptime' failed with traceback:
Traceback (most recent call last):
  File "/home/bradfernan/VENV/py3_venv/lib64/python3.7/site-packages/nornir/core/task.py", line 85, in start
    r = self.task(self, **self.params)
  File "exercise1a.py", line 14, in get_uptime
    uptime = task.run(task=netmiko_send_command, command_string=cmd)
  File "/home/bradfernan/VENV/py3_venv/lib64/python3.7/site-packages/nornir/core/task.py", line 147, in run
    raise NornirSubTaskError(task=task, result=r)
nornir.core.exceptions.NornirSubTaskError: Subtask: <function netmiko_send_command at 0x7f3e4e080cb0> (failed)


2021-01-05 11:21:22,893 -  nornir.core -     INFO -        run() - Running task 'get_uptime' with args {} on 9 hosts
2021-01-05 11:21:50,359 - nornir.core.task -    ERROR -      start() - Host 'srx2': task 'netmiko_send_command' failed with traceback:
Traceback (most recent call last):
  File "/home/bradfernan/VENV/py3_venv/lib64/python3.7/site-packages/paramiko/channel.py", line 699, in recv
    out = self.in_buffer.read(nbytes, self.timeout)
  File "/home/bradfernan/VENV/py3_venv/lib64/python3.7/site-packages/paramiko/buffered_pipe.py", line 164, in read
    raise PipeTimeout()
paramiko.buffered_pipe.PipeTimeout

During handling of the above exception, another exception occurred:

Traceback (most recent call last):
  File "/home/bradfernan/VENV/py3_venv/lib64/python3.7/site-packages/netmiko/base_connection.py", line 564, in _read_channel_expect
    new_data = self.remote_conn.recv(MAX_BUFFER)
  File "/home/bradfernan/VENV/py3_venv/lib64/python3.7/site-packages/paramiko/channel.py", line 701, in recv
    raise socket.timeout()
socket.timeout

During handling of the above exception, another exception occurred:

Traceback (most recent call last):
  File "/home/bradfernan/VENV/py3_venv/lib64/python3.7/site-packages/nornir/core/task.py", line 85, in start
    r = self.task(self, **self.params)
  File "/home/bradfernan/VENV/py3_venv/lib64/python3.7/site-packages/nornir/plugins/tasks/networking/netmiko_send_command.py", line 32, in netmiko_send_command
    result = net_connect.send_command(command_string, **kwargs)
  File "/home/bradfernan/VENV/py3_venv/lib64/python3.7/site-packages/netmiko/utilities.py", line 347, in wrapper_decorator
    return func(self, *args, **kwargs)
  File "/home/bradfernan/VENV/py3_venv/lib64/python3.7/site-packages/netmiko/base_connection.py", line 1415, in send_command
    new_data = self.read_until_pattern(pattern=re.escape(cmd))
  File "/home/bradfernan/VENV/py3_venv/lib64/python3.7/site-packages/netmiko/base_connection.py", line 641, in read_until_pattern
    return self._read_channel_expect(*args, **kwargs)
  File "/home/bradfernan/VENV/py3_venv/lib64/python3.7/site-packages/netmiko/base_connection.py", line 575, in _read_channel_expect
    "Timed-out reading channel, data not available."
netmiko.ssh_exception.NetmikoTimeoutException: Timed-out reading channel, data not available.

2021-01-05 11:21:50,360 - nornir.core.task -    ERROR -      start() - Host 'srx2': task 'get_uptime' failed with traceback:
Traceback (most recent call last):
  File "/home/bradfernan/VENV/py3_venv/lib64/python3.7/site-packages/nornir/core/task.py", line 85, in start
    r = self.task(self, **self.params)
  File "exercise1a.py", line 14, in get_uptime
    uptime = task.run(task=netmiko_send_command, command_string=cmd)
  File "/home/bradfernan/VENV/py3_venv/lib64/python3.7/site-packages/nornir/core/task.py", line 147, in run
    raise NornirSubTaskError(task=task, result=r)
nornir.core.exceptions.NornirSubTaskError: Subtask: <function netmiko_send_command at 0x7fd3b8790440> (failed)


2021-01-05 11:25:19,243 -  nornir.core -     INFO -        run() - Running task 'get_uptime' with args {} on 9 hosts
2021-01-05 11:25:46,347 - nornir.core.task -    ERROR -      start() - Host 'srx2': task 'netmiko_send_command' failed with traceback:
Traceback (most recent call last):
  File "/home/bradfernan/VENV/py3_venv/lib64/python3.7/site-packages/paramiko/channel.py", line 699, in recv
    out = self.in_buffer.read(nbytes, self.timeout)
  File "/home/bradfernan/VENV/py3_venv/lib64/python3.7/site-packages/paramiko/buffered_pipe.py", line 164, in read
    raise PipeTimeout()
paramiko.buffered_pipe.PipeTimeout

During handling of the above exception, another exception occurred:

Traceback (most recent call last):
  File "/home/bradfernan/VENV/py3_venv/lib64/python3.7/site-packages/netmiko/base_connection.py", line 564, in _read_channel_expect
    new_data = self.remote_conn.recv(MAX_BUFFER)
  File "/home/bradfernan/VENV/py3_venv/lib64/python3.7/site-packages/paramiko/channel.py", line 701, in recv
    raise socket.timeout()
socket.timeout

During handling of the above exception, another exception occurred:

Traceback (most recent call last):
  File "/home/bradfernan/VENV/py3_venv/lib64/python3.7/site-packages/nornir/core/task.py", line 85, in start
    r = self.task(self, **self.params)
  File "/home/bradfernan/VENV/py3_venv/lib64/python3.7/site-packages/nornir/plugins/tasks/networking/netmiko_send_command.py", line 32, in netmiko_send_command
    result = net_connect.send_command(command_string, **kwargs)
  File "/home/bradfernan/VENV/py3_venv/lib64/python3.7/site-packages/netmiko/utilities.py", line 347, in wrapper_decorator
    return func(self, *args, **kwargs)
  File "/home/bradfernan/VENV/py3_venv/lib64/python3.7/site-packages/netmiko/base_connection.py", line 1415, in send_command
    new_data = self.read_until_pattern(pattern=re.escape(cmd))
  File "/home/bradfernan/VENV/py3_venv/lib64/python3.7/site-packages/netmiko/base_connection.py", line 641, in read_until_pattern
    return self._read_channel_expect(*args, **kwargs)
  File "/home/bradfernan/VENV/py3_venv/lib64/python3.7/site-packages/netmiko/base_connection.py", line 575, in _read_channel_expect
    "Timed-out reading channel, data not available."
netmiko.ssh_exception.NetmikoTimeoutException: Timed-out reading channel, data not available.

2021-01-05 11:25:46,347 - nornir.core.task -    ERROR -      start() - Host 'srx2': task 'get_uptime' failed with traceback:
Traceback (most recent call last):
  File "/home/bradfernan/VENV/py3_venv/lib64/python3.7/site-packages/nornir/core/task.py", line 85, in start
    r = self.task(self, **self.params)
  File "exercise1a.py", line 14, in get_uptime
    uptime = task.run(task=netmiko_send_command, command_string=cmd)
  File "/home/bradfernan/VENV/py3_venv/lib64/python3.7/site-packages/nornir/core/task.py", line 147, in run
    raise NornirSubTaskError(task=task, result=r)
nornir.core.exceptions.NornirSubTaskError: Subtask: <function netmiko_send_command at 0x7f001a9b7cb0> (failed)


2021-01-05 11:29:10,096 -  nornir.core -     INFO -        run() - Running task 'get_uptime' with args {} on 9 hosts
2021-01-05 11:29:36,935 - nornir.core.task -    ERROR -      start() - Host 'srx2': task 'netmiko_send_command' failed with traceback:
Traceback (most recent call last):
  File "/home/bradfernan/VENV/py3_venv/lib64/python3.7/site-packages/paramiko/channel.py", line 699, in recv
    out = self.in_buffer.read(nbytes, self.timeout)
  File "/home/bradfernan/VENV/py3_venv/lib64/python3.7/site-packages/paramiko/buffered_pipe.py", line 164, in read
    raise PipeTimeout()
paramiko.buffered_pipe.PipeTimeout

During handling of the above exception, another exception occurred:

Traceback (most recent call last):
  File "/home/bradfernan/VENV/py3_venv/lib64/python3.7/site-packages/netmiko/base_connection.py", line 564, in _read_channel_expect
    new_data = self.remote_conn.recv(MAX_BUFFER)
  File "/home/bradfernan/VENV/py3_venv/lib64/python3.7/site-packages/paramiko/channel.py", line 701, in recv
    raise socket.timeout()
socket.timeout

During handling of the above exception, another exception occurred:

Traceback (most recent call last):
  File "/home/bradfernan/VENV/py3_venv/lib64/python3.7/site-packages/nornir/core/task.py", line 85, in start
    r = self.task(self, **self.params)
  File "/home/bradfernan/VENV/py3_venv/lib64/python3.7/site-packages/nornir/plugins/tasks/networking/netmiko_send_command.py", line 32, in netmiko_send_command
    result = net_connect.send_command(command_string, **kwargs)
  File "/home/bradfernan/VENV/py3_venv/lib64/python3.7/site-packages/netmiko/utilities.py", line 347, in wrapper_decorator
    return func(self, *args, **kwargs)
  File "/home/bradfernan/VENV/py3_venv/lib64/python3.7/site-packages/netmiko/base_connection.py", line 1415, in send_command
    new_data = self.read_until_pattern(pattern=re.escape(cmd))
  File "/home/bradfernan/VENV/py3_venv/lib64/python3.7/site-packages/netmiko/base_connection.py", line 641, in read_until_pattern
    return self._read_channel_expect(*args, **kwargs)
  File "/home/bradfernan/VENV/py3_venv/lib64/python3.7/site-packages/netmiko/base_connection.py", line 575, in _read_channel_expect
    "Timed-out reading channel, data not available."
netmiko.ssh_exception.NetmikoTimeoutException: Timed-out reading channel, data not available.

2021-01-05 11:29:36,935 - nornir.core.task -    ERROR -      start() - Host 'srx2': task 'get_uptime' failed with traceback:
Traceback (most recent call last):
  File "/home/bradfernan/VENV/py3_venv/lib64/python3.7/site-packages/nornir/core/task.py", line 85, in start
    r = self.task(self, **self.params)
  File "exercise1a.py", line 14, in get_uptime
    uptime = task.run(task=netmiko_send_command, command_string=cmd)
  File "/home/bradfernan/VENV/py3_venv/lib64/python3.7/site-packages/nornir/core/task.py", line 147, in run
    raise NornirSubTaskError(task=task, result=r)
nornir.core.exceptions.NornirSubTaskError: Subtask: <function netmiko_send_command at 0x7fa619d45cb0> (failed)


2021-01-05 11:31:52,345 -  nornir.core -     INFO -        run() - Running task 'get_uptime' with args {} on 9 hosts
2021-01-05 11:32:19,430 - nornir.core.task -    ERROR -      start() - Host 'srx2': task 'netmiko_send_command' failed with traceback:
Traceback (most recent call last):
  File "/home/bradfernan/VENV/py3_venv/lib64/python3.7/site-packages/paramiko/channel.py", line 699, in recv
    out = self.in_buffer.read(nbytes, self.timeout)
  File "/home/bradfernan/VENV/py3_venv/lib64/python3.7/site-packages/paramiko/buffered_pipe.py", line 164, in read
    raise PipeTimeout()
paramiko.buffered_pipe.PipeTimeout

During handling of the above exception, another exception occurred:

Traceback (most recent call last):
  File "/home/bradfernan/VENV/py3_venv/lib64/python3.7/site-packages/netmiko/base_connection.py", line 564, in _read_channel_expect
    new_data = self.remote_conn.recv(MAX_BUFFER)
  File "/home/bradfernan/VENV/py3_venv/lib64/python3.7/site-packages/paramiko/channel.py", line 701, in recv
    raise socket.timeout()
socket.timeout

During handling of the above exception, another exception occurred:

Traceback (most recent call last):
  File "/home/bradfernan/VENV/py3_venv/lib64/python3.7/site-packages/nornir/core/task.py", line 85, in start
    r = self.task(self, **self.params)
  File "/home/bradfernan/VENV/py3_venv/lib64/python3.7/site-packages/nornir/plugins/tasks/networking/netmiko_send_command.py", line 32, in netmiko_send_command
    result = net_connect.send_command(command_string, **kwargs)
  File "/home/bradfernan/VENV/py3_venv/lib64/python3.7/site-packages/netmiko/utilities.py", line 347, in wrapper_decorator
    return func(self, *args, **kwargs)
  File "/home/bradfernan/VENV/py3_venv/lib64/python3.7/site-packages/netmiko/base_connection.py", line 1415, in send_command
    new_data = self.read_until_pattern(pattern=re.escape(cmd))
  File "/home/bradfernan/VENV/py3_venv/lib64/python3.7/site-packages/netmiko/base_connection.py", line 641, in read_until_pattern
    return self._read_channel_expect(*args, **kwargs)
  File "/home/bradfernan/VENV/py3_venv/lib64/python3.7/site-packages/netmiko/base_connection.py", line 575, in _read_channel_expect
    "Timed-out reading channel, data not available."
netmiko.ssh_exception.NetmikoTimeoutException: Timed-out reading channel, data not available.

2021-01-05 11:32:19,431 - nornir.core.task -    ERROR -      start() - Host 'srx2': task 'get_uptime' failed with traceback:
Traceback (most recent call last):
  File "/home/bradfernan/VENV/py3_venv/lib64/python3.7/site-packages/nornir/core/task.py", line 85, in start
    r = self.task(self, **self.params)
  File "exercise1a.py", line 14, in get_uptime
    uptime = task.run(task=netmiko_send_command, command_string=cmd)
  File "/home/bradfernan/VENV/py3_venv/lib64/python3.7/site-packages/nornir/core/task.py", line 147, in run
    raise NornirSubTaskError(task=task, result=r)
nornir.core.exceptions.NornirSubTaskError: Subtask: <function netmiko_send_command at 0x7f3224e55440> (failed)


2021-01-05 11:34:09,538 -  nornir.core -     INFO -        run() - Running task 'get_uptime' with args {} on 9 hosts
2021-01-05 11:34:36,435 - nornir.core.task -    ERROR -      start() - Host 'srx2': task 'netmiko_send_command' failed with traceback:
Traceback (most recent call last):
  File "/home/bradfernan/VENV/py3_venv/lib64/python3.7/site-packages/paramiko/channel.py", line 699, in recv
    out = self.in_buffer.read(nbytes, self.timeout)
  File "/home/bradfernan/VENV/py3_venv/lib64/python3.7/site-packages/paramiko/buffered_pipe.py", line 164, in read
    raise PipeTimeout()
paramiko.buffered_pipe.PipeTimeout

During handling of the above exception, another exception occurred:

Traceback (most recent call last):
  File "/home/bradfernan/VENV/py3_venv/lib64/python3.7/site-packages/netmiko/base_connection.py", line 564, in _read_channel_expect
    new_data = self.remote_conn.recv(MAX_BUFFER)
  File "/home/bradfernan/VENV/py3_venv/lib64/python3.7/site-packages/paramiko/channel.py", line 701, in recv
    raise socket.timeout()
socket.timeout

During handling of the above exception, another exception occurred:

Traceback (most recent call last):
  File "/home/bradfernan/VENV/py3_venv/lib64/python3.7/site-packages/nornir/core/task.py", line 85, in start
    r = self.task(self, **self.params)
  File "/home/bradfernan/VENV/py3_venv/lib64/python3.7/site-packages/nornir/plugins/tasks/networking/netmiko_send_command.py", line 32, in netmiko_send_command
    result = net_connect.send_command(command_string, **kwargs)
  File "/home/bradfernan/VENV/py3_venv/lib64/python3.7/site-packages/netmiko/utilities.py", line 347, in wrapper_decorator
    return func(self, *args, **kwargs)
  File "/home/bradfernan/VENV/py3_venv/lib64/python3.7/site-packages/netmiko/base_connection.py", line 1415, in send_command
    new_data = self.read_until_pattern(pattern=re.escape(cmd))
  File "/home/bradfernan/VENV/py3_venv/lib64/python3.7/site-packages/netmiko/base_connection.py", line 641, in read_until_pattern
    return self._read_channel_expect(*args, **kwargs)
  File "/home/bradfernan/VENV/py3_venv/lib64/python3.7/site-packages/netmiko/base_connection.py", line 575, in _read_channel_expect
    "Timed-out reading channel, data not available."
netmiko.ssh_exception.NetmikoTimeoutException: Timed-out reading channel, data not available.

2021-01-05 11:34:36,435 - nornir.core.task -    ERROR -      start() - Host 'srx2': task 'get_uptime' failed with traceback:
Traceback (most recent call last):
  File "/home/bradfernan/VENV/py3_venv/lib64/python3.7/site-packages/nornir/core/task.py", line 85, in start
    r = self.task(self, **self.params)
  File "exercise1a.py", line 14, in get_uptime
    uptime = task.run(task=netmiko_send_command, command_string=cmd)
  File "/home/bradfernan/VENV/py3_venv/lib64/python3.7/site-packages/nornir/core/task.py", line 147, in run
    raise NornirSubTaskError(task=task, result=r)
nornir.core.exceptions.NornirSubTaskError: Subtask: <function netmiko_send_command at 0x7f577179b440> (failed)


2021-01-05 11:37:30,455 -  nornir.core -     INFO -        run() - Running task 'get_uptime' with args {} on 1 hosts
2021-01-05 11:37:57,500 - nornir.core.task -    ERROR -      start() - Host 'srx2': task 'netmiko_send_command' failed with traceback:
Traceback (most recent call last):
  File "/home/bradfernan/VENV/py3_venv/lib64/python3.7/site-packages/paramiko/channel.py", line 699, in recv
    out = self.in_buffer.read(nbytes, self.timeout)
  File "/home/bradfernan/VENV/py3_venv/lib64/python3.7/site-packages/paramiko/buffered_pipe.py", line 164, in read
    raise PipeTimeout()
paramiko.buffered_pipe.PipeTimeout

During handling of the above exception, another exception occurred:

Traceback (most recent call last):
  File "/home/bradfernan/VENV/py3_venv/lib64/python3.7/site-packages/netmiko/base_connection.py", line 564, in _read_channel_expect
    new_data = self.remote_conn.recv(MAX_BUFFER)
  File "/home/bradfernan/VENV/py3_venv/lib64/python3.7/site-packages/paramiko/channel.py", line 701, in recv
    raise socket.timeout()
socket.timeout

During handling of the above exception, another exception occurred:

Traceback (most recent call last):
  File "/home/bradfernan/VENV/py3_venv/lib64/python3.7/site-packages/nornir/core/task.py", line 85, in start
    r = self.task(self, **self.params)
  File "/home/bradfernan/VENV/py3_venv/lib64/python3.7/site-packages/nornir/plugins/tasks/networking/netmiko_send_command.py", line 32, in netmiko_send_command
    result = net_connect.send_command(command_string, **kwargs)
  File "/home/bradfernan/VENV/py3_venv/lib64/python3.7/site-packages/netmiko/utilities.py", line 347, in wrapper_decorator
    return func(self, *args, **kwargs)
  File "/home/bradfernan/VENV/py3_venv/lib64/python3.7/site-packages/netmiko/base_connection.py", line 1415, in send_command
    new_data = self.read_until_pattern(pattern=re.escape(cmd))
  File "/home/bradfernan/VENV/py3_venv/lib64/python3.7/site-packages/netmiko/base_connection.py", line 641, in read_until_pattern
    return self._read_channel_expect(*args, **kwargs)
  File "/home/bradfernan/VENV/py3_venv/lib64/python3.7/site-packages/netmiko/base_connection.py", line 575, in _read_channel_expect
    "Timed-out reading channel, data not available."
netmiko.ssh_exception.NetmikoTimeoutException: Timed-out reading channel, data not available.

2021-01-05 11:37:57,500 - nornir.core.task -    ERROR -      start() - Host 'srx2': task 'get_uptime' failed with traceback:
Traceback (most recent call last):
  File "/home/bradfernan/VENV/py3_venv/lib64/python3.7/site-packages/nornir/core/task.py", line 85, in start
    r = self.task(self, **self.params)
  File "exercise1a.py", line 14, in get_uptime
    uptime = task.run(task=netmiko_send_command, command_string=cmd)
  File "/home/bradfernan/VENV/py3_venv/lib64/python3.7/site-packages/nornir/core/task.py", line 147, in run
    raise NornirSubTaskError(task=task, result=r)
nornir.core.exceptions.NornirSubTaskError: Subtask: <function netmiko_send_command at 0x7f1889a2dcb0> (failed)


2021-01-05 11:41:17,548 -  nornir.core -     INFO -        run() - Running task 'get_uptime' with args {} on 1 hosts
2021-01-05 11:41:44,659 - nornir.core.task -    ERROR -      start() - Host 'srx2': task 'netmiko_send_command' failed with traceback:
Traceback (most recent call last):
  File "/home/bradfernan/VENV/py3_venv/lib64/python3.7/site-packages/paramiko/channel.py", line 699, in recv
    out = self.in_buffer.read(nbytes, self.timeout)
  File "/home/bradfernan/VENV/py3_venv/lib64/python3.7/site-packages/paramiko/buffered_pipe.py", line 164, in read
    raise PipeTimeout()
paramiko.buffered_pipe.PipeTimeout

During handling of the above exception, another exception occurred:

Traceback (most recent call last):
  File "/home/bradfernan/VENV/py3_venv/lib64/python3.7/site-packages/netmiko/base_connection.py", line 564, in _read_channel_expect
    new_data = self.remote_conn.recv(MAX_BUFFER)
  File "/home/bradfernan/VENV/py3_venv/lib64/python3.7/site-packages/paramiko/channel.py", line 701, in recv
    raise socket.timeout()
socket.timeout

During handling of the above exception, another exception occurred:

Traceback (most recent call last):
  File "/home/bradfernan/VENV/py3_venv/lib64/python3.7/site-packages/nornir/core/task.py", line 85, in start
    r = self.task(self, **self.params)
  File "/home/bradfernan/VENV/py3_venv/lib64/python3.7/site-packages/nornir/plugins/tasks/networking/netmiko_send_command.py", line 32, in netmiko_send_command
    result = net_connect.send_command(command_string, **kwargs)
  File "/home/bradfernan/VENV/py3_venv/lib64/python3.7/site-packages/netmiko/utilities.py", line 347, in wrapper_decorator
    return func(self, *args, **kwargs)
  File "/home/bradfernan/VENV/py3_venv/lib64/python3.7/site-packages/netmiko/base_connection.py", line 1415, in send_command
    new_data = self.read_until_pattern(pattern=re.escape(cmd))
  File "/home/bradfernan/VENV/py3_venv/lib64/python3.7/site-packages/netmiko/base_connection.py", line 641, in read_until_pattern
    return self._read_channel_expect(*args, **kwargs)
  File "/home/bradfernan/VENV/py3_venv/lib64/python3.7/site-packages/netmiko/base_connection.py", line 575, in _read_channel_expect
    "Timed-out reading channel, data not available."
netmiko.ssh_exception.NetmikoTimeoutException: Timed-out reading channel, data not available.

2021-01-05 11:41:44,659 - nornir.core.task -    ERROR -      start() - Host 'srx2': task 'get_uptime' failed with traceback:
Traceback (most recent call last):
  File "/home/bradfernan/VENV/py3_venv/lib64/python3.7/site-packages/nornir/core/task.py", line 85, in start
    r = self.task(self, **self.params)
  File "exercise1a.py", line 14, in get_uptime
    uptime = task.run(task=netmiko_send_command, command_string=cmd)
  File "/home/bradfernan/VENV/py3_venv/lib64/python3.7/site-packages/nornir/core/task.py", line 147, in run
    raise NornirSubTaskError(task=task, result=r)
nornir.core.exceptions.NornirSubTaskError: Subtask: <function netmiko_send_command at 0x7faa76852440> (failed)


2021-01-05 11:43:29,098 -  nornir.core -     INFO -        run() - Running task 'get_uptime' with args {} on 1 hosts
2021-01-05 11:43:56,120 - nornir.core.task -    ERROR -      start() - Host 'srx2': task 'netmiko_send_command' failed with traceback:
Traceback (most recent call last):
  File "/home/bradfernan/VENV/py3_venv/lib64/python3.7/site-packages/paramiko/channel.py", line 699, in recv
    out = self.in_buffer.read(nbytes, self.timeout)
  File "/home/bradfernan/VENV/py3_venv/lib64/python3.7/site-packages/paramiko/buffered_pipe.py", line 164, in read
    raise PipeTimeout()
paramiko.buffered_pipe.PipeTimeout

During handling of the above exception, another exception occurred:

Traceback (most recent call last):
  File "/home/bradfernan/VENV/py3_venv/lib64/python3.7/site-packages/netmiko/base_connection.py", line 564, in _read_channel_expect
    new_data = self.remote_conn.recv(MAX_BUFFER)
  File "/home/bradfernan/VENV/py3_venv/lib64/python3.7/site-packages/paramiko/channel.py", line 701, in recv
    raise socket.timeout()
socket.timeout

During handling of the above exception, another exception occurred:

Traceback (most recent call last):
  File "/home/bradfernan/VENV/py3_venv/lib64/python3.7/site-packages/nornir/core/task.py", line 85, in start
    r = self.task(self, **self.params)
  File "/home/bradfernan/VENV/py3_venv/lib64/python3.7/site-packages/nornir/plugins/tasks/networking/netmiko_send_command.py", line 32, in netmiko_send_command
    result = net_connect.send_command(command_string, **kwargs)
  File "/home/bradfernan/VENV/py3_venv/lib64/python3.7/site-packages/netmiko/utilities.py", line 347, in wrapper_decorator
    return func(self, *args, **kwargs)
  File "/home/bradfernan/VENV/py3_venv/lib64/python3.7/site-packages/netmiko/base_connection.py", line 1415, in send_command
    new_data = self.read_until_pattern(pattern=re.escape(cmd))
  File "/home/bradfernan/VENV/py3_venv/lib64/python3.7/site-packages/netmiko/base_connection.py", line 641, in read_until_pattern
    return self._read_channel_expect(*args, **kwargs)
  File "/home/bradfernan/VENV/py3_venv/lib64/python3.7/site-packages/netmiko/base_connection.py", line 575, in _read_channel_expect
    "Timed-out reading channel, data not available."
netmiko.ssh_exception.NetmikoTimeoutException: Timed-out reading channel, data not available.

2021-01-05 11:43:56,121 - nornir.core.task -    ERROR -      start() - Host 'srx2': task 'get_uptime' failed with traceback:
Traceback (most recent call last):
  File "/home/bradfernan/VENV/py3_venv/lib64/python3.7/site-packages/nornir/core/task.py", line 85, in start
    r = self.task(self, **self.params)
  File "exercise1a.py", line 14, in get_uptime
    uptime = task.run(task=netmiko_send_command, command_string=cmd)
  File "/home/bradfernan/VENV/py3_venv/lib64/python3.7/site-packages/nornir/core/task.py", line 147, in run
    raise NornirSubTaskError(task=task, result=r)
nornir.core.exceptions.NornirSubTaskError: Subtask: <function netmiko_send_command at 0x7fd32bdefcb0> (failed)


2021-01-05 11:45:48,960 -  nornir.core -     INFO -        run() - Running task 'netmiko_send_command' with args {'command_string': 'show system uptime | match System'} on 1 hosts
2021-01-05 11:46:54,612 -  nornir.core -     INFO -        run() - Running task 'netmiko_send_command' with args {'command_string': 'show system uptime'} on 1 hosts
2021-01-05 11:53:03,859 -  nornir.core -     INFO -        run() - Running task 'get_uptime' with args {} on 1 hosts
2021-01-05 11:53:30,952 - nornir.core.task -    ERROR -      start() - Host 'srx2': task 'netmiko_send_command' failed with traceback:
Traceback (most recent call last):
  File "/home/bradfernan/VENV/py3_venv/lib64/python3.7/site-packages/paramiko/channel.py", line 699, in recv
    out = self.in_buffer.read(nbytes, self.timeout)
  File "/home/bradfernan/VENV/py3_venv/lib64/python3.7/site-packages/paramiko/buffered_pipe.py", line 164, in read
    raise PipeTimeout()
paramiko.buffered_pipe.PipeTimeout

During handling of the above exception, another exception occurred:

Traceback (most recent call last):
  File "/home/bradfernan/VENV/py3_venv/lib64/python3.7/site-packages/netmiko/base_connection.py", line 564, in _read_channel_expect
    new_data = self.remote_conn.recv(MAX_BUFFER)
  File "/home/bradfernan/VENV/py3_venv/lib64/python3.7/site-packages/paramiko/channel.py", line 701, in recv
    raise socket.timeout()
socket.timeout

During handling of the above exception, another exception occurred:

Traceback (most recent call last):
  File "/home/bradfernan/VENV/py3_venv/lib64/python3.7/site-packages/nornir/core/task.py", line 85, in start
    r = self.task(self, **self.params)
  File "/home/bradfernan/VENV/py3_venv/lib64/python3.7/site-packages/nornir/plugins/tasks/networking/netmiko_send_command.py", line 32, in netmiko_send_command
    result = net_connect.send_command(command_string, **kwargs)
  File "/home/bradfernan/VENV/py3_venv/lib64/python3.7/site-packages/netmiko/utilities.py", line 347, in wrapper_decorator
    return func(self, *args, **kwargs)
  File "/home/bradfernan/VENV/py3_venv/lib64/python3.7/site-packages/netmiko/base_connection.py", line 1415, in send_command
    new_data = self.read_until_pattern(pattern=re.escape(cmd))
  File "/home/bradfernan/VENV/py3_venv/lib64/python3.7/site-packages/netmiko/base_connection.py", line 641, in read_until_pattern
    return self._read_channel_expect(*args, **kwargs)
  File "/home/bradfernan/VENV/py3_venv/lib64/python3.7/site-packages/netmiko/base_connection.py", line 575, in _read_channel_expect
    "Timed-out reading channel, data not available."
netmiko.ssh_exception.NetmikoTimeoutException: Timed-out reading channel, data not available.

2021-01-05 11:53:30,953 - nornir.core.task -    ERROR -      start() - Host 'srx2': task 'get_uptime' failed with traceback:
Traceback (most recent call last):
  File "/home/bradfernan/VENV/py3_venv/lib64/python3.7/site-packages/nornir/core/task.py", line 85, in start
    r = self.task(self, **self.params)
  File "exercise1a.py", line 14, in get_uptime
    uptime = task.run(task=netmiko_send_command, command_string=cmd)
  File "/home/bradfernan/VENV/py3_venv/lib64/python3.7/site-packages/nornir/core/task.py", line 147, in run
    raise NornirSubTaskError(task=task, result=r)
nornir.core.exceptions.NornirSubTaskError: Subtask: <function netmiko_send_command at 0x7f5a16b45cb0> (failed)


2021-01-05 11:53:50,172 -  nornir.core -     INFO -        run() - Running task 'get_uptime' with args {} on 1 hosts
2021-01-05 11:54:17,294 - nornir.core.task -    ERROR -      start() - Host 'srx2': task 'netmiko_send_command' failed with traceback:
Traceback (most recent call last):
  File "/home/bradfernan/VENV/py3_venv/lib64/python3.7/site-packages/paramiko/channel.py", line 699, in recv
    out = self.in_buffer.read(nbytes, self.timeout)
  File "/home/bradfernan/VENV/py3_venv/lib64/python3.7/site-packages/paramiko/buffered_pipe.py", line 164, in read
    raise PipeTimeout()
paramiko.buffered_pipe.PipeTimeout

During handling of the above exception, another exception occurred:

Traceback (most recent call last):
  File "/home/bradfernan/VENV/py3_venv/lib64/python3.7/site-packages/netmiko/base_connection.py", line 564, in _read_channel_expect
    new_data = self.remote_conn.recv(MAX_BUFFER)
  File "/home/bradfernan/VENV/py3_venv/lib64/python3.7/site-packages/paramiko/channel.py", line 701, in recv
    raise socket.timeout()
socket.timeout

During handling of the above exception, another exception occurred:

Traceback (most recent call last):
  File "/home/bradfernan/VENV/py3_venv/lib64/python3.7/site-packages/nornir/core/task.py", line 85, in start
    r = self.task(self, **self.params)
  File "/home/bradfernan/VENV/py3_venv/lib64/python3.7/site-packages/nornir/plugins/tasks/networking/netmiko_send_command.py", line 32, in netmiko_send_command
    result = net_connect.send_command(command_string, **kwargs)
  File "/home/bradfernan/VENV/py3_venv/lib64/python3.7/site-packages/netmiko/utilities.py", line 347, in wrapper_decorator
    return func(self, *args, **kwargs)
  File "/home/bradfernan/VENV/py3_venv/lib64/python3.7/site-packages/netmiko/base_connection.py", line 1415, in send_command
    new_data = self.read_until_pattern(pattern=re.escape(cmd))
  File "/home/bradfernan/VENV/py3_venv/lib64/python3.7/site-packages/netmiko/base_connection.py", line 641, in read_until_pattern
    return self._read_channel_expect(*args, **kwargs)
  File "/home/bradfernan/VENV/py3_venv/lib64/python3.7/site-packages/netmiko/base_connection.py", line 575, in _read_channel_expect
    "Timed-out reading channel, data not available."
netmiko.ssh_exception.NetmikoTimeoutException: Timed-out reading channel, data not available.

2021-01-05 11:54:17,294 - nornir.core.task -    ERROR -      start() - Host 'srx2': task 'get_uptime' failed with traceback:
Traceback (most recent call last):
  File "/home/bradfernan/VENV/py3_venv/lib64/python3.7/site-packages/nornir/core/task.py", line 85, in start
    r = self.task(self, **self.params)
  File "exercise1a.py", line 14, in get_uptime
    uptime = task.run(task=netmiko_send_command, command_string=cmd)
  File "/home/bradfernan/VENV/py3_venv/lib64/python3.7/site-packages/nornir/core/task.py", line 147, in run
    raise NornirSubTaskError(task=task, result=r)
nornir.core.exceptions.NornirSubTaskError: Subtask: <function netmiko_send_command at 0x7fe749da4cb0> (failed)


2021-01-05 11:54:50,161 -  nornir.core -     INFO -        run() - Running task 'netmiko_send_command' with args {'command_string': 'show system uptime'} on 1 hosts
2021-01-05 11:55:18,013 -  nornir.core -     INFO -        run() - Running task 'netmiko_send_command' with args {'command_string': 'show configuration'} on 1 hosts
2021-01-05 11:56:37,477 -  nornir.core -     INFO -        run() - Running task 'netmiko_send_command' with args {'command_string': 'show system uptime'} on 1 hosts
2021-01-05 11:57:11,787 -  nornir.core -     INFO -        run() - Running task 'netmiko_send_command' with args {'command_string': 'show system uptime'} on 1 hosts
2021-01-05 11:57:36,947 -  nornir.core -     INFO -        run() - Running task 'get_uptime' with args {} on 1 hosts
2021-01-05 11:58:03,981 - nornir.core.task -    ERROR -      start() - Host 'srx2': task 'netmiko_send_command' failed with traceback:
Traceback (most recent call last):
  File "/home/bradfernan/VENV/py3_venv/lib64/python3.7/site-packages/paramiko/channel.py", line 699, in recv
    out = self.in_buffer.read(nbytes, self.timeout)
  File "/home/bradfernan/VENV/py3_venv/lib64/python3.7/site-packages/paramiko/buffered_pipe.py", line 164, in read
    raise PipeTimeout()
paramiko.buffered_pipe.PipeTimeout

During handling of the above exception, another exception occurred:

Traceback (most recent call last):
  File "/home/bradfernan/VENV/py3_venv/lib64/python3.7/site-packages/netmiko/base_connection.py", line 564, in _read_channel_expect
    new_data = self.remote_conn.recv(MAX_BUFFER)
  File "/home/bradfernan/VENV/py3_venv/lib64/python3.7/site-packages/paramiko/channel.py", line 701, in recv
    raise socket.timeout()
socket.timeout

During handling of the above exception, another exception occurred:

Traceback (most recent call last):
  File "/home/bradfernan/VENV/py3_venv/lib64/python3.7/site-packages/nornir/core/task.py", line 85, in start
    r = self.task(self, **self.params)
  File "/home/bradfernan/VENV/py3_venv/lib64/python3.7/site-packages/nornir/plugins/tasks/networking/netmiko_send_command.py", line 32, in netmiko_send_command
    result = net_connect.send_command(command_string, **kwargs)
  File "/home/bradfernan/VENV/py3_venv/lib64/python3.7/site-packages/netmiko/utilities.py", line 347, in wrapper_decorator
    return func(self, *args, **kwargs)
  File "/home/bradfernan/VENV/py3_venv/lib64/python3.7/site-packages/netmiko/base_connection.py", line 1415, in send_command
    new_data = self.read_until_pattern(pattern=re.escape(cmd))
  File "/home/bradfernan/VENV/py3_venv/lib64/python3.7/site-packages/netmiko/base_connection.py", line 641, in read_until_pattern
    return self._read_channel_expect(*args, **kwargs)
  File "/home/bradfernan/VENV/py3_venv/lib64/python3.7/site-packages/netmiko/base_connection.py", line 575, in _read_channel_expect
    "Timed-out reading channel, data not available."
netmiko.ssh_exception.NetmikoTimeoutException: Timed-out reading channel, data not available.

2021-01-05 11:58:03,981 - nornir.core.task -    ERROR -      start() - Host 'srx2': task 'get_uptime' failed with traceback:
Traceback (most recent call last):
  File "/home/bradfernan/VENV/py3_venv/lib64/python3.7/site-packages/nornir/core/task.py", line 85, in start
    r = self.task(self, **self.params)
  File "exercise1a.py", line 14, in get_uptime
    uptime = task.run(task=netmiko_send_command, command_string=cmd)
  File "/home/bradfernan/VENV/py3_venv/lib64/python3.7/site-packages/nornir/core/task.py", line 147, in run
    raise NornirSubTaskError(task=task, result=r)
nornir.core.exceptions.NornirSubTaskError: Subtask: <function netmiko_send_command at 0x7f51b026b440> (failed)


2021-01-05 17:17:49,143 -  nornir.core -     INFO -        run() - Running task 'get_uptime' with args {} on 1 hosts
2021-01-05 17:20:07,273 -  nornir.core -     INFO -        run() - Running task 'get_uptime' with args {} on 1 hosts
2021-01-05 17:20:34,298 - nornir.core.task -    ERROR -      start() - Host 'srx2': task 'netmiko_send_command' failed with traceback:
Traceback (most recent call last):
  File "/home/bradfernan/VENV/py3_venv/lib64/python3.7/site-packages/paramiko/channel.py", line 699, in recv
    out = self.in_buffer.read(nbytes, self.timeout)
  File "/home/bradfernan/VENV/py3_venv/lib64/python3.7/site-packages/paramiko/buffered_pipe.py", line 164, in read
    raise PipeTimeout()
paramiko.buffered_pipe.PipeTimeout

During handling of the above exception, another exception occurred:

Traceback (most recent call last):
  File "/home/bradfernan/VENV/py3_venv/lib64/python3.7/site-packages/netmiko/base_connection.py", line 564, in _read_channel_expect
    new_data = self.remote_conn.recv(MAX_BUFFER)
  File "/home/bradfernan/VENV/py3_venv/lib64/python3.7/site-packages/paramiko/channel.py", line 701, in recv
    raise socket.timeout()
socket.timeout

During handling of the above exception, another exception occurred:

Traceback (most recent call last):
  File "/home/bradfernan/VENV/py3_venv/lib64/python3.7/site-packages/nornir/core/task.py", line 85, in start
    r = self.task(self, **self.params)
  File "/home/bradfernan/VENV/py3_venv/lib64/python3.7/site-packages/nornir/plugins/tasks/networking/netmiko_send_command.py", line 32, in netmiko_send_command
    result = net_connect.send_command(command_string, **kwargs)
  File "/home/bradfernan/VENV/py3_venv/lib64/python3.7/site-packages/netmiko/utilities.py", line 347, in wrapper_decorator
    return func(self, *args, **kwargs)
  File "/home/bradfernan/VENV/py3_venv/lib64/python3.7/site-packages/netmiko/base_connection.py", line 1415, in send_command
    new_data = self.read_until_pattern(pattern=re.escape(cmd))
  File "/home/bradfernan/VENV/py3_venv/lib64/python3.7/site-packages/netmiko/base_connection.py", line 641, in read_until_pattern
    return self._read_channel_expect(*args, **kwargs)
  File "/home/bradfernan/VENV/py3_venv/lib64/python3.7/site-packages/netmiko/base_connection.py", line 575, in _read_channel_expect
    "Timed-out reading channel, data not available."
netmiko.ssh_exception.NetmikoTimeoutException: Timed-out reading channel, data not available.

2021-01-05 17:20:34,298 - nornir.core.task -    ERROR -      start() - Host 'srx2': task 'get_uptime' failed with traceback:
Traceback (most recent call last):
  File "/home/bradfernan/VENV/py3_venv/lib64/python3.7/site-packages/nornir/core/task.py", line 85, in start
    r = self.task(self, **self.params)
  File "exercise1a.py", line 14, in get_uptime
    uptime = task.run(task=netmiko_send_command, command_string=cmd)
  File "/home/bradfernan/VENV/py3_venv/lib64/python3.7/site-packages/nornir/core/task.py", line 147, in run
    raise NornirSubTaskError(task=task, result=r)
nornir.core.exceptions.NornirSubTaskError: Subtask: <function netmiko_send_command at 0x7fe740ad8440> (failed)


2021-01-05 17:23:30,699 -  nornir.core -     INFO -        run() - Running task 'get_uptime' with args {} on 1 hosts
2021-01-05 17:24:23,196 -  nornir.core -     INFO -        run() - Running task 'get_uptime' with args {} on 1 hosts
2021-01-05 17:24:50,241 - nornir.core.task -    ERROR -      start() - Host 'srx2': task 'netmiko_send_command' failed with traceback:
Traceback (most recent call last):
  File "/home/bradfernan/VENV/py3_venv/lib64/python3.7/site-packages/paramiko/channel.py", line 699, in recv
    out = self.in_buffer.read(nbytes, self.timeout)
  File "/home/bradfernan/VENV/py3_venv/lib64/python3.7/site-packages/paramiko/buffered_pipe.py", line 164, in read
    raise PipeTimeout()
paramiko.buffered_pipe.PipeTimeout

During handling of the above exception, another exception occurred:

Traceback (most recent call last):
  File "/home/bradfernan/VENV/py3_venv/lib64/python3.7/site-packages/netmiko/base_connection.py", line 564, in _read_channel_expect
    new_data = self.remote_conn.recv(MAX_BUFFER)
  File "/home/bradfernan/VENV/py3_venv/lib64/python3.7/site-packages/paramiko/channel.py", line 701, in recv
    raise socket.timeout()
socket.timeout

During handling of the above exception, another exception occurred:

Traceback (most recent call last):
  File "/home/bradfernan/VENV/py3_venv/lib64/python3.7/site-packages/nornir/core/task.py", line 85, in start
    r = self.task(self, **self.params)
  File "/home/bradfernan/VENV/py3_venv/lib64/python3.7/site-packages/nornir/plugins/tasks/networking/netmiko_send_command.py", line 32, in netmiko_send_command
    result = net_connect.send_command(command_string, **kwargs)
  File "/home/bradfernan/VENV/py3_venv/lib64/python3.7/site-packages/netmiko/utilities.py", line 347, in wrapper_decorator
    return func(self, *args, **kwargs)
  File "/home/bradfernan/VENV/py3_venv/lib64/python3.7/site-packages/netmiko/base_connection.py", line 1415, in send_command
    new_data = self.read_until_pattern(pattern=re.escape(cmd))
  File "/home/bradfernan/VENV/py3_venv/lib64/python3.7/site-packages/netmiko/base_connection.py", line 641, in read_until_pattern
    return self._read_channel_expect(*args, **kwargs)
  File "/home/bradfernan/VENV/py3_venv/lib64/python3.7/site-packages/netmiko/base_connection.py", line 575, in _read_channel_expect
    "Timed-out reading channel, data not available."
netmiko.ssh_exception.NetmikoTimeoutException: Timed-out reading channel, data not available.

2021-01-05 17:24:50,241 - nornir.core.task -    ERROR -      start() - Host 'srx2': task 'get_uptime' failed with traceback:
Traceback (most recent call last):
  File "/home/bradfernan/VENV/py3_venv/lib64/python3.7/site-packages/nornir/core/task.py", line 85, in start
    r = self.task(self, **self.params)
  File "exercise1a.py", line 14, in get_uptime
    uptime = task.run(task=netmiko_send_command, command_string=cmd)
  File "/home/bradfernan/VENV/py3_venv/lib64/python3.7/site-packages/nornir/core/task.py", line 147, in run
    raise NornirSubTaskError(task=task, result=r)
nornir.core.exceptions.NornirSubTaskError: Subtask: <function netmiko_send_command at 0x7fbd7c65b440> (failed)


2021-01-05 17:26:14,555 -  nornir.core -     INFO -        run() - Running task 'get_uptime' with args {} on 9 hosts
2021-01-05 17:26:41,587 - nornir.core.task -    ERROR -      start() - Host 'srx2': task 'netmiko_send_command' failed with traceback:
Traceback (most recent call last):
  File "/home/bradfernan/VENV/py3_venv/lib64/python3.7/site-packages/paramiko/channel.py", line 699, in recv
    out = self.in_buffer.read(nbytes, self.timeout)
  File "/home/bradfernan/VENV/py3_venv/lib64/python3.7/site-packages/paramiko/buffered_pipe.py", line 164, in read
    raise PipeTimeout()
paramiko.buffered_pipe.PipeTimeout

During handling of the above exception, another exception occurred:

Traceback (most recent call last):
  File "/home/bradfernan/VENV/py3_venv/lib64/python3.7/site-packages/netmiko/base_connection.py", line 564, in _read_channel_expect
    new_data = self.remote_conn.recv(MAX_BUFFER)
  File "/home/bradfernan/VENV/py3_venv/lib64/python3.7/site-packages/paramiko/channel.py", line 701, in recv
    raise socket.timeout()
socket.timeout

During handling of the above exception, another exception occurred:

Traceback (most recent call last):
  File "/home/bradfernan/VENV/py3_venv/lib64/python3.7/site-packages/nornir/core/task.py", line 85, in start
    r = self.task(self, **self.params)
  File "/home/bradfernan/VENV/py3_venv/lib64/python3.7/site-packages/nornir/plugins/tasks/networking/netmiko_send_command.py", line 32, in netmiko_send_command
    result = net_connect.send_command(command_string, **kwargs)
  File "/home/bradfernan/VENV/py3_venv/lib64/python3.7/site-packages/netmiko/utilities.py", line 347, in wrapper_decorator
    return func(self, *args, **kwargs)
  File "/home/bradfernan/VENV/py3_venv/lib64/python3.7/site-packages/netmiko/base_connection.py", line 1415, in send_command
    new_data = self.read_until_pattern(pattern=re.escape(cmd))
  File "/home/bradfernan/VENV/py3_venv/lib64/python3.7/site-packages/netmiko/base_connection.py", line 641, in read_until_pattern
    return self._read_channel_expect(*args, **kwargs)
  File "/home/bradfernan/VENV/py3_venv/lib64/python3.7/site-packages/netmiko/base_connection.py", line 575, in _read_channel_expect
    "Timed-out reading channel, data not available."
netmiko.ssh_exception.NetmikoTimeoutException: Timed-out reading channel, data not available.

2021-01-05 17:26:41,587 - nornir.core.task -    ERROR -      start() - Host 'srx2': task 'get_uptime' failed with traceback:
Traceback (most recent call last):
  File "/home/bradfernan/VENV/py3_venv/lib64/python3.7/site-packages/nornir/core/task.py", line 85, in start
    r = self.task(self, **self.params)
  File "exercise1a.py", line 14, in get_uptime
    uptime = task.run(task=netmiko_send_command, command_string=cmd)
  File "/home/bradfernan/VENV/py3_venv/lib64/python3.7/site-packages/nornir/core/task.py", line 147, in run
    raise NornirSubTaskError(task=task, result=r)
nornir.core.exceptions.NornirSubTaskError: Subtask: <function netmiko_send_command at 0x7fd168a9dcb0> (failed)


2021-01-05 17:27:06,235 -  nornir.core -     INFO -        run() - Running task 'get_uptime' with args {} on 1 hosts
2021-01-05 17:27:33,062 - nornir.core.task -    ERROR -      start() - Host 'srx2': task 'netmiko_send_command' failed with traceback:
Traceback (most recent call last):
  File "/home/bradfernan/VENV/py3_venv/lib64/python3.7/site-packages/paramiko/channel.py", line 699, in recv
    out = self.in_buffer.read(nbytes, self.timeout)
  File "/home/bradfernan/VENV/py3_venv/lib64/python3.7/site-packages/paramiko/buffered_pipe.py", line 164, in read
    raise PipeTimeout()
paramiko.buffered_pipe.PipeTimeout

During handling of the above exception, another exception occurred:

Traceback (most recent call last):
  File "/home/bradfernan/VENV/py3_venv/lib64/python3.7/site-packages/netmiko/base_connection.py", line 564, in _read_channel_expect
    new_data = self.remote_conn.recv(MAX_BUFFER)
  File "/home/bradfernan/VENV/py3_venv/lib64/python3.7/site-packages/paramiko/channel.py", line 701, in recv
    raise socket.timeout()
socket.timeout

During handling of the above exception, another exception occurred:

Traceback (most recent call last):
  File "/home/bradfernan/VENV/py3_venv/lib64/python3.7/site-packages/nornir/core/task.py", line 85, in start
    r = self.task(self, **self.params)
  File "/home/bradfernan/VENV/py3_venv/lib64/python3.7/site-packages/nornir/plugins/tasks/networking/netmiko_send_command.py", line 32, in netmiko_send_command
    result = net_connect.send_command(command_string, **kwargs)
  File "/home/bradfernan/VENV/py3_venv/lib64/python3.7/site-packages/netmiko/utilities.py", line 347, in wrapper_decorator
    return func(self, *args, **kwargs)
  File "/home/bradfernan/VENV/py3_venv/lib64/python3.7/site-packages/netmiko/base_connection.py", line 1415, in send_command
    new_data = self.read_until_pattern(pattern=re.escape(cmd))
  File "/home/bradfernan/VENV/py3_venv/lib64/python3.7/site-packages/netmiko/base_connection.py", line 641, in read_until_pattern
    return self._read_channel_expect(*args, **kwargs)
  File "/home/bradfernan/VENV/py3_venv/lib64/python3.7/site-packages/netmiko/base_connection.py", line 575, in _read_channel_expect
    "Timed-out reading channel, data not available."
netmiko.ssh_exception.NetmikoTimeoutException: Timed-out reading channel, data not available.

2021-01-05 17:27:33,063 - nornir.core.task -    ERROR -      start() - Host 'srx2': task 'get_uptime' failed with traceback:
Traceback (most recent call last):
  File "/home/bradfernan/VENV/py3_venv/lib64/python3.7/site-packages/nornir/core/task.py", line 85, in start
    r = self.task(self, **self.params)
  File "exercise1a.py", line 14, in get_uptime
    uptime = task.run(task=netmiko_send_command, command_string=cmd)
  File "/home/bradfernan/VENV/py3_venv/lib64/python3.7/site-packages/nornir/core/task.py", line 147, in run
    raise NornirSubTaskError(task=task, result=r)
nornir.core.exceptions.NornirSubTaskError: Subtask: <function netmiko_send_command at 0x7f7868d18440> (failed)


2021-01-05 17:27:59,524 -  nornir.core -     INFO -        run() - Running task 'get_uptime' with args {} on 1 hosts
2021-01-05 17:29:22,706 -  nornir.core -     INFO -        run() - Running task 'get_uptime' with args {} on 1 hosts
2021-01-05 17:29:49,771 - nornir.core.task -    ERROR -      start() - Host 'srx2': task 'netmiko_send_command' failed with traceback:
Traceback (most recent call last):
  File "/home/bradfernan/VENV/py3_venv/lib64/python3.7/site-packages/paramiko/channel.py", line 699, in recv
    out = self.in_buffer.read(nbytes, self.timeout)
  File "/home/bradfernan/VENV/py3_venv/lib64/python3.7/site-packages/paramiko/buffered_pipe.py", line 164, in read
    raise PipeTimeout()
paramiko.buffered_pipe.PipeTimeout

During handling of the above exception, another exception occurred:

Traceback (most recent call last):
  File "/home/bradfernan/VENV/py3_venv/lib64/python3.7/site-packages/netmiko/base_connection.py", line 564, in _read_channel_expect
    new_data = self.remote_conn.recv(MAX_BUFFER)
  File "/home/bradfernan/VENV/py3_venv/lib64/python3.7/site-packages/paramiko/channel.py", line 701, in recv
    raise socket.timeout()
socket.timeout

During handling of the above exception, another exception occurred:

Traceback (most recent call last):
  File "/home/bradfernan/VENV/py3_venv/lib64/python3.7/site-packages/nornir/core/task.py", line 85, in start
    r = self.task(self, **self.params)
  File "/home/bradfernan/VENV/py3_venv/lib64/python3.7/site-packages/nornir/plugins/tasks/networking/netmiko_send_command.py", line 32, in netmiko_send_command
    result = net_connect.send_command(command_string, **kwargs)
  File "/home/bradfernan/VENV/py3_venv/lib64/python3.7/site-packages/netmiko/utilities.py", line 347, in wrapper_decorator
    return func(self, *args, **kwargs)
  File "/home/bradfernan/VENV/py3_venv/lib64/python3.7/site-packages/netmiko/base_connection.py", line 1415, in send_command
    new_data = self.read_until_pattern(pattern=re.escape(cmd))
  File "/home/bradfernan/VENV/py3_venv/lib64/python3.7/site-packages/netmiko/base_connection.py", line 641, in read_until_pattern
    return self._read_channel_expect(*args, **kwargs)
  File "/home/bradfernan/VENV/py3_venv/lib64/python3.7/site-packages/netmiko/base_connection.py", line 575, in _read_channel_expect
    "Timed-out reading channel, data not available."
netmiko.ssh_exception.NetmikoTimeoutException: Timed-out reading channel, data not available.

2021-01-05 17:29:49,772 - nornir.core.task -    ERROR -      start() - Host 'srx2': task 'get_uptime' failed with traceback:
Traceback (most recent call last):
  File "/home/bradfernan/VENV/py3_venv/lib64/python3.7/site-packages/nornir/core/task.py", line 85, in start
    r = self.task(self, **self.params)
  File "exercise1a.py", line 14, in get_uptime
    uptime = task.run(task=netmiko_send_command, command_string=cmd)
  File "/home/bradfernan/VENV/py3_venv/lib64/python3.7/site-packages/nornir/core/task.py", line 147, in run
    raise NornirSubTaskError(task=task, result=r)
nornir.core.exceptions.NornirSubTaskError: Subtask: <function netmiko_send_command at 0x7fe507a553b0> (failed)


2021-01-05 17:31:37,553 -  nornir.core -     INFO -        run() - Running task 'get_uptime' with args {} on 1 hosts
2021-01-05 17:32:04,594 - nornir.core.task -    ERROR -      start() - Host 'srx2': task 'netmiko_send_command' failed with traceback:
Traceback (most recent call last):
  File "/home/bradfernan/VENV/py3_venv/lib64/python3.7/site-packages/paramiko/channel.py", line 699, in recv
    out = self.in_buffer.read(nbytes, self.timeout)
  File "/home/bradfernan/VENV/py3_venv/lib64/python3.7/site-packages/paramiko/buffered_pipe.py", line 164, in read
    raise PipeTimeout()
paramiko.buffered_pipe.PipeTimeout

During handling of the above exception, another exception occurred:

Traceback (most recent call last):
  File "/home/bradfernan/VENV/py3_venv/lib64/python3.7/site-packages/netmiko/base_connection.py", line 564, in _read_channel_expect
    new_data = self.remote_conn.recv(MAX_BUFFER)
  File "/home/bradfernan/VENV/py3_venv/lib64/python3.7/site-packages/paramiko/channel.py", line 701, in recv
    raise socket.timeout()
socket.timeout

During handling of the above exception, another exception occurred:

Traceback (most recent call last):
  File "/home/bradfernan/VENV/py3_venv/lib64/python3.7/site-packages/nornir/core/task.py", line 85, in start
    r = self.task(self, **self.params)
  File "/home/bradfernan/VENV/py3_venv/lib64/python3.7/site-packages/nornir/plugins/tasks/networking/netmiko_send_command.py", line 32, in netmiko_send_command
    result = net_connect.send_command(command_string, **kwargs)
  File "/home/bradfernan/VENV/py3_venv/lib64/python3.7/site-packages/netmiko/utilities.py", line 347, in wrapper_decorator
    return func(self, *args, **kwargs)
  File "/home/bradfernan/VENV/py3_venv/lib64/python3.7/site-packages/netmiko/base_connection.py", line 1415, in send_command
    new_data = self.read_until_pattern(pattern=re.escape(cmd))
  File "/home/bradfernan/VENV/py3_venv/lib64/python3.7/site-packages/netmiko/base_connection.py", line 641, in read_until_pattern
    return self._read_channel_expect(*args, **kwargs)
  File "/home/bradfernan/VENV/py3_venv/lib64/python3.7/site-packages/netmiko/base_connection.py", line 575, in _read_channel_expect
    "Timed-out reading channel, data not available."
netmiko.ssh_exception.NetmikoTimeoutException: Timed-out reading channel, data not available.

2021-01-05 17:32:04,595 - nornir.core.task -    ERROR -      start() - Host 'srx2': task 'get_uptime' failed with traceback:
Traceback (most recent call last):
  File "/home/bradfernan/VENV/py3_venv/lib64/python3.7/site-packages/nornir/core/task.py", line 85, in start
    r = self.task(self, **self.params)
  File "/home/bradfernan/bradfernan/week4/exercise1/exercise1a.py", line 14, in get_uptime
    uptime = task.run(task=netmiko_send_command, command_string=cmd)
  File "/home/bradfernan/VENV/py3_venv/lib64/python3.7/site-packages/nornir/core/task.py", line 147, in run
    raise NornirSubTaskError(task=task, result=r)
nornir.core.exceptions.NornirSubTaskError: Subtask: <function netmiko_send_command at 0x7fd911332d40> (failed)


2021-01-05 17:34:05,461 -  nornir.core -     INFO -        run() - Running task 'get_uptime' with args {} on 1 hosts
2021-01-05 17:34:32,513 - nornir.core.task -    ERROR -      start() - Host 'srx2': task 'netmiko_send_command' failed with traceback:
Traceback (most recent call last):
  File "/home/bradfernan/VENV/py3_venv/lib64/python3.7/site-packages/paramiko/channel.py", line 699, in recv
    out = self.in_buffer.read(nbytes, self.timeout)
  File "/home/bradfernan/VENV/py3_venv/lib64/python3.7/site-packages/paramiko/buffered_pipe.py", line 164, in read
    raise PipeTimeout()
paramiko.buffered_pipe.PipeTimeout

During handling of the above exception, another exception occurred:

Traceback (most recent call last):
  File "/home/bradfernan/VENV/py3_venv/lib64/python3.7/site-packages/netmiko/base_connection.py", line 564, in _read_channel_expect
    new_data = self.remote_conn.recv(MAX_BUFFER)
  File "/home/bradfernan/VENV/py3_venv/lib64/python3.7/site-packages/paramiko/channel.py", line 701, in recv
    raise socket.timeout()
socket.timeout

During handling of the above exception, another exception occurred:

Traceback (most recent call last):
  File "/home/bradfernan/VENV/py3_venv/lib64/python3.7/site-packages/nornir/core/task.py", line 85, in start
    r = self.task(self, **self.params)
  File "/home/bradfernan/VENV/py3_venv/lib64/python3.7/site-packages/nornir/plugins/tasks/networking/netmiko_send_command.py", line 32, in netmiko_send_command
    result = net_connect.send_command(command_string, **kwargs)
  File "/home/bradfernan/VENV/py3_venv/lib64/python3.7/site-packages/netmiko/utilities.py", line 347, in wrapper_decorator
    return func(self, *args, **kwargs)
  File "/home/bradfernan/VENV/py3_venv/lib64/python3.7/site-packages/netmiko/base_connection.py", line 1415, in send_command
    new_data = self.read_until_pattern(pattern=re.escape(cmd))
  File "/home/bradfernan/VENV/py3_venv/lib64/python3.7/site-packages/netmiko/base_connection.py", line 641, in read_until_pattern
    return self._read_channel_expect(*args, **kwargs)
  File "/home/bradfernan/VENV/py3_venv/lib64/python3.7/site-packages/netmiko/base_connection.py", line 575, in _read_channel_expect
    "Timed-out reading channel, data not available."
netmiko.ssh_exception.NetmikoTimeoutException: Timed-out reading channel, data not available.

2021-01-05 17:34:32,513 - nornir.core.task -    ERROR -      start() - Host 'srx2': task 'get_uptime' failed with traceback:
Traceback (most recent call last):
  File "/home/bradfernan/VENV/py3_venv/lib64/python3.7/site-packages/nornir/core/task.py", line 85, in start
    r = self.task(self, **self.params)
  File "exercise1a.py", line 14, in get_uptime
    uptime = task.run(task=netmiko_send_command, command_string=cmd)
  File "/home/bradfernan/VENV/py3_venv/lib64/python3.7/site-packages/nornir/core/task.py", line 147, in run
    raise NornirSubTaskError(task=task, result=r)
nornir.core.exceptions.NornirSubTaskError: Subtask: <function netmiko_send_command at 0x7f7abbccacb0> (failed)


2021-01-05 17:36:25,722 -  nornir.core -     INFO -        run() - Running task 'get_uptime' with args {} on 1 hosts
2021-01-05 17:36:52,476 - nornir.core.task -    ERROR -      start() - Host 'srx2': task 'netmiko_send_command' failed with traceback:
Traceback (most recent call last):
  File "/home/bradfernan/VENV/py3_venv/lib64/python3.7/site-packages/paramiko/channel.py", line 699, in recv
    out = self.in_buffer.read(nbytes, self.timeout)
  File "/home/bradfernan/VENV/py3_venv/lib64/python3.7/site-packages/paramiko/buffered_pipe.py", line 164, in read
    raise PipeTimeout()
paramiko.buffered_pipe.PipeTimeout

During handling of the above exception, another exception occurred:

Traceback (most recent call last):
  File "/home/bradfernan/VENV/py3_venv/lib64/python3.7/site-packages/netmiko/base_connection.py", line 564, in _read_channel_expect
    new_data = self.remote_conn.recv(MAX_BUFFER)
  File "/home/bradfernan/VENV/py3_venv/lib64/python3.7/site-packages/paramiko/channel.py", line 701, in recv
    raise socket.timeout()
socket.timeout

During handling of the above exception, another exception occurred:

Traceback (most recent call last):
  File "/home/bradfernan/VENV/py3_venv/lib64/python3.7/site-packages/nornir/core/task.py", line 85, in start
    r = self.task(self, **self.params)
  File "/home/bradfernan/VENV/py3_venv/lib64/python3.7/site-packages/nornir/plugins/tasks/networking/netmiko_send_command.py", line 32, in netmiko_send_command
    result = net_connect.send_command(command_string, **kwargs)
  File "/home/bradfernan/VENV/py3_venv/lib64/python3.7/site-packages/netmiko/utilities.py", line 347, in wrapper_decorator
    return func(self, *args, **kwargs)
  File "/home/bradfernan/VENV/py3_venv/lib64/python3.7/site-packages/netmiko/base_connection.py", line 1415, in send_command
    new_data = self.read_until_pattern(pattern=re.escape(cmd))
  File "/home/bradfernan/VENV/py3_venv/lib64/python3.7/site-packages/netmiko/base_connection.py", line 641, in read_until_pattern
    return self._read_channel_expect(*args, **kwargs)
  File "/home/bradfernan/VENV/py3_venv/lib64/python3.7/site-packages/netmiko/base_connection.py", line 575, in _read_channel_expect
    "Timed-out reading channel, data not available."
netmiko.ssh_exception.NetmikoTimeoutException: Timed-out reading channel, data not available.

2021-01-05 17:36:52,477 - nornir.core.task -    ERROR -      start() - Host 'srx2': task 'get_uptime' failed with traceback:
Traceback (most recent call last):
  File "/home/bradfernan/VENV/py3_venv/lib64/python3.7/site-packages/nornir/core/task.py", line 85, in start
    r = self.task(self, **self.params)
  File "exercise1a.py", line 14, in get_uptime
    uptime = task.run(task=netmiko_send_command, command_string=cmd)
  File "/home/bradfernan/VENV/py3_venv/lib64/python3.7/site-packages/nornir/core/task.py", line 147, in run
    raise NornirSubTaskError(task=task, result=r)
nornir.core.exceptions.NornirSubTaskError: Subtask: <function netmiko_send_command at 0x7f4d019aecb0> (failed)


2021-01-05 17:38:26,298 -  nornir.core -     INFO -        run() - Running task 'get_uptime' with args {} on 1 hosts
2021-01-05 17:39:11,651 -  nornir.core -     INFO -        run() - Running task 'get_uptime' with args {} on 1 hosts
2021-01-05 17:41:16,242 -  nornir.core -     INFO -        run() - Running task 'get_uptime' with args {} on 1 hosts
2021-01-05 17:41:43,279 - nornir.core.task -    ERROR -      start() - Host 'srx2': task 'netmiko_send_command' failed with traceback:
Traceback (most recent call last):
  File "/home/bradfernan/VENV/py3_venv/lib64/python3.7/site-packages/paramiko/channel.py", line 699, in recv
    out = self.in_buffer.read(nbytes, self.timeout)
  File "/home/bradfernan/VENV/py3_venv/lib64/python3.7/site-packages/paramiko/buffered_pipe.py", line 164, in read
    raise PipeTimeout()
paramiko.buffered_pipe.PipeTimeout

During handling of the above exception, another exception occurred:

Traceback (most recent call last):
  File "/home/bradfernan/VENV/py3_venv/lib64/python3.7/site-packages/netmiko/base_connection.py", line 564, in _read_channel_expect
    new_data = self.remote_conn.recv(MAX_BUFFER)
  File "/home/bradfernan/VENV/py3_venv/lib64/python3.7/site-packages/paramiko/channel.py", line 701, in recv
    raise socket.timeout()
socket.timeout

During handling of the above exception, another exception occurred:

Traceback (most recent call last):
  File "/home/bradfernan/VENV/py3_venv/lib64/python3.7/site-packages/nornir/core/task.py", line 85, in start
    r = self.task(self, **self.params)
  File "/home/bradfernan/VENV/py3_venv/lib64/python3.7/site-packages/nornir/plugins/tasks/networking/netmiko_send_command.py", line 32, in netmiko_send_command
    result = net_connect.send_command(command_string, **kwargs)
  File "/home/bradfernan/VENV/py3_venv/lib64/python3.7/site-packages/netmiko/utilities.py", line 347, in wrapper_decorator
    return func(self, *args, **kwargs)
  File "/home/bradfernan/VENV/py3_venv/lib64/python3.7/site-packages/netmiko/base_connection.py", line 1415, in send_command
    new_data = self.read_until_pattern(pattern=re.escape(cmd))
  File "/home/bradfernan/VENV/py3_venv/lib64/python3.7/site-packages/netmiko/base_connection.py", line 641, in read_until_pattern
    return self._read_channel_expect(*args, **kwargs)
  File "/home/bradfernan/VENV/py3_venv/lib64/python3.7/site-packages/netmiko/base_connection.py", line 575, in _read_channel_expect
    "Timed-out reading channel, data not available."
netmiko.ssh_exception.NetmikoTimeoutException: Timed-out reading channel, data not available.

2021-01-05 17:41:43,279 - nornir.core.task -    ERROR -      start() - Host 'srx2': task 'get_uptime' failed with traceback:
Traceback (most recent call last):
  File "/home/bradfernan/VENV/py3_venv/lib64/python3.7/site-packages/nornir/core/task.py", line 85, in start
    r = self.task(self, **self.params)
  File "exercise1a.py", line 14, in get_uptime
    uptime = task.run(task=netmiko_send_command, command_string=cmd)
  File "/home/bradfernan/VENV/py3_venv/lib64/python3.7/site-packages/nornir/core/task.py", line 147, in run
    raise NornirSubTaskError(task=task, result=r)
nornir.core.exceptions.NornirSubTaskError: Subtask: <function netmiko_send_command at 0x7f041f15e440> (failed)


2021-01-05 17:48:52,252 -  nornir.core -     INFO -        run() - Running task 'get_uptime' with args {} on 1 hosts
2021-01-05 17:53:28,070 -  nornir.core -     INFO -        run() - Running task 'get_uptime' with args {} on 1 hosts
2021-01-05 17:53:36,800 - nornir.core.task -    ERROR -      start() - Host 'srx2': task 'get_uptime' failed with traceback:
Traceback (most recent call last):
  File "/home/bradfernan/VENV/py3_venv/lib64/python3.7/site-packages/nornir/core/task.py", line 85, in start
    r = self.task(self, **self.params)
  File "exercise1a.py", line 20, in get_uptime
    if task.host.groups[0] == 'junos':
  File "exercise1a.py", line 20, in get_uptime
    if task.host.groups[0] == 'junos':
  File "/usr/lib64/python3.7/bdb.py", line 88, in trace_dispatch
    return self.dispatch_line(frame)
  File "/usr/lib64/python3.7/bdb.py", line 113, in dispatch_line
    if self.quitting: raise BdbQuit
bdb.BdbQuit

2021-01-05 17:54:14,820 -  nornir.core -     INFO -        run() - Running task 'get_uptime' with args {} on 1 hosts
2021-01-05 17:55:16,049 -  nornir.core -     INFO -        run() - Running task 'get_uptime' with args {} on 1 hosts
2021-01-05 17:55:50,270 -  nornir.core -     INFO -        run() - Running task 'get_uptime' with args {} on 9 hosts
2021-01-05 17:57:12,603 -  nornir.core -     INFO -        run() - Running task 'get_uptime' with args {} on 9 hosts
2021-01-05 17:57:50,066 -  nornir.core -     INFO -        run() - Running task 'get_uptime' with args {} on 9 hosts
2021-01-05 18:00:03,329 -  nornir.core -     INFO -        run() - Running task 'get_uptime' with args {} on 9 hosts
2021-01-05 20:45:32,449 -  nornir.core -     INFO -        run() - Running task 'get_uptime' with args {} on 9 hosts
2021-01-05 20:47:57,015 -  nornir.core -     INFO -        run() - Running task 'get_uptime' with args {} on 9 hosts
2021-01-05 20:47:57,016 - nornir.core.task -    ERROR -      start() - Host 'cisco3': task 'get_uptime' failed with traceback:
Traceback (most recent call last):
  File "/home/bradfernan/VENV/py3_venv/lib64/python3.7/site-packages/nornir/core/task.py", line 85, in start
    r = self.task(self, **self.params)
  File "exercise1a.py", line 18, in get_uptime
    uptime = task.run(task=netmiko_send_command, command_string=cmd)
UnboundLocalError: local variable 'cmd' referenced before assignment

2021-01-05 20:47:57,016 - nornir.core.task -    ERROR -      start() - Host 'cisco4': task 'get_uptime' failed with traceback:
Traceback (most recent call last):
  File "/home/bradfernan/VENV/py3_venv/lib64/python3.7/site-packages/nornir/core/task.py", line 85, in start
    r = self.task(self, **self.params)
  File "exercise1a.py", line 18, in get_uptime
    uptime = task.run(task=netmiko_send_command, command_string=cmd)
UnboundLocalError: local variable 'cmd' referenced before assignment

2021-01-05 20:47:57,016 - nornir.core.task -    ERROR -      start() - Host 'nxos1': task 'get_uptime' failed with traceback:
Traceback (most recent call last):
  File "/home/bradfernan/VENV/py3_venv/lib64/python3.7/site-packages/nornir/core/task.py", line 85, in start
    r = self.task(self, **self.params)
  File "exercise1a.py", line 18, in get_uptime
    uptime = task.run(task=netmiko_send_command, command_string=cmd)
UnboundLocalError: local variable 'cmd' referenced before assignment

2021-01-05 20:47:57,017 - nornir.core.task -    ERROR -      start() - Host 'nxos2': task 'get_uptime' failed with traceback:
Traceback (most recent call last):
  File "/home/bradfernan/VENV/py3_venv/lib64/python3.7/site-packages/nornir/core/task.py", line 85, in start
    r = self.task(self, **self.params)
  File "exercise1a.py", line 18, in get_uptime
    uptime = task.run(task=netmiko_send_command, command_string=cmd)
UnboundLocalError: local variable 'cmd' referenced before assignment

2021-01-05 20:47:57,019 - nornir.core.task -    ERROR -      start() - Host 'srx2': task 'get_uptime' failed with traceback:
Traceback (most recent call last):
  File "/home/bradfernan/VENV/py3_venv/lib64/python3.7/site-packages/nornir/core/task.py", line 85, in start
    r = self.task(self, **self.params)
  File "exercise1a.py", line 18, in get_uptime
    uptime = task.run(task=netmiko_send_command, command_string=cmd)
UnboundLocalError: local variable 'cmd' referenced before assignment

2021-01-05 20:49:44,946 -  nornir.core -     INFO -        run() - Running task 'get_uptime' with args {} on 9 hosts
2021-01-05 20:53:35,359 -  nornir.core -     INFO -        run() - Running task 'get_uptime' with args {} on 9 hosts
2021-01-05 20:55:18,841 -  nornir.core -     INFO -        run() - Running task 'get_uptime' with args {} on 9 hosts
2021-01-05 20:56:40,459 -  nornir.core -     INFO -        run() - Running task 'get_uptime' with args {} on 4 hosts
2021-01-05 20:57:17,993 -  nornir.core -     INFO -        run() - Running task 'get_uptime' with args {} on 4 hosts
2021-01-05 20:57:42,830 -  nornir.core -     INFO -        run() - Running task 'get_uptime' with args {} on 9 hosts
2021-01-05 20:58:09,702 - nornir.core.task -    ERROR -      start() - Host 'srx2': task 'netmiko_send_command' failed with traceback:
Traceback (most recent call last):
  File "/home/bradfernan/VENV/py3_venv/lib64/python3.7/site-packages/paramiko/channel.py", line 699, in recv
    out = self.in_buffer.read(nbytes, self.timeout)
  File "/home/bradfernan/VENV/py3_venv/lib64/python3.7/site-packages/paramiko/buffered_pipe.py", line 164, in read
    raise PipeTimeout()
paramiko.buffered_pipe.PipeTimeout

During handling of the above exception, another exception occurred:

Traceback (most recent call last):
  File "/home/bradfernan/VENV/py3_venv/lib64/python3.7/site-packages/netmiko/base_connection.py", line 564, in _read_channel_expect
    new_data = self.remote_conn.recv(MAX_BUFFER)
  File "/home/bradfernan/VENV/py3_venv/lib64/python3.7/site-packages/paramiko/channel.py", line 701, in recv
    raise socket.timeout()
socket.timeout

During handling of the above exception, another exception occurred:

Traceback (most recent call last):
  File "/home/bradfernan/VENV/py3_venv/lib64/python3.7/site-packages/nornir/core/task.py", line 85, in start
    r = self.task(self, **self.params)
  File "/home/bradfernan/VENV/py3_venv/lib64/python3.7/site-packages/nornir/plugins/tasks/networking/netmiko_send_command.py", line 32, in netmiko_send_command
    result = net_connect.send_command(command_string, **kwargs)
  File "/home/bradfernan/VENV/py3_venv/lib64/python3.7/site-packages/netmiko/utilities.py", line 347, in wrapper_decorator
    return func(self, *args, **kwargs)
  File "/home/bradfernan/VENV/py3_venv/lib64/python3.7/site-packages/netmiko/base_connection.py", line 1415, in send_command
    new_data = self.read_until_pattern(pattern=re.escape(cmd))
  File "/home/bradfernan/VENV/py3_venv/lib64/python3.7/site-packages/netmiko/base_connection.py", line 641, in read_until_pattern
    return self._read_channel_expect(*args, **kwargs)
  File "/home/bradfernan/VENV/py3_venv/lib64/python3.7/site-packages/netmiko/base_connection.py", line 575, in _read_channel_expect
    "Timed-out reading channel, data not available."
netmiko.ssh_exception.NetmikoTimeoutException: Timed-out reading channel, data not available.

2021-01-05 20:58:09,702 - nornir.core.task -    ERROR -      start() - Host 'srx2': task 'get_uptime' failed with traceback:
Traceback (most recent call last):
  File "/home/bradfernan/VENV/py3_venv/lib64/python3.7/site-packages/nornir/core/task.py", line 85, in start
    r = self.task(self, **self.params)
  File "exercise1a.py", line 19, in get_uptime
    uptime = task.run(task=netmiko_send_command, command_string=cmd)
  File "/home/bradfernan/VENV/py3_venv/lib64/python3.7/site-packages/nornir/core/task.py", line 147, in run
    raise NornirSubTaskError(task=task, result=r)
nornir.core.exceptions.NornirSubTaskError: Subtask: <function netmiko_send_command at 0x7fbd6ef99d40> (failed)


2021-01-05 21:02:29,065 -  nornir.core -     INFO -        run() - Running task 'get_uptime' with args {} on 9 hosts
2021-01-05 21:02:56,167 - nornir.core.task -    ERROR -      start() - Host 'srx2': task 'netmiko_send_command' failed with traceback:
Traceback (most recent call last):
  File "/home/bradfernan/VENV/py3_venv/lib64/python3.7/site-packages/paramiko/channel.py", line 699, in recv
    out = self.in_buffer.read(nbytes, self.timeout)
  File "/home/bradfernan/VENV/py3_venv/lib64/python3.7/site-packages/paramiko/buffered_pipe.py", line 164, in read
    raise PipeTimeout()
paramiko.buffered_pipe.PipeTimeout

During handling of the above exception, another exception occurred:

Traceback (most recent call last):
  File "/home/bradfernan/VENV/py3_venv/lib64/python3.7/site-packages/netmiko/base_connection.py", line 564, in _read_channel_expect
    new_data = self.remote_conn.recv(MAX_BUFFER)
  File "/home/bradfernan/VENV/py3_venv/lib64/python3.7/site-packages/paramiko/channel.py", line 701, in recv
    raise socket.timeout()
socket.timeout

During handling of the above exception, another exception occurred:

Traceback (most recent call last):
  File "/home/bradfernan/VENV/py3_venv/lib64/python3.7/site-packages/nornir/core/task.py", line 85, in start
    r = self.task(self, **self.params)
  File "/home/bradfernan/VENV/py3_venv/lib64/python3.7/site-packages/nornir/plugins/tasks/networking/netmiko_send_command.py", line 32, in netmiko_send_command
    result = net_connect.send_command(command_string, **kwargs)
  File "/home/bradfernan/VENV/py3_venv/lib64/python3.7/site-packages/netmiko/utilities.py", line 347, in wrapper_decorator
    return func(self, *args, **kwargs)
  File "/home/bradfernan/VENV/py3_venv/lib64/python3.7/site-packages/netmiko/base_connection.py", line 1415, in send_command
    new_data = self.read_until_pattern(pattern=re.escape(cmd))
  File "/home/bradfernan/VENV/py3_venv/lib64/python3.7/site-packages/netmiko/base_connection.py", line 641, in read_until_pattern
    return self._read_channel_expect(*args, **kwargs)
  File "/home/bradfernan/VENV/py3_venv/lib64/python3.7/site-packages/netmiko/base_connection.py", line 575, in _read_channel_expect
    "Timed-out reading channel, data not available."
netmiko.ssh_exception.NetmikoTimeoutException: Timed-out reading channel, data not available.

2021-01-05 21:02:56,167 - nornir.core.task -    ERROR -      start() - Host 'srx2': task 'get_uptime' failed with traceback:
Traceback (most recent call last):
  File "/home/bradfernan/VENV/py3_venv/lib64/python3.7/site-packages/nornir/core/task.py", line 85, in start
    r = self.task(self, **self.params)
  File "exercise1a.py", line 18, in get_uptime
    task.run(task=netmiko_send_command, command_string=cmd)
  File "/home/bradfernan/VENV/py3_venv/lib64/python3.7/site-packages/nornir/core/task.py", line 147, in run
    raise NornirSubTaskError(task=task, result=r)
nornir.core.exceptions.NornirSubTaskError: Subtask: <function netmiko_send_command at 0x7f74adf86cb0> (failed)


2021-01-05 21:03:20,126 -  nornir.core -     INFO -        run() - Running task 'get_uptime' with args {} on 9 hosts
2021-01-05 21:07:49,989 -  nornir.core -     INFO -        run() - Running task 'get_uptime' with args {} on 9 hosts
2021-01-05 21:09:51,472 -  nornir.core -     INFO -        run() - Running task 'get_uptime' with args {} on 9 hosts
2021-01-05 21:13:00,715 - nornir.core.task -    ERROR -      start() - Host 'cisco3': task 'get_uptime' failed with traceback:
Traceback (most recent call last):
  File "/home/bradfernan/VENV/py3_venv/lib64/python3.7/site-packages/nornir/core/task.py", line 85, in start
    r = self.task(self, **self.params)
  File "exercise1a.py", line 13, in get_uptime
    if task.host.groups[0] == 'junos':
  File "exercise1a.py", line 13, in get_uptime
    if task.host.groups[0] == 'junos':
  File "/usr/lib64/python3.7/bdb.py", line 88, in trace_dispatch
    return self.dispatch_line(frame)
  File "/usr/lib64/python3.7/bdb.py", line 113, in dispatch_line
    if self.quitting: raise BdbQuit
bdb.BdbQuit

2021-01-05 21:13:04,672 - nornir.core.task -    ERROR -      start() - Host 'cisco4': task 'get_uptime' failed with traceback:
Traceback (most recent call last):
  File "/home/bradfernan/VENV/py3_venv/lib64/python3.7/site-packages/nornir/core/task.py", line 85, in start
    r = self.task(self, **self.params)
  File "exercise1a.py", line 13, in get_uptime
    if task.host.groups[0] == 'junos':
  File "exercise1a.py", line 13, in get_uptime
    if task.host.groups[0] == 'junos':
  File "/usr/lib64/python3.7/bdb.py", line 88, in trace_dispatch
    return self.dispatch_line(frame)
  File "/usr/lib64/python3.7/bdb.py", line 113, in dispatch_line
    if self.quitting: raise BdbQuit
bdb.BdbQuit

2021-01-05 21:13:07,004 - nornir.core.task -    ERROR -      start() - Host 'nxos1': task 'get_uptime' failed with traceback:
Traceback (most recent call last):
  File "/home/bradfernan/VENV/py3_venv/lib64/python3.7/site-packages/nornir/core/task.py", line 85, in start
    r = self.task(self, **self.params)
  File "exercise1a.py", line 13, in get_uptime
    if task.host.groups[0] == 'junos':
  File "exercise1a.py", line 13, in get_uptime
    if task.host.groups[0] == 'junos':
  File "/usr/lib64/python3.7/bdb.py", line 88, in trace_dispatch
    return self.dispatch_line(frame)
  File "/usr/lib64/python3.7/bdb.py", line 113, in dispatch_line
    if self.quitting: raise BdbQuit
bdb.BdbQuit

2021-01-05 21:13:08,402 - nornir.core.task -    ERROR -      start() - Host 'nxos2': task 'get_uptime' failed with traceback:
Traceback (most recent call last):
  File "/home/bradfernan/VENV/py3_venv/lib64/python3.7/site-packages/nornir/core/task.py", line 85, in start
    r = self.task(self, **self.params)
  File "exercise1a.py", line 13, in get_uptime
    if task.host.groups[0] == 'junos':
  File "exercise1a.py", line 13, in get_uptime
    if task.host.groups[0] == 'junos':
  File "/usr/lib64/python3.7/bdb.py", line 88, in trace_dispatch
    return self.dispatch_line(frame)
  File "/usr/lib64/python3.7/bdb.py", line 113, in dispatch_line
    if self.quitting: raise BdbQuit
bdb.BdbQuit

2021-01-05 21:13:10,096 - nornir.core.task -    ERROR -      start() - Host 'arista1': task 'get_uptime' failed with traceback:
Traceback (most recent call last):
  File "/home/bradfernan/VENV/py3_venv/lib64/python3.7/site-packages/nornir/core/task.py", line 85, in start
    r = self.task(self, **self.params)
  File "exercise1a.py", line 13, in get_uptime
    if task.host.groups[0] == 'junos':
  File "exercise1a.py", line 13, in get_uptime
    if task.host.groups[0] == 'junos':
  File "/usr/lib64/python3.7/bdb.py", line 88, in trace_dispatch
    return self.dispatch_line(frame)
  File "/usr/lib64/python3.7/bdb.py", line 113, in dispatch_line
    if self.quitting: raise BdbQuit
bdb.BdbQuit

2021-01-05 21:13:11,071 - nornir.core.task -    ERROR -      start() - Host 'arista2': task 'get_uptime' failed with traceback:
Traceback (most recent call last):
  File "/home/bradfernan/VENV/py3_venv/lib64/python3.7/site-packages/nornir/core/task.py", line 85, in start
    r = self.task(self, **self.params)
  File "exercise1a.py", line 13, in get_uptime
    if task.host.groups[0] == 'junos':
  File "exercise1a.py", line 13, in get_uptime
    if task.host.groups[0] == 'junos':
  File "/usr/lib64/python3.7/bdb.py", line 88, in trace_dispatch
    return self.dispatch_line(frame)
  File "/usr/lib64/python3.7/bdb.py", line 113, in dispatch_line
    if self.quitting: raise BdbQuit
bdb.BdbQuit

2021-01-05 21:13:26,731 - nornir.core.task -    ERROR -      start() - Host 'arista3': task 'get_uptime' failed with traceback:
Traceback (most recent call last):
  File "/home/bradfernan/VENV/py3_venv/lib64/python3.7/site-packages/nornir/core/task.py", line 85, in start
    r = self.task(self, **self.params)
  File "exercise1a.py", line 13, in get_uptime
    if task.host.groups[0] == 'junos':
  File "exercise1a.py", line 13, in get_uptime
    if task.host.groups[0] == 'junos':
  File "/usr/lib64/python3.7/bdb.py", line 88, in trace_dispatch
    return self.dispatch_line(frame)
  File "/usr/lib64/python3.7/bdb.py", line 113, in dispatch_line
    if self.quitting: raise BdbQuit
bdb.BdbQuit

2021-01-05 21:13:27,464 - nornir.core.task -    ERROR -      start() - Host 'arista4': task 'get_uptime' failed with traceback:
Traceback (most recent call last):
  File "/home/bradfernan/VENV/py3_venv/lib64/python3.7/site-packages/nornir/core/task.py", line 85, in start
    r = self.task(self, **self.params)
  File "exercise1a.py", line 13, in get_uptime
    if task.host.groups[0] == 'junos':
  File "exercise1a.py", line 13, in get_uptime
    if task.host.groups[0] == 'junos':
  File "/usr/lib64/python3.7/bdb.py", line 88, in trace_dispatch
    return self.dispatch_line(frame)
  File "/usr/lib64/python3.7/bdb.py", line 113, in dispatch_line
    if self.quitting: raise BdbQuit
bdb.BdbQuit

2021-01-05 21:13:28,404 - nornir.core.task -    ERROR -      start() - Host 'srx2': task 'get_uptime' failed with traceback:
Traceback (most recent call last):
  File "/home/bradfernan/VENV/py3_venv/lib64/python3.7/site-packages/nornir/core/task.py", line 85, in start
    r = self.task(self, **self.params)
  File "exercise1a.py", line 13, in get_uptime
    if task.host.groups[0] == 'junos':
  File "exercise1a.py", line 13, in get_uptime
    if task.host.groups[0] == 'junos':
  File "/usr/lib64/python3.7/bdb.py", line 88, in trace_dispatch
    return self.dispatch_line(frame)
  File "/usr/lib64/python3.7/bdb.py", line 113, in dispatch_line
    if self.quitting: raise BdbQuit
bdb.BdbQuit

2021-01-05 21:18:03,972 -  nornir.core -     INFO -        run() - Running task 'get_uptime' with args {} on 9 hosts
2021-01-05 21:19:10,353 -  nornir.core -     INFO -        run() - Running task 'get_uptime' with args {} on 9 hosts
2021-01-05 21:22:11,175 -  nornir.core -     INFO -        run() - Running task 'get_uptime' with args {} on 9 hosts
