2021-01-15 23:00:22,080 -  nornir.core -     INFO -        run() - Running task 'load_yaml' with args {'file': 'acl.yaml'} on 1 hosts
2021-01-15 23:02:04,673 -  nornir.core -     INFO -        run() - Running task 'load_file' with args {} on 1 hosts
2021-01-15 23:02:15,373 - nornir.core.task -    ERROR -      start() - Host 'srx2': task 'load_file' failed with traceback:
Traceback (most recent call last):
  File "/home/bradfernan/VENV/py3_venv/lib64/python3.7/site-packages/nornir/core/task.py", line 85, in start
    r = self.task(self, **self.params)
  File "exercise4a.py", line 7, in load_file
    ipdb.set_trace()
  File "/usr/lib64/python3.7/bdb.py", line 92, in trace_dispatch
    return self.dispatch_return(frame, arg)
  File "/usr/lib64/python3.7/bdb.py", line 154, in dispatch_return
    if self.quitting: raise BdbQuit
bdb.BdbQuit

2021-01-15 23:31:18,429 -  nornir.core -     INFO -        run() - Running task 'load_file' with args {} on 1 hosts
2021-01-15 23:31:30,031 - nornir.core.task -    ERROR -      start() - Host 'srx2': task 'build_acl' failed with traceback:
Traceback (most recent call last):
  File "/home/bradfernan/VENV/py3_venv/lib64/python3.7/site-packages/nornir/core/task.py", line 85, in start
    r = self.task(self, **self.params)
  File "exercise4a.py", line 8, in build_acl
    ipdb.set_trace()
  File "/usr/lib64/python3.7/bdb.py", line 92, in trace_dispatch
    return self.dispatch_return(frame, arg)
  File "/usr/lib64/python3.7/bdb.py", line 154, in dispatch_return
    if self.quitting: raise BdbQuit
bdb.BdbQuit

2021-01-15 23:31:30,031 - nornir.core.task -    ERROR -      start() - Host 'srx2': task 'load_file' failed with traceback:
Traceback (most recent call last):
  File "/home/bradfernan/VENV/py3_venv/lib64/python3.7/site-packages/nornir/core/task.py", line 85, in start
    r = self.task(self, **self.params)
  File "exercise4a.py", line 13, in load_file
    task.run(task=build_acl, file_data=file_data)
  File "/home/bradfernan/VENV/py3_venv/lib64/python3.7/site-packages/nornir/core/task.py", line 142, in run
    r = run_task.start(self.host, self.nornir)
nornir.core.exceptions.NornirSubTaskError: Subtask: <function build_acl at 0x7f6f43e8ba70> (failed)


2021-01-15 23:45:16,220 -  nornir.core -     INFO -        run() - Running task 'load_file' with args {} on 1 hosts
2021-01-15 23:46:35,570 - nornir.core.task -    ERROR -      start() - Host 'srx2': task 'render_config' failed with traceback:
Traceback (most recent call last):
  File "/home/bradfernan/VENV/py3_venv/lib64/python3.7/site-packages/nornir/core/task.py", line 85, in start
    r = self.task(self, **self.params)
  File "exercise4a.py", line 7, in render_config
    ipdb.set_trace()
  File "/usr/lib64/python3.7/bdb.py", line 92, in trace_dispatch
    return self.dispatch_return(frame, arg)
  File "/usr/lib64/python3.7/bdb.py", line 154, in dispatch_return
    if self.quitting: raise BdbQuit
bdb.BdbQuit

2021-01-15 23:46:35,570 - nornir.core.task -    ERROR -      start() - Host 'srx2': task 'load_file' failed with traceback:
Traceback (most recent call last):
  File "/home/bradfernan/VENV/py3_venv/lib64/python3.7/site-packages/nornir/core/task.py", line 85, in start
    r = self.task(self, **self.params)
  File "exercise4a.py", line 21, in load_file
    task.run(task=render_config, acl_template=acl_config)
  File "/home/bradfernan/VENV/py3_venv/lib64/python3.7/site-packages/nornir/core/task.py", line 142, in run
    r = run_task.start(self.host, self.nornir)
nornir.core.exceptions.NornirSubTaskError: Subtask: <function render_config at 0x7fa745951ef0> (failed)


2021-01-15 23:49:16,500 -  nornir.core -     INFO -        run() - Running task 'load_file' with args {} on 1 hosts
2021-01-15 23:49:16,512 - nornir.core.task -    ERROR -      start() - Host 'srx2': task 'template_string' failed with traceback:
Traceback (most recent call last):
  File "/home/bradfernan/VENV/py3_venv/lib64/python3.7/site-packages/nornir/core/task.py", line 85, in start
    r = self.task(self, **self.params)
  File "/home/bradfernan/VENV/py3_venv/lib64/python3.7/site-packages/nornir/plugins/tasks/text/template_string.py", line 26, in template_string
    template=template, host=task.host, jinja_filters=jinja_filters, **kwargs
  File "/home/bradfernan/VENV/py3_venv/lib64/python3.7/site-packages/nornir/core/helpers/jinja_helper.py", line 28, in render_from_string
    return t.render(**kwargs)
  File "/home/bradfernan/VENV/py3_venv/lib64/python3.7/site-packages/jinja2/environment.py", line 1090, in render
    self.environment.handle_exception()
  File "/home/bradfernan/VENV/py3_venv/lib64/python3.7/site-packages/jinja2/environment.py", line 832, in handle_exception
    reraise(*rewrite_traceback_stack(source=source))
  File "/home/bradfernan/VENV/py3_venv/lib64/python3.7/site-packages/jinja2/_compat.py", line 28, in reraise
    raise value.with_traceback(tb)
  File "<template>", line 1, in top-level template code
jinja2.exceptions.UndefinedError: 'acl_name' is undefined

2021-01-15 23:49:16,512 - nornir.core.task -    ERROR -      start() - Host 'srx2': task 'build_acl' failed with traceback:
Traceback (most recent call last):
  File "/home/bradfernan/VENV/py3_venv/lib64/python3.7/site-packages/nornir/core/task.py", line 85, in start
    r = self.task(self, **self.params)
  File "exercise4a.py", line 15, in build_acl
    task.run(task=text.template_string, template=acl_config)
  File "/home/bradfernan/VENV/py3_venv/lib64/python3.7/site-packages/nornir/core/task.py", line 147, in run
    raise NornirSubTaskError(task=task, result=r)
nornir.core.exceptions.NornirSubTaskError: Subtask: <function template_string at 0x7efc7415b710> (failed)


2021-01-15 23:49:16,512 - nornir.core.task -    ERROR -      start() - Host 'srx2': task 'load_file' failed with traceback:
Traceback (most recent call last):
  File "/home/bradfernan/VENV/py3_venv/lib64/python3.7/site-packages/nornir/core/task.py", line 85, in start
    r = self.task(self, **self.params)
  File "exercise4a.py", line 21, in load_file
    acl_config = task.run(task=build_acl, file_data=file_data)
  File "/home/bradfernan/VENV/py3_venv/lib64/python3.7/site-packages/nornir/core/task.py", line 147, in run
    raise NornirSubTaskError(task=task, result=r)
nornir.core.exceptions.NornirSubTaskError: Subtask: <function build_acl at 0x7efc94a3ea70> (failed)


2021-01-15 23:51:14,718 -  nornir.core -     INFO -        run() - Running task 'load_file' with args {} on 1 hosts
2021-01-15 23:51:14,724 - nornir.core.task -    ERROR -      start() - Host 'srx2': task 'template_string' failed with traceback:
Traceback (most recent call last):
  File "/home/bradfernan/VENV/py3_venv/lib64/python3.7/site-packages/nornir/core/task.py", line 85, in start
    r = self.task(self, **self.params)
  File "/home/bradfernan/VENV/py3_venv/lib64/python3.7/site-packages/nornir/plugins/tasks/text/template_string.py", line 26, in template_string
    template=template, host=task.host, jinja_filters=jinja_filters, **kwargs
  File "/home/bradfernan/VENV/py3_venv/lib64/python3.7/site-packages/nornir/core/helpers/jinja_helper.py", line 28, in render_from_string
    return t.render(**kwargs)
  File "/home/bradfernan/VENV/py3_venv/lib64/python3.7/site-packages/jinja2/environment.py", line 1090, in render
    self.environment.handle_exception()
  File "/home/bradfernan/VENV/py3_venv/lib64/python3.7/site-packages/jinja2/environment.py", line 832, in handle_exception
    reraise(*rewrite_traceback_stack(source=source))
  File "/home/bradfernan/VENV/py3_venv/lib64/python3.7/site-packages/jinja2/_compat.py", line 28, in reraise
    raise value.with_traceback(tb)
  File "<template>", line 1, in top-level template code
jinja2.exceptions.UndefinedError: 'acl_name' is undefined

2021-01-15 23:51:14,725 - nornir.core.task -    ERROR -      start() - Host 'srx2': task 'build_acl' failed with traceback:
Traceback (most recent call last):
  File "/home/bradfernan/VENV/py3_venv/lib64/python3.7/site-packages/nornir/core/task.py", line 85, in start
    r = self.task(self, **self.params)
  File "exercise4a.py", line 15, in build_acl
    task.run(task=text.template_string, template=acl_config)
  File "/home/bradfernan/VENV/py3_venv/lib64/python3.7/site-packages/nornir/core/task.py", line 147, in run
    raise NornirSubTaskError(task=task, result=r)
nornir.core.exceptions.NornirSubTaskError: Subtask: <function template_string at 0x7f4049c93710> (failed)


2021-01-15 23:51:14,725 - nornir.core.task -    ERROR -      start() - Host 'srx2': task 'load_file' failed with traceback:
Traceback (most recent call last):
  File "/home/bradfernan/VENV/py3_venv/lib64/python3.7/site-packages/nornir/core/task.py", line 85, in start
    r = self.task(self, **self.params)
  File "exercise4a.py", line 22, in load_file
    acl_config = task.run(task=build_acl, file_data=file_data)
  File "/home/bradfernan/VENV/py3_venv/lib64/python3.7/site-packages/nornir/core/task.py", line 147, in run
    raise NornirSubTaskError(task=task, result=r)
nornir.core.exceptions.NornirSubTaskError: Subtask: <function build_acl at 0x7f406a57aa70> (failed)


2021-01-15 23:55:32,047 -  nornir.core -     INFO -        run() - Running task 'load_file' with args {} on 1 hosts
2021-01-15 23:55:49,344 - nornir.core.task -    ERROR -      start() - Host 'srx2': task 'build_acl' failed with traceback:
Traceback (most recent call last):
  File "/home/bradfernan/VENV/py3_venv/lib64/python3.7/site-packages/nornir/core/task.py", line 85, in start
    r = self.task(self, **self.params)
  File "exercise4a.py", line 19, in build_acl
    ipdb.set_trace()
  File "/usr/lib64/python3.7/bdb.py", line 92, in trace_dispatch
    return self.dispatch_return(frame, arg)
  File "/usr/lib64/python3.7/bdb.py", line 154, in dispatch_return
    if self.quitting: raise BdbQuit
bdb.BdbQuit

2021-01-15 23:55:49,344 - nornir.core.task -    ERROR -      start() - Host 'srx2': task 'load_file' failed with traceback:
Traceback (most recent call last):
  File "/home/bradfernan/VENV/py3_venv/lib64/python3.7/site-packages/nornir/core/task.py", line 85, in start
    r = self.task(self, **self.params)
  File "exercise4a.py", line 25, in load_file
    acl_config = task.run(task=build_acl, file_data=file_data)
  File "/home/bradfernan/VENV/py3_venv/lib64/python3.7/site-packages/nornir/core/task.py", line 142, in run
    r = run_task.start(self.host, self.nornir)
nornir.core.exceptions.NornirSubTaskError: Subtask: <function build_acl at 0x7f8d6ef8da70> (failed)


2021-01-16 00:01:12,275 -  nornir.core -     INFO -        run() - Running task 'load_file' with args {} on 1 hosts
2021-01-16 00:01:27,352 - nornir.core.task -    ERROR -      start() - Host 'srx2': task 'build_acl' failed with traceback:
Traceback (most recent call last):
  File "/home/bradfernan/VENV/py3_venv/lib64/python3.7/site-packages/nornir/core/task.py", line 85, in start
    r = self.task(self, **self.params)
  File "exercise4a.py", line 22, in build_acl
    ipdb.set_trace()
  File "/usr/lib64/python3.7/bdb.py", line 92, in trace_dispatch
    return self.dispatch_return(frame, arg)
  File "/usr/lib64/python3.7/bdb.py", line 154, in dispatch_return
    if self.quitting: raise BdbQuit
bdb.BdbQuit

2021-01-16 00:01:27,353 - nornir.core.task -    ERROR -      start() - Host 'srx2': task 'load_file' failed with traceback:
Traceback (most recent call last):
  File "/home/bradfernan/VENV/py3_venv/lib64/python3.7/site-packages/nornir/core/task.py", line 85, in start
    r = self.task(self, **self.params)
  File "exercise4a.py", line 28, in load_file
    acl_config = task.run(task=build_acl, file_data=file_data)
  File "/home/bradfernan/VENV/py3_venv/lib64/python3.7/site-packages/nornir/core/task.py", line 142, in run
    r = run_task.start(self.host, self.nornir)
nornir.core.exceptions.NornirSubTaskError: Subtask: <function build_acl at 0x7f2370e89a70> (failed)


2021-01-16 00:07:49,787 -  nornir.core -     INFO -        run() - Running task 'load_file' with args {} on 1 hosts
2021-01-16 00:08:20,201 - nornir.core.task -    ERROR -      start() - Host 'srx2': task 'build_acl' failed with traceback:
Traceback (most recent call last):
  File "/home/bradfernan/VENV/py3_venv/lib64/python3.7/site-packages/nornir/core/task.py", line 85, in start
    r = self.task(self, **self.params)
  File "exercise4a.py", line 28, in build_acl
    ipdb.set_trace()
  File "/usr/lib64/python3.7/bdb.py", line 92, in trace_dispatch
    return self.dispatch_return(frame, arg)
  File "/usr/lib64/python3.7/bdb.py", line 154, in dispatch_return
    if self.quitting: raise BdbQuit
bdb.BdbQuit

2021-01-16 00:08:20,202 - nornir.core.task -    ERROR -      start() - Host 'srx2': task 'load_file' failed with traceback:
Traceback (most recent call last):
  File "/home/bradfernan/VENV/py3_venv/lib64/python3.7/site-packages/nornir/core/task.py", line 85, in start
    r = self.task(self, **self.params)
  File "exercise4a.py", line 34, in load_file
    acl_config = task.run(task=build_acl, file_data=file_data)
  File "/home/bradfernan/VENV/py3_venv/lib64/python3.7/site-packages/nornir/core/task.py", line 142, in run
    r = run_task.start(self.host, self.nornir)
nornir.core.exceptions.NornirSubTaskError: Subtask: <function build_acl at 0x7f21a5e6aef0> (failed)


2021-01-16 00:10:13,367 -  nornir.core -     INFO -        run() - Running task 'load_file' with args {} on 1 hosts
2021-01-16 00:10:46,307 - nornir.core.task -    ERROR -      start() - Host 'srx2': task 'build_acl' failed with traceback:
Traceback (most recent call last):
  File "/home/bradfernan/VENV/py3_venv/lib64/python3.7/site-packages/nornir/core/task.py", line 85, in start
    r = self.task(self, **self.params)
  File "exercise4a.py", line 30, in build_acl
    ipdb.set_trace()
  File "/usr/lib64/python3.7/bdb.py", line 92, in trace_dispatch
    return self.dispatch_return(frame, arg)
  File "/usr/lib64/python3.7/bdb.py", line 154, in dispatch_return
    if self.quitting: raise BdbQuit
bdb.BdbQuit

2021-01-16 00:10:46,307 - nornir.core.task -    ERROR -      start() - Host 'srx2': task 'load_file' failed with traceback:
Traceback (most recent call last):
  File "/home/bradfernan/VENV/py3_venv/lib64/python3.7/site-packages/nornir/core/task.py", line 85, in start
    r = self.task(self, **self.params)
  File "exercise4a.py", line 36, in load_file
    acl_config = task.run(task=build_acl, file_data=file_data)
  File "/home/bradfernan/VENV/py3_venv/lib64/python3.7/site-packages/nornir/core/task.py", line 142, in run
    r = run_task.start(self.host, self.nornir)
nornir.core.exceptions.NornirSubTaskError: Subtask: <function build_acl at 0x7f6b4332da70> (failed)


2021-01-16 00:12:26,366 -  nornir.core -     INFO -        run() - Running task 'load_file' with args {} on 1 hosts
2021-01-16 00:12:53,326 - nornir.core.task -    ERROR -      start() - Host 'srx2': task 'build_acl' failed with traceback:
Traceback (most recent call last):
  File "/home/bradfernan/VENV/py3_venv/lib64/python3.7/site-packages/nornir/core/task.py", line 85, in start
    r = self.task(self, **self.params)
  File "exercise4a.py", line 30, in build_acl
    ipdb.set_trace()
  File "/usr/lib64/python3.7/bdb.py", line 92, in trace_dispatch
    return self.dispatch_return(frame, arg)
  File "/usr/lib64/python3.7/bdb.py", line 154, in dispatch_return
    if self.quitting: raise BdbQuit
bdb.BdbQuit

2021-01-16 00:12:53,326 - nornir.core.task -    ERROR -      start() - Host 'srx2': task 'load_file' failed with traceback:
Traceback (most recent call last):
  File "/home/bradfernan/VENV/py3_venv/lib64/python3.7/site-packages/nornir/core/task.py", line 85, in start
    r = self.task(self, **self.params)
  File "exercise4a.py", line 36, in load_file
    acl_config = task.run(task=build_acl, file_data=file_data)
  File "/home/bradfernan/VENV/py3_venv/lib64/python3.7/site-packages/nornir/core/task.py", line 142, in run
    r = run_task.start(self.host, self.nornir)
nornir.core.exceptions.NornirSubTaskError: Subtask: <function build_acl at 0x7f9a46ad4a70> (failed)


2021-01-16 00:13:17,700 -  nornir.core -     INFO -        run() - Running task 'load_file' with args {} on 1 hosts
2021-01-16 00:14:23,821 -  nornir.core -     INFO -        run() - Running task 'load_file' with args {} on 1 hosts
2021-01-16 00:14:35,725 - nornir.core.task -    ERROR -      start() - Host 'srx2': task 'build_acl' failed with traceback:
Traceback (most recent call last):
  File "/home/bradfernan/VENV/py3_venv/lib64/python3.7/site-packages/nornir/core/task.py", line 85, in start
    r = self.task(self, **self.params)
  File "exercise4a.py", line 30, in build_acl
    for line in full_config:
  File "exercise4a.py", line 30, in build_acl
    for line in full_config:
  File "/usr/lib64/python3.7/bdb.py", line 88, in trace_dispatch
    return self.dispatch_line(frame)
  File "/usr/lib64/python3.7/bdb.py", line 113, in dispatch_line
    if self.quitting: raise BdbQuit
bdb.BdbQuit

2021-01-16 00:14:35,725 - nornir.core.task -    ERROR -      start() - Host 'srx2': task 'load_file' failed with traceback:
Traceback (most recent call last):
  File "/home/bradfernan/VENV/py3_venv/lib64/python3.7/site-packages/nornir/core/task.py", line 85, in start
    r = self.task(self, **self.params)
  File "exercise4a.py", line 38, in load_file
    acl_config = task.run(task=build_acl, file_data=file_data)
  File "/home/bradfernan/VENV/py3_venv/lib64/python3.7/site-packages/nornir/core/task.py", line 142, in run
    r = run_task.start(self.host, self.nornir)
nornir.core.exceptions.NornirSubTaskError: Subtask: <function build_acl at 0x7f0fade91a70> (failed)


2021-01-16 00:15:15,092 -  nornir.core -     INFO -        run() - Running task 'load_file' with args {} on 1 hosts
2021-01-16 00:16:26,925 -  nornir.core -     INFO -        run() - Running task 'load_file' with args {} on 1 hosts
2021-01-16 00:16:49,145 -  nornir.core -     INFO -        run() - Running task 'load_file' with args {} on 1 hosts
2021-01-16 00:18:22,094 - nornir.core.task -    ERROR -      start() - Host 'srx2': task 'build_acl' failed with traceback:
Traceback (most recent call last):
  File "/home/bradfernan/VENV/py3_venv/lib64/python3.7/site-packages/nornir/core/task.py", line 85, in start
    r = self.task(self, **self.params)
  File "exercise4a.py", line 33, in build_acl
    pprint(line[0].result)
  File "exercise4a.py", line 33, in build_acl
    pprint(line[0].result)
  File "/usr/lib64/python3.7/bdb.py", line 88, in trace_dispatch
    return self.dispatch_line(frame)
  File "/usr/lib64/python3.7/bdb.py", line 113, in dispatch_line
    if self.quitting: raise BdbQuit
bdb.BdbQuit

2021-01-16 00:18:22,094 - nornir.core.task -    ERROR -      start() - Host 'srx2': task 'load_file' failed with traceback:
Traceback (most recent call last):
  File "/home/bradfernan/VENV/py3_venv/lib64/python3.7/site-packages/nornir/core/task.py", line 85, in start
    r = self.task(self, **self.params)
  File "exercise4a.py", line 39, in load_file
    acl_config = task.run(task=build_acl, file_data=file_data)
  File "/home/bradfernan/VENV/py3_venv/lib64/python3.7/site-packages/nornir/core/task.py", line 142, in run
    r = run_task.start(self.host, self.nornir)
nornir.core.exceptions.NornirSubTaskError: Subtask: <function build_acl at 0x7efcd3ddda70> (failed)


2021-01-16 00:18:32,243 -  nornir.core -     INFO -        run() - Running task 'load_file' with args {} on 1 hosts
2021-01-16 00:18:42,858 - nornir.core.task -    ERROR -      start() - Host 'srx2': task 'build_acl' failed with traceback:
Traceback (most recent call last):
  File "/home/bradfernan/VENV/py3_venv/lib64/python3.7/site-packages/nornir/core/task.py", line 85, in start
    r = self.task(self, **self.params)
  File "exercise4a.py", line 33, in build_acl
    pprint(line[0].result)
  File "exercise4a.py", line 33, in build_acl
    pprint(line[0].result)
  File "/usr/lib64/python3.7/bdb.py", line 88, in trace_dispatch
    return self.dispatch_line(frame)
  File "/usr/lib64/python3.7/bdb.py", line 113, in dispatch_line
    if self.quitting: raise BdbQuit
bdb.BdbQuit

2021-01-16 00:18:42,858 - nornir.core.task -    ERROR -      start() - Host 'srx2': task 'load_file' failed with traceback:
Traceback (most recent call last):
  File "/home/bradfernan/VENV/py3_venv/lib64/python3.7/site-packages/nornir/core/task.py", line 85, in start
    r = self.task(self, **self.params)
  File "exercise4a.py", line 39, in load_file
    acl_config = task.run(task=build_acl, file_data=file_data)
  File "/home/bradfernan/VENV/py3_venv/lib64/python3.7/site-packages/nornir/core/task.py", line 142, in run
    r = run_task.start(self.host, self.nornir)
nornir.core.exceptions.NornirSubTaskError: Subtask: <function build_acl at 0x7f2a49381a70> (failed)


2021-01-16 00:18:52,968 -  nornir.core -     INFO -        run() - Running task 'load_file' with args {} on 1 hosts
2021-01-16 00:20:14,864 -  nornir.core -     INFO -        run() - Running task 'load_file' with args {} on 1 hosts
