2021-02-04 14:46:58,082 -  nornir.core -     INFO -        run() - Running task 'transform_nornir' with args {} on 1 hosts
2021-02-04 14:50:59,274 - nornir.core.task -    ERROR -      start() - Host 'nxos1': task 'transform_nornir' failed with traceback:
Traceback (most recent call last):
  File "/home/bradfernan/VENV/py3_venv/lib64/python3.7/site-packages/nornir/core/task.py", line 85, in start
    r = self.task(self, **self.params)
  File "exercise2a.py", line 6, in transform_nornir
    import ipdb; ipdb.set_trace()
  File "/usr/lib64/python3.7/bdb.py", line 92, in trace_dispatch
    return self.dispatch_return(frame, arg)
  File "/usr/lib64/python3.7/bdb.py", line 154, in dispatch_return
    if self.quitting: raise BdbQuit
bdb.BdbQuit

2021-02-04 23:33:05,526 -  nornir.core -     INFO -        run() - Running task 'netmiko_send_command' with args {'command_string': 'show version'} on 10 hosts
2021-02-04 23:33:05,527 - nornir.core.task -    ERROR -      start() - Host 'localhost': task 'netmiko_send_command' failed with traceback:
Traceback (most recent call last):
  File "/home/bradfernan/VENV/py3_venv/lib64/python3.7/site-packages/nornir/core/task.py", line 85, in start
    r = self.task(self, **self.params)
  File "/home/bradfernan/VENV/py3_venv/lib64/python3.7/site-packages/nornir/plugins/tasks/networking/netmiko_send_command.py", line 26, in netmiko_send_command
    net_connect = task.host.get_connection("netmiko", task.nornir.config)
  File "/home/bradfernan/VENV/py3_venv/lib64/python3.7/site-packages/nornir/core/inventory.py", line 302, in get_connection
    extras=conn.extras,
  File "/home/bradfernan/VENV/py3_venv/lib64/python3.7/site-packages/nornir/core/inventory.py", line 352, in open_connection
    configuration=configuration,
  File "/home/bradfernan/VENV/py3_venv/lib64/python3.7/site-packages/nornir/plugins/connections/netmiko.py", line 58, in open
    self.connection = ConnectHandler(**parameters)
  File "/home/bradfernan/VENV/py3_venv/lib64/python3.7/site-packages/netmiko/ssh_dispatcher.py", line 287, in ConnectHandler
    device_type = kwargs["device_type"]
KeyError: 'device_type'

2021-02-04 23:33:41,651 -  nornir.core -     INFO -        run() - Running task 'netmiko_send_command' with args {'command_string': 'show version'} on 10 hosts
2021-02-04 23:33:41,652 - nornir.core.task -    ERROR -      start() - Host 'localhost': task 'netmiko_send_command' failed with traceback:
Traceback (most recent call last):
  File "/home/bradfernan/VENV/py3_venv/lib64/python3.7/site-packages/nornir/core/task.py", line 85, in start
    r = self.task(self, **self.params)
  File "/home/bradfernan/VENV/py3_venv/lib64/python3.7/site-packages/nornir/plugins/tasks/networking/netmiko_send_command.py", line 26, in netmiko_send_command
    net_connect = task.host.get_connection("netmiko", task.nornir.config)
  File "/home/bradfernan/VENV/py3_venv/lib64/python3.7/site-packages/nornir/core/inventory.py", line 302, in get_connection
    extras=conn.extras,
  File "/home/bradfernan/VENV/py3_venv/lib64/python3.7/site-packages/nornir/core/inventory.py", line 352, in open_connection
    configuration=configuration,
  File "/home/bradfernan/VENV/py3_venv/lib64/python3.7/site-packages/nornir/plugins/connections/netmiko.py", line 58, in open
    self.connection = ConnectHandler(**parameters)
  File "/home/bradfernan/VENV/py3_venv/lib64/python3.7/site-packages/netmiko/ssh_dispatcher.py", line 287, in ConnectHandler
    device_type = kwargs["device_type"]
KeyError: 'device_type'

2021-02-04 23:44:00,357 -  nornir.core -     INFO -        run() - Running task 'netmiko_send_command' with args {'command_string': 'show version'} on 9 hosts
2021-02-04 23:53:57,997 -  nornir.core -     INFO -        run() - Running task 'netmiko_send_command' with args {'command_string': 'show version'} on 9 hosts
2021-02-05 08:16:39,512 -  nornir.core -     INFO -        run() - Running task 'napalm_get' with args {'getters': ['facts']} on 2 hosts
2021-02-05 08:16:39,514 - nornir.core.task -    ERROR -      start() - Host 'nxos1': task 'napalm_get' failed with traceback:
Traceback (most recent call last):
  File "/home/bradfernan/VENV/py3_venv/lib64/python3.7/site-packages/nornir/core/task.py", line 85, in start
    r = self.task(self, **self.params)
  File "/home/bradfernan/VENV/py3_venv/lib64/python3.7/site-packages/nornir/plugins/tasks/networking/napalm_get.py", line 49, in napalm_get
    device = task.host.get_connection("napalm", task.nornir.config)
  File "/home/bradfernan/VENV/py3_venv/lib64/python3.7/site-packages/nornir/core/inventory.py", line 302, in get_connection
    extras=conn.extras,
  File "/home/bradfernan/VENV/py3_venv/lib64/python3.7/site-packages/nornir/core/inventory.py", line 352, in open_connection
    configuration=configuration,
  File "/home/bradfernan/VENV/py3_venv/lib64/python3.7/site-packages/nornir/plugins/connections/napalm.py", line 49, in open
    network_driver = get_network_driver(platform)
  File "/home/bradfernan/VENV/py3_venv/lib64/python3.7/site-packages/napalm/base/__init__.py", line 68, in get_network_driver
    raise ModuleImportError("Please provide a valid driver name.")
napalm.base.exceptions.ModuleImportError: Please provide a valid driver name.

2021-02-05 08:16:39,514 - nornir.core.task -    ERROR -      start() - Host 'nxos2': task 'napalm_get' failed with traceback:
Traceback (most recent call last):
  File "/home/bradfernan/VENV/py3_venv/lib64/python3.7/site-packages/nornir/core/task.py", line 85, in start
    r = self.task(self, **self.params)
  File "/home/bradfernan/VENV/py3_venv/lib64/python3.7/site-packages/nornir/plugins/tasks/networking/napalm_get.py", line 49, in napalm_get
    device = task.host.get_connection("napalm", task.nornir.config)
  File "/home/bradfernan/VENV/py3_venv/lib64/python3.7/site-packages/nornir/core/inventory.py", line 302, in get_connection
    extras=conn.extras,
  File "/home/bradfernan/VENV/py3_venv/lib64/python3.7/site-packages/nornir/core/inventory.py", line 352, in open_connection
    configuration=configuration,
  File "/home/bradfernan/VENV/py3_venv/lib64/python3.7/site-packages/nornir/plugins/connections/napalm.py", line 49, in open
    network_driver = get_network_driver(platform)
  File "/home/bradfernan/VENV/py3_venv/lib64/python3.7/site-packages/napalm/base/__init__.py", line 68, in get_network_driver
    raise ModuleImportError("Please provide a valid driver name.")
napalm.base.exceptions.ModuleImportError: Please provide a valid driver name.

2021-02-05 08:18:06,531 -  nornir.core -     INFO -        run() - Running task 'napalm_get' with args {'getters': ['facts']} on 2 hosts
2021-02-05 08:18:06,532 - nornir.core.task -    ERROR -      start() - Host 'nxos1': task 'napalm_get' failed with traceback:
Traceback (most recent call last):
  File "/home/bradfernan/VENV/py3_venv/lib64/python3.7/site-packages/nornir/core/task.py", line 85, in start
    r = self.task(self, **self.params)
  File "/home/bradfernan/VENV/py3_venv/lib64/python3.7/site-packages/nornir/plugins/tasks/networking/napalm_get.py", line 49, in napalm_get
    device = task.host.get_connection("napalm", task.nornir.config)
  File "/home/bradfernan/VENV/py3_venv/lib64/python3.7/site-packages/nornir/core/inventory.py", line 302, in get_connection
    extras=conn.extras,
  File "/home/bradfernan/VENV/py3_venv/lib64/python3.7/site-packages/nornir/core/inventory.py", line 352, in open_connection
    configuration=configuration,
  File "/home/bradfernan/VENV/py3_venv/lib64/python3.7/site-packages/nornir/plugins/connections/napalm.py", line 49, in open
    network_driver = get_network_driver(platform)
  File "/home/bradfernan/VENV/py3_venv/lib64/python3.7/site-packages/napalm/base/__init__.py", line 68, in get_network_driver
    raise ModuleImportError("Please provide a valid driver name.")
napalm.base.exceptions.ModuleImportError: Please provide a valid driver name.

2021-02-05 08:18:06,533 - nornir.core.task -    ERROR -      start() - Host 'nxos2': task 'napalm_get' failed with traceback:
Traceback (most recent call last):
  File "/home/bradfernan/VENV/py3_venv/lib64/python3.7/site-packages/nornir/core/task.py", line 85, in start
    r = self.task(self, **self.params)
  File "/home/bradfernan/VENV/py3_venv/lib64/python3.7/site-packages/nornir/plugins/tasks/networking/napalm_get.py", line 49, in napalm_get
    device = task.host.get_connection("napalm", task.nornir.config)
  File "/home/bradfernan/VENV/py3_venv/lib64/python3.7/site-packages/nornir/core/inventory.py", line 302, in get_connection
    extras=conn.extras,
  File "/home/bradfernan/VENV/py3_venv/lib64/python3.7/site-packages/nornir/core/inventory.py", line 352, in open_connection
    configuration=configuration,
  File "/home/bradfernan/VENV/py3_venv/lib64/python3.7/site-packages/nornir/plugins/connections/napalm.py", line 49, in open
    network_driver = get_network_driver(platform)
  File "/home/bradfernan/VENV/py3_venv/lib64/python3.7/site-packages/napalm/base/__init__.py", line 68, in get_network_driver
    raise ModuleImportError("Please provide a valid driver name.")
napalm.base.exceptions.ModuleImportError: Please provide a valid driver name.

2021-02-05 08:22:06,081 -  nornir.core -     INFO -        run() - Running task 'napalm_get' with args {'getters': ['facts']} on 2 hosts
2021-02-05 08:22:06,082 - nornir.core.task -    ERROR -      start() - Host 'nxos1': task 'napalm_get' failed with traceback:
Traceback (most recent call last):
  File "/home/bradfernan/VENV/py3_venv/lib64/python3.7/site-packages/nornir/core/task.py", line 85, in start
    r = self.task(self, **self.params)
  File "/home/bradfernan/VENV/py3_venv/lib64/python3.7/site-packages/nornir/plugins/tasks/networking/napalm_get.py", line 49, in napalm_get
    device = task.host.get_connection("napalm", task.nornir.config)
  File "/home/bradfernan/VENV/py3_venv/lib64/python3.7/site-packages/nornir/core/inventory.py", line 302, in get_connection
    extras=conn.extras,
  File "/home/bradfernan/VENV/py3_venv/lib64/python3.7/site-packages/nornir/core/inventory.py", line 352, in open_connection
    configuration=configuration,
  File "/home/bradfernan/VENV/py3_venv/lib64/python3.7/site-packages/nornir/plugins/connections/napalm.py", line 49, in open
    network_driver = get_network_driver(platform)
  File "/home/bradfernan/VENV/py3_venv/lib64/python3.7/site-packages/napalm/base/__init__.py", line 68, in get_network_driver
    raise ModuleImportError("Please provide a valid driver name.")
napalm.base.exceptions.ModuleImportError: Please provide a valid driver name.

2021-02-05 08:22:06,082 - nornir.core.task -    ERROR -      start() - Host 'nxos2': task 'napalm_get' failed with traceback:
Traceback (most recent call last):
  File "/home/bradfernan/VENV/py3_venv/lib64/python3.7/site-packages/nornir/core/task.py", line 85, in start
    r = self.task(self, **self.params)
  File "/home/bradfernan/VENV/py3_venv/lib64/python3.7/site-packages/nornir/plugins/tasks/networking/napalm_get.py", line 49, in napalm_get
    device = task.host.get_connection("napalm", task.nornir.config)
  File "/home/bradfernan/VENV/py3_venv/lib64/python3.7/site-packages/nornir/core/inventory.py", line 302, in get_connection
    extras=conn.extras,
  File "/home/bradfernan/VENV/py3_venv/lib64/python3.7/site-packages/nornir/core/inventory.py", line 352, in open_connection
    configuration=configuration,
  File "/home/bradfernan/VENV/py3_venv/lib64/python3.7/site-packages/nornir/plugins/connections/napalm.py", line 49, in open
    network_driver = get_network_driver(platform)
  File "/home/bradfernan/VENV/py3_venv/lib64/python3.7/site-packages/napalm/base/__init__.py", line 68, in get_network_driver
    raise ModuleImportError("Please provide a valid driver name.")
napalm.base.exceptions.ModuleImportError: Please provide a valid driver name.

2021-02-05 08:30:32,209 -  nornir.core -     INFO -        run() - Running task 'napalm_get' with args {'getters': ['facts']} on 2 hosts
2021-02-05 08:30:32,210 - nornir.core.task -    ERROR -      start() - Host 'nxos1': task 'napalm_get' failed with traceback:
Traceback (most recent call last):
  File "/home/bradfernan/VENV/py3_venv/lib64/python3.7/site-packages/nornir/core/task.py", line 85, in start
    r = self.task(self, **self.params)
  File "/home/bradfernan/VENV/py3_venv/lib64/python3.7/site-packages/nornir/plugins/tasks/networking/napalm_get.py", line 49, in napalm_get
    device = task.host.get_connection("napalm", task.nornir.config)
  File "/home/bradfernan/VENV/py3_venv/lib64/python3.7/site-packages/nornir/core/inventory.py", line 302, in get_connection
    extras=conn.extras,
  File "/home/bradfernan/VENV/py3_venv/lib64/python3.7/site-packages/nornir/core/inventory.py", line 352, in open_connection
    configuration=configuration,
  File "/home/bradfernan/VENV/py3_venv/lib64/python3.7/site-packages/nornir/plugins/connections/napalm.py", line 49, in open
    network_driver = get_network_driver(platform)
  File "/home/bradfernan/VENV/py3_venv/lib64/python3.7/site-packages/napalm/base/__init__.py", line 68, in get_network_driver
    raise ModuleImportError("Please provide a valid driver name.")
napalm.base.exceptions.ModuleImportError: Please provide a valid driver name.

2021-02-05 08:30:32,210 - nornir.core.task -    ERROR -      start() - Host 'nxos2': task 'napalm_get' failed with traceback:
Traceback (most recent call last):
  File "/home/bradfernan/VENV/py3_venv/lib64/python3.7/site-packages/nornir/core/task.py", line 85, in start
    r = self.task(self, **self.params)
  File "/home/bradfernan/VENV/py3_venv/lib64/python3.7/site-packages/nornir/plugins/tasks/networking/napalm_get.py", line 49, in napalm_get
    device = task.host.get_connection("napalm", task.nornir.config)
  File "/home/bradfernan/VENV/py3_venv/lib64/python3.7/site-packages/nornir/core/inventory.py", line 302, in get_connection
    extras=conn.extras,
  File "/home/bradfernan/VENV/py3_venv/lib64/python3.7/site-packages/nornir/core/inventory.py", line 352, in open_connection
    configuration=configuration,
  File "/home/bradfernan/VENV/py3_venv/lib64/python3.7/site-packages/nornir/plugins/connections/napalm.py", line 49, in open
    network_driver = get_network_driver(platform)
  File "/home/bradfernan/VENV/py3_venv/lib64/python3.7/site-packages/napalm/base/__init__.py", line 68, in get_network_driver
    raise ModuleImportError("Please provide a valid driver name.")
napalm.base.exceptions.ModuleImportError: Please provide a valid driver name.

2021-02-05 08:35:12,270 -  nornir.core -     INFO -        run() - Running task 'napalm_get' with args {'getters': ['facts']} on 2 hosts
2021-02-05 08:35:12,271 - nornir.core.task -    ERROR -      start() - Host 'nxos1': task 'napalm_get' failed with traceback:
Traceback (most recent call last):
  File "/home/bradfernan/VENV/py3_venv/lib64/python3.7/site-packages/nornir/core/task.py", line 85, in start
    r = self.task(self, **self.params)
  File "/home/bradfernan/VENV/py3_venv/lib64/python3.7/site-packages/nornir/plugins/tasks/networking/napalm_get.py", line 49, in napalm_get
    device = task.host.get_connection("napalm", task.nornir.config)
  File "/home/bradfernan/VENV/py3_venv/lib64/python3.7/site-packages/nornir/core/inventory.py", line 302, in get_connection
    extras=conn.extras,
  File "/home/bradfernan/VENV/py3_venv/lib64/python3.7/site-packages/nornir/core/inventory.py", line 352, in open_connection
    configuration=configuration,
  File "/home/bradfernan/VENV/py3_venv/lib64/python3.7/site-packages/nornir/plugins/connections/napalm.py", line 49, in open
    network_driver = get_network_driver(platform)
  File "/home/bradfernan/VENV/py3_venv/lib64/python3.7/site-packages/napalm/base/__init__.py", line 68, in get_network_driver
    raise ModuleImportError("Please provide a valid driver name.")
napalm.base.exceptions.ModuleImportError: Please provide a valid driver name.

2021-02-05 08:35:12,271 - nornir.core.task -    ERROR -      start() - Host 'nxos2': task 'napalm_get' failed with traceback:
Traceback (most recent call last):
  File "/home/bradfernan/VENV/py3_venv/lib64/python3.7/site-packages/nornir/core/task.py", line 85, in start
    r = self.task(self, **self.params)
  File "/home/bradfernan/VENV/py3_venv/lib64/python3.7/site-packages/nornir/plugins/tasks/networking/napalm_get.py", line 49, in napalm_get
    device = task.host.get_connection("napalm", task.nornir.config)
  File "/home/bradfernan/VENV/py3_venv/lib64/python3.7/site-packages/nornir/core/inventory.py", line 302, in get_connection
    extras=conn.extras,
  File "/home/bradfernan/VENV/py3_venv/lib64/python3.7/site-packages/nornir/core/inventory.py", line 352, in open_connection
    configuration=configuration,
  File "/home/bradfernan/VENV/py3_venv/lib64/python3.7/site-packages/nornir/plugins/connections/napalm.py", line 49, in open
    network_driver = get_network_driver(platform)
  File "/home/bradfernan/VENV/py3_venv/lib64/python3.7/site-packages/napalm/base/__init__.py", line 68, in get_network_driver
    raise ModuleImportError("Please provide a valid driver name.")
napalm.base.exceptions.ModuleImportError: Please provide a valid driver name.

2021-02-05 08:37:04,591 -  nornir.core -     INFO -        run() - Running task 'napalm_get' with args {'getters': ['facts']} on 2 hosts
2021-02-05 08:37:04,592 - nornir.core.task -    ERROR -      start() - Host 'nxos1': task 'napalm_get' failed with traceback:
Traceback (most recent call last):
  File "/home/bradfernan/VENV/py3_venv/lib64/python3.7/site-packages/nornir/core/task.py", line 85, in start
    r = self.task(self, **self.params)
  File "/home/bradfernan/VENV/py3_venv/lib64/python3.7/site-packages/nornir/plugins/tasks/networking/napalm_get.py", line 49, in napalm_get
    device = task.host.get_connection("napalm", task.nornir.config)
  File "/home/bradfernan/VENV/py3_venv/lib64/python3.7/site-packages/nornir/core/inventory.py", line 302, in get_connection
    extras=conn.extras,
  File "/home/bradfernan/VENV/py3_venv/lib64/python3.7/site-packages/nornir/core/inventory.py", line 352, in open_connection
    configuration=configuration,
  File "/home/bradfernan/VENV/py3_venv/lib64/python3.7/site-packages/nornir/plugins/connections/napalm.py", line 49, in open
    network_driver = get_network_driver(platform)
  File "/home/bradfernan/VENV/py3_venv/lib64/python3.7/site-packages/napalm/base/__init__.py", line 68, in get_network_driver
    raise ModuleImportError("Please provide a valid driver name.")
napalm.base.exceptions.ModuleImportError: Please provide a valid driver name.

2021-02-05 08:37:04,592 - nornir.core.task -    ERROR -      start() - Host 'nxos2': task 'napalm_get' failed with traceback:
Traceback (most recent call last):
  File "/home/bradfernan/VENV/py3_venv/lib64/python3.7/site-packages/nornir/core/task.py", line 85, in start
    r = self.task(self, **self.params)
  File "/home/bradfernan/VENV/py3_venv/lib64/python3.7/site-packages/nornir/plugins/tasks/networking/napalm_get.py", line 49, in napalm_get
    device = task.host.get_connection("napalm", task.nornir.config)
  File "/home/bradfernan/VENV/py3_venv/lib64/python3.7/site-packages/nornir/core/inventory.py", line 302, in get_connection
    extras=conn.extras,
  File "/home/bradfernan/VENV/py3_venv/lib64/python3.7/site-packages/nornir/core/inventory.py", line 352, in open_connection
    configuration=configuration,
  File "/home/bradfernan/VENV/py3_venv/lib64/python3.7/site-packages/nornir/plugins/connections/napalm.py", line 49, in open
    network_driver = get_network_driver(platform)
  File "/home/bradfernan/VENV/py3_venv/lib64/python3.7/site-packages/napalm/base/__init__.py", line 68, in get_network_driver
    raise ModuleImportError("Please provide a valid driver name.")
napalm.base.exceptions.ModuleImportError: Please provide a valid driver name.

2021-02-05 08:38:10,229 -  nornir.core -     INFO -        run() - Running task 'napalm_get' with args {'getters': ['facts']} on 2 hosts
2021-02-05 08:38:10,230 - nornir.core.task -    ERROR -      start() - Host 'nxos1': task 'napalm_get' failed with traceback:
Traceback (most recent call last):
  File "/home/bradfernan/VENV/py3_venv/lib64/python3.7/site-packages/nornir/core/task.py", line 85, in start
    r = self.task(self, **self.params)
  File "/home/bradfernan/VENV/py3_venv/lib64/python3.7/site-packages/nornir/plugins/tasks/networking/napalm_get.py", line 49, in napalm_get
    device = task.host.get_connection("napalm", task.nornir.config)
  File "/home/bradfernan/VENV/py3_venv/lib64/python3.7/site-packages/nornir/core/inventory.py", line 302, in get_connection
    extras=conn.extras,
  File "/home/bradfernan/VENV/py3_venv/lib64/python3.7/site-packages/nornir/core/inventory.py", line 352, in open_connection
    configuration=configuration,
  File "/home/bradfernan/VENV/py3_venv/lib64/python3.7/site-packages/nornir/plugins/connections/napalm.py", line 49, in open
    network_driver = get_network_driver(platform)
  File "/home/bradfernan/VENV/py3_venv/lib64/python3.7/site-packages/napalm/base/__init__.py", line 68, in get_network_driver
    raise ModuleImportError("Please provide a valid driver name.")
napalm.base.exceptions.ModuleImportError: Please provide a valid driver name.

2021-02-05 08:38:10,231 - nornir.core.task -    ERROR -      start() - Host 'nxos2': task 'napalm_get' failed with traceback:
Traceback (most recent call last):
  File "/home/bradfernan/VENV/py3_venv/lib64/python3.7/site-packages/nornir/core/task.py", line 85, in start
    r = self.task(self, **self.params)
  File "/home/bradfernan/VENV/py3_venv/lib64/python3.7/site-packages/nornir/plugins/tasks/networking/napalm_get.py", line 49, in napalm_get
    device = task.host.get_connection("napalm", task.nornir.config)
  File "/home/bradfernan/VENV/py3_venv/lib64/python3.7/site-packages/nornir/core/inventory.py", line 302, in get_connection
    extras=conn.extras,
  File "/home/bradfernan/VENV/py3_venv/lib64/python3.7/site-packages/nornir/core/inventory.py", line 352, in open_connection
    configuration=configuration,
  File "/home/bradfernan/VENV/py3_venv/lib64/python3.7/site-packages/nornir/plugins/connections/napalm.py", line 49, in open
    network_driver = get_network_driver(platform)
  File "/home/bradfernan/VENV/py3_venv/lib64/python3.7/site-packages/napalm/base/__init__.py", line 68, in get_network_driver
    raise ModuleImportError("Please provide a valid driver name.")
napalm.base.exceptions.ModuleImportError: Please provide a valid driver name.

2021-02-05 08:38:45,949 -  nornir.core -     INFO -        run() - Running task 'napalm_get' with args {'getters': ['config']} on 2 hosts
2021-02-05 08:38:45,951 - nornir.core.task -    ERROR -      start() - Host 'nxos1': task 'napalm_get' failed with traceback:
Traceback (most recent call last):
  File "/home/bradfernan/VENV/py3_venv/lib64/python3.7/site-packages/nornir/core/task.py", line 85, in start
    r = self.task(self, **self.params)
  File "/home/bradfernan/VENV/py3_venv/lib64/python3.7/site-packages/nornir/plugins/tasks/networking/napalm_get.py", line 49, in napalm_get
    device = task.host.get_connection("napalm", task.nornir.config)
  File "/home/bradfernan/VENV/py3_venv/lib64/python3.7/site-packages/nornir/core/inventory.py", line 302, in get_connection
    extras=conn.extras,
  File "/home/bradfernan/VENV/py3_venv/lib64/python3.7/site-packages/nornir/core/inventory.py", line 352, in open_connection
    configuration=configuration,
  File "/home/bradfernan/VENV/py3_venv/lib64/python3.7/site-packages/nornir/plugins/connections/napalm.py", line 49, in open
    network_driver = get_network_driver(platform)
  File "/home/bradfernan/VENV/py3_venv/lib64/python3.7/site-packages/napalm/base/__init__.py", line 68, in get_network_driver
    raise ModuleImportError("Please provide a valid driver name.")
napalm.base.exceptions.ModuleImportError: Please provide a valid driver name.

2021-02-05 08:38:45,951 - nornir.core.task -    ERROR -      start() - Host 'nxos2': task 'napalm_get' failed with traceback:
Traceback (most recent call last):
  File "/home/bradfernan/VENV/py3_venv/lib64/python3.7/site-packages/nornir/core/task.py", line 85, in start
    r = self.task(self, **self.params)
  File "/home/bradfernan/VENV/py3_venv/lib64/python3.7/site-packages/nornir/plugins/tasks/networking/napalm_get.py", line 49, in napalm_get
    device = task.host.get_connection("napalm", task.nornir.config)
  File "/home/bradfernan/VENV/py3_venv/lib64/python3.7/site-packages/nornir/core/inventory.py", line 302, in get_connection
    extras=conn.extras,
  File "/home/bradfernan/VENV/py3_venv/lib64/python3.7/site-packages/nornir/core/inventory.py", line 352, in open_connection
    configuration=configuration,
  File "/home/bradfernan/VENV/py3_venv/lib64/python3.7/site-packages/nornir/plugins/connections/napalm.py", line 49, in open
    network_driver = get_network_driver(platform)
  File "/home/bradfernan/VENV/py3_venv/lib64/python3.7/site-packages/napalm/base/__init__.py", line 68, in get_network_driver
    raise ModuleImportError("Please provide a valid driver name.")
napalm.base.exceptions.ModuleImportError: Please provide a valid driver name.

2021-02-05 21:07:56,694 -  nornir.core -     INFO -        run() - Running task 'napalm_get' with args {'getters': ['facts']} on 2 hosts
2021-02-05 21:07:56,695 - nornir.core.task -    ERROR -      start() - Host 'nxos1': task 'napalm_get' failed with traceback:
Traceback (most recent call last):
  File "/home/bradfernan/VENV/py3_venv/lib64/python3.7/site-packages/nornir/core/task.py", line 85, in start
    r = self.task(self, **self.params)
  File "/home/bradfernan/VENV/py3_venv/lib64/python3.7/site-packages/nornir/plugins/tasks/networking/napalm_get.py", line 49, in napalm_get
    device = task.host.get_connection("napalm", task.nornir.config)
  File "/home/bradfernan/VENV/py3_venv/lib64/python3.7/site-packages/nornir/core/inventory.py", line 302, in get_connection
    extras=conn.extras,
  File "/home/bradfernan/VENV/py3_venv/lib64/python3.7/site-packages/nornir/core/inventory.py", line 352, in open_connection
    configuration=configuration,
  File "/home/bradfernan/VENV/py3_venv/lib64/python3.7/site-packages/nornir/plugins/connections/napalm.py", line 49, in open
    network_driver = get_network_driver(platform)
  File "/home/bradfernan/VENV/py3_venv/lib64/python3.7/site-packages/napalm/base/__init__.py", line 68, in get_network_driver
    raise ModuleImportError("Please provide a valid driver name.")
napalm.base.exceptions.ModuleImportError: Please provide a valid driver name.

2021-02-05 21:07:56,696 - nornir.core.task -    ERROR -      start() - Host 'nxos2': task 'napalm_get' failed with traceback:
Traceback (most recent call last):
  File "/home/bradfernan/VENV/py3_venv/lib64/python3.7/site-packages/nornir/core/task.py", line 85, in start
    r = self.task(self, **self.params)
  File "/home/bradfernan/VENV/py3_venv/lib64/python3.7/site-packages/nornir/plugins/tasks/networking/napalm_get.py", line 49, in napalm_get
    device = task.host.get_connection("napalm", task.nornir.config)
  File "/home/bradfernan/VENV/py3_venv/lib64/python3.7/site-packages/nornir/core/inventory.py", line 302, in get_connection
    extras=conn.extras,
  File "/home/bradfernan/VENV/py3_venv/lib64/python3.7/site-packages/nornir/core/inventory.py", line 352, in open_connection
    configuration=configuration,
  File "/home/bradfernan/VENV/py3_venv/lib64/python3.7/site-packages/nornir/plugins/connections/napalm.py", line 49, in open
    network_driver = get_network_driver(platform)
  File "/home/bradfernan/VENV/py3_venv/lib64/python3.7/site-packages/napalm/base/__init__.py", line 68, in get_network_driver
    raise ModuleImportError("Please provide a valid driver name.")
napalm.base.exceptions.ModuleImportError: Please provide a valid driver name.

2021-02-05 21:12:00,056 -  nornir.core -     INFO -        run() - Running task 'napalm_get' with args {'getters': ['facts']} on 2 hosts
2021-02-05 21:12:00,057 - nornir.core.task -    ERROR -      start() - Host 'nxos1': task 'napalm_get' failed with traceback:
Traceback (most recent call last):
  File "/home/bradfernan/VENV/py3_venv/lib64/python3.7/site-packages/nornir/core/task.py", line 85, in start
    r = self.task(self, **self.params)
  File "/home/bradfernan/VENV/py3_venv/lib64/python3.7/site-packages/nornir/plugins/tasks/networking/napalm_get.py", line 49, in napalm_get
    device = task.host.get_connection("napalm", task.nornir.config)
  File "/home/bradfernan/VENV/py3_venv/lib64/python3.7/site-packages/nornir/core/inventory.py", line 302, in get_connection
    extras=conn.extras,
  File "/home/bradfernan/VENV/py3_venv/lib64/python3.7/site-packages/nornir/core/inventory.py", line 352, in open_connection
    configuration=configuration,
  File "/home/bradfernan/VENV/py3_venv/lib64/python3.7/site-packages/nornir/plugins/connections/napalm.py", line 49, in open
    network_driver = get_network_driver(platform)
  File "/home/bradfernan/VENV/py3_venv/lib64/python3.7/site-packages/napalm/base/__init__.py", line 68, in get_network_driver
    raise ModuleImportError("Please provide a valid driver name.")
napalm.base.exceptions.ModuleImportError: Please provide a valid driver name.

2021-02-05 21:12:00,057 - nornir.core.task -    ERROR -      start() - Host 'nxos2': task 'napalm_get' failed with traceback:
Traceback (most recent call last):
  File "/home/bradfernan/VENV/py3_venv/lib64/python3.7/site-packages/nornir/core/task.py", line 85, in start
    r = self.task(self, **self.params)
  File "/home/bradfernan/VENV/py3_venv/lib64/python3.7/site-packages/nornir/plugins/tasks/networking/napalm_get.py", line 49, in napalm_get
    device = task.host.get_connection("napalm", task.nornir.config)
  File "/home/bradfernan/VENV/py3_venv/lib64/python3.7/site-packages/nornir/core/inventory.py", line 302, in get_connection
    extras=conn.extras,
  File "/home/bradfernan/VENV/py3_venv/lib64/python3.7/site-packages/nornir/core/inventory.py", line 352, in open_connection
    configuration=configuration,
  File "/home/bradfernan/VENV/py3_venv/lib64/python3.7/site-packages/nornir/plugins/connections/napalm.py", line 49, in open
    network_driver = get_network_driver(platform)
  File "/home/bradfernan/VENV/py3_venv/lib64/python3.7/site-packages/napalm/base/__init__.py", line 68, in get_network_driver
    raise ModuleImportError("Please provide a valid driver name.")
napalm.base.exceptions.ModuleImportError: Please provide a valid driver name.

2021-02-05 21:19:04,301 -  nornir.core -     INFO -        run() - Running task 'napalm_get' with args {'getters': ['facts']} on 2 hosts
2021-02-05 21:19:04,302 - nornir.core.task -    ERROR -      start() - Host 'nxos1': task 'napalm_get' failed with traceback:
Traceback (most recent call last):
  File "/home/bradfernan/VENV/py3_venv/lib64/python3.7/site-packages/nornir/core/task.py", line 85, in start
    r = self.task(self, **self.params)
  File "/home/bradfernan/VENV/py3_venv/lib64/python3.7/site-packages/nornir/plugins/tasks/networking/napalm_get.py", line 49, in napalm_get
    device = task.host.get_connection("napalm", task.nornir.config)
  File "/home/bradfernan/VENV/py3_venv/lib64/python3.7/site-packages/nornir/core/inventory.py", line 302, in get_connection
    extras=conn.extras,
  File "/home/bradfernan/VENV/py3_venv/lib64/python3.7/site-packages/nornir/core/inventory.py", line 352, in open_connection
    configuration=configuration,
  File "/home/bradfernan/VENV/py3_venv/lib64/python3.7/site-packages/nornir/plugins/connections/napalm.py", line 49, in open
    network_driver = get_network_driver(platform)
  File "/home/bradfernan/VENV/py3_venv/lib64/python3.7/site-packages/napalm/base/__init__.py", line 68, in get_network_driver
    raise ModuleImportError("Please provide a valid driver name.")
napalm.base.exceptions.ModuleImportError: Please provide a valid driver name.

2021-02-05 21:19:04,302 - nornir.core.task -    ERROR -      start() - Host 'nxos2': task 'napalm_get' failed with traceback:
Traceback (most recent call last):
  File "/home/bradfernan/VENV/py3_venv/lib64/python3.7/site-packages/nornir/core/task.py", line 85, in start
    r = self.task(self, **self.params)
  File "/home/bradfernan/VENV/py3_venv/lib64/python3.7/site-packages/nornir/plugins/tasks/networking/napalm_get.py", line 49, in napalm_get
    device = task.host.get_connection("napalm", task.nornir.config)
  File "/home/bradfernan/VENV/py3_venv/lib64/python3.7/site-packages/nornir/core/inventory.py", line 302, in get_connection
    extras=conn.extras,
  File "/home/bradfernan/VENV/py3_venv/lib64/python3.7/site-packages/nornir/core/inventory.py", line 352, in open_connection
    configuration=configuration,
  File "/home/bradfernan/VENV/py3_venv/lib64/python3.7/site-packages/nornir/plugins/connections/napalm.py", line 49, in open
    network_driver = get_network_driver(platform)
  File "/home/bradfernan/VENV/py3_venv/lib64/python3.7/site-packages/napalm/base/__init__.py", line 68, in get_network_driver
    raise ModuleImportError("Please provide a valid driver name.")
napalm.base.exceptions.ModuleImportError: Please provide a valid driver name.

2021-02-05 21:24:40,940 -  nornir.core -     INFO -        run() - Running task 'napalm_get' with args {'getters': ['facts']} on 2 hosts
2021-02-05 21:24:40,941 - nornir.core.task -    ERROR -      start() - Host 'nxos1': task 'napalm_get' failed with traceback:
Traceback (most recent call last):
  File "/home/bradfernan/VENV/py3_venv/lib64/python3.7/site-packages/nornir/core/task.py", line 85, in start
    r = self.task(self, **self.params)
  File "/home/bradfernan/VENV/py3_venv/lib64/python3.7/site-packages/nornir/plugins/tasks/networking/napalm_get.py", line 49, in napalm_get
    device = task.host.get_connection("napalm", task.nornir.config)
  File "/home/bradfernan/VENV/py3_venv/lib64/python3.7/site-packages/nornir/core/inventory.py", line 302, in get_connection
    extras=conn.extras,
  File "/home/bradfernan/VENV/py3_venv/lib64/python3.7/site-packages/nornir/core/inventory.py", line 352, in open_connection
    configuration=configuration,
  File "/home/bradfernan/VENV/py3_venv/lib64/python3.7/site-packages/nornir/plugins/connections/napalm.py", line 49, in open
    network_driver = get_network_driver(platform)
  File "/home/bradfernan/VENV/py3_venv/lib64/python3.7/site-packages/napalm/base/__init__.py", line 68, in get_network_driver
    raise ModuleImportError("Please provide a valid driver name.")
napalm.base.exceptions.ModuleImportError: Please provide a valid driver name.

2021-02-05 21:24:40,941 - nornir.core.task -    ERROR -      start() - Host 'nxos2': task 'napalm_get' failed with traceback:
Traceback (most recent call last):
  File "/home/bradfernan/VENV/py3_venv/lib64/python3.7/site-packages/nornir/core/task.py", line 85, in start
    r = self.task(self, **self.params)
  File "/home/bradfernan/VENV/py3_venv/lib64/python3.7/site-packages/nornir/plugins/tasks/networking/napalm_get.py", line 49, in napalm_get
    device = task.host.get_connection("napalm", task.nornir.config)
  File "/home/bradfernan/VENV/py3_venv/lib64/python3.7/site-packages/nornir/core/inventory.py", line 302, in get_connection
    extras=conn.extras,
  File "/home/bradfernan/VENV/py3_venv/lib64/python3.7/site-packages/nornir/core/inventory.py", line 352, in open_connection
    configuration=configuration,
  File "/home/bradfernan/VENV/py3_venv/lib64/python3.7/site-packages/nornir/plugins/connections/napalm.py", line 49, in open
    network_driver = get_network_driver(platform)
  File "/home/bradfernan/VENV/py3_venv/lib64/python3.7/site-packages/napalm/base/__init__.py", line 68, in get_network_driver
    raise ModuleImportError("Please provide a valid driver name.")
napalm.base.exceptions.ModuleImportError: Please provide a valid driver name.

2021-02-05 21:25:10,290 -  nornir.core -     INFO -        run() - Running task 'napalm_get' with args {'getters': ['facts']} on 2 hosts
2021-02-05 21:25:10,292 - nornir.core.task -    ERROR -      start() - Host 'nxos1': task 'napalm_get' failed with traceback:
Traceback (most recent call last):
  File "/home/bradfernan/VENV/py3_venv/lib64/python3.7/site-packages/nornir/core/task.py", line 85, in start
    r = self.task(self, **self.params)
  File "/home/bradfernan/VENV/py3_venv/lib64/python3.7/site-packages/nornir/plugins/tasks/networking/napalm_get.py", line 49, in napalm_get
    device = task.host.get_connection("napalm", task.nornir.config)
  File "/home/bradfernan/VENV/py3_venv/lib64/python3.7/site-packages/nornir/core/inventory.py", line 302, in get_connection
    extras=conn.extras,
  File "/home/bradfernan/VENV/py3_venv/lib64/python3.7/site-packages/nornir/core/inventory.py", line 352, in open_connection
    configuration=configuration,
  File "/home/bradfernan/VENV/py3_venv/lib64/python3.7/site-packages/nornir/plugins/connections/napalm.py", line 49, in open
    network_driver = get_network_driver(platform)
  File "/home/bradfernan/VENV/py3_venv/lib64/python3.7/site-packages/napalm/base/__init__.py", line 68, in get_network_driver
    raise ModuleImportError("Please provide a valid driver name.")
napalm.base.exceptions.ModuleImportError: Please provide a valid driver name.

2021-02-05 21:25:10,292 - nornir.core.task -    ERROR -      start() - Host 'nxos2': task 'napalm_get' failed with traceback:
Traceback (most recent call last):
  File "/home/bradfernan/VENV/py3_venv/lib64/python3.7/site-packages/nornir/core/task.py", line 85, in start
    r = self.task(self, **self.params)
  File "/home/bradfernan/VENV/py3_venv/lib64/python3.7/site-packages/nornir/plugins/tasks/networking/napalm_get.py", line 49, in napalm_get
    device = task.host.get_connection("napalm", task.nornir.config)
  File "/home/bradfernan/VENV/py3_venv/lib64/python3.7/site-packages/nornir/core/inventory.py", line 302, in get_connection
    extras=conn.extras,
  File "/home/bradfernan/VENV/py3_venv/lib64/python3.7/site-packages/nornir/core/inventory.py", line 352, in open_connection
    configuration=configuration,
  File "/home/bradfernan/VENV/py3_venv/lib64/python3.7/site-packages/nornir/plugins/connections/napalm.py", line 49, in open
    network_driver = get_network_driver(platform)
  File "/home/bradfernan/VENV/py3_venv/lib64/python3.7/site-packages/napalm/base/__init__.py", line 68, in get_network_driver
    raise ModuleImportError("Please provide a valid driver name.")
napalm.base.exceptions.ModuleImportError: Please provide a valid driver name.

2021-02-05 21:26:41,175 -  nornir.core -     INFO -        run() - Running task 'napalm_get' with args {'getters': ['facts']} on 2 hosts
2021-02-05 21:26:41,176 - nornir.core.task -    ERROR -      start() - Host 'nxos1': task 'napalm_get' failed with traceback:
Traceback (most recent call last):
  File "/home/bradfernan/VENV/py3_venv/lib64/python3.7/site-packages/nornir/core/task.py", line 85, in start
    r = self.task(self, **self.params)
  File "/home/bradfernan/VENV/py3_venv/lib64/python3.7/site-packages/nornir/plugins/tasks/networking/napalm_get.py", line 49, in napalm_get
    device = task.host.get_connection("napalm", task.nornir.config)
  File "/home/bradfernan/VENV/py3_venv/lib64/python3.7/site-packages/nornir/core/inventory.py", line 302, in get_connection
    extras=conn.extras,
  File "/home/bradfernan/VENV/py3_venv/lib64/python3.7/site-packages/nornir/core/inventory.py", line 352, in open_connection
    configuration=configuration,
  File "/home/bradfernan/VENV/py3_venv/lib64/python3.7/site-packages/nornir/plugins/connections/napalm.py", line 49, in open
    network_driver = get_network_driver(platform)
  File "/home/bradfernan/VENV/py3_venv/lib64/python3.7/site-packages/napalm/base/__init__.py", line 68, in get_network_driver
    raise ModuleImportError("Please provide a valid driver name.")
napalm.base.exceptions.ModuleImportError: Please provide a valid driver name.

2021-02-05 21:26:41,176 - nornir.core.task -    ERROR -      start() - Host 'nxos2': task 'napalm_get' failed with traceback:
Traceback (most recent call last):
  File "/home/bradfernan/VENV/py3_venv/lib64/python3.7/site-packages/nornir/core/task.py", line 85, in start
    r = self.task(self, **self.params)
  File "/home/bradfernan/VENV/py3_venv/lib64/python3.7/site-packages/nornir/plugins/tasks/networking/napalm_get.py", line 49, in napalm_get
    device = task.host.get_connection("napalm", task.nornir.config)
  File "/home/bradfernan/VENV/py3_venv/lib64/python3.7/site-packages/nornir/core/inventory.py", line 302, in get_connection
    extras=conn.extras,
  File "/home/bradfernan/VENV/py3_venv/lib64/python3.7/site-packages/nornir/core/inventory.py", line 352, in open_connection
    configuration=configuration,
  File "/home/bradfernan/VENV/py3_venv/lib64/python3.7/site-packages/nornir/plugins/connections/napalm.py", line 49, in open
    network_driver = get_network_driver(platform)
  File "/home/bradfernan/VENV/py3_venv/lib64/python3.7/site-packages/napalm/base/__init__.py", line 68, in get_network_driver
    raise ModuleImportError("Please provide a valid driver name.")
napalm.base.exceptions.ModuleImportError: Please provide a valid driver name.

2021-02-05 21:26:56,790 -  nornir.core -     INFO -        run() - Running task 'napalm_get' with args {'getters': ['facts']} on 2 hosts
2021-02-05 21:26:56,792 - nornir.core.task -    ERROR -      start() - Host 'nxos1': task 'napalm_get' failed with traceback:
Traceback (most recent call last):
  File "/home/bradfernan/VENV/py3_venv/lib64/python3.7/site-packages/nornir/core/task.py", line 85, in start
    r = self.task(self, **self.params)
  File "/home/bradfernan/VENV/py3_venv/lib64/python3.7/site-packages/nornir/plugins/tasks/networking/napalm_get.py", line 49, in napalm_get
    device = task.host.get_connection("napalm", task.nornir.config)
  File "/home/bradfernan/VENV/py3_venv/lib64/python3.7/site-packages/nornir/core/inventory.py", line 302, in get_connection
    extras=conn.extras,
  File "/home/bradfernan/VENV/py3_venv/lib64/python3.7/site-packages/nornir/core/inventory.py", line 352, in open_connection
    configuration=configuration,
  File "/home/bradfernan/VENV/py3_venv/lib64/python3.7/site-packages/nornir/plugins/connections/napalm.py", line 49, in open
    network_driver = get_network_driver(platform)
  File "/home/bradfernan/VENV/py3_venv/lib64/python3.7/site-packages/napalm/base/__init__.py", line 68, in get_network_driver
    raise ModuleImportError("Please provide a valid driver name.")
napalm.base.exceptions.ModuleImportError: Please provide a valid driver name.

2021-02-05 21:26:56,792 - nornir.core.task -    ERROR -      start() - Host 'nxos2': task 'napalm_get' failed with traceback:
Traceback (most recent call last):
  File "/home/bradfernan/VENV/py3_venv/lib64/python3.7/site-packages/nornir/core/task.py", line 85, in start
    r = self.task(self, **self.params)
  File "/home/bradfernan/VENV/py3_venv/lib64/python3.7/site-packages/nornir/plugins/tasks/networking/napalm_get.py", line 49, in napalm_get
    device = task.host.get_connection("napalm", task.nornir.config)
  File "/home/bradfernan/VENV/py3_venv/lib64/python3.7/site-packages/nornir/core/inventory.py", line 302, in get_connection
    extras=conn.extras,
  File "/home/bradfernan/VENV/py3_venv/lib64/python3.7/site-packages/nornir/core/inventory.py", line 352, in open_connection
    configuration=configuration,
  File "/home/bradfernan/VENV/py3_venv/lib64/python3.7/site-packages/nornir/plugins/connections/napalm.py", line 49, in open
    network_driver = get_network_driver(platform)
  File "/home/bradfernan/VENV/py3_venv/lib64/python3.7/site-packages/napalm/base/__init__.py", line 68, in get_network_driver
    raise ModuleImportError("Please provide a valid driver name.")
napalm.base.exceptions.ModuleImportError: Please provide a valid driver name.

2021-02-05 21:33:30,915 -  nornir.core -     INFO -        run() - Running task 'napalm_get' with args {'getters': ['facts']} on 2 hosts
2021-02-05 21:33:30,917 - nornir.core.task -    ERROR -      start() - Host 'nxos1': task 'napalm_get' failed with traceback:
Traceback (most recent call last):
  File "/home/bradfernan/VENV/py3_venv/lib64/python3.7/site-packages/nornir/core/task.py", line 85, in start
    r = self.task(self, **self.params)
  File "/home/bradfernan/VENV/py3_venv/lib64/python3.7/site-packages/nornir/plugins/tasks/networking/napalm_get.py", line 49, in napalm_get
    device = task.host.get_connection("napalm", task.nornir.config)
  File "/home/bradfernan/VENV/py3_venv/lib64/python3.7/site-packages/nornir/core/inventory.py", line 302, in get_connection
    extras=conn.extras,
  File "/home/bradfernan/VENV/py3_venv/lib64/python3.7/site-packages/nornir/core/inventory.py", line 352, in open_connection
    configuration=configuration,
  File "/home/bradfernan/VENV/py3_venv/lib64/python3.7/site-packages/nornir/plugins/connections/napalm.py", line 49, in open
    network_driver = get_network_driver(platform)
  File "/home/bradfernan/VENV/py3_venv/lib64/python3.7/site-packages/napalm/base/__init__.py", line 68, in get_network_driver
    raise ModuleImportError("Please provide a valid driver name.")
napalm.base.exceptions.ModuleImportError: Please provide a valid driver name.

2021-02-05 21:33:30,917 - nornir.core.task -    ERROR -      start() - Host 'nxos2': task 'napalm_get' failed with traceback:
Traceback (most recent call last):
  File "/home/bradfernan/VENV/py3_venv/lib64/python3.7/site-packages/nornir/core/task.py", line 85, in start
    r = self.task(self, **self.params)
  File "/home/bradfernan/VENV/py3_venv/lib64/python3.7/site-packages/nornir/plugins/tasks/networking/napalm_get.py", line 49, in napalm_get
    device = task.host.get_connection("napalm", task.nornir.config)
  File "/home/bradfernan/VENV/py3_venv/lib64/python3.7/site-packages/nornir/core/inventory.py", line 302, in get_connection
    extras=conn.extras,
  File "/home/bradfernan/VENV/py3_venv/lib64/python3.7/site-packages/nornir/core/inventory.py", line 352, in open_connection
    configuration=configuration,
  File "/home/bradfernan/VENV/py3_venv/lib64/python3.7/site-packages/nornir/plugins/connections/napalm.py", line 49, in open
    network_driver = get_network_driver(platform)
  File "/home/bradfernan/VENV/py3_venv/lib64/python3.7/site-packages/napalm/base/__init__.py", line 68, in get_network_driver
    raise ModuleImportError("Please provide a valid driver name.")
napalm.base.exceptions.ModuleImportError: Please provide a valid driver name.

2021-02-05 21:36:37,091 -  nornir.core -     INFO -        run() - Running task 'napalm_get' with args {'getters': ['facts']} on 2 hosts
2021-02-05 21:36:37,092 - nornir.core.task -    ERROR -      start() - Host 'nxos1': task 'napalm_get' failed with traceback:
Traceback (most recent call last):
  File "/home/bradfernan/VENV/py3_venv/lib64/python3.7/site-packages/nornir/core/task.py", line 85, in start
    r = self.task(self, **self.params)
  File "/home/bradfernan/VENV/py3_venv/lib64/python3.7/site-packages/nornir/plugins/tasks/networking/napalm_get.py", line 49, in napalm_get
    device = task.host.get_connection("napalm", task.nornir.config)
  File "/home/bradfernan/VENV/py3_venv/lib64/python3.7/site-packages/nornir/core/inventory.py", line 302, in get_connection
    extras=conn.extras,
  File "/home/bradfernan/VENV/py3_venv/lib64/python3.7/site-packages/nornir/core/inventory.py", line 352, in open_connection
    configuration=configuration,
  File "/home/bradfernan/VENV/py3_venv/lib64/python3.7/site-packages/nornir/plugins/connections/napalm.py", line 49, in open
    network_driver = get_network_driver(platform)
  File "/home/bradfernan/VENV/py3_venv/lib64/python3.7/site-packages/napalm/base/__init__.py", line 68, in get_network_driver
    raise ModuleImportError("Please provide a valid driver name.")
napalm.base.exceptions.ModuleImportError: Please provide a valid driver name.

2021-02-05 21:36:37,093 - nornir.core.task -    ERROR -      start() - Host 'nxos2': task 'napalm_get' failed with traceback:
Traceback (most recent call last):
  File "/home/bradfernan/VENV/py3_venv/lib64/python3.7/site-packages/nornir/core/task.py", line 85, in start
    r = self.task(self, **self.params)
  File "/home/bradfernan/VENV/py3_venv/lib64/python3.7/site-packages/nornir/plugins/tasks/networking/napalm_get.py", line 49, in napalm_get
    device = task.host.get_connection("napalm", task.nornir.config)
  File "/home/bradfernan/VENV/py3_venv/lib64/python3.7/site-packages/nornir/core/inventory.py", line 302, in get_connection
    extras=conn.extras,
  File "/home/bradfernan/VENV/py3_venv/lib64/python3.7/site-packages/nornir/core/inventory.py", line 352, in open_connection
    configuration=configuration,
  File "/home/bradfernan/VENV/py3_venv/lib64/python3.7/site-packages/nornir/plugins/connections/napalm.py", line 49, in open
    network_driver = get_network_driver(platform)
  File "/home/bradfernan/VENV/py3_venv/lib64/python3.7/site-packages/napalm/base/__init__.py", line 68, in get_network_driver
    raise ModuleImportError("Please provide a valid driver name.")
napalm.base.exceptions.ModuleImportError: Please provide a valid driver name.

2021-02-05 21:41:18,014 -  nornir.core -     INFO -        run() - Running task 'napalm_get' with args {'getters': ['facts']} on 2 hosts
2021-02-05 21:41:20,428 - nornir.core.task -    ERROR -      start() - Host 'nxos2': task 'napalm_get' failed with traceback:
Traceback (most recent call last):
  File "/home/bradfernan/VENV/py3_venv/lib64/python3.7/site-packages/napalm/nxos/nxos.py", line 698, in open
    self._send_command("show hostname")
  File "/home/bradfernan/VENV/py3_venv/lib64/python3.7/site-packages/napalm/nxos/nxos.py", line 712, in _send_command
    return self.device.show(command, raw_text=raw_text)
  File "/home/bradfernan/VENV/py3_venv/lib64/python3.7/site-packages/napalm/nxapi_plumbing/device.py", line 67, in show
    result = self.show_list(commands, raw_text)
  File "/home/bradfernan/VENV/py3_venv/lib64/python3.7/site-packages/napalm/nxapi_plumbing/device.py", line 95, in show_list
    return self.api._nxapi_command(commands, method=cmd_method)
  File "/home/bradfernan/VENV/py3_venv/lib64/python3.7/site-packages/napalm/nxapi_plumbing/api_client.py", line 110, in _nxapi_command
    response = self._send_request(commands, method=method)
  File "/home/bradfernan/VENV/py3_venv/lib64/python3.7/site-packages/napalm/nxapi_plumbing/api_client.py", line 79, in _send_request
    raise NXAPIAuthError(msg)
napalm.nxapi_plumbing.errors.NXAPIAuthError: Authentication to NX-API failed please verify your username, password, and hostname.

During handling of the above exception, another exception occurred:

Traceback (most recent call last):
  File "/home/bradfernan/VENV/py3_venv/lib64/python3.7/site-packages/nornir/core/task.py", line 85, in start
    r = self.task(self, **self.params)
  File "/home/bradfernan/VENV/py3_venv/lib64/python3.7/site-packages/nornir/plugins/tasks/networking/napalm_get.py", line 49, in napalm_get
    device = task.host.get_connection("napalm", task.nornir.config)
  File "/home/bradfernan/VENV/py3_venv/lib64/python3.7/site-packages/nornir/core/inventory.py", line 302, in get_connection
    extras=conn.extras,
  File "/home/bradfernan/VENV/py3_venv/lib64/python3.7/site-packages/nornir/core/inventory.py", line 352, in open_connection
    configuration=configuration,
  File "/home/bradfernan/VENV/py3_venv/lib64/python3.7/site-packages/nornir/plugins/connections/napalm.py", line 51, in open
    connection.open()
  File "/home/bradfernan/VENV/py3_venv/lib64/python3.7/site-packages/napalm/nxos/nxos.py", line 701, in open
    raise ConnectionException("Cannot connect to {}".format(self.hostname))
napalm.base.exceptions.ConnectionException: Cannot connect to nxos2.lasthop.io

2021-02-05 21:41:20,441 - nornir.core.task -    ERROR -      start() - Host 'nxos1': task 'napalm_get' failed with traceback:
Traceback (most recent call last):
  File "/home/bradfernan/VENV/py3_venv/lib64/python3.7/site-packages/napalm/nxos/nxos.py", line 698, in open
    self._send_command("show hostname")
  File "/home/bradfernan/VENV/py3_venv/lib64/python3.7/site-packages/napalm/nxos/nxos.py", line 712, in _send_command
    return self.device.show(command, raw_text=raw_text)
  File "/home/bradfernan/VENV/py3_venv/lib64/python3.7/site-packages/napalm/nxapi_plumbing/device.py", line 67, in show
    result = self.show_list(commands, raw_text)
  File "/home/bradfernan/VENV/py3_venv/lib64/python3.7/site-packages/napalm/nxapi_plumbing/device.py", line 95, in show_list
    return self.api._nxapi_command(commands, method=cmd_method)
  File "/home/bradfernan/VENV/py3_venv/lib64/python3.7/site-packages/napalm/nxapi_plumbing/api_client.py", line 110, in _nxapi_command
    response = self._send_request(commands, method=method)
  File "/home/bradfernan/VENV/py3_venv/lib64/python3.7/site-packages/napalm/nxapi_plumbing/api_client.py", line 79, in _send_request
    raise NXAPIAuthError(msg)
napalm.nxapi_plumbing.errors.NXAPIAuthError: Authentication to NX-API failed please verify your username, password, and hostname.

During handling of the above exception, another exception occurred:

Traceback (most recent call last):
  File "/home/bradfernan/VENV/py3_venv/lib64/python3.7/site-packages/nornir/core/task.py", line 85, in start
    r = self.task(self, **self.params)
  File "/home/bradfernan/VENV/py3_venv/lib64/python3.7/site-packages/nornir/plugins/tasks/networking/napalm_get.py", line 49, in napalm_get
    device = task.host.get_connection("napalm", task.nornir.config)
  File "/home/bradfernan/VENV/py3_venv/lib64/python3.7/site-packages/nornir/core/inventory.py", line 302, in get_connection
    extras=conn.extras,
  File "/home/bradfernan/VENV/py3_venv/lib64/python3.7/site-packages/nornir/core/inventory.py", line 352, in open_connection
    configuration=configuration,
  File "/home/bradfernan/VENV/py3_venv/lib64/python3.7/site-packages/nornir/plugins/connections/napalm.py", line 51, in open
    connection.open()
  File "/home/bradfernan/VENV/py3_venv/lib64/python3.7/site-packages/napalm/nxos/nxos.py", line 701, in open
    raise ConnectionException("Cannot connect to {}".format(self.hostname))
napalm.base.exceptions.ConnectionException: Cannot connect to nxos1.lasthop.io

2021-02-05 21:42:07,358 -  nornir.core -     INFO -        run() - Running task 'napalm_get' with args {'getters': ['facts']} on 2 hosts
2021-02-05 21:42:10,086 - nornir.core.task -    ERROR -      start() - Host 'nxos1': task 'napalm_get' failed with traceback:
Traceback (most recent call last):
  File "/home/bradfernan/VENV/py3_venv/lib64/python3.7/site-packages/napalm/nxos/nxos.py", line 698, in open
    self._send_command("show hostname")
  File "/home/bradfernan/VENV/py3_venv/lib64/python3.7/site-packages/napalm/nxos/nxos.py", line 712, in _send_command
    return self.device.show(command, raw_text=raw_text)
  File "/home/bradfernan/VENV/py3_venv/lib64/python3.7/site-packages/napalm/nxapi_plumbing/device.py", line 67, in show
    result = self.show_list(commands, raw_text)
  File "/home/bradfernan/VENV/py3_venv/lib64/python3.7/site-packages/napalm/nxapi_plumbing/device.py", line 95, in show_list
    return self.api._nxapi_command(commands, method=cmd_method)
  File "/home/bradfernan/VENV/py3_venv/lib64/python3.7/site-packages/napalm/nxapi_plumbing/api_client.py", line 110, in _nxapi_command
    response = self._send_request(commands, method=method)
  File "/home/bradfernan/VENV/py3_venv/lib64/python3.7/site-packages/napalm/nxapi_plumbing/api_client.py", line 79, in _send_request
    raise NXAPIAuthError(msg)
napalm.nxapi_plumbing.errors.NXAPIAuthError: Authentication to NX-API failed please verify your username, password, and hostname.

During handling of the above exception, another exception occurred:

Traceback (most recent call last):
  File "/home/bradfernan/VENV/py3_venv/lib64/python3.7/site-packages/nornir/core/task.py", line 85, in start
    r = self.task(self, **self.params)
  File "/home/bradfernan/VENV/py3_venv/lib64/python3.7/site-packages/nornir/plugins/tasks/networking/napalm_get.py", line 49, in napalm_get
    device = task.host.get_connection("napalm", task.nornir.config)
  File "/home/bradfernan/VENV/py3_venv/lib64/python3.7/site-packages/nornir/core/inventory.py", line 302, in get_connection
    extras=conn.extras,
  File "/home/bradfernan/VENV/py3_venv/lib64/python3.7/site-packages/nornir/core/inventory.py", line 352, in open_connection
    configuration=configuration,
  File "/home/bradfernan/VENV/py3_venv/lib64/python3.7/site-packages/nornir/plugins/connections/napalm.py", line 51, in open
    connection.open()
  File "/home/bradfernan/VENV/py3_venv/lib64/python3.7/site-packages/napalm/nxos/nxos.py", line 701, in open
    raise ConnectionException("Cannot connect to {}".format(self.hostname))
napalm.base.exceptions.ConnectionException: Cannot connect to nxos1.lasthop.io

2021-02-05 21:42:10,088 - nornir.core.task -    ERROR -      start() - Host 'nxos2': task 'napalm_get' failed with traceback:
Traceback (most recent call last):
  File "/home/bradfernan/VENV/py3_venv/lib64/python3.7/site-packages/napalm/nxos/nxos.py", line 698, in open
    self._send_command("show hostname")
  File "/home/bradfernan/VENV/py3_venv/lib64/python3.7/site-packages/napalm/nxos/nxos.py", line 712, in _send_command
    return self.device.show(command, raw_text=raw_text)
  File "/home/bradfernan/VENV/py3_venv/lib64/python3.7/site-packages/napalm/nxapi_plumbing/device.py", line 67, in show
    result = self.show_list(commands, raw_text)
  File "/home/bradfernan/VENV/py3_venv/lib64/python3.7/site-packages/napalm/nxapi_plumbing/device.py", line 95, in show_list
    return self.api._nxapi_command(commands, method=cmd_method)
  File "/home/bradfernan/VENV/py3_venv/lib64/python3.7/site-packages/napalm/nxapi_plumbing/api_client.py", line 110, in _nxapi_command
    response = self._send_request(commands, method=method)
  File "/home/bradfernan/VENV/py3_venv/lib64/python3.7/site-packages/napalm/nxapi_plumbing/api_client.py", line 79, in _send_request
    raise NXAPIAuthError(msg)
napalm.nxapi_plumbing.errors.NXAPIAuthError: Authentication to NX-API failed please verify your username, password, and hostname.

During handling of the above exception, another exception occurred:

Traceback (most recent call last):
  File "/home/bradfernan/VENV/py3_venv/lib64/python3.7/site-packages/nornir/core/task.py", line 85, in start
    r = self.task(self, **self.params)
  File "/home/bradfernan/VENV/py3_venv/lib64/python3.7/site-packages/nornir/plugins/tasks/networking/napalm_get.py", line 49, in napalm_get
    device = task.host.get_connection("napalm", task.nornir.config)
  File "/home/bradfernan/VENV/py3_venv/lib64/python3.7/site-packages/nornir/core/inventory.py", line 302, in get_connection
    extras=conn.extras,
  File "/home/bradfernan/VENV/py3_venv/lib64/python3.7/site-packages/nornir/core/inventory.py", line 352, in open_connection
    configuration=configuration,
  File "/home/bradfernan/VENV/py3_venv/lib64/python3.7/site-packages/nornir/plugins/connections/napalm.py", line 51, in open
    connection.open()
  File "/home/bradfernan/VENV/py3_venv/lib64/python3.7/site-packages/napalm/nxos/nxos.py", line 701, in open
    raise ConnectionException("Cannot connect to {}".format(self.hostname))
napalm.base.exceptions.ConnectionException: Cannot connect to nxos2.lasthop.io

2021-02-05 21:44:43,107 -  nornir.core -     INFO -        run() - Running task 'napalm_get' with args {'getters': ['facts']} on 2 hosts
2021-02-05 22:07:45,891 -  nornir.core -     INFO -        run() - Running task 'napalm_get' with args {'getters': ['facts']} on 2 hosts
