2021-01-26 22:36:52,645 -  nornir.core -     INFO -        run() - Running task 'render_config' with args {} on 1 hosts
2021-01-26 22:36:52,646 - nornir.core.task -    ERROR -      start() - Host 'nxos1': task 'render_config' failed with traceback:
Traceback (most recent call last):
  File "/home/bradfernan/VENV/py3_venv/lib64/python3.7/site-packages/nornir/core/task.py", line 85, in start
    r = self.task(self, **self.params)
  File "exercise2a.py", line 9, in render_config
    rendered_data = task.run(task=template_file,
NameError: name 'template_file' is not defined

2021-01-26 22:37:44,209 -  nornir.core -     INFO -        run() - Running task 'render_config' with args {} on 1 hosts
2021-01-26 22:37:44,210 - nornir.core.task -    ERROR -      start() - Host 'nxos1': task 'render_config' failed with traceback:
Traceback (most recent call last):
  File "/home/bradfernan/VENV/py3_venv/lib64/python3.7/site-packages/nornir/core/task.py", line 85, in start
    r = self.task(self, **self.params)
  File "exercise2a.py", line 9, in render_config
    rendered_data = task.run(task=template_file,
NameError: name 'template_file' is not defined

2021-01-26 22:39:04,769 -  nornir.core -     INFO -        run() - Running task 'render_config' with args {} on 1 hosts
2021-01-26 22:39:04,770 - nornir.core.task -    ERROR -      start() - Host 'nxos1': task 'render_config' failed with traceback:
Traceback (most recent call last):
  File "/home/bradfernan/VENV/py3_venv/lib64/python3.7/site-packages/nornir/core/task.py", line 85, in start
    r = self.task(self, **self.params)
  File "exercise2a.py", line 9, in render_config
    rendered_data = task.run(task=template_file,
NameError: name 'template_file' is not defined

2021-01-26 22:40:09,176 -  nornir.core -     INFO -        run() - Running task 'render_config' with args {} on 1 hosts
2021-01-26 22:40:09,177 - nornir.core.task -    ERROR -      start() - Host 'nxos1': task 'render_config' failed with traceback:
Traceback (most recent call last):
  File "/home/bradfernan/VENV/py3_venv/lib64/python3.7/site-packages/nornir/core/task.py", line 85, in start
    r = self.task(self, **self.params)
  File "exercise2a.py", line 9, in render_config
    rendered_data = task.run(task=template_file,
NameError: name 'template_file' is not defined

2021-01-26 22:41:14,230 -  nornir.core -     INFO -        run() - Running task 'render_config' with args {} on 1 hosts
2021-01-26 22:43:25,992 - nornir.core.task -    ERROR -      start() - Host 'nxos1': task 'render_config' failed with traceback:
Traceback (most recent call last):
  File "/home/bradfernan/VENV/py3_venv/lib64/python3.7/site-packages/nornir/core/task.py", line 85, in start
    r = self.task(self, **self.params)
  File "exercise2a.py", line 13, in render_config
    ipdb.set_trace()
  File "/usr/lib64/python3.7/bdb.py", line 92, in trace_dispatch
    return self.dispatch_return(frame, arg)
  File "/usr/lib64/python3.7/bdb.py", line 154, in dispatch_return
    if self.quitting: raise BdbQuit
bdb.BdbQuit

2021-01-26 22:44:44,121 -  nornir.core -     INFO -        run() - Running task 'render_config' with args {} on 1 hosts
2021-01-26 22:48:34,787 - nornir.core.task -    ERROR -      start() - Host 'nxos1': task 'render_config' failed with traceback:
Traceback (most recent call last):
  File "/home/bradfernan/VENV/py3_venv/lib64/python3.7/site-packages/nornir/core/task.py", line 85, in start
    r = self.task(self, **self.params)
  File "exercise2a.py", line 13, in render_config
    ipdb.set_trace()
  File "/usr/lib64/python3.7/bdb.py", line 92, in trace_dispatch
    return self.dispatch_return(frame, arg)
  File "/usr/lib64/python3.7/bdb.py", line 154, in dispatch_return
    if self.quitting: raise BdbQuit
bdb.BdbQuit

2021-01-26 22:50:03,874 -  nornir.core -     INFO -        run() - Running task 'render_config' with args {} on 1 hosts
2021-01-26 23:17:39,224 - nornir.core.task -    ERROR -      start() - Host 'nxos1': task 'render_config' failed with traceback:
Traceback (most recent call last):
  File "/home/bradfernan/VENV/py3_venv/lib64/python3.7/site-packages/nornir/core/task.py", line 85, in start
    r = self.task(self, **self.params)
  File "exercise2a.py", line 13, in render_config
    ipdb.set_trace()
  File "/usr/lib64/python3.7/bdb.py", line 92, in trace_dispatch
    return self.dispatch_return(frame, arg)
  File "/usr/lib64/python3.7/bdb.py", line 154, in dispatch_return
    if self.quitting: raise BdbQuit
bdb.BdbQuit

2021-01-26 23:29:17,087 -  nornir.core -     INFO -        run() - Running task 'render_config' with args {} on 1 hosts
2021-01-26 23:29:46,034 -  nornir.core -     INFO -        run() - Running task 'render_config' with args {} on 1 hosts
2021-01-26 23:34:36,342 -  nornir.core -     INFO -        run() - Running task 'render_config' with args {} on 2 hosts
2021-01-26 23:36:54,608 -  nornir.core -     INFO -        run() - Running task 'render_config' with args {} on 2 hosts
2021-01-26 23:37:09,375 -  nornir.core -     INFO -        run() - Running task 'render_config' with args {} on 2 hosts
2021-01-26 23:38:51,945 -  nornir.core -     INFO -        run() - Running task 'render_config' with args {} on 1 hosts
2021-01-26 23:39:17,715 - nornir.core.task -    ERROR -      start() - Host 'nxos1': task 'render_config' failed with traceback:
Traceback (most recent call last):
  File "/home/bradfernan/VENV/py3_venv/lib64/python3.7/site-packages/nornir/core/task.py", line 85, in start
    r = self.task(self, **self.params)
  File "exercise2a.py", line 15, in render_config
    print_result(rendered_data[0].result)
  File "exercise2a.py", line 15, in render_config
    print_result(rendered_data[0].result)
  File "/usr/lib64/python3.7/bdb.py", line 88, in trace_dispatch
    return self.dispatch_line(frame)
  File "/usr/lib64/python3.7/bdb.py", line 113, in dispatch_line
    if self.quitting: raise BdbQuit
bdb.BdbQuit

2021-01-26 23:39:36,150 -  nornir.core -     INFO -        run() - Running task 'render_config' with args {} on 1 hosts
2021-01-26 23:40:35,826 -  nornir.core -     INFO -        run() - Running task 'render_config' with args {} on 1 hosts
2021-01-26 23:41:00,786 -  nornir.core -     INFO -        run() - Running task 'render_config' with args {} on 1 hosts
2021-01-26 23:42:38,174 -  nornir.core -     INFO -        run() - Running task 'render_config' with args {} on 1 hosts
2021-01-26 23:43:05,718 -  nornir.core -     INFO -        run() - Running task 'render_config' with args {} on 2 hosts
2021-01-27 08:10:23,856 -  nornir.core -     INFO -        run() - Running task 'render_config' with args {} on 2 hosts
2021-01-27 08:10:23,868 - nornir.core.task -    ERROR -      start() - Host 'nxos2': task 'template_file' failed with traceback:
Traceback (most recent call last):
  File "/home/bradfernan/VENV/py3_venv/lib64/python3.7/site-packages/nornir/core/task.py", line 85, in start
    r = self.task(self, **self.params)
  File "/home/bradfernan/VENV/py3_venv/lib64/python3.7/site-packages/nornir/plugins/tasks/text/template_file.py", line 35, in template_file
    **kwargs
  File "/home/bradfernan/VENV/py3_venv/lib64/python3.7/site-packages/nornir/core/helpers/jinja_helper.py", line 18, in render_from_file
    return t.render(**kwargs)
  File "/home/bradfernan/VENV/py3_venv/lib64/python3.7/site-packages/jinja2/environment.py", line 1090, in render
    self.environment.handle_exception()
  File "/home/bradfernan/VENV/py3_venv/lib64/python3.7/site-packages/jinja2/environment.py", line 832, in handle_exception
    reraise(*rewrite_traceback_stack(source=source))
  File "/home/bradfernan/VENV/py3_venv/lib64/python3.7/site-packages/jinja2/_compat.py", line 28, in reraise
    raise value.with_traceback(tb)
  File "./loopback_int.j2", line 1, in top-level template code
    {%- for data in loopbacks %}
jinja2.exceptions.UndefinedError: 'loopbacks' is undefined

2021-01-27 08:10:23,868 - nornir.core.task -    ERROR -      start() - Host 'nxos2': task 'render_config' failed with traceback:
Traceback (most recent call last):
  File "/home/bradfernan/VENV/py3_venv/lib64/python3.7/site-packages/nornir/core/task.py", line 85, in start
    r = self.task(self, **self.params)
  File "exercise2a.py", line 13, in render_config
    **task.host)
  File "/home/bradfernan/VENV/py3_venv/lib64/python3.7/site-packages/nornir/core/task.py", line 147, in run
    raise NornirSubTaskError(task=task, result=r)
nornir.core.exceptions.NornirSubTaskError: Subtask: <function template_file at 0x7f68be77d290> (failed)


2021-01-27 08:20:05,319 -  nornir.core -     INFO -        run() - Running task 'render_config' with args {} on 2 hosts
2021-01-27 08:20:05,327 - nornir.core.task -    ERROR -      start() - Host 'nxos2': task 'template_file' failed with traceback:
Traceback (most recent call last):
  File "/home/bradfernan/VENV/py3_venv/lib64/python3.7/site-packages/nornir/core/task.py", line 85, in start
    r = self.task(self, **self.params)
  File "/home/bradfernan/VENV/py3_venv/lib64/python3.7/site-packages/nornir/plugins/tasks/text/template_file.py", line 35, in template_file
    **kwargs
  File "/home/bradfernan/VENV/py3_venv/lib64/python3.7/site-packages/nornir/core/helpers/jinja_helper.py", line 18, in render_from_file
    return t.render(**kwargs)
  File "/home/bradfernan/VENV/py3_venv/lib64/python3.7/site-packages/jinja2/environment.py", line 1090, in render
    self.environment.handle_exception()
  File "/home/bradfernan/VENV/py3_venv/lib64/python3.7/site-packages/jinja2/environment.py", line 832, in handle_exception
    reraise(*rewrite_traceback_stack(source=source))
  File "/home/bradfernan/VENV/py3_venv/lib64/python3.7/site-packages/jinja2/_compat.py", line 28, in reraise
    raise value.with_traceback(tb)
  File "./loopback_int.j2", line 1, in top-level template code
    {%- for data in loopbacks %}
jinja2.exceptions.UndefinedError: 'loopbacks' is undefined

2021-01-27 08:20:05,328 - nornir.core.task -    ERROR -      start() - Host 'nxos2': task 'render_config' failed with traceback:
Traceback (most recent call last):
  File "/home/bradfernan/VENV/py3_venv/lib64/python3.7/site-packages/nornir/core/task.py", line 85, in start
    r = self.task(self, **self.params)
  File "exercise2a.py", line 10, in render_config
    task=text.template_file, path=".", template=template, **task.host)
  File "/home/bradfernan/VENV/py3_venv/lib64/python3.7/site-packages/nornir/core/task.py", line 147, in run
    raise NornirSubTaskError(task=task, result=r)
nornir.core.exceptions.NornirSubTaskError: Subtask: <function template_file at 0x7fb2fe4c2e60> (failed)


2021-01-27 08:20:22,563 -  nornir.core -     INFO -        run() - Running task 'render_config' with args {} on 2 hosts
2021-01-27 08:30:42,470 -  nornir.core -     INFO -        run() - Running task 'render_config' with args {} on 2 hosts
2021-01-27 08:30:42,478 - nornir.core.task -    ERROR -      start() - Host 'nxos2': task 'template_file' failed with traceback:
Traceback (most recent call last):
  File "/home/bradfernan/VENV/py3_venv/lib64/python3.7/site-packages/nornir/core/task.py", line 85, in start
    r = self.task(self, **self.params)
  File "/home/bradfernan/VENV/py3_venv/lib64/python3.7/site-packages/nornir/plugins/tasks/text/template_file.py", line 35, in template_file
    **kwargs
  File "/home/bradfernan/VENV/py3_venv/lib64/python3.7/site-packages/nornir/core/helpers/jinja_helper.py", line 18, in render_from_file
    return t.render(**kwargs)
  File "/home/bradfernan/VENV/py3_venv/lib64/python3.7/site-packages/jinja2/environment.py", line 1090, in render
    self.environment.handle_exception()
  File "/home/bradfernan/VENV/py3_venv/lib64/python3.7/site-packages/jinja2/environment.py", line 832, in handle_exception
    reraise(*rewrite_traceback_stack(source=source))
  File "/home/bradfernan/VENV/py3_venv/lib64/python3.7/site-packages/jinja2/_compat.py", line 28, in reraise
    raise value.with_traceback(tb)
  File "./loopback_int.j2", line 1, in top-level template code
    {%- for data in loopbacks %}
jinja2.exceptions.UndefinedError: 'loopbacks' is undefined

2021-01-27 08:30:42,478 - nornir.core.task -    ERROR -      start() - Host 'nxos2': task 'render_config' failed with traceback:
Traceback (most recent call last):
  File "exercise2b.py", line 11, in render_config
    task=text.template_file, path=".", template=template, **task.host)
  File "/home/bradfernan/VENV/py3_venv/lib64/python3.7/site-packages/nornir/core/task.py", line 147, in run
    raise NornirSubTaskError(task=task, result=r)
nornir.core.exceptions.NornirSubTaskError: Subtask: <function template_file at 0x7f8f9471f050> (failed)


During handling of the above exception, another exception occurred:

Traceback (most recent call last):
  File "/home/bradfernan/VENV/py3_venv/lib64/python3.7/site-packages/nornir/core/task.py", line 85, in start
    r = self.task(self, **self.params)
  File "exercise2b.py", line 12, in render_config
    except NornirSubTask:
NameError: name 'NornirSubTask' is not defined

2021-01-27 08:34:13,263 -  nornir.core -     INFO -        run() - Running task 'render_config' with args {} on 2 hosts
2021-01-27 08:34:13,272 - nornir.core.task -    ERROR -      start() - Host 'nxos2': task 'template_file' failed with traceback:
Traceback (most recent call last):
  File "/home/bradfernan/VENV/py3_venv/lib64/python3.7/site-packages/nornir/core/task.py", line 85, in start
    r = self.task(self, **self.params)
  File "/home/bradfernan/VENV/py3_venv/lib64/python3.7/site-packages/nornir/plugins/tasks/text/template_file.py", line 35, in template_file
    **kwargs
  File "/home/bradfernan/VENV/py3_venv/lib64/python3.7/site-packages/nornir/core/helpers/jinja_helper.py", line 18, in render_from_file
    return t.render(**kwargs)
  File "/home/bradfernan/VENV/py3_venv/lib64/python3.7/site-packages/jinja2/environment.py", line 1090, in render
    self.environment.handle_exception()
  File "/home/bradfernan/VENV/py3_venv/lib64/python3.7/site-packages/jinja2/environment.py", line 832, in handle_exception
    reraise(*rewrite_traceback_stack(source=source))
  File "/home/bradfernan/VENV/py3_venv/lib64/python3.7/site-packages/jinja2/_compat.py", line 28, in reraise
    raise value.with_traceback(tb)
  File "./loopback_int.j2", line 1, in top-level template code
    {%- for data in loopbacks %}
jinja2.exceptions.UndefinedError: 'loopbacks' is undefined

2021-01-27 08:34:13,272 - nornir.core.task -    ERROR -      start() - Host 'nxos2': task 'render_config' failed with traceback:
Traceback (most recent call last):
  File "exercise2b.py", line 11, in render_config
    task=text.template_file, path=".", template=template, **task.host)
  File "/home/bradfernan/VENV/py3_venv/lib64/python3.7/site-packages/nornir/core/task.py", line 147, in run
    raise NornirSubTaskError(task=task, result=r)
nornir.core.exceptions.NornirSubTaskError: Subtask: <function template_file at 0x7fd5fd452b00> (failed)


During handling of the above exception, another exception occurred:

Traceback (most recent call last):
  File "/home/bradfernan/VENV/py3_venv/lib64/python3.7/site-packages/nornir/core/task.py", line 85, in start
    r = self.task(self, **self.params)
  File "exercise2b.py", line 12, in render_config
    except NornirSubTaskError:
NameError: name 'NornirSubTaskError' is not defined

2021-01-27 08:37:53,994 -  nornir.core -     INFO -        run() - Running task 'render_config' with args {} on 2 hosts
2021-01-27 08:37:54,002 - nornir.core.task -    ERROR -      start() - Host 'nxos2': task 'template_file' failed with traceback:
Traceback (most recent call last):
  File "/home/bradfernan/VENV/py3_venv/lib64/python3.7/site-packages/nornir/core/task.py", line 85, in start
    r = self.task(self, **self.params)
  File "/home/bradfernan/VENV/py3_venv/lib64/python3.7/site-packages/nornir/plugins/tasks/text/template_file.py", line 35, in template_file
    **kwargs
  File "/home/bradfernan/VENV/py3_venv/lib64/python3.7/site-packages/nornir/core/helpers/jinja_helper.py", line 18, in render_from_file
    return t.render(**kwargs)
  File "/home/bradfernan/VENV/py3_venv/lib64/python3.7/site-packages/jinja2/environment.py", line 1090, in render
    self.environment.handle_exception()
  File "/home/bradfernan/VENV/py3_venv/lib64/python3.7/site-packages/jinja2/environment.py", line 832, in handle_exception
    reraise(*rewrite_traceback_stack(source=source))
  File "/home/bradfernan/VENV/py3_venv/lib64/python3.7/site-packages/jinja2/_compat.py", line 28, in reraise
    raise value.with_traceback(tb)
  File "./loopback_int.j2", line 1, in top-level template code
    {%- for data in loopbacks %}
jinja2.exceptions.UndefinedError: 'loopbacks' is undefined

2021-01-27 08:43:33,825 -  nornir.core -     INFO -        run() - Running task 'render_config' with args {} on 2 hosts
2021-01-27 08:43:33,833 - nornir.core.task -    ERROR -      start() - Host 'nxos2': task 'template_file' failed with traceback:
Traceback (most recent call last):
  File "/home/bradfernan/VENV/py3_venv/lib64/python3.7/site-packages/nornir/core/task.py", line 85, in start
    r = self.task(self, **self.params)
  File "/home/bradfernan/VENV/py3_venv/lib64/python3.7/site-packages/nornir/plugins/tasks/text/template_file.py", line 35, in template_file
    **kwargs
  File "/home/bradfernan/VENV/py3_venv/lib64/python3.7/site-packages/nornir/core/helpers/jinja_helper.py", line 18, in render_from_file
    return t.render(**kwargs)
  File "/home/bradfernan/VENV/py3_venv/lib64/python3.7/site-packages/jinja2/environment.py", line 1090, in render
    self.environment.handle_exception()
  File "/home/bradfernan/VENV/py3_venv/lib64/python3.7/site-packages/jinja2/environment.py", line 832, in handle_exception
    reraise(*rewrite_traceback_stack(source=source))
  File "/home/bradfernan/VENV/py3_venv/lib64/python3.7/site-packages/jinja2/_compat.py", line 28, in reraise
    raise value.with_traceback(tb)
  File "./loopback_int.j2", line 1, in top-level template code
    {%- for data in loopbacks %}
jinja2.exceptions.UndefinedError: 'loopbacks' is undefined

2021-01-27 08:46:21,265 -  nornir.core -     INFO -        run() - Running task 'render_config' with args {} on 2 hosts
2021-01-27 08:46:21,274 - nornir.core.task -    ERROR -      start() - Host 'nxos2': task 'template_file' failed with traceback:
Traceback (most recent call last):
  File "/home/bradfernan/VENV/py3_venv/lib64/python3.7/site-packages/nornir/core/task.py", line 85, in start
    r = self.task(self, **self.params)
  File "/home/bradfernan/VENV/py3_venv/lib64/python3.7/site-packages/nornir/plugins/tasks/text/template_file.py", line 35, in template_file
    **kwargs
  File "/home/bradfernan/VENV/py3_venv/lib64/python3.7/site-packages/nornir/core/helpers/jinja_helper.py", line 18, in render_from_file
    return t.render(**kwargs)
  File "/home/bradfernan/VENV/py3_venv/lib64/python3.7/site-packages/jinja2/environment.py", line 1090, in render
    self.environment.handle_exception()
  File "/home/bradfernan/VENV/py3_venv/lib64/python3.7/site-packages/jinja2/environment.py", line 832, in handle_exception
    reraise(*rewrite_traceback_stack(source=source))
  File "/home/bradfernan/VENV/py3_venv/lib64/python3.7/site-packages/jinja2/_compat.py", line 28, in reraise
    raise value.with_traceback(tb)
  File "./loopback_int.j2", line 1, in top-level template code
    {%- for data in loopbacks %}
jinja2.exceptions.UndefinedError: 'loopbacks' is undefined

